Workbook

Sheet Summary
A1: Northline freight bill audit, September 2026 freight bills, Halvorsen Building Products
A2: Prepared for Ingrid Solheim, controller; report prepared October 16, 2026
A3: Agreement NFL-2026-HBP; Northline freight bills dated in September 2026
A5: Finding | B5: Value | C5: Read from
A6: Freight bills in the file | B6: =COUNTA(Invoices!A4:A26,Invoices!P4:P26) -> 46 | C6: Invoices
A7: Total billed by Northline | B7: =ROUND(SUM(Invoices!O4:O26,Invoices!AD4:AD26),2) -> 24281.01 | C7: Invoices
A8: Total due under the contract | B8: =Audit!B28 -> 22823.31 | C8: Audit
A9: Net difference, billed less due | B9: =ROUND(B7-B8,2) -> 1457.7 | C9: Summary
A10: Overcharges claimed | B10: ='Claim Schedule'!E16 -> 1534.88 | C10: Claim Schedule
A11: Undercharges reported, not netted | B11: =Undercharges!E7 -> 77.18 | C11: Undercharges
A12: Overcharges as a share of billings | B12: =ROUND(B10/B7,4) -> 0.0632 | C12: Summary
A13: Freight bills claimed | B13: =COUNTA('Claim Schedule'!B4:B15) -> 12 | C13: Claim Schedule
A14: Freight bills underbilled | B14: =COUNTA(Undercharges!B4:B6) -> 3 | C14: Undercharges
A15: Freight bills with an exception | B15: =COUNTA(Exceptions!A4:A18) -> 15 | C15: Exceptions
A16: Freight bills billed as the contract provides | B16: =B6-B15 -> 31 | C16: Summary
A17: Billed items accepted on a document or a written confirmation | B17: =Audit!B30 -> 5 | C17: Audit
A18: Freight bills rated under a corrected pro number | B18: =COUNTA('Pro Matches'!A4:A4) -> 1 | C18: Pro Matches
A19: Exceptions by contract term
A20: Duplicate freight bills (7.1) | B20: =COUNTIF(Exceptions!C4:C18,"7.1*") -> 2 | C20: Exceptions
A21: Class not the product group class (4.3) | B21: =COUNTIF(Exceptions!C4:C18,"4.3*") -> 1 | C21: Exceptions
A22: Reweigh that does not hold (4.5) | B22: =COUNTIF(Exceptions!C4:C18,"4.5*") -> 2 | C22: Exceptions
A23: Deficit weight rule not applied (4.2) | B23: =COUNTIF(Exceptions!C4:C18,"4.2*") -> 2 | C23: Exceptions
A24: Fuel surcharge on the wrong week (5.2) | B24: =COUNTIF(Exceptions!C4:C18,"5.2*") -> 4 | C24: Exceptions
A25: Accessorial overbilled or omitted (6.1) | B25: =COUNTIF(Exceptions!C4:C18,"6.1*") -> 4 | C25: Exceptions
A26: Overcharges claimed by contract term
A27: Claimed under section 7.1, duplicate freight bills | B27: =ROUND(SUMIF('Claim Schedule'!F4:F15,"7.1",'Claim Schedule'!E4:E15),2) -> 1051.33 | C27: Claim Schedule
A28: Claimed under section 4.2, deficit weight | B28: =ROUND(SUMIF('Claim Schedule'!F4:F15,"4.2",'Claim Schedule'!E4:E15),2) -> 162.52 | C28: Claim Schedule
A29: Claimed under section 4.3, class | B29: =ROUND(SUMIF('Claim Schedule'!F4:F15,"4.3",'Claim Schedule'!E4:E15),2) -> 46.25 | C29: Claim Schedule
A30: Claimed under section 4.5, reweigh | B30: =ROUND(SUMIF('Claim Schedule'!F4:F15,"4.5",'Claim Schedule'!E4:E15),2) -> 96.29 | C30: Claim Schedule
A31: Claimed under section 5.2, fuel week | B31: =ROUND(SUMIF('Claim Schedule'!F4:F15,"5.2",'Claim Schedule'!E4:E15),2) -> 5.49 | C31: Claim Schedule
A32: Claimed under section 6.1, accessorial overbilled | B32: =ROUND(SUMIF('Claim Schedule'!F4:F15,"6.1",'Claim Schedule'!E4:E15),2) -> 173 | C32: Claim Schedule
A33: Largest single exception
A34: Largest overcharge on one freight bill | B34: =MAX('Claim Schedule'!E4:E15) -> 603.63 | C34: Claim Schedule
A35: Freight bill carrying it | B35: =INDEX('Claim Schedule'!B4:B15,MATCH(B34,'Claim Schedule'!E4:E15,0)) -> NFL-90360 | C35: Claim Schedule
A38: Every value on this page reads from the tab named beside it; the Audit tab rates each freight bill from the BOL, Invoices, Tariff, Fuel Index, Billing File, Confirmations and Pro Matches tabs, which copy the files in the folder or record the audit's reading of them.

Sheet Terms
A1: Contract terms the audit applies, agreement NFL-2026-HBP
A3: Term | B3: Value | C3: Section
A4: Discount off the class-rated linehaul | B4: 0.62 | C4: 4.4
A5: Minimum charge, net of discount ($) | B5: 118.4 | C5: 4.4
A6: Reweigh tolerance over declared weight | B6: 0.05 | C6: 4.5
A7: Overcharge claim window (days from bill date) | B7: 180 | C7: 7.2
A8: Carrier balance-due window on undercharges (days) | B8: 90 | C8: 7.3
A9: Percent divisor for the billed surcharge column | B9: 100 | C9: Invoice file, FSC_PCT in percent
A10: Fuel percentage where the bulletin and the table disagree | B10: table governs | C10: 5.3
A12: Rating method. The linehaul is the class 70 lane rate for the destination state at the shipment's weight break, times the class factor for the contract class, at the contract weight. The contract weight is the bill of lading weight, and the billed weight stands only on a certified scale ticket more than five percent over the declared weight; a reweigh with no certified ticket, or inside the tolerance, reverts to the bill of lading weight. The contract class is the product group class, and a billed class stands only on a signed inspection certificate in the billing file. The gross charge is the lesser of the own-break figure and the next break's minimum weight at the next break's rate. The net linehaul is the gross less the discount, rounded to the cent, with the minimum charge as a floor. The fuel surcharge is the net linehaul times the percentage the tariff table gives for the DOE index in force on the pickup date, rounded to the cent; where the bulletin disagrees with the table, the table governs. Accessorials are added at the Exhibit B flat rate where the bill of lading requests the service or the shipping desk confirmed it in writing before delivery, a redelivery included. A freight bill whose pro number matches no bill of lading is rated against the bill of lading its ship date, state, weight and class identify, under a corrected pro number. A second bill on a pro already billed is due at zero under section 7.1. Undercharges are reported and not netted under section 7.3.

Sheet Tariff
A1: Exhibit B tariff tables, copied from northline_contract_rates_2026.xlsx
A3: DEST_STATE | B3: L5C | C3: 5C | D3: 1M | E3: 2M | F3: 5M | H3: NMFC_CLASS | I3: FACTOR | K3: PRODUCT_GROUP | L3: NMFC_CLASS | M3: SERVICE | N3: BOL_FLAG | O3: CHARGE | Q3: PRICE_AT_LEAST | R3: FSC_PCT
A4: MN | B4: 58.4 | C4: 49.1 | D4: 41.75 | E4: 34.2 | F4: 27.85 | H4: 50 | I4: 0.8 | K4: Gypsum and cement board | L4: 55 | M4: Liftgate delivery | N4: LIFTGATE | O4: 75 | Q4: 3 | R4: 0.195
A5: SD | B5: 61.2 | C5: 51.65 | D5: 43.9 | E5: 36.05 | F5: 29.4 | H5: 55 | I5: 0.88 | K5: Fasteners and hardware | L5: 60 | M5: Residential delivery | N5: RESIDENTIAL | O5: 95 | Q5: 3.1 | R5: 0.205
A6: MT | B6: 84.7 | C6: 71.3 | D6: 60.85 | E6: 49.95 | F6: 40.6 | H6: 60 | I6: 0.94 | K6: Metal roofing panels | L6: 70 | M6: Limited access delivery | N6: LIMITED_ACCESS | O6: 85 | Q6: 3.2 | R6: 0.215
A7: IA | B7: 66.35 | C7: 55.9 | D7: 47.6 | E7: 39.1 | F7: 31.85 | H7: 70 | I7: 1 | K7: Sealants and coatings | L7: 85 | M7: Inside delivery | N7: INSIDE_DELIVERY | O7: 60 | Q7: 3.3 | R7: 0.225
A8: WI | B8: 70.15 | C8: 59.05 | D8: 50.3 | E8: 41.3 | F8: 33.65 | H8: 85 | I8: 1.15 | K8: Vinyl siding | L8: 92.5 | M8: Redelivery | N8: None | O8: 88 | Q8: 3.4 | R8: 0.235
A9: NE | B9: 69.4 | C9: 58.45 | D9: 49.8 | E9: 40.9 | F9: 33.3 | H9: 92.5 | I9: 1.3 | K9: Windows and doors | L9: 100 | M9: Reconsignment | N9: None | O9: 110 | Q9: 3.5 | R9: 0.245
A10: ND | B10: 44.9 | C10: 37.8 | D10: 32.15 | E10: 26.4 | F10: 21.5 | H10: 100 | I10: 1.45 | Q10: 3.55 | R10: 0.25
Q11: 3.6 | R11: 0.255
A12: Minimum weight (lb) | B12: 1 | C12: 500 | D12: 1000 | E12: 2000 | F12: 5000 | Q12: 3.65 | R12: 0.26
Q13: 3.7 | R13: 0.265
Q14: 3.75 | R14: 0.27
Q15: 3.8 | R15: 0.275
Q16: 3.85 | R16: 0.28
Q17: 3.9 | R17: 0.285
Q18: 3.95 | R18: 0.29
Q19: 4 | R19: 0.295
Q20: 4.1 | R20: 0.305
Q21: 4.2 | R21: 0.315

Sheet Fuel Index
A1: DOE index by week from the September bulletin, the surcharge percentage the tariff table gives it, and the percentage the bulletin printed
A3: INDEX_MONDAY | B3: DOE_PRICE | C3: FSC_PCT | D3: BULLETIN_PCT
A4: 08/03/2026 | B4: 3.618 | C4: =VLOOKUP(B4,Tariff!$Q$4:$R$21,2,TRUE) -> 0.255 | D4: 0.255
A5: 08/10/2026 | B5: 3.641 | C5: =VLOOKUP(B5,Tariff!$Q$4:$R$21,2,TRUE) -> 0.255 | D5: 0.255
A6: 08/17/2026 | B6: 3.677 | C6: =VLOOKUP(B6,Tariff!$Q$4:$R$21,2,TRUE) -> 0.26 | D6: 0.26
A7: 08/24/2026 | B7: 3.664 | C7: =VLOOKUP(B7,Tariff!$Q$4:$R$21,2,TRUE) -> 0.26 | D7: 0.26
A8: 08/31/2026 | B8: 3.712 | C8: =VLOOKUP(B8,Tariff!$Q$4:$R$21,2,TRUE) -> 0.265 | D8: 0.265
A9: 09/07/2026 | B9: 3.748 | C9: =VLOOKUP(B9,Tariff!$Q$4:$R$21,2,TRUE) -> 0.265 | D9: 0.265
A10: 09/14/2026 | B10: 3.691 | C10: =VLOOKUP(B10,Tariff!$Q$4:$R$21,2,TRUE) -> 0.26 | D10: 0.26
A11: 09/21/2026 | B11: 3.803 | C11: =VLOOKUP(B11,Tariff!$Q$4:$R$21,2,TRUE) -> 0.275 | D11: 0.27
A12: 09/28/2026 | B12: 3.779 | C12: =VLOOKUP(B12,Tariff!$Q$4:$R$21,2,TRUE) -> 0.27 | D12: 0.27
A14: FSC_PCT reads the tariff table at each week's DOE price and is the percentage the audit applies; BULLETIN_PCT is the figure printed in the bulletin, which is informational under section 5.3. The August weeks govern the two late-August pickups billed in September.

Sheet BOL
A1: Bills of lading, bills_of_lading_sept_2026.csv, copied line for line in the file's two side-by-side panels
A3: BOL_NO | B3: PRO_NO | C3: PICKUP_DATE | D3: CONSIGNEE_CITY | E3: DEST_STATE | F3: PRODUCT_GROUP | G3: PIECES | H3: WEIGHT_LB | I3: LIFTGATE | J3: RESIDENTIAL | K3: LIMITED_ACCESS | L3: INSIDE_DELIVERY | M3: DELIVERED_DATE | N3: BOL_NO_2 | O3: PRO_NO_2 | P3: PICKUP_DATE_2 | Q3: CONSIGNEE_CITY_2 | R3: DEST_STATE_2 | S3: PRODUCT_GROUP_2 | T3: PIECES_2 | U3: WEIGHT_LB_2 | V3: LIFTGATE_2 | W3: RESIDENTIAL_2 | X3: LIMITED_ACCESS_2 | Y3: INSIDE_DELIVERY_2 | Z3: DELIVERED_DATE_2
A4: HBP-44790 | B4: 217598 | C4: 08/27/2026 | D4: Hudson | E4: WI | F4: Metal roofing panels | G4: 9 | H4: 3150 | I4: N | J4: N | K4: N | L4: N | M4: 08/31/2026 | N4: HBP-44826 | O4: 217666 | P4: 09/18/2026 | Q4: Hudson | R4: WI | S4: Gypsum and cement board | T4: 2 | U4: 905 | V4: N | W4: N | X4: N | Y4: N | Z4: 09/21/2026
A5: HBP-44802 | B5: 217611 | C5: 08/28/2026 | D5: Aberdeen | E5: SD | F5: Gypsum and cement board | G5: 3 | H5: 1180 | I5: N | J5: N | K5: N | L5: N | M5: 09/01/2026 | N5: HBP-44853 | O5: 217724 | P5: 09/18/2026 | Q5: Bismarck | R5: ND | S5: Gypsum and cement board | T5: 8 | U5: 1450 | V5: N | W5: Y | X5: N | Y5: Y | Z5: 09/22/2026
A6: HBP-44817 | B6: 217645 | C6: 09/01/2026 | D6: Superior | E6: WI | F6: Metal roofing panels | G6: 2 | H6: 1240 | I6: N | J6: N | K6: Y | L6: N | M6: 09/04/2026 | N6: HBP-44896 | O6: 217833 | P6: 09/18/2026 | Q6: Fergus Falls | R6: MN | S6: Vinyl siding | T6: 2 | U6: 950 | V6: Y | W6: Y | X6: N | Y6: N | Z6: 09/21/2026
A7: HBP-44868 | B7: 217763 | C7: 09/01/2026 | D7: Sioux City | E7: IA | F7: Fasteners and hardware | G7: 7 | H7: 1620 | I7: Y | J7: N | K7: N | L7: N | M7: 09/04/2026 | N7: HBP-44918 | O7: 217883 | P7: 09/18/2026 | Q7: Eau Claire | R7: WI | S7: Windows and doors | T7: 3 | U7: 1010 | V7: N | W7: Y | X7: N | Y7: N | Z7: 09/21/2026
A8: HBP-44843 | B8: 217703 | C8: 09/03/2026 | D8: Moorhead | E8: MN | F8: Sealants and coatings | G8: 4 | H8: 720 | I8: Y | J8: N | K8: Y | L8: N | M8: 09/07/2026 | N8: HBP-44906 | O8: 217851 | P8: 09/21/2026 | Q8: Alexandria | R8: MN | S8: Sealants and coatings | T8: 11 | U8: 4470 | V8: N | W8: N | X8: N | Y8: N | Z8: 09/25/2026
A9: HBP-44895 | B9: 217822 | C9: 09/07/2026 | D9: Hudson | E9: WI | F9: Metal roofing panels | G9: 8 | H9: 4210 | I9: Y | J9: N | K9: N | L9: N | M9: 09/09/2026 | N9: HBP-44913 | O9: 217864 | P9: 09/21/2026 | Q9: Glendive | R9: MT | S9: Metal roofing panels | T9: 2 | U9: 1220 | V9: N | W9: N | X9: N | Y9: N | Z9: 09/23/2026
A10: HBP-44832 | B10: 217675 | C10: 09/08/2026 | D10: Miles City | E10: MT | F10: Fasteners and hardware | G10: 3 | H10: 1760 | I10: N | J10: N | K10: N | L10: N | M10: 09/14/2026 | N10: HBP-44863 | O10: 217757 | P10: 09/22/2026 | Q10: Eau Claire | R10: WI | S10: Windows and doors | T10: 1 | U10: 830 | V10: N | W10: N | X10: N | Y10: N | Z10: 09/25/2026
A11: HBP-44839 | B11: 217700 | C11: 09/09/2026 | D11: Aberdeen | E11: SD | F11: Metal roofing panels | G11: 6 | H11: 1980 | I11: N | J11: N | K11: N | L11: N | M11: 09/10/2026 | N11: HBP-44885 | O11: 217803 | P11: 09/22/2026 | Q11: Mason City | R11: IA | S11: Vinyl siding | T11: 11 | U11: 3560 | V11: N | W11: N | X11: N | Y11: Y | Z11: 09/24/2026
A12: HBP-44875 | B12: 217784 | C12: 09/09/2026 | D12: Minot | E12: ND | F12: Sealants and coatings | G12: 14 | H12: 2430 | I12: N | J12: N | K12: Y | L12: N | M12: 09/14/2026 | N12: HBP-44910 | O12: 217894 | P12: 09/22/2026 | Q12: Sioux City | R12: IA | S12: Sealants and coatings | T12: 5 | U12: 890 | V12: N | W12: N | X12: N | Y12: N | Z12: 09/25/2026
A13: HBP-44902 | B13: 217846 | C13: 09/09/2026 | D13: Hudson | E13: WI | F13: Windows and doors | G13: 9 | H13: 1590 | I13: Y | J13: N | K13: N | L13: N | M13: 09/14/2026 | N13: HBP-44874 | O13: 217775 | P13: 09/23/2026 | Q13: Grand Island | R13: NE | S13: Vinyl siding | T13: 2 | U13: 1040 | V13: N | W13: N | X13: N | Y13: N | Z13: 09/28/2026
A14: HBP-44858 | B14: 217738 | C14: 09/10/2026 | D14: Brainerd | E14: MN | F14: Fasteners and hardware | G14: 2 | H14: 1130 | I14: Y | J14: N | K14: N | L14: N | M14: 09/11/2026 | N14: HBP-44912 | O14: 217867 | P14: 09/23/2026 | Q14: Dickinson | R14: ND | S14: Vinyl siding | T14: 4 | U14: 1720 | V14: N | W14: N | X14: N | Y14: N | Z14: 09/28/2026
A15: HBP-44861 | B15: 217836 | C15: 09/10/2026 | D15: Grand Island | E15: NE | F15: Windows and doors | G15: 5 | H15: 2360 | I15: Y | J15: N | K15: N | L15: N | M15: 09/14/2026 | N15: HBP-44901 | O15: 217841 | P15: 09/24/2026 | Q15: Miles City | R15: MT | S15: Fasteners and hardware | T15: 5 | U15: 2060 | V15: Y | W15: N | X15: N | Y15: Y | Z15: 09/28/2026
... A25: HBP-44915 | B25: 217873 | C25: 09/17/2026 | D25: Glendive | E25: MT | F25: Windows and doors | G25: 7 | H25: 2790 | I25: Y | J25: N | K25: N | L25: Y | M25: 09/18/2026 | N25: HBP-44927 | O25: 217915 | P25: 09/30/2026 | Q25: Norfolk | R25: NE | S25: Metal roofing panels | T25: 22 | U25: 4120 | V25: N | W25: N | X25: N | Y25: N | Z25: 10/02/2026

Sheet Invoices
A1: Northline freight bills, northline_invoices_sept_2026.csv, copied line for line in the file's two side-by-side panels
A3: INVOICE_NO | B3: PRO_NO | C3: INVOICE_DATE | D3: SHIP_DATE | E3: DEST_STATE | F3: BILLED_WEIGHT | G3: BILLED_CLASS | H3: BASE_CHARGE | I3: DISCOUNT_AMT | J3: NET_LINEHAUL | K3: FSC_PCT | L3: FSC_AMT | M3: ACCESSORIAL_DESC | N3: ACCESSORIAL_AMT | O3: INVOICE_TOTAL | P3: INVOICE_NO_2 | Q3: PRO_NO_2 | R3: INVOICE_DATE_2 | S3: SHIP_DATE_2 | T3: DEST_STATE_2 | U3: BILLED_WEIGHT_2 | V3: BILLED_CLASS_2 | W3: BASE_CHARGE_2 | X3: DISCOUNT_AMT_2 | Y3: NET_LINEHAUL_2 | Z3: FSC_PCT_2 | AA3: FSC_AMT_2 | AB3: ACCESSORIAL_DESC_2 | AC3: ACCESSORIAL_AMT_2 | AD3: INVOICE_TOTAL_2
A4: NFL-90302 | B4: 217598 | C4: 09/02/2026 | D4: 08/27/2026 | E4: WI | F4: 3150 | G4: 70 | H4: 1300.95 | I4: 806.59 | J4: 494.36 | K4: 26.5 | L4: 131.01 | M4: None | N4: 0 | O4: 625.37 | P4: NFL-90338 | Q4: 217666 | R4: 09/23/2026 | S4: 09/18/2026 | T4: WI | U4: 905 | V4: 55 | W4: 442.64 | X4: 274.44 | Y4: 168.2 | Z4: 26 | AA4: 43.73 | AB4: None | AC4: 0 | AD4: 211.93
A5: NFL-90304 | B5: 217611 | C5: 09/03/2026 | D5: 08/28/2026 | E5: SD | F5: 1180 | G5: 55 | H5: 455.86 | I5: 282.63 | J5: 173.23 | K5: 26 | L5: 45.04 | M5: None | N5: 0 | O5: 218.27 | P5: NFL-90339 | Q5: 217724 | R5: 09/23/2026 | S5: 09/18/2026 | T5: ND | U5: 1450 | V5: 55 | W5: 410.23 | X5: 254.34 | Y5: 155.89 | Z5: 26 | AA5: 40.53 | AB5: Residential delivery/Inside delivery/Liftgate delivery | AC5: 230 | AD5: 426.42
A6: NFL-90311 | B6: 217645 | C6: 09/05/2026 | D6: 09/01/2026 | E6: WI | F6: 1240 | G6: 70 | H6: 623.72 | I6: 386.71 | J6: 237.01 | K6: 26.5 | L6: 62.81 | M6: Limited access delivery | N6: 85 | O6: 384.82 | P6: NFL-90340 | Q6: 217883 | R6: 09/23/2026 | S6: 09/18/2026 | T6: WI | U6: 1010 | V6: 100 | W6: 736.64 | X6: 456.72 | Y6: 279.92 | Z6: 26 | AA6: 72.78 | AB6: Residential delivery | AC6: 95 | AD6: 447.7
A7: NFL-90313 | B7: 217763 | C7: 09/07/2026 | D7: 09/01/2026 | E7: IA | F7: 1620 | G7: 60 | H7: 724.85 | I7: 449.41 | J7: 275.44 | K7: 26.5 | L7: 72.99 | M7: Liftgate delivery | N7: 75 | O7: 423.43 | P7: NFL-90341 | Q7: 217803 | R7: 09/25/2026 | S7: 09/22/2026 | T7: IA | U7: 3560 | V7: 92.5 | W7: 1809.55 | X7: 1121.92 | Y7: 687.63 | Z7: 27.5 | AA7: 189.1 | AB7: Inside delivery | AC7: 60 | AD7: 936.73
A8: NFL-90314 | B8: 217822 | C8: 09/12/2026 | D8: 09/07/2026 | E8: WI | F8: 4210 | G8: 70 | H8: 1682.5 | I8: 1043.15 | J8: 639.35 | K8: 26.5 | L8: 169.43 | M8: Liftgate delivery | N8: 75 | O8: 883.78 | P8: NFL-90342 | Q8: 217894 | R8: 09/25/2026 | S8: 09/22/2026 | T8: IA | U8: 890 | V8: 85 | W8: 547.4 | X8: 339.39 | Y8: 208.01 | Z8: 27.5 | AA8: 57.2 | AB8: Redelivery | AC8: 88 | AD8: 353.21
A9: NFL-90316 | B9: 217675 | C9: 09/12/2026 | D9: 09/08/2026 | E9: MT | F9: 1760 | G9: 60 | H9: 939.06 | I9: 582.22 | J9: 356.84 | K9: 26.5 | L9: 94.56 | M9: None | N9: 0 | O9: 451.4 | P9: NFL-90343 | Q9: 217757 | R9: 09/26/2026 | S9: 09/22/2026 | T9: WI | U9: 830 | V9: 100 | W9: 710.67 | X9: 440.62 | Y9: 270.05 | Z9: 27.5 | AA9: 74.26 | AB9: None | AC9: 0 | AD9: 344.31
A10: NFL-90317 | B10: 217738 | C10: 09/13/2026 | D10: 09/10/2026 | E10: MN | F10: 1130 | G10: 60 | H10: 443.47 | I10: 274.95 | J10: 168.52 | K10: 26.5 | L10: 44.66 | M10: None | N10: 0 | O10: 213.18 | P10: NFL-90344 | Q10: 217851 | R10: 09/27/2026 | S10: 09/21/2026 | T10: MN | U10: 4470 | V10: 85 | W10: 1601.38 | X10: 992.86 | Y10: 608.52 | Z10: 27.5 | AA10: 167.34 | AB10: None | AC10: 0 | AD10: 775.86
A11: NFL-90318 | B11: 217846 | C11: 09/14/2026 | D11: 09/09/2026 | E11: WI | F11: 1590 | G11: 100 | H11: 1159.67 | I11: 719 | J11: 440.67 | K11: 26.5 | L11: 116.78 | M11: Liftgate delivery | N11: 75 | O11: 632.45 | P11: NFL-90345 | Q11: 217775 | R11: 09/29/2026 | S11: 09/23/2026 | T11: NE | U11: 1040 | V11: 92.5 | W11: 673.3 | X11: 417.45 | Y11: 255.85 | Z11: 27.5 | AA11: 70.36 | AB11: None | AC11: 0 | AD11: 326.21
A12: NFL-90319 | B12: 217703 | C12: 09/15/2026 | D12: 09/03/2026 | E12: MN | F12: 720 | G12: 85 | H12: 406.55 | I12: 252.06 | J12: 154.49 | K12: 26 | L12: 40.17 | M12: Liftgate delivery/Limited access delivery | N12: 160 | O12: 354.66 | P12: NFL-90346 | Q12: 217864 | R12: 09/30/2026 | S12: 09/21/2026 | T12: MT | U12: 1220 | V12: 70 | W12: 742.37 | X12: 460.27 | Y12: 282.1 | Z12: 27 | AA12: 76.17 | AB12: None | AC12: 0 | AD12: 358.27
A13: NFL-90320 | B13: 217836 | C13: 09/16/2026 | D13: 09/10/2026 | E13: NE | F13: 2360 | G13: 100 | H13: 1399.6 | I13: 867.75 | J13: 531.85 | K13: 26.5 | L13: 140.94 | M13: Liftgate delivery | N13: 85 | O13: 757.79 | P13: NFL-90347 | Q13: 217841 | R13: 09/30/2026 | S13: 09/24/2026 | T13: MT | U13: 2060 | V13: 60 | W13: 967.23 | X13: 599.68 | Y13: 367.55 | Z13: 27.5 | AA13: 101.08 | AB13: Liftgate delivery/Inside delivery | AC13: 135 | AD13: 603.63
A14: NFL-90321 | B14: 217700 | C14: 09/15/2026 | D14: 09/09/2026 | E14: SD | F14: 1980 | G14: 70 | H14: 721 | I14: 447.02 | J14: 273.98 | K14: 26.5 | L14: 72.6 | M14: None | N14: 0 | O14: 346.58 | P14: NFL-90348 | Q14: 217750 | R14: 09/30/2026 | S14: 09/25/2026 | T14: MT | U14: 2980 | V14: 55 | W14: 1309.89 | X14: 812.13 | Y14: 497.76 | Z14: 27.5 | AA14: 136.88 | AB14: Liftgate delivery | AC14: 75 | AD14: 709.64
A15: NFL-90322 | B15: 217784 | C15: 09/15/2026 | D15: 09/09/2026 | E15: ND | F15: 2430 | G15: 92.5 | H15: 833.98 | I15: 517.07 | J15: 316.91 | K15: 26.5 | L15: 83.98 | M15: Limited access delivery | N15: 85 | O15: 485.89 | P15: NFL-90349 | Q15: 217883 | R15: 10/01/2026 | S15: 09/18/2026 | T15: WI | U15: 1010 | V15: 100 | W15: 736.64 | X15: 456.72 | Y15: 279.92 | Z15: 26 | AA15: 72.78 | AB15: Residential delivery | AC15: 95 | AD15: 447.7
... A26: NFL-90337 | B26: 217833 | C26: 09/21/2026 | D26: 09/18/2026 | E26: MN | F26: 950 | G26: 92.5 | H26: 542.75 | I26: 336.5 | J26: 206.25 | K26: 26 | L26: 53.63 | M26: Liftgate delivery/Residential delivery | N26: 170 | O26: 429.88 | P26: NFL-90360 | Q26: 217841 | R26: 10/02/2026 | S26: 09/24/2026 | T26: MT | U26: 2060 | V26: 60 | W26: 967.23 | X26: 599.68 | Y26: 367.55 | Z26: 27.5 | AA26: 101.08 | AB26: Liftgate delivery/Inside delivery | AC26: 135 | AD26: 603.63

Sheet Billing File
A1: Documents Northline lists in its billing file, northline_billing_file_sept_2026.docx, with the audit's reading of each one
A3: PRO_NO | B3: FREIGHT_BILL | C3: DOCUMENT | D3: PARTICULARS | E3: READ_AS | F3: QUALIFIES | G3: APPLIES_TO
A4: 217645 | B4: NFL-90311 | C4: Delivery receipt notation | D4: Gated yard, 48 minutes on site | E4: Delivery receipt | F4: No | G4: none
A5: 217703 | B5: NFL-90319 | C5: Delivery receipt notation | D5: Liftgate at a gated site, both services on the bill of lading | E5: Delivery receipt | F5: No | G5: none
A6: 217784 | B6: NFL-90322 | C6: Reclass notice | D6: Rating system entry from a density figure, initialed by a dock clerk, no inspector | E6: Not an inspection certificate | F6: No | G6: 4.3 class
A7: 217792 | B7: NFL-90328 | C7: Inspection certificate | D7: Certificate 0931 signed by the Northline freight inspector, class 70 | E7: Signed inspection certificate | F7: Yes | G7: 4.3 class
A8: 217873 | B8: NFL-90336 | C8: Scale ticket | D8: Fargo Public Scale ticket 88213, net 3,010 lb, weighmaster signed | E8: Certified scale ticket | F8: Yes | G8: 4.5 weight
A9: 217820 | B9: NFL-90351 | C9: Dock scale readout | D9: Forklift scale printout, 1,620 lb, initialed by the dock lead, no weighmaster and no certification | E9: Not a certified scale ticket | F9: No | G9: 4.5 weight
A10: 217712 | B10: NFL-90355 | C10: Scale ticket | D10: Glendive platform scale ticket 4471, net 2,290 lb, weighmaster signed | E10: Certified scale ticket | F10: Yes | G10: 4.5 weight
A11: 217883 | B11: NFL-90340 | C11: Delivery receipt notation | D11: Residential address, service on the bill of lading | E11: Delivery receipt | F11: No | G11: none
A12: 217841 | B12: NFL-90347 | C12: Delivery receipt notation | D12: Liftgate and inside delivery, both services on the bill of lading | E12: Delivery receipt | F12: No | G12: none
A14: QUALIFIES reads Yes where the document is a certified scale ticket under section 4.5 or an inspection certificate signed by the carrier's inspector under section 4.3; a certified ticket inside the five percent tolerance still reverts to the bill of lading weight on the Audit tab.

Sheet Confirmations
A1: Services the shipping desk confirmed to Northline in writing, shipping_desk_correspondence_sept_2026.docx
A3: PRO_NO | B3: FREIGHT_BILL | C3: SERVICE | D3: CONFIRMED_BY | E3: CONFIRMED_DATE | F3: DELIVERED_DATE | G3: CHARGE | H3: DUE_UNDER_6_1
A4: 217861 | B4: NFL-90330 | C4: Liftgate delivery | D4: Shipping lead's email to Northline customer service | E4: 09/16/2026 | F4: =IFERROR(INDEX(BOL!$M$4:$M$25,MATCH(A4,BOL!$B$4:$B$25,0)),INDEX(BOL!$Z$4:$Z$25,MATCH(A4,BOL!$O$4:$O$25,0))) -> 09/18/2026 | G4: =INDEX(Tariff!$O$4:$O$9,MATCH(C4,Tariff!$M$4:$M$9,0)) -> 75 | H4: =IF(DATEVALUE(E4)<DATEVALUE(F4),"Yes","No") -> Yes
A5: 217733 | B5: NFL-90324 | C5: Reconsignment | D5: Shipping lead's email to Northline customer service | E5: 09/15/2026 | F5: =IFERROR(INDEX(BOL!$M$4:$M$25,MATCH(A5,BOL!$B$4:$B$25,0)),INDEX(BOL!$Z$4:$Z$25,MATCH(A5,BOL!$O$4:$O$25,0))) -> 09/18/2026 | G5: =INDEX(Tariff!$O$4:$O$9,MATCH(C5,Tariff!$M$4:$M$9,0)) -> 110 | H5: =IF(DATEVALUE(E5)<DATEVALUE(F5),"Yes","No") -> Yes
A6: 217858 | B6: NFL-90334 | C6: Redelivery | D6: Shipping lead's email to Northline customer service | E6: 09/17/2026 | F6: =IFERROR(INDEX(BOL!$M$4:$M$25,MATCH(A6,BOL!$B$4:$B$25,0)),INDEX(BOL!$Z$4:$Z$25,MATCH(A6,BOL!$O$4:$O$25,0))) -> 09/18/2026 | G6: =INDEX(Tariff!$O$4:$O$9,MATCH(C6,Tariff!$M$4:$M$9,0)) -> 88 | H6: =IF(DATEVALUE(E6)<DATEVALUE(F6),"Yes","No") -> Yes
A8: Section 6.1 makes a service billable where the bill of lading requests it or the shipper confirmed it in writing before delivery. The liftgate Northline asked about on the Bismarck delivery after the fact and the redelivery on the Sioux City sealants were declined and are not listed.

Sheet Pro Matches
A1: Freight bills whose pro number matches no bill of lading, matched to the bill of lading the shipment identifies
A3: BILLED_PRO | B3: FREIGHT_BILL | C3: BOL_PRO | D3: BOL_NO | E3: BASIS
A4: 217876 | B4: NFL-90352 | C4: 217867 | D4: HBP-44912 | E4: No bill of lading carries 217876; HBP-44912 for pro 217867 matches the 09/23/2026 ship date, the state ND, the 1,720 lb weight and class 92.5, and no other freight bill bills pro 217867
A6: The Audit tab rates such a bill against the matched bill of lading under a corrected pro number and reports it to Northline for a corrected freight bill; it is rated, not set aside.

Sheet Audit
A1: Every freight bill rated under the contract beside what Northline billed; the left panel rates the invoice file's left panel, the right panel its right
A3: INVOICE_NO | B3: PRO_BILLED | C3: PRO_NO | D3: PICKUP_DATE | E3: DEST_STATE | F3: PRODUCT_GROUP | G3: BOL_WEIGHT | H3: BILLED_WEIGHT | I3: CERTIFIED_TICKET | J3: CONTRACT_WEIGHT | K3: GROUP_CLASS | L3: BILLED_CLASS | M3: INSPECTION_CERT | N3: CONTRACT_CLASS | O3: CLASS_FACTOR | P3: BREAK | Q3: RATE_CWT | R3: OWN_BREAK_CHARGE | S3: NEXT_BREAK_CHARGE | T3: GROSS_LINEHAUL | U3: NET_LINEHAUL | V3: FSC_MONDAY | W3: FSC_PCT | X3: FSC_DUE | Y3: LIFTGATE | Z3: RESIDENTIAL | AA3: LIMITED_ACCESS | AB3: INSIDE_DELIVERY | AC3: BOL_ACCESSORIALS | AD3: CONFIRMED_ACCESSORIALS | AE3: ACCESSORIALS_DUE | AF3: DUPLICATE | AG3: CONTRACT_TOTAL | AH3: BILLED_TOTAL | AI3: VARIANCE | AJ3: BILLED_BASE | AK3: BILLED_FSC_PCT | AL3: BILLED_ACCESSORIALS | AM3: EXCEPTION | AN3: SETTLED_BY | AP3: INVOICE_NO_2 | AQ3: PRO_BILLED_2 | AR3: PRO_NO_2 | AS3: PICKUP_DATE_2 | AT3: DEST_STATE_2 | AU3: PRODUCT_GROUP_2 | AV3: BOL_WEIGHT_2 | AW3: BILLED_WEIGHT_2 | AX3: CERTIFIED_TICKET_2 | AY3: CONTRACT_WEIGHT_2 | AZ3: GROUP_CLASS_2 | BA3: BILLED_CLASS_2 | BB3: INSPECTION_CERT_2 | BC3: CONTRACT_CLASS_2 | BD3: CLASS_FACTOR_2 | BE3: BREAK_2 | BF3: RATE_CWT_2 | BG3: OWN_BREAK_CHARGE_2 | BH3: NEXT_BREAK_CHARGE_2 | BI3: GROSS_LINEHAUL_2 | BJ3: NET_LINEHAUL_2 | BK3: FSC_MONDAY_2 | BL3: FSC_PCT_2 | BM3: FSC_DUE_2 | BN3: LIFTGATE_2 | BO3: RESIDENTIAL_2 | BP3: LIMITED_ACCESS_2 | BQ3: INSIDE_DELIVERY_2 | BR3: BOL_ACCESSORIALS_2 | BS3: CONFIRMED_ACCESSORIALS_2 | BT3: ACCESSORIALS_DUE_2 | BU3: DUPLICATE_2 | BV3: CONTRACT_TOTAL_2 | BW3: BILLED_TOTAL_2 | BX3: VARIANCE_2 | BY3: BILLED_BASE_2 | BZ3: BILLED_FSC_PCT_2 | CA3: BILLED_ACCESSORIALS_2 | CB3: EXCEPTION_2 | CC3: SETTLED_BY_2
A4: =Invoices!A4 -> NFL-90302 | B4: =Invoices!B4 -> 217598 | C4: =IFERROR(INDEX('Pro Matches'!$C$4:$C$4,MATCH(B4,'Pro Matches'!$A$4:$A$4,0)),B4) -> 217598 | D4: =IFERROR(INDEX(BOL!$C$4:$C$25,MATCH(C4,BOL!$B$4:$B$25,0)),INDEX(BOL!$P$4:$P$25,MATCH(C4,BOL!$O$4:$O$25,0))) -> 08/27/2026 | E4: =IFERROR(INDEX(BOL!$E$4:$E$25,MATCH(C4,BOL!$B$4:$B$25,0)),INDEX(BOL!$R$4:$R$25,MATCH(C4,BOL!$O$4:$O$25,0))) -> WI | F4: =IFERROR(INDEX(BOL!$F$4:$F$25,MATCH(C4,BOL!$B$4:$B$25,0)),INDEX(BOL!$S$4:$S$25,MATCH(C4,BOL!$O$4:$O$25,0))) -> Metal roofing panels | G4: =IFERROR(INDEX(BOL!$H$4:$H$25,MATCH(C4,BOL!$B$4:$B$25,0)),INDEX(BOL!$U$4:$U$25,MATCH(C4,BOL!$O$4:$O$25,0))) -> 3150 | H4: =Invoices!F4 -> 3150 | I4: =IF(COUNTIFS('Billing File'!$A$4:$A$12,C4,'Billing File'!$G$4:$G$12,"4.5 weight",'Billing File'!$F$4:$F$12,"Yes")>0,"Yes","No") -> No | J4: =IF(AND(I4="Yes",H4>G4*(1+Terms!$B$6)),H4,G4) -> 3150 | K4: =INDEX(Tariff!$L$4:$L$9,MATCH(F4,Tariff!$K$4:$K$9,0)) -> 70 | L4: =Invoices!G4 -> 70 | M4: =IF(COUNTIFS('Billing File'!$A$4:$A$12,C4,'Billing File'!$G$4:$G$12,"4.3 class",'Billing File'!$F$4:$F$12,"Yes")>0,"Yes","No") -> No | N4: =IF(M4="Yes",L4,K4) -> 70 | O4: =INDEX(Tariff!$I$4:$I$10,MATCH(N4,Tariff!$H$4:$H$10,0)) -> 1 | P4: =MATCH(J4,Tariff!$B$12:$F$12,1) -> 4 | Q4: =INDEX(Tariff!$B$4:$F$10,MATCH(E4,Tariff!$A$4:$A$10,0),P4) -> 41.3 | R4: =ROUND(J4/100*Q4*O4,2) -> 1300.95 | S4: =IF(P4<5,ROUND(INDEX(Tariff!$B$12:$F$12,P4+1)/100*INDEX(Tariff!$B$4:$F$10,MATCH(E4,Tariff!$A$4:$A$10,0),P4+1)*O4,2),R4) -> 1682.5 | T4: =MIN(R4,S4) -> 1300.95 | U4: =MAX(ROUND(T4*(1-Terms!$B$4),2),Terms!$B$5) -> 494.36 | V4: =TEXT(DATEVALUE(D4)-WEEKDAY(DATEVALUE(D4),2)+1,"mm/dd/yyyy") -> 08/24/2026 | W4: =INDEX('Fuel Index'!$C$4:$C$12,MATCH(V4,'Fuel Index'!$A$4:$A$12,0)) -> 0.26 | X4: =ROUND(U4*W4,2) -> 128.53 | Y4: =IFERROR(INDEX(BOL!$I$4:$I$25,MATCH(C4,BOL!$B$4:$B$25,0)),INDEX(BOL!$V$4:$V$25,MATCH(C4,BOL!$O$4:$O$25,0))) -> N | Z4: =IFERROR(INDEX(BOL!$J$4:$J$25,MATCH(C4,BOL!$B$4:$B$25,0)),INDEX(BOL!$W$4:$W$25,MATCH(C4,BOL!$O$4:$O$25,0))) -> N | AA4: =IFERROR(INDEX(BOL!$K$4:$K$25,MATCH(C4,BOL!$B$4:$B$25,0)),INDEX(BOL!$X$4:$X$25,MATCH(C4,BOL!$O$4:$O$25,0))) -> N | AB4: =IFERROR(INDEX(BOL!$L$4:$L$25,MATCH(C4,BOL!$B$4:$B$25,0)),INDEX(BOL!$Y$4:$Y$25,MATCH(C4,BOL!$O$4:$O$25,0))) -> N | AC4: =(Y4="Y")*Tariff!$O$4+(Z4="Y")*Tariff!$O$5+(AA4="Y")*Tariff!$O$6+(AB4="Y")*Tariff!$O$7 -> 0 | AD4: =SUMIFS(Confirmations!$G$4:$G$6,Confirmations!$A$4:$A$6,C4,Confirmations!$H$4:$H$6,"Yes") -> 0 | AE4: =AC4+AD4 -> 0 | AF4: =IF(COUNTIFS(Invoices!$B$4:$Q$26,B4,Invoices!$A$4:$P$26,"<"&A4)>0,"Yes","No") -> No | AG4: =IF(AF4="Yes",0,ROUND(U4+X4+AE4,2)) -> 622.89 | AH4: =Invoices!O4 -> 625.37 | AI4: =ROUND(AH4-AG4,2) -> 2.48 | AJ4: =Invoices!H4 -> 1300.95 | AK4: =ROUND(Invoices!K4/Terms!$B$9,4) -> 0.265 | AL4: =Invoices!N4 -> 0 | AM4: =IF(AF4="Yes","7.1 duplicate bill",IF(L4<>N4,"4.3 class",IF(H4<>J4,"4.5 reweigh",IF(AJ4<>T4,"4.2 deficit weight",IF(AK4<>ROUND(W4,4),"5.2 fuel week",IF(AL4>AE4,"6.1 accessorial overbilled",IF(AL4<AE4,"6.1 accessorial omitted",""))))))) -> 5.2 fuel week | AN4: =IF(AND(M4="Yes",L4<>K4),"4.3 inspection certificate",IF(AND(I4="Yes",H4<>G4,H4=J4),"4.5 certified scale ticket",IF(AD4>0,"6.1 written confirmation",IF(C4<>B4,"corrected pro number","")))) | AP4: =Invoices!P4 -> NFL-90338 | AQ4: =Invoices!Q4 -> 217666 | AR4: =IFERROR(INDEX('Pro Matches'!$C$4:$C$4,MATCH(AQ4,'Pro Matches'!$A$4:$A$4,0)),AQ4) -> 217666 | AS4: =IFERROR(INDEX(BOL!$C$4:$C$25,MATCH(AR4,BOL!$B$4:$B$25,0)),INDEX(BOL!$P$4:$P$25,MATCH(AR4,BOL!$O$4:$O$25,0))) -> 09/18/2026 | AT4: =IFERROR(INDEX(BOL!$E$4:$E$25,MATCH(AR4,BOL!$B$4:$B$25,0)),INDEX(BOL!$R$4:$R$25,MATCH(AR4,BOL!$O$4:$O$25,0))) -> WI | AU4: =IFERROR(INDEX(BOL!$F$4:$F$25,MATCH(AR4,BOL!$B$4:$B$25,0)),INDEX(BOL!$S$4:$S$25,MATCH(AR4,BOL!$O$4:$O$25,0))) -> Gypsum and cement board | AV4: =IFERROR(INDEX(BOL!$H$4:$H$25,MATCH(AR4,BOL!$B$4:$B$25,0)),INDEX(BOL!$U$4:$U$25,MATCH(AR4,BOL!$O$4:$O$25,0))) -> 905 | AW4: =Invoices!U4 -> 905 | AX4: =IF(COUNTIFS('Billing File'!$A$4:$A$12,AR4,'Billing File'!$G$4:$G$12,"4.5 weight",'Billing File'!$F$4:$F$12,"Yes")>0,"Yes","No") -> No | AY4: =IF(AND(AX4="Yes",AW4>AV4*(1+Terms!$B$6)),AW4,AV4) -> 905 | AZ4: =INDEX(Tariff!$L$4:$L$9,MATCH(AU4,Tariff!$K$4:$K$9,0)) -> 55 | BA4: =Invoices!V4 -> 55 | BB4: =IF(COUNTIFS('Billing File'!$A$4:$A$12,AR4,'Billing File'!$G$4:$G$12,"4.3 class",'Billing File'!$F$4:$F$12,"Yes")>0,"Yes","No") -> No | BC4: =IF(BB4="Yes",BA4,AZ4) -> 55 | BD4: =INDEX(Tariff!$I$4:$I$10,MATCH(BC4,Tariff!$H$4:$H$10,0)) -> 0.88 | BE4: =MATCH(AY4,Tariff!$B$12:$F$12,1) -> 2 | BF4: =INDEX(Tariff!$B$4:$F$10,MATCH(AT4,Tariff!$A$4:$A$10,0),BE4) -> 59.05 | BG4: =ROUND(AY4/100*BF4*BD4,2) -> 470.27 | BH4: =IF(BE4<5,ROUND(INDEX(Tariff!$B$12:$F$12,BE4+1)/100*INDEX(Tariff!$B$4:$F$10,MATCH(AT4,Tariff!$A$4:$A$10,0),BE4+1)*BD4,2),BG4) -> 442.64 | BI4: =MIN(BG4,BH4) -> 442.64 | BJ4: =MAX(ROUND(BI4*(1-Terms!$B$4),2),Terms!$B$5) -> 168.2 | BK4: =TEXT(DATEVALUE(AS4)-WEEKDAY(DATEVALUE(AS4),2)+1,"mm/dd/yyyy") -> 09/14/2026 | BL4: =INDEX('Fuel Index'!$C$4:$C$12,MATCH(BK4,'Fuel Index'!$A$4:$A$12,0)) -> 0.26 | BM4: =ROUND(BJ4*BL4,2) -> 43.73 | BN4: =IFERROR(INDEX(BOL!$I$4:$I$25,MATCH(AR4,BOL!$B$4:$B$25,0)),INDEX(BOL!$V$4:$V$25,MATCH(AR4,BOL!$O$4:$O$25,0))) -> N | BO4: =IFERROR(INDEX(BOL!$J$4:$J$25,MATCH(AR4,BOL!$B$4:$B$25,0)),INDEX(BOL!$W$4:$W$25,MATCH(AR4,BOL!$O$4:$O$25,0))) -> N | BP4: =IFERROR(INDEX(BOL!$K$4:$K$25,MATCH(AR4,BOL!$B$4:$B$25,0)),INDEX(BOL!$X$4:$X$25,MATCH(AR4,BOL!$O$4:$O$25,0))) -> N | BQ4: =IFERROR(INDEX(BOL!$L$4:$L$25,MATCH(AR4,BOL!$B$4:$B$25,0)),INDEX(BOL!$Y$4:$Y$25,MATCH(AR4,BOL!$O$4:$O$25,0))) -> N | BR4: =(BN4="Y")*Tariff!$O$4+(BO4="Y")*Tariff!$O$5+(BP4="Y")*Tariff!$O$6+(BQ4="Y")*Tariff!$O$7 -> 0 | BS4: =SUMIFS(Confirmations!$G$4:$G$6,Confirmations!$A$4:$A$6,AR4,Confirmations!$H$4:$H$6,"Yes") -> 0 | BT4: =BR4+BS4 -> 0 | BU4: =IF(COUNTIFS(Invoices!$B$4:$Q$26,AQ4,Invoices!$A$4:$P$26,"<"&AP4)>0,"Yes","No") -> No | BV4: =IF(BU4="Yes",0,ROUND(BJ4+BM4+BT4,2)) -> 211.93 | BW4: =Invoices!AD4 -> 211.93 | BX4: =ROUND(BW4-BV4,2) -> 0 | BY4: =Invoices!W4 -> 442.64 | BZ4: =ROUND(Invoices!Z4/Terms!$B$9,4) -> 0.26 | CA4: =Invoices!AC4 -> 0 | CB4: =IF(BU4="Yes","7.1 duplicate bill",IF(BA4<>BC4,"4.3 class",IF(AW4<>AY4,"4.5 reweigh",IF(BY4<>BI4,"4.2 deficit weight",IF(BZ4<>ROUND(BL4,4),"5.2 fuel week",IF(CA4>BT4,"6.1 accessorial overbilled",IF(CA4<BT4,"6.1 accessorial omitted",""))))))) | CC4: =IF(AND(BB4="Yes",BA4<>AZ4),"4.3 inspection certificate",IF(AND(AX4="Yes",AW4<>AV4,AW4=AY4),"4.5 certified scale ticket",IF(BS4>0,"6.1 written confirmation",IF(AR4<>AQ4,"corrected pro number",""))))
A5: =Invoices!A5 -> NFL-90304 | B5: =Invoices!B5 -> 217611 | C5: =IFERROR(INDEX('Pro Matches'!$C$4:$C$4,MATCH(B5,'Pro Matches'!$A$4:$A$4,0)),B5) -> 217611 | D5: =IFERROR(INDEX(BOL!$C$4:$C$25,MATCH(C5,BOL!$B$4:$B$25,0)),INDEX(BOL!$P$4:$P$25,MATCH(C5,BOL!$O$4:$O$25,0))) -> 08/28/2026 | E5: =IFERROR(INDEX(BOL!$E$4:$E$25,MATCH(C5,BOL!$B$4:$B$25,0)),INDEX(BOL!$R$4:$R$25,MATCH(C5,BOL!$O$4:$O$25,0))) -> SD | F5: =IFERROR(INDEX(BOL!$F$4:$F$25,MATCH(C5,BOL!$B$4:$B$25,0)),INDEX(BOL!$S$4:$S$25,MATCH(C5,BOL!$O$4:$O$25,0))) -> Gypsum and cement board | G5: =IFERROR(INDEX(BOL!$H$4:$H$25,MATCH(C5,BOL!$B$4:$B$25,0)),INDEX(BOL!$U$4:$U$25,MATCH(C5,BOL!$O$4:$O$25,0))) -> 1180 | H5: =Invoices!F5 -> 1180 | I5: =IF(COUNTIFS('Billing File'!$A$4:$A$12,C5,'Billing File'!$G$4:$G$12,"4.5 weight",'Billing File'!$F$4:$F$12,"Yes")>0,"Yes","No") -> No | J5: =IF(AND(I5="Yes",H5>G5*(1+Terms!$B$6)),H5,G5) -> 1180 | K5: =INDEX(Tariff!$L$4:$L$9,MATCH(F5,Tariff!$K$4:$K$9,0)) -> 55 | L5: =Invoices!G5 -> 55 | M5: =IF(COUNTIFS('Billing File'!$A$4:$A$12,C5,'Billing File'!$G$4:$G$12,"4.3 class",'Billing File'!$F$4:$F$12,"Yes")>0,"Yes","No") -> No | N5: =IF(M5="Yes",L5,K5) -> 55 | O5: =INDEX(Tariff!$I$4:$I$10,MATCH(N5,Tariff!$H$4:$H$10,0)) -> 0.88 | P5: =MATCH(J5,Tariff!$B$12:$F$12,1) -> 3 | Q5: =INDEX(Tariff!$B$4:$F$10,MATCH(E5,Tariff!$A$4:$A$10,0),P5) -> 43.9 | R5: =ROUND(J5/100*Q5*O5,2) -> 455.86 | S5: =IF(P5<5,ROUND(INDEX(Tariff!$B$12:$F$12,P5+1)/100*INDEX(Tariff!$B$4:$F$10,MATCH(E5,Tariff!$A$4:$A$10,0),P5+1)*O5,2),R5) -> 634.48 | T5: =MIN(R5,S5) -> 455.86 | U5: =MAX(ROUND(T5*(1-Terms!$B$4),2),Terms!$B$5) -> 173.23 | V5: =TEXT(DATEVALUE(D5)-WEEKDAY(DATEVALUE(D5),2)+1,"mm/dd/yyyy") -> 08/24/2026 | W5: =INDEX('Fuel Index'!$C$4:$C$12,MATCH(V5,'Fuel Index'!$A$4:$A$12,0)) -> 0.26 | X5: =ROUND(U5*W5,2) -> 45.04 | Y5: =IFERROR(INDEX(BOL!$I$4:$I$25,MATCH(C5,BOL!$B$4:$B$25,0)),INDEX(BOL!$V$4:$V$25,MATCH(C5,BOL!$O$4:$O$25,0))) -> N | Z5: =IFERROR(INDEX(BOL!$J$4:$J$25,MATCH(C5,BOL!$B$4:$B$25,0)),INDEX(BOL!$W$4:$W$25,MATCH(C5,BOL!$O$4:$O$25,0))) -> N | AA5: =IFERROR(INDEX(BOL!$K$4:$K$25,MATCH(C5,BOL!$B$4:$B$25,0)),INDEX(BOL!$X$4:$X$25,MATCH(C5,BOL!$O$4:$O$25,0))) -> N | AB5: =IFERROR(INDEX(BOL!$L$4:$L$25,MATCH(C5,BOL!$B$4:$B$25,0)),INDEX(BOL!$Y$4:$Y$25,MATCH(C5,BOL!$O$4:$O$25,0))) -> N | AC5: =(Y5="Y")*Tariff!$O$4+(Z5="Y")*Tariff!$O$5+(AA5="Y")*Tariff!$O$6+(AB5="Y")*Tariff!$O$7 -> 0 | AD5: =SUMIFS(Confirmations!$G$4:$G$6,Confirmations!$A$4:$A$6,C5,Confirmations!$H$4:$H$6,"Yes") -> 0 | AE5: =AC5+AD5 -> 0 | AF5: =IF(COUNTIFS(Invoices!$B$4:$Q$26,B5,Invoices!$A$4:$P$26,"<"&A5)>0,"Yes","No") -> No | AG5: =IF(AF5="Yes",0,ROUND(U5+X5+AE5,2)) -> 218.27 | AH5: =Invoices!O5 -> 218.27 | AI5: =ROUND(AH5-AG5,2) -> 0 | AJ5: =Invoices!H5 -> 455.86 | AK5: =ROUND(Invoices!K5/Terms!$B$9,4) -> 0.26 | AL5: =Invoices!N5 -> 0 | AM5: =IF(AF5="Yes","7.1 duplicate bill",IF(L5<>N5,"4.3 class",IF(H5<>J5,"4.5 reweigh",IF(AJ5<>T5,"4.2 deficit weight",IF(AK5<>ROUND(W5,4),"5.2 fuel week",IF(AL5>AE5,"6.1 accessorial overbilled",IF(AL5<AE5,"6.1 accessorial omitted",""))))))) | AN5: =IF(AND(M5="Yes",L5<>K5),"4.3 inspection certificate",IF(AND(I5="Yes",H5<>G5,H5=J5),"4.5 certified scale ticket",IF(AD5>0,"6.1 written confirmation",IF(C5<>B5,"corrected pro number","")))) | AP5: =Invoices!P5 -> NFL-90339 | AQ5: =Invoices!Q5 -> 217724 | AR5: =IFERROR(INDEX('Pro Matches'!$C$4:$C$4,MATCH(AQ5,'Pro Matches'!$A$4:$A$4,0)),AQ5) -> 217724 | AS5: =IFERROR(INDEX(BOL!$C$4:$C$25,MATCH(AR5,BOL!$B$4:$B$25,0)),INDEX(BOL!$P$4:$P$25,MATCH(AR5,BOL!$O$4:$O$25,0))) -> 09/18/2026 | AT5: =IFERROR(INDEX(BOL!$E$4:$E$25,MATCH(AR5,BOL!$B$4:$B$25,0)),INDEX(BOL!$R$4:$R$25,MATCH(AR5,BOL!$O$4:$O$25,0))) -> ND | AU5: =IFERROR(INDEX(BOL!$F$4:$F$25,MATCH(AR5,BOL!$B$4:$B$25,0)),INDEX(BOL!$S$4:$S$25,MATCH(AR5,BOL!$O$4:$O$25,0))) -> Gypsum and cement board | AV5: =IFERROR(INDEX(BOL!$H$4:$H$25,MATCH(AR5,BOL!$B$4:$B$25,0)),INDEX(BOL!$U$4:$U$25,MATCH(AR5,BOL!$O$4:$O$25,0))) -> 1450 | AW5: =Invoices!U5 -> 1450 | AX5: =IF(COUNTIFS('Billing File'!$A$4:$A$12,AR5,'Billing File'!$G$4:$G$12,"4.5 weight",'Billing File'!$F$4:$F$12,"Yes")>0,"Yes","No") -> No | AY5: =IF(AND(AX5="Yes",AW5>AV5*(1+Terms!$B$6)),AW5,AV5) -> 1450 | AZ5: =INDEX(Tariff!$L$4:$L$9,MATCH(AU5,Tariff!$K$4:$K$9,0)) -> 55 | BA5: =Invoices!V5 -> 55 | BB5: =IF(COUNTIFS('Billing File'!$A$4:$A$12,AR5,'Billing File'!$G$4:$G$12,"4.3 class",'Billing File'!$F$4:$F$12,"Yes")>0,"Yes","No") -> No | BC5: =IF(BB5="Yes",BA5,AZ5) -> 55 | BD5: =INDEX(Tariff!$I$4:$I$10,MATCH(BC5,Tariff!$H$4:$H$10,0)) -> 0.88 | BE5: =MATCH(AY5,Tariff!$B$12:$F$12,1) -> 3 | BF5: =INDEX(Tariff!$B$4:$F$10,MATCH(AT5,Tariff!$A$4:$A$10,0),BE5) -> 32.15 | BG5: =ROUND(AY5/100*BF5*BD5,2) -> 410.23 | BH5: =IF(BE5<5,ROUND(INDEX(Tariff!$B$12:$F$12,BE5+1)/100*INDEX(Tariff!$B$4:$F$10,MATCH(AT5,Tariff!$A$4:$A$10,0),BE5+1)*BD5,2),BG5) -> 464.64 | BI5: =MIN(BG5,BH5) -> 410.23 | BJ5: =MAX(ROUND(BI5*(1-Terms!$B$4),2),Terms!$B$5) -> 155.89 | BK5: =TEXT(DATEVALUE(AS5)-WEEKDAY(DATEVALUE(AS5),2)+1,"mm/dd/yyyy") -> 09/14/2026 | BL5: =INDEX('Fuel Index'!$C$4:$C$12,MATCH(BK5,'Fuel Index'!$A$4:$A$12,0)) -> 0.26 | BM5: =ROUND(BJ5*BL5,2) -> 40.53 | BN5: =IFERROR(INDEX(BOL!$I$4:$I$25,MATCH(AR5,BOL!$B$4:$B$25,0)),INDEX(BOL!$V$4:$V$25,MATCH(AR5,BOL!$O$4:$O$25,0))) -> N | BO5: =IFERROR(INDEX(BOL!$J$4:$J$25,MATCH(AR5,BOL!$B$4:$B$25,0)),INDEX(BOL!$W$4:$W$25,MATCH(AR5,BOL!$O$4:$O$25,0))) -> Y | BP5: =IFERROR(INDEX(BOL!$K$4:$K$25,MATCH(AR5,BOL!$B$4:$B$25,0)),INDEX(BOL!$X$4:$X$25,MATCH(AR5,BOL!$O$4:$O$25,0))) -> N | BQ5: =IFERROR(INDEX(BOL!$L$4:$L$25,MATCH(AR5,BOL!$B$4:$B$25,0)),INDEX(BOL!$Y$4:$Y$25,MATCH(AR5,BOL!$O$4:$O$25,0))) -> Y | BR5: =(BN5="Y")*Tariff!$O$4+(BO5="Y")*Tariff!$O$5+(BP5="Y")*Tariff!$O$6+(BQ5="Y")*Tariff!$O$7 -> 155 | BS5: =SUMIFS(Confirmations!$G$4:$G$6,Confirmations!$A$4:$A$6,AR5,Confirmations!$H$4:$H$6,"Yes") -> 0 | BT5: =BR5+BS5 -> 155 | BU5: =IF(COUNTIFS(Invoices!$B$4:$Q$26,AQ5,Invoices!$A$4:$P$26,"<"&AP5)>0,"Yes","No") -> No | BV5: =IF(BU5="Yes",0,ROUND(BJ5+BM5+BT5,2)) -> 351.42 | BW5: =Invoices!AD5 -> 426.42 | BX5: =ROUND(BW5-BV5,2) -> 75 | BY5: =Invoices!W5 -> 410.23 | BZ5: =ROUND(Invoices!Z5/Terms!$B$9,4) -> 0.26 | CA5: =Invoices!AC5 -> 230 | CB5: =IF(BU5="Yes","7.1 duplicate bill",IF(BA5<>BC5,"4.3 class",IF(AW5<>AY5,"4.5 reweigh",IF(BY5<>BI5,"4.2 deficit weight",IF(BZ5<>ROUND(BL5,4),"5.2 fuel week",IF(CA5>BT5,"6.1 accessorial overbilled",IF(CA5<BT5,"6.1 accessorial omitted",""))))))) -> 6.1 accessorial overbilled | CC5: =IF(AND(BB5="Yes",BA5<>AZ5),"4.3 inspection certificate",IF(AND(AX5="Yes",AW5<>AV5,AW5=AY5),"4.5 certified scale ticket",IF(BS5>0,"6.1 written confirmation",IF(AR5<>AQ5,"corrected pro number",""))))
A6: =Invoices!A6 -> NFL-90311 | B6: =Invoices!B6 -> 217645 | C6: =IFERROR(INDEX('Pro Matches'!$C$4:$C$4,MATCH(B6,'Pro Matches'!$A$4:$A$4,0)),B6) -> 217645 | D6: =IFERROR(INDEX(BOL!$C$4:$C$25,MATCH(C6,BOL!$B$4:$B$25,0)),INDEX(BOL!$P$4:$P$25,MATCH(C6,BOL!$O$4:$O$25,0))) -> 09/01/2026 | E6: =IFERROR(INDEX(BOL!$E$4:$E$25,MATCH(C6,BOL!$B$4:$B$25,0)),INDEX(BOL!$R$4:$R$25,MATCH(C6,BOL!$O$4:$O$25,0))) -> WI | F6: =IFERROR(INDEX(BOL!$F$4:$F$25,MATCH(C6,BOL!$B$4:$B$25,0)),INDEX(BOL!$S$4:$S$25,MATCH(C6,BOL!$O$4:$O$25,0))) -> Metal roofing panels | G6: =IFERROR(INDEX(BOL!$H$4:$H$25,MATCH(C6,BOL!$B$4:$B$25,0)),INDEX(BOL!$U$4:$U$25,MATCH(C6,BOL!$O$4:$O$25,0))) -> 1240 | H6: =Invoices!F6 -> 1240 | I6: =IF(COUNTIFS('Billing File'!$A$4:$A$12,C6,'Billing File'!$G$4:$G$12,"4.5 weight",'Billing File'!$F$4:$F$12,"Yes")>0,"Yes","No") -> No | J6: =IF(AND(I6="Yes",H6>G6*(1+Terms!$B$6)),H6,G6) -> 1240 | K6: =INDEX(Tariff!$L$4:$L$9,MATCH(F6,Tariff!$K$4:$K$9,0)) -> 70 | L6: =Invoices!G6 -> 70 | M6: =IF(COUNTIFS('Billing File'!$A$4:$A$12,C6,'Billing File'!$G$4:$G$12,"4.3 class",'Billing File'!$F$4:$F$12,"Yes")>0,"Yes","No") -> No | N6: =IF(M6="Yes",L6,K6) -> 70 | O6: =INDEX(Tariff!$I$4:$I$10,MATCH(N6,Tariff!$H$4:$H$10,0)) -> 1 | P6: =MATCH(J6,Tariff!$B$12:$F$12,1) -> 3 | Q6: =INDEX(Tariff!$B$4:$F$10,MATCH(E6,Tariff!$A$4:$A$10,0),P6) -> 50.3 | R6: =ROUND(J6/100*Q6*O6,2) -> 623.72 | S6: =IF(P6<5,ROUND(INDEX(Tariff!$B$12:$F$12,P6+1)/100*INDEX(Tariff!$B$4:$F$10,MATCH(E6,Tariff!$A$4:$A$10,0),P6+1)*O6,2),R6) -> 826 | T6: =MIN(R6,S6) -> 623.72 | U6: =MAX(ROUND(T6*(1-Terms!$B$4),2),Terms!$B$5) -> 237.01 | V6: =TEXT(DATEVALUE(D6)-WEEKDAY(DATEVALUE(D6),2)+1,"mm/dd/yyyy") -> 08/31/2026 | W6: =INDEX('Fuel Index'!$C$4:$C$12,MATCH(V6,'Fuel Index'!$A$4:$A$12,0)) -> 0.265 | X6: =ROUND(U6*W6,2) -> 62.81 | Y6: =IFERROR(INDEX(BOL!$I$4:$I$25,MATCH(C6,BOL!$B$4:$B$25,0)),INDEX(BOL!$V$4:$V$25,MATCH(C6,BOL!$O$4:$O$25,0))) -> N | Z6: =IFERROR(INDEX(BOL!$J$4:$J$25,MATCH(C6,BOL!$B$4:$B$25,0)),INDEX(BOL!$W$4:$W$25,MATCH(C6,BOL!$O$4:$O$25,0))) -> N | AA6: =IFERROR(INDEX(BOL!$K$4:$K$25,MATCH(C6,BOL!$B$4:$B$25,0)),INDEX(BOL!$X$4:$X$25,MATCH(C6,BOL!$O$4:$O$25,0))) -> Y | AB6: =IFERROR(INDEX(BOL!$L$4:$L$25,MATCH(C6,BOL!$B$4:$B$25,0)),INDEX(BOL!$Y$4:$Y$25,MATCH(C6,BOL!$O$4:$O$25,0))) -> N | AC6: =(Y6="Y")*Tariff!$O$4+(Z6="Y")*Tariff!$O$5+(AA6="Y")*Tariff!$O$6+(AB6="Y")*Tariff!$O$7 -> 85 | AD6: =SUMIFS(Confirmations!$G$4:$G$6,Confirmations!$A$4:$A$6,C6,Confirmations!$H$4:$H$6,"Yes") -> 0 | AE6: =AC6+AD6 -> 85 | AF6: =IF(COUNTIFS(Invoices!$B$4:$Q$26,B6,Invoices!$A$4:$P$26,"<"&A6)>0,"Yes","No") -> No | AG6: =IF(AF6="Yes",0,ROUND(U6+X6+AE6,2)) -> 384.82 | AH6: =Invoices!O6 -> 384.82 | AI6: =ROUND(AH6-AG6,2) -> 0 | AJ6: =Invoices!H6 -> 623.72 | AK6: =ROUND(Invoices!K6/Terms!$B$9,4) -> 0.265 | AL6: =Invoices!N6 -> 85 | AM6: =IF(AF6="Yes","7.1 duplicate bill",IF(L6<>N6,"4.3 class",IF(H6<>J6,"4.5 reweigh",IF(AJ6<>T6,"4.2 deficit weight",IF(AK6<>ROUND(W6,4),"5.2 fuel week",IF(AL6>AE6,"6.1 accessorial overbilled",IF(AL6<AE6,"6.1 accessorial omitted",""))))))) | AN6: =IF(AND(M6="Yes",L6<>K6),"4.3 inspection certificate",IF(AND(I6="Yes",H6<>G6,H6=J6),"4.5 certified scale ticket",IF(AD6>0,"6.1 written confirmation",IF(C6<>B6,"corrected pro number","")))) | AP6: =Invoices!P6 -> NFL-90340 | AQ6: =Invoices!Q6 -> 217883 | AR6: =IFERROR(INDEX('Pro Matches'!$C$4:$C$4,MATCH(AQ6,'Pro Matches'!$A$4:$A$4,0)),AQ6) -> 217883 | AS6: =IFERROR(INDEX(BOL!$C$4:$C$25,MATCH(AR6,BOL!$B$4:$B$25,0)),INDEX(BOL!$P$4:$P$25,MATCH(AR6,BOL!$O$4:$O$25,0))) -> 09/18/2026 | AT6: =IFERROR(INDEX(BOL!$E$4:$E$25,MATCH(AR6,BOL!$B$4:$B$25,0)),INDEX(BOL!$R$4:$R$25,MATCH(AR6,BOL!$O$4:$O$25,0))) -> WI | AU6: =IFERROR(INDEX(BOL!$F$4:$F$25,MATCH(AR6,BOL!$B$4:$B$25,0)),INDEX(BOL!$S$4:$S$25,MATCH(AR6,BOL!$O$4:$O$25,0))) -> Windows and doors | AV6: =IFERROR(INDEX(BOL!$H$4:$H$25,MATCH(AR6,BOL!$B$4:$B$25,0)),INDEX(BOL!$U$4:$U$25,MATCH(AR6,BOL!$O$4:$O$25,0))) -> 1010 | AW6: =Invoices!U6 -> 1010 | AX6: =IF(COUNTIFS('Billing File'!$A$4:$A$12,AR6,'Billing File'!$G$4:$G$12,"4.5 weight",'Billing File'!$F$4:$F$12,"Yes")>0,"Yes","No") -> No | AY6: =IF(AND(AX6="Yes",AW6>AV6*(1+Terms!$B$6)),AW6,AV6) -> 1010 | AZ6: =INDEX(Tariff!$L$4:$L$9,MATCH(AU6,Tariff!$K$4:$K$9,0)) -> 100 | BA6: =Invoices!V6 -> 100 | BB6: =IF(COUNTIFS('Billing File'!$A$4:$A$12,AR6,'Billing File'!$G$4:$G$12,"4.3 class",'Billing File'!$F$4:$F$12,"Yes")>0,"Yes","No") -> No | BC6: =IF(BB6="Yes",BA6,AZ6) -> 100 | BD6: =INDEX(Tariff!$I$4:$I$10,MATCH(BC6,Tariff!$H$4:$H$10,0)) -> 1.45 | BE6: =MATCH(AY6,Tariff!$B$12:$F$12,1) -> 3 | BF6: =INDEX(Tariff!$B$4:$F$10,MATCH(AT6,Tariff!$A$4:$A$10,0),BE6) -> 50.3 | BG6: =ROUND(AY6/100*BF6*BD6,2) -> 736.64 | BH6: =IF(BE6<5,ROUND(INDEX(Tariff!$B$12:$F$12,BE6+1)/100*INDEX(Tariff!$B$4:$F$10,MATCH(AT6,Tariff!$A$4:$A$10,0),BE6+1)*BD6,2),BG6) -> 1197.7 | BI6: =MIN(BG6,BH6) -> 736.64 | BJ6: =MAX(ROUND(BI6*(1-Terms!$B$4),2),Terms!$B$5) -> 279.92 | BK6: =TEXT(DATEVALUE(AS6)-WEEKDAY(DATEVALUE(AS6),2)+1,"mm/dd/yyyy") -> 09/14/2026 | BL6: =INDEX('Fuel Index'!$C$4:$C$12,MATCH(BK6,'Fuel Index'!$A$4:$A$12,0)) -> 0.26 | BM6: =ROUND(BJ6*BL6,2) -> 72.78 | BN6: =IFERROR(INDEX(BOL!$I$4:$I$25,MATCH(AR6,BOL!$B$4:$B$25,0)),INDEX(BOL!$V$4:$V$25,MATCH(AR6,BOL!$O$4:$O$25,0))) -> N | BO6: =IFERROR(INDEX(BOL!$J$4:$J$25,MATCH(AR6,BOL!$B$4:$B$25,0)),INDEX(BOL!$W$4:$W$25,MATCH(AR6,BOL!$O$4:$O$25,0))) -> Y | BP6: =IFERROR(INDEX(BOL!$K$4:$K$25,MATCH(AR6,BOL!$B$4:$B$25,0)),INDEX(BOL!$X$4:$X$25,MATCH(AR6,BOL!$O$4:$O$25,0))) -> N | BQ6: =IFERROR(INDEX(BOL!$L$4:$L$25,MATCH(AR6,BOL!$B$4:$B$25,0)),INDEX(BOL!$Y$4:$Y$25,MATCH(AR6,BOL!$O$4:$O$25,0))) -> N | BR6: =(BN6="Y")*Tariff!$O$4+(BO6="Y")*Tariff!$O$5+(BP6="Y")*Tariff!$O$6+(BQ6="Y")*Tariff!$O$7 -> 95 | BS6: =SUMIFS(Confirmations!$G$4:$G$6,Confirmations!$A$4:$A$6,AR6,Confirmations!$H$4:$H$6,"Yes") -> 0 | BT6: =BR6+BS6 -> 95 | BU6: =IF(COUNTIFS(Invoices!$B$4:$Q$26,AQ6,Invoices!$A$4:$P$26,"<"&AP6)>0,"Yes","No") -> No | BV6: =IF(BU6="Yes",0,ROUND(BJ6+BM6+BT6,2)) -> 447.7 | BW6: =Invoices!AD6 -> 447.7 | BX6: =ROUND(BW6-BV6,2) -> 0 | BY6: =Invoices!W6 -> 736.64 | BZ6: =ROUND(Invoices!Z6/Terms!$B$9,4) -> 0.26 | CA6: =Invoices!AC6 -> 95 | CB6: =IF(BU6="Yes","7.1 duplicate bill",IF(BA6<>BC6,"4.3 class",IF(AW6<>AY6,"4.5 reweigh",IF(BY6<>BI6,"4.2 deficit weight",IF(BZ6<>ROUND(BL6,4),"5.2 fuel week",IF(CA6>BT6,"6.1 accessorial overbilled",IF(CA6<BT6,"6.1 accessorial omitted",""))))))) | CC6: =IF(AND(BB6="Yes",BA6<>AZ6),"4.3 inspection certificate",IF(AND(AX6="Yes",AW6<>AV6,AW6=AY6),"4.5 certified scale ticket",IF(BS6>0,"6.1 written confirmation",IF(AR6<>AQ6,"corrected pro number",""))))
A7: =Invoices!A7 -> NFL-90313 | B7: =Invoices!B7 -> 217763 | C7: =IFERROR(INDEX('Pro Matches'!$C$4:$C$4,MATCH(B7,'Pro Matches'!$A$4:$A$4,0)),B7) -> 217763 | D7: =IFERROR(INDEX(BOL!$C$4:$C$25,MATCH(C7,BOL!$B$4:$B$25,0)),INDEX(BOL!$P$4:$P$25,MATCH(C7,BOL!$O$4:$O$25,0))) -> 09/01/2026 | E7: =IFERROR(INDEX(BOL!$E$4:$E$25,MATCH(C7,BOL!$B$4:$B$25,0)),INDEX(BOL!$R$4:$R$25,MATCH(C7,BOL!$O$4:$O$25,0))) -> IA | F7: =IFERROR(INDEX(BOL!$F$4:$F$25,MATCH(C7,BOL!$B$4:$B$25,0)),INDEX(BOL!$S$4:$S$25,MATCH(C7,BOL!$O$4:$O$25,0))) -> Fasteners and hardware | G7: =IFERROR(INDEX(BOL!$H$4:$H$25,MATCH(C7,BOL!$B$4:$B$25,0)),INDEX(BOL!$U$4:$U$25,MATCH(C7,BOL!$O$4:$O$25,0))) -> 1620 | H7: =Invoices!F7 -> 1620 | I7: =IF(COUNTIFS('Billing File'!$A$4:$A$12,C7,'Billing File'!$G$4:$G$12,"4.5 weight",'Billing File'!$F$4:$F$12,"Yes")>0,"Yes","No") -> No | J7: =IF(AND(I7="Yes",H7>G7*(1+Terms!$B$6)),H7,G7) -> 1620 | K7: =INDEX(Tariff!$L$4:$L$9,MATCH(F7,Tariff!$K$4:$K$9,0)) -> 60 | L7: =Invoices!G7 -> 60 | M7: =IF(COUNTIFS('Billing File'!$A$4:$A$12,C7,'Billing File'!$G$4:$G$12,"4.3 class",'Billing File'!$F$4:$F$12,"Yes")>0,"Yes","No") -> No | N7: =IF(M7="Yes",L7,K7) -> 60 | O7: =INDEX(Tariff!$I$4:$I$10,MATCH(N7,Tariff!$H$4:$H$10,0)) -> 0.94 | P7: =MATCH(J7,Tariff!$B$12:$F$12,1) -> 3 | Q7: =INDEX(Tariff!$B$4:$F$10,MATCH(E7,Tariff!$A$4:$A$10,0),P7) -> 47.6 | R7: =ROUND(J7/100*Q7*O7,2) -> 724.85 | S7: =IF(P7<5,ROUND(INDEX(Tariff!$B$12:$F$12,P7+1)/100*INDEX(Tariff!$B$4:$F$10,MATCH(E7,Tariff!$A$4:$A$10,0),P7+1)*O7,2),R7) -> 735.08 | T7: =MIN(R7,S7) -> 724.85 | U7: =MAX(ROUND(T7*(1-Terms!$B$4),2),Terms!$B$5) -> 275.44 | V7: =TEXT(DATEVALUE(D7)-WEEKDAY(DATEVALUE(D7),2)+1,"mm/dd/yyyy") -> 08/31/2026 | W7: =INDEX('Fuel Index'!$C$4:$C$12,MATCH(V7,'Fuel Index'!$A$4:$A$12,0)) -> 0.265 | X7: =ROUND(U7*W7,2) -> 72.99 | Y7: =IFERROR(INDEX(BOL!$I$4:$I$25,MATCH(C7,BOL!$B$4:$B$25,0)),INDEX(BOL!$V$4:$V$25,MATCH(C7,BOL!$O$4:$O$25,0))) -> Y | Z7: =IFERROR(INDEX(BOL!$J$4:$J$25,MATCH(C7,BOL!$B$4:$B$25,0)),INDEX(BOL!$W$4:$W$25,MATCH(C7,BOL!$O$4:$O$25,0))) -> N | AA7: =IFERROR(INDEX(BOL!$K$4:$K$25,MATCH(C7,BOL!$B$4:$B$25,0)),INDEX(BOL!$X$4:$X$25,MATCH(C7,BOL!$O$4:$O$25,0))) -> N | AB7: =IFERROR(INDEX(BOL!$L$4:$L$25,MATCH(C7,BOL!$B$4:$B$25,0)),INDEX(BOL!$Y$4:$Y$25,MATCH(C7,BOL!$O$4:$O$25,0))) -> N | AC7: =(Y7="Y")*Tariff!$O$4+(Z7="Y")*Tariff!$O$5+(AA7="Y")*Tariff!$O$6+(AB7="Y")*Tariff!$O$7 -> 75 | AD7: =SUMIFS(Confirmations!$G$4:$G$6,Confirmations!$A$4:$A$6,C7,Confirmations!$H$4:$H$6,"Yes") -> 0 | AE7: =AC7+AD7 -> 75 | AF7: =IF(COUNTIFS(Invoices!$B$4:$Q$26,B7,Invoices!$A$4:$P$26,"<"&A7)>0,"Yes","No") -> No | AG7: =IF(AF7="Yes",0,ROUND(U7+X7+AE7,2)) -> 423.43 | AH7: =Invoices!O7 -> 423.43 | AI7: =ROUND(AH7-AG7,2) -> 0 | AJ7: =Invoices!H7 -> 724.85 | AK7: =ROUND(Invoices!K7/Terms!$B$9,4) -> 0.265 | AL7: =Invoices!N7 -> 75 | AM7: =IF(AF7="Yes","7.1 duplicate bill",IF(L7<>N7,"4.3 class",IF(H7<>J7,"4.5 reweigh",IF(AJ7<>T7,"4.2 deficit weight",IF(AK7<>ROUND(W7,4),"5.2 fuel week",IF(AL7>AE7,"6.1 accessorial overbilled",IF(AL7<AE7,"6.1 accessorial omitted",""))))))) | AN7: =IF(AND(M7="Yes",L7<>K7),"4.3 inspection certificate",IF(AND(I7="Yes",H7<>G7,H7=J7),"4.5 certified scale ticket",IF(AD7>0,"6.1 written confirmation",IF(C7<>B7,"corrected pro number","")))) | AP7: =Invoices!P7 -> NFL-90341 | AQ7: =Invoices!Q7 -> 217803 | AR7: =IFERROR(INDEX('Pro Matches'!$C$4:$C$4,MATCH(AQ7,'Pro Matches'!$A$4:$A$4,0)),AQ7) -> 217803 | AS7: =IFERROR(INDEX(BOL!$C$4:$C$25,MATCH(AR7,BOL!$B$4:$B$25,0)),INDEX(BOL!$P$4:$P$25,MATCH(AR7,BOL!$O$4:$O$25,0))) -> 09/22/2026 | AT7: =IFERROR(INDEX(BOL!$E$4:$E$25,MATCH(AR7,BOL!$B$4:$B$25,0)),INDEX(BOL!$R$4:$R$25,MATCH(AR7,BOL!$O$4:$O$25,0))) -> IA | AU7: =IFERROR(INDEX(BOL!$F$4:$F$25,MATCH(AR7,BOL!$B$4:$B$25,0)),INDEX(BOL!$S$4:$S$25,MATCH(AR7,BOL!$O$4:$O$25,0))) -> Vinyl siding | AV7: =IFERROR(INDEX(BOL!$H$4:$H$25,MATCH(AR7,BOL!$B$4:$B$25,0)),INDEX(BOL!$U$4:$U$25,MATCH(AR7,BOL!$O$4:$O$25,0))) -> 3560 | AW7: =Invoices!U7 -> 3560 | AX7: =IF(COUNTIFS('Billing File'!$A$4:$A$12,AR7,'Billing File'!$G$4:$G$12,"4.5 weight",'Billing File'!$F$4:$F$12,"Yes")>0,"Yes","No") -> No | AY7: =IF(AND(AX7="Yes",AW7>AV7*(1+Terms!$B$6)),AW7,AV7) -> 3560 | AZ7: =INDEX(Tariff!$L$4:$L$9,MATCH(AU7,Tariff!$K$4:$K$9,0)) -> 92.5 | BA7: =Invoices!V7 -> 92.5 | BB7: =IF(COUNTIFS('Billing File'!$A$4:$A$12,AR7,'Billing File'!$G$4:$G$12,"4.3 class",'Billing File'!$F$4:$F$12,"Yes")>0,"Yes","No") -> No | BC7: =IF(BB7="Yes",BA7,AZ7) -> 92.5 | BD7: =INDEX(Tariff!$I$4:$I$10,MATCH(BC7,Tariff!$H$4:$H$10,0)) -> 1.3 | BE7: =MATCH(AY7,Tariff!$B$12:$F$12,1) -> 4 | BF7: =INDEX(Tariff!$B$4:$F$10,MATCH(AT7,Tariff!$A$4:$A$10,0),BE7) -> 39.1 | BG7: =ROUND(AY7/100*BF7*BD7,2) -> 1809.55 | BH7: =IF(BE7<5,ROUND(INDEX(Tariff!$B$12:$F$12,BE7+1)/100*INDEX(Tariff!$B$4:$F$10,MATCH(AT7,Tariff!$A$4:$A$10,0),BE7+1)*BD7,2),BG7) -> 2070.25 | BI7: =MIN(BG7,BH7) -> 1809.55 | BJ7: =MAX(ROUND(BI7*(1-Terms!$B$4),2),Terms!$B$5) -> 687.63 | BK7: =TEXT(DATEVALUE(AS7)-WEEKDAY(DATEVALUE(AS7),2)+1,"mm/dd/yyyy") -> 09/21/2026 | BL7: =INDEX('Fuel Index'!$C$4:$C$12,MATCH(BK7,'Fuel Index'!$A$4:$A$12,0)) -> 0.275 | BM7: =ROUND(BJ7*BL7,2) -> 189.1 | BN7: =IFERROR(INDEX(BOL!$I$4:$I$25,MATCH(AR7,BOL!$B$4:$B$25,0)),INDEX(BOL!$V$4:$V$25,MATCH(AR7,BOL!$O$4:$O$25,0))) -> N | BO7: =IFERROR(INDEX(BOL!$J$4:$J$25,MATCH(AR7,BOL!$B$4:$B$25,0)),INDEX(BOL!$W$4:$W$25,MATCH(AR7,BOL!$O$4:$O$25,0))) -> N | BP7: =IFERROR(INDEX(BOL!$K$4:$K$25,MATCH(AR7,BOL!$B$4:$B$25,0)),INDEX(BOL!$X$4:$X$25,MATCH(AR7,BOL!$O$4:$O$25,0))) -> N | BQ7: =IFERROR(INDEX(BOL!$L$4:$L$25,MATCH(AR7,BOL!$B$4:$B$25,0)),INDEX(BOL!$Y$4:$Y$25,MATCH(AR7,BOL!$O$4:$O$25,0))) -> Y | BR7: =(BN7="Y")*Tariff!$O$4+(BO7="Y")*Tariff!$O$5+(BP7="Y")*Tariff!$O$6+(BQ7="Y")*Tariff!$O$7 -> 60 | BS7: =SUMIFS(Confirmations!$G$4:$G$6,Confirmations!$A$4:$A$6,AR7,Confirmations!$H$4:$H$6,"Yes") -> 0 | BT7: =BR7+BS7 -> 60 | BU7: =IF(COUNTIFS(Invoices!$B$4:$Q$26,AQ7,Invoices!$A$4:$P$26,"<"&AP7)>0,"Yes","No") -> No | BV7: =IF(BU7="Yes",0,ROUND(BJ7+BM7+BT7,2)) -> 936.73 | BW7: =Invoices!AD7 -> 936.73 | BX7: =ROUND(BW7-BV7,2) -> 0 | BY7: =Invoices!W7 -> 1809.55 | BZ7: =ROUND(Invoices!Z7/Terms!$B$9,4) -> 0.275 | CA7: =Invoices!AC7 -> 60 | CB7: =IF(BU7="Yes","7.1 duplicate bill",IF(BA7<>BC7,"4.3 class",IF(AW7<>AY7,"4.5 reweigh",IF(BY7<>BI7,"4.2 deficit weight",IF(BZ7<>ROUND(BL7,4),"5.2 fuel week",IF(CA7>BT7,"6.1 accessorial overbilled",IF(CA7<BT7,"6.1 accessorial omitted",""))))))) | CC7: =IF(AND(BB7="Yes",BA7<>AZ7),"4.3 inspection certificate",IF(AND(AX7="Yes",AW7<>AV7,AW7=AY7),"4.5 certified scale ticket",IF(BS7>0,"6.1 written confirmation",IF(AR7<>AQ7,"corrected pro number",""))))
A8: =Invoices!A8 -> NFL-90314 | B8: =Invoices!B8 -> 217822 | C8: =IFERROR(INDEX('Pro Matches'!$C$4:$C$4,MATCH(B8,'Pro Matches'!$A$4:$A$4,0)),B8) -> 217822 | D8: =IFERROR(INDEX(BOL!$C$4:$C$25,MATCH(C8,BOL!$B$4:$B$25,0)),INDEX(BOL!$P$4:$P$25,MATCH(C8,BOL!$O$4:$O$25,0))) -> 09/07/2026 | E8: =IFERROR(INDEX(BOL!$E$4:$E$25,MATCH(C8,BOL!$B$4:$B$25,0)),INDEX(BOL!$R$4:$R$25,MATCH(C8,BOL!$O$4:$O$25,0))) -> WI | F8: =IFERROR(INDEX(BOL!$F$4:$F$25,MATCH(C8,BOL!$B$4:$B$25,0)),INDEX(BOL!$S$4:$S$25,MATCH(C8,BOL!$O$4:$O$25,0))) -> Metal roofing panels | G8: =IFERROR(INDEX(BOL!$H$4:$H$25,MATCH(C8,BOL!$B$4:$B$25,0)),INDEX(BOL!$U$4:$U$25,MATCH(C8,BOL!$O$4:$O$25,0))) -> 4210 | H8: =Invoices!F8 -> 4210 | I8: =IF(COUNTIFS('Billing File'!$A$4:$A$12,C8,'Billing File'!$G$4:$G$12,"4.5 weight",'Billing File'!$F$4:$F$12,"Yes")>0,"Yes","No") -> No | J8: =IF(AND(I8="Yes",H8>G8*(1+Terms!$B$6)),H8,G8) -> 4210 | K8: =INDEX(Tariff!$L$4:$L$9,MATCH(F8,Tariff!$K$4:$K$9,0)) -> 70 | L8: =Invoices!G8 -> 70 | M8: =IF(COUNTIFS('Billing File'!$A$4:$A$12,C8,'Billing File'!$G$4:$G$12,"4.3 class",'Billing File'!$F$4:$F$12,"Yes")>0,"Yes","No") -> No | N8: =IF(M8="Yes",L8,K8) -> 70 | O8: =INDEX(Tariff!$I$4:$I$10,MATCH(N8,Tariff!$H$4:$H$10,0)) -> 1 | P8: =MATCH(J8,Tariff!$B$12:$F$12,1) -> 4 | Q8: =INDEX(Tariff!$B$4:$F$10,MATCH(E8,Tariff!$A$4:$A$10,0),P8) -> 41.3 | R8: =ROUND(J8/100*Q8*O8,2) -> 1738.73 | S8: =IF(P8<5,ROUND(INDEX(Tariff!$B$12:$F$12,P8+1)/100*INDEX(Tariff!$B$4:$F$10,MATCH(E8,Tariff!$A$4:$A$10,0),P8+1)*O8,2),R8) -> 1682.5 | T8: =MIN(R8,S8) -> 1682.5 | U8: =MAX(ROUND(T8*(1-Terms!$B$4),2),Terms!$B$5) -> 639.35 | V8: =TEXT(DATEVALUE(D8)-WEEKDAY(DATEVALUE(D8),2)+1,"mm/dd/yyyy") -> 09/07/2026 | W8: =INDEX('Fuel Index'!$C$4:$C$12,MATCH(V8,'Fuel Index'!$A$4:$A$12,0)) -> 0.265 | X8: =ROUND(U8*W8,2) -> 169.43 | Y8: =IFERROR(INDEX(BOL!$I$4:$I$25,MATCH(C8,BOL!$B$4:$B$25,0)),INDEX(BOL!$V$4:$V$25,MATCH(C8,BOL!$O$4:$O$25,0))) -> Y | Z8: =IFERROR(INDEX(BOL!$J$4:$J$25,MATCH(C8,BOL!$B$4:$B$25,0)),INDEX(BOL!$W$4:$W$25,MATCH(C8,BOL!$O$4:$O$25,0))) -> N | AA8: =IFERROR(INDEX(BOL!$K$4:$K$25,MATCH(C8,BOL!$B$4:$B$25,0)),INDEX(BOL!$X$4:$X$25,MATCH(C8,BOL!$O$4:$O$25,0))) -> N | AB8: =IFERROR(INDEX(BOL!$L$4:$L$25,MATCH(C8,BOL!$B$4:$B$25,0)),INDEX(BOL!$Y$4:$Y$25,MATCH(C8,BOL!$O$4:$O$25,0))) -> N | AC8: =(Y8="Y")*Tariff!$O$4+(Z8="Y")*Tariff!$O$5+(AA8="Y")*Tariff!$O$6+(AB8="Y")*Tariff!$O$7 -> 75 | AD8: =SUMIFS(Confirmations!$G$4:$G$6,Confirmations!$A$4:$A$6,C8,Confirmations!$H$4:$H$6,"Yes") -> 0 | AE8: =AC8+AD8 -> 75 | AF8: =IF(COUNTIFS(Invoices!$B$4:$Q$26,B8,Invoices!$A$4:$P$26,"<"&A8)>0,"Yes","No") -> No | AG8: =IF(AF8="Yes",0,ROUND(U8+X8+AE8,2)) -> 883.78 | AH8: =Invoices!O8 -> 883.78 | AI8: =ROUND(AH8-AG8,2) -> 0 | AJ8: =Invoices!H8 -> 1682.5 | AK8: =ROUND(Invoices!K8/Terms!$B$9,4) -> 0.265 | AL8: =Invoices!N8 -> 75 | AM8: =IF(AF8="Yes","7.1 duplicate bill",IF(L8<>N8,"4.3 class",IF(H8<>J8,"4.5 reweigh",IF(AJ8<>T8,"4.2 deficit weight",IF(AK8<>ROUND(W8,4),"5.2 fuel week",IF(AL8>AE8,"6.1 accessorial overbilled",IF(AL8<AE8,"6.1 accessorial omitted",""))))))) | AN8: =IF(AND(M8="Yes",L8<>K8),"4.3 inspection certificate",IF(AND(I8="Yes",H8<>G8,H8=J8),"4.5 certified scale ticket",IF(AD8>0,"6.1 written confirmation",IF(C8<>B8,"corrected pro number","")))) | AP8: =Invoices!P8 -> NFL-90342 | AQ8: =Invoices!Q8 -> 217894 | AR8: =IFERROR(INDEX('Pro Matches'!$C$4:$C$4,MATCH(AQ8,'Pro Matches'!$A$4:$A$4,0)),AQ8) -> 217894 | AS8: =IFERROR(INDEX(BOL!$C$4:$C$25,MATCH(AR8,BOL!$B$4:$B$25,0)),INDEX(BOL!$P$4:$P$25,MATCH(AR8,BOL!$O$4:$O$25,0))) -> 09/22/2026 | AT8: =IFERROR(INDEX(BOL!$E$4:$E$25,MATCH(AR8,BOL!$B$4:$B$25,0)),INDEX(BOL!$R$4:$R$25,MATCH(AR8,BOL!$O$4:$O$25,0))) -> IA | AU8: =IFERROR(INDEX(BOL!$F$4:$F$25,MATCH(AR8,BOL!$B$4:$B$25,0)),INDEX(BOL!$S$4:$S$25,MATCH(AR8,BOL!$O$4:$O$25,0))) -> Sealants and coatings | AV8: =IFERROR(INDEX(BOL!$H$4:$H$25,MATCH(AR8,BOL!$B$4:$B$25,0)),INDEX(BOL!$U$4:$U$25,MATCH(AR8,BOL!$O$4:$O$25,0))) -> 890 | AW8: =Invoices!U8 -> 890 | AX8: =IF(COUNTIFS('Billing File'!$A$4:$A$12,AR8,'Billing File'!$G$4:$G$12,"4.5 weight",'Billing File'!$F$4:$F$12,"Yes")>0,"Yes","No") -> No | AY8: =IF(AND(AX8="Yes",AW8>AV8*(1+Terms!$B$6)),AW8,AV8) -> 890 | AZ8: =INDEX(Tariff!$L$4:$L$9,MATCH(AU8,Tariff!$K$4:$K$9,0)) -> 85 | BA8: =Invoices!V8 -> 85 | BB8: =IF(COUNTIFS('Billing File'!$A$4:$A$12,AR8,'Billing File'!$G$4:$G$12,"4.3 class",'Billing File'!$F$4:$F$12,"Yes")>0,"Yes","No") -> No | BC8: =IF(BB8="Yes",BA8,AZ8) -> 85 | BD8: =INDEX(Tariff!$I$4:$I$10,MATCH(BC8,Tariff!$H$4:$H$10,0)) -> 1.15 | BE8: =MATCH(AY8,Tariff!$B$12:$F$12,1) -> 2 | BF8: =INDEX(Tariff!$B$4:$F$10,MATCH(AT8,Tariff!$A$4:$A$10,0),BE8) -> 55.9 | BG8: =ROUND(AY8/100*BF8*BD8,2) -> 572.14 | BH8: =IF(BE8<5,ROUND(INDEX(Tariff!$B$12:$F$12,BE8+1)/100*INDEX(Tariff!$B$4:$F$10,MATCH(AT8,Tariff!$A$4:$A$10,0),BE8+1)*BD8,2),BG8) -> 547.4 | BI8: =MIN(BG8,BH8) -> 547.4 | BJ8: =MAX(ROUND(BI8*(1-Terms!$B$4),2),Terms!$B$5) -> 208.01 | BK8: =TEXT(DATEVALUE(AS8)-WEEKDAY(DATEVALUE(AS8),2)+1,"mm/dd/yyyy") -> 09/21/2026 | BL8: =INDEX('Fuel Index'!$C$4:$C$12,MATCH(BK8,'Fuel Index'!$A$4:$A$12,0)) -> 0.275 | BM8: =ROUND(BJ8*BL8,2) -> 57.2 | BN8: =IFERROR(INDEX(BOL!$I$4:$I$25,MATCH(AR8,BOL!$B$4:$B$25,0)),INDEX(BOL!$V$4:$V$25,MATCH(AR8,BOL!$O$4:$O$25,0))) -> N | BO8: =IFERROR(INDEX(BOL!$J$4:$J$25,MATCH(AR8,BOL!$B$4:$B$25,0)),INDEX(BOL!$W$4:$W$25,MATCH(AR8,BOL!$O$4:$O$25,0))) -> N | BP8: =IFERROR(INDEX(BOL!$K$4:$K$25,MATCH(AR8,BOL!$B$4:$B$25,0)),INDEX(BOL!$X$4:$X$25,MATCH(AR8,BOL!$O$4:$O$25,0))) -> N | BQ8: =IFERROR(INDEX(BOL!$L$4:$L$25,MATCH(AR8,BOL!$B$4:$B$25,0)),INDEX(BOL!$Y$4:$Y$25,MATCH(AR8,BOL!$O$4:$O$25,0))) -> N | BR8: =(BN8="Y")*Tariff!$O$4+(BO8="Y")*Tariff!$O$5+(BP8="Y")*Tariff!$O$6+(BQ8="Y")*Tariff!$O$7 -> 0 | BS8: =SUMIFS(Confirmations!$G$4:$G$6,Confirmations!$A$4:$A$6,AR8,Confirmations!$H$4:$H$6,"Yes") -> 0 | BT8: =BR8+BS8 -> 0 | BU8: =IF(COUNTIFS(Invoices!$B$4:$Q$26,AQ8,Invoices!$A$4:$P$26,"<"&AP8)>0,"Yes","No") -> No | BV8: =IF(BU8="Yes",0,ROUND(BJ8+BM8+BT8,2)) -> 265.21 | BW8: =Invoices!AD8 -> 353.21 | BX8: =ROUND(BW8-BV8,2) -> 88 | BY8: =Invoices!W8 -> 547.4 | BZ8: =ROUND(Invoices!Z8/Terms!$B$9,4) -> 0.275 | CA8: =Invoices!AC8 -> 88 | CB8: =IF(BU8="Yes","7.1 duplicate bill",IF(BA8<>BC8,"4.3 class",IF(AW8<>AY8,"4.5 reweigh",IF(BY8<>BI8,"4.2 deficit weight",IF(BZ8<>ROUND(BL8,4),"5.2 fuel week",IF(CA8>BT8,"6.1 accessorial overbilled",IF(CA8<BT8,"6.1 accessorial omitted",""))))))) -> 6.1 accessorial overbilled | CC8: =IF(AND(BB8="Yes",BA8<>AZ8),"4.3 inspection certificate",IF(AND(AX8="Yes",AW8<>AV8,AW8=AY8),"4.5 certified scale ticket",IF(BS8>0,"6.1 written confirmation",IF(AR8<>AQ8,"corrected pro number",""))))
