Workbook

Sheet Summary
A1: Concrete acceptance summary, project 2417, Harbor View Parking Structure, placements of August and September 2026
A2: Prepared for the engineer of record and the owner's representative under Section 03 30 00, 3.12.1; summary prepared October 21, 2026
A4: Finding | B4: M-4000 | C4: M-6000 | D4: Read from
A5: Project number | B5: 2417 | C5: 2417 | D5: Placement log and break record
A6: Specified strength f'c (psi) | B6: =Parameters!B4 -> 4000 | C6: =Parameters!C4 -> 6000 | D6: Parameters
A7: Strength tests used for acceptance | B7: ='Acceptance decks'!B25 -> 12 | C7: ='Acceptance columns'!B17 -> 10 | D7: Acceptance tabs
A8: Sets cast and not used for acceptance | B8: =COUNTIFS(Samples!$H$4:$H$32,B4,Samples!$Y$4:$Y$32,"No") -> 6 | C8: =COUNTIFS(Samples!$H$4:$H$32,C4,Samples!$Y$4:$Y$32,"No") -> 0 | D8: Samples and Tests
A9: Lowest strength test (psi) | B9: ='Acceptance decks'!B26 -> 3460 | C9: ='Acceptance columns'!B18 -> 5400 | D9: Acceptance tabs
A10: Moving averages of three below f'c, criterion (a) | B10: ='Acceptance decks'!B27 -> 3 | C10: ='Acceptance columns'!B19 -> 5 | D10: Acceptance tabs
A11: Lowest moving average of three (psi) | B11: ='Acceptance decks'!B28 -> 3706.7 | C11: ='Acceptance columns'!B20 -> 5860 | D11: Acceptance tabs
A12: Tests below f'c by more than the allowance, criterion (b) | B12: ='Acceptance decks'!B29 -> 2 | C12: ='Acceptance columns'!B21 -> 0 | D12: Acceptance tabs
A13: Placements with a test failing criterion (b) | B13: ='Acceptance decks'!B33 -> P-05 P-06 | C13: ='Acceptance columns'!B25 -> None | D13: Acceptance tabs
A14: Acceptance under 3.11.1 | B14: ='Acceptance decks'!B34 -> Does not meet 3.11.1 | C14: ='Acceptance columns'!B26 -> Does not meet 3.11.1 | D14: Acceptance tabs
A15: What 3.11.2 calls for next | B15: =IF(AND(B12>0,B10>0),"Report each placement to the engineer of record; the contractor investigates under ACI 318-19 section 26.12.6, which may include cores under ASTM C42, and takes steps to increase the average of subsequent strength tests",IF(B12>0,"Report each placement to the engineer of record; the contractor investigates under ACI 318-19 section 26.12.6, which may include cores under ASTM C42",IF(B10>0,"The contractor takes steps to increase the average of subsequent strength tests; no placement goes to investigation","No action"))) -> Report each placement to the engineer of record; the contractor investigates under ACI 318-19 section 26.12.6, which may include cores under ASTM C42, and takes steps to increase the average of subsequent strength tests | C15: =IF(AND(C12>0,C10>0),"Report each placement to the engineer of record; the contractor investigates under ACI 318-19 section 26.12.6, which may include cores under ASTM C42, and takes steps to increase the average of subsequent strength tests",IF(C12>0,"Report each placement to the engineer of record; the contractor investigates under ACI 318-19 section 26.12.6, which may include cores under ASTM C42",IF(C10>0,"The contractor takes steps to increase the average of subsequent strength tests; no placement goes to investigation","No action"))) -> The contractor takes steps to increase the average of subsequent strength tests; no placement goes to investigation | D15: 3.11.2
A16: Core average floor, 85 percent of f'c (psi) | B16: =Parameters!B6 -> 3400 | C16: =Parameters!C6 -> 5100 | D16: Parameters
A17: Core single floor, 75 percent of f'c (psi) | B17: =Parameters!B7 -> 3000 | C17: =Parameters!C7 -> 4500 | D17: Parameters
A18: Sampling, sets and notes, both mixtures
A19: Days on which a mixture was sampled short of 3.10.1 | B19: =Sampling!D31 -> 7 | D19: Sampling
A20: Days short, listed | B20: =Sampling!D32 -> 08/10 M-4000; 08/14 M-4000; 08/17 M-4000; 08/21 M-4000; 08/26 M-4000; 08/29 M-4000; 09/11 M-4000 | D20: Sampling
A21: Sets cast and not used, both mixtures | B21: =COUNTIF(Samples!$Y$4:$Y$32,"No") -> 6 | D21: Samples and Tests
A22: Tests with a within-test range note | B22: =Tests!D34 -> 2 | D22: Tests
A23: Tests used that carry a curing note | B23: =Tests!D35 -> 3 | D23: Tests
A24: Samples outside a fresh concrete limit | B24: =Tests!D36 -> 3 | D24: Tests
A25: Cylinders on the break record | B25: =Cylinders!D115 -> 110 | D25: Cylinders
A27: Every value on this page reads from the tab named beside it. The Cylinders tab computes each cylinder strength and age from the break record and the field sampling log, and the Tests, Acceptance and Sampling tabs read from it.

Sheet Parameters
A1: Parameters and conventions the summary applies, from Section 03 30 00, LP-07 and the project file
A3: Parameter | B3: M-4000 | C3: M-6000 | D3: Source
A4: Specified strength f'c (psi) | B4: 4000 | C4: 6000 | D4: Section 03 30 00, 2.4
A5: Criterion (b) allowance below f'c (psi) | B5: =IF(B4<=5000,500,B4*0.1) -> 500 | C5: =IF(C4<=5000,500,C4*0.1) -> 600 | D5: 3.11.1(b)
A6: Core average floor, 85 percent of f'c (psi) | B6: =B4*0.85 -> 3400 | C6: =C4*0.85 -> 5100 | D6: 3.11.2
A7: Core single floor, 75 percent of f'c (psi) | B7: =B4*0.75 -> 3000 | C7: =C4*0.75 -> 4500 | D7: 3.11.2
A8: Slump, low limit (in) | B8: 3 | C8: 5 | D8: 2.4
A9: Slump, high limit (in) | B9: 5 | C9: 7 | D9: 2.4
A10: Air content, low limit (percent) | B10: 4.5 | C10: 2 | D10: 2.4
A11: Air content, high limit (percent) | B11: 7.5 | C11: 4 | D11: 2.4
A12: Maximum concrete temperature (F) | B12: 90 | C12: 90 | D12: 2.4
A13: Approved mix design, Kolstad Ready Mix | B13: 4A317 | C13: 6S224 | D13: 2.4
A15: Parameter | B15: Value | D15: Source
A16: Cubic yards per strength test | B16: 150 | D16: 3.10.1
A17: Square feet of slab or wall surface per strength test | B17: 5000 | D17: 3.10.1
A18: Cylinders per test, 6 by 12 | B18: 2 | D18: 3.10.2
A19: Cylinders per test, 4 by 8 | B19: 3 | D19: 3.10.2
A20: Test age (hours), 28 days | B20: 672 | D20: 3.10.3
A21: Age tolerance (hours) either side | B21: 20 | D21: 3.10.3; LP-07 1.2
A22: Range limit, two 6 by 12 cylinders (percent) | B22: 6.6 | D22: 3.10.4; LP-07 2.3
A23: Range limit, three 4 by 8 cylinders (percent) | B23: 10.6 | D23: 3.10.4; LP-07 2.3
A24: Initial curing, low limit (F) | B24: 60 | D24: 3.10.6
A25: Initial curing, high limit (F) | B25: 80 | D25: 3.10.6
A26: Initial curing, longest period (hours) | B26: 48 | D26: 3.10.6
A27: Rounding unit for strengths (psi) | B27: 10 | D27: 3.10.3; LP-07 2.2
... A31: Latest age reported for information (days) | B31: 31 | D31: Cylinders broken near 28 days
A33: Conventions the figures rest on | D33: Source
A34: Age is reckoned in hours from the time of molding on the field sampling log to the time of the break, and a cylinder counts at 28 days when it is within 20 hours of 672 hours. | D34: 3.10.3; LP-07 1.2
A35: Each cylinder strength is the load over the area from the average of the two measured diameters, with pi carried in full and the average diameter carried without rounding. | D35: 3.10.3; LP-07 2.1
A36: A cylinder with a defect written on the break record is discarded, and the reserve cylinder broken at 28 days enters the test in its place. | D36: 3.10.5
A37: Sets molded from one delivery ticket are one sample and make one strength test, and one truck batched at one time is one delivery ticket whatever number was written on the line. | D37: 3.10.2
A38: L. Brandvold's lines are on the 12 hour clock, and each time is read into the hours the placement log gives for the placement. | D38: LP-07 1.4; placement log
A39: The cast date of a set is the date the placement log gives for the placement it was molded from. | D39: Placement log; laboratory memo item 3
A40: The box thermometer is read as a low and a high, whichever was written first. | D40: LP-07 1.5
A41: Field cured cylinders are reported apart and are not strength tests. | D41: 3.10.6
A42: A test is set aside only on the written direction of the engineer of record. | D42: 3.10.7
A43: Tests run in the order their samples were molded, by date and time, and the first two averages of each mixture take in the last two July tests used for acceptance, as corrected by the laboratory's letter of September 15. | D43: 3.11.3; July transmittal
A44: A moving average equal to f'c meets criterion (a), and a test below f'c by exactly the allowance meets criterion (b). | D44: 3.11.1
... A46: Sampling is judged on the day's total of each mixture across every placement of the day, and it is met only by strength tests used for acceptance. | D46: 3.10.1

Sheet Placements
A1: Placement log, placement_log_2417.csv, line for line, with the mixture of each placement
A3: PLACEMENT_ID | B3: DATE | C3: ELEMENT | D3: MIX_DESIGN | E3: CUBIC_YARDS | F3: SURFACE_AREA_SF | G3: START | H3: FINISH | I3: MIXTURE
A4: P-01 | B4: 08/03/2026 | C4: Level 2 deck bay A | D4: 4A317 | E4: 104 | F4: 4810 | G4: 06:40 | H4: 11:25 | I4: =IF(D4=Parameters!$B$13,Parameters!$B$3,Parameters!$C$3) -> M-4000
A5: P-02 | B5: 08/05/2026 | C5: Level 2 deck bay B | D5: 4A317 | E5: 98 | F5: 4540 | G5: 06:55 | H5: 11:10 | I5: =IF(D5=Parameters!$B$13,Parameters!$B$3,Parameters!$C$3) -> M-4000
A6: P-03 | B6: 08/05/2026 | C6: Level 2 stair landings | D6: 4A317 | E6: 9 | F6: 410 | G6: 11:30 | H6: 12:20 | I6: =IF(D6=Parameters!$B$13,Parameters!$B$3,Parameters!$C$3) -> M-4000
A7: P-04 | B7: 08/06/2026 | C7: Columns Level 2 grid 1 to 4 | D7: 6S224 | E7: 38 | G7: 08:50 | H7: 12:05 | I7: =IF(D7=Parameters!$B$13,Parameters!$B$3,Parameters!$C$3) -> M-6000
A8: P-05 | B8: 08/10/2026 | C8: Level 2 deck bays C and D | D8: 4A317 | E8: 318 | F8: 14720 | G8: 05:50 | H8: 16:10 | I8: =IF(D8=Parameters!$B$13,Parameters!$B$3,Parameters!$C$3) -> M-4000
A9: P-06 | B9: 08/12/2026 | C9: Level 3 deck bay A | D9: 4A317 | E9: 101 | F9: 4670 | G9: 06:45 | H9: 11:35 | I9: =IF(D9=Parameters!$B$13,Parameters!$B$3,Parameters!$C$3) -> M-4000
A10: P-07 | B10: 08/13/2026 | C10: Columns Level 2 grid 5 to 8 | D10: 6S224 | E10: 41 | G10: 08:20 | H10: 11:50 | I10: =IF(D10=Parameters!$B$13,Parameters!$B$3,Parameters!$C$3) -> M-6000
A11: P-08 | B11: 08/14/2026 | C11: Level 3 deck bay B | D11: 4A317 | E11: 112 | F11: 5180 | G11: 06:30 | H11: 11:55 | I11: =IF(D11=Parameters!$B$13,Parameters!$B$3,Parameters!$C$3) -> M-4000
A12: P-09 | B12: 08/15/2026 | C12: Ramp slab south lower run | D12: 4A317 | E12: 150 | F12: 4860 | G12: 05:55 | H12: 12:40 | I12: =IF(D12=Parameters!$B$13,Parameters!$B$3,Parameters!$C$3) -> M-4000
A13: P-10 | B13: 08/17/2026 | C13: Level 3 deck bay C | D13: 4A317 | E13: 151 | F13: 6990 | G13: 06:35 | H13: 13:05 | I13: =IF(D13=Parameters!$B$13,Parameters!$B$3,Parameters!$C$3) -> M-4000
A14: P-11 | B14: 08/18/2026 | C14: Columns Level 3 grid 1 to 4 | D14: 6S224 | E14: 36 | G14: 09:05 | H14: 12:15 | I14: =IF(D14=Parameters!$B$13,Parameters!$B$3,Parameters!$C$3) -> M-6000
A15: P-12 | B15: 08/19/2026 | C15: Level 3 deck bay D | D15: 4A317 | E15: 106 | F15: 4905 | G15: 06:50 | H15: 11:45 | I15: =IF(D15=Parameters!$B$13,Parameters!$B$3,Parameters!$C$3) -> M-4000
A16: P-13 | B16: 08/20/2026 | C16: Columns Level 3 grid 5 to 8 | D16: 6S224 | E16: 37 | G16: 08:40 | H16: 11:55 | I16: =IF(D16=Parameters!$B$13,Parameters!$B$3,Parameters!$C$3) -> M-6000
A17: P-14 | B17: 08/21/2026 | C17: Ramp slab north | D17: 4A317 | E17: 96 | F17: 3110 | G17: 07:10 | H17: 11:20 | I17: =IF(D17=Parameters!$B$13,Parameters!$B$3,Parameters!$C$3) -> M-4000
A18: P-15 | B18: 08/24/2026 | C18: Level 4 deck bay A | D18: 4A317 | E18: 103 | F18: 4770 | G18: 09:30 | H18: 14:50 | I18: =IF(D18=Parameters!$B$13,Parameters!$B$3,Parameters!$C$3) -> M-4000
A19: P-16 | B19: 08/24/2026 | C19: Columns Level 3 grid 9 to 12 | D19: 6S224 | E19: 39 | G19: 12:40 | H19: 15:35 | I19: =IF(D19=Parameters!$B$13,Parameters!$B$3,Parameters!$C$3) -> M-6000
A20: P-17 | B20: 08/26/2026 | C20: Level 4 deck bay B | D20: 4A317 | E20: 99 | F20: 4580 | G20: 06:35 | H20: 11:15 | I20: =IF(D20=Parameters!$B$13,Parameters!$B$3,Parameters!$C$3) -> M-4000
A21: P-18 | B21: 08/26/2026 | C21: Columns Level 4 grid 1 to 4 | D21: 6S224 | E21: 40 | G21: 09:50 | H21: 13:10 | I21: =IF(D21=Parameters!$B$13,Parameters!$B$3,Parameters!$C$3) -> M-6000
A22: P-19 | B22: 08/27/2026 | C22: Shear walls stair 2 lifts 1 and 2 | D22: 6S224 | E22: 52 | F22: 1390 | G22: 07:30 | H22: 12:30 | I22: =IF(D22=Parameters!$B$13,Parameters!$B$3,Parameters!$C$3) -> M-6000
A23: P-20 | B23: 08/29/2026 | C23: Level 4 deck bay C | D23: 4A317 | E23: 107 | F23: 4950 | G23: 07:45 | H23: 13:20 | I23: =IF(D23=Parameters!$B$13,Parameters!$B$3,Parameters!$C$3) -> M-4000
A24: P-21 | B24: 08/31/2026 | C24: Level 4 deck bay D and crossover | D24: 4A317 | E24: 212 | F24: 9810 | G24: 06:10 | H24: 14:35 | I24: =IF(D24=Parameters!$B$13,Parameters!$B$3,Parameters!$C$3) -> M-4000
A25: P-22 | B25: 09/02/2026 | C25: Columns Level 4 grid 5 to 8 | D25: 6S224 | E25: 38 | G25: 08:35 | H25: 11:40 | I25: =IF(D25=Parameters!$B$13,Parameters!$B$3,Parameters!$C$3) -> M-6000
A26: P-23 | B26: 09/03/2026 | C26: Shear walls stair 2 lifts 3 and 4 | D26: 6S224 | E26: 49 | F26: 1310 | G26: 07:20 | H26: 12:10 | I26: =IF(D26=Parameters!$B$13,Parameters!$B$3,Parameters!$C$3) -> M-6000
A27: P-24 | B27: 09/08/2026 | C27: Ramp slab south upper run | D27: 4A317 | E27: 88 | F27: 2850 | G27: 07:35 | H27: 11:50 | I27: =IF(D27=Parameters!$B$13,Parameters!$B$3,Parameters!$C$3) -> M-4000
A28: P-25 | B28: 09/10/2026 | C28: Shear walls stair 1 lifts 1 and 2 | D28: 6S224 | E28: 49 | F28: 1310 | G28: 07:05 | H28: 11:30 | I28: =IF(D28=Parameters!$B$13,Parameters!$B$3,Parameters!$C$3) -> M-6000
A29: P-26 | B29: 09/10/2026 | C29: Columns Level 4 grid 9 to 12 | D29: 6S224 | E29: 37 | G29: 12:15 | H29: 15:20 | I29: =IF(D29=Parameters!$B$13,Parameters!$B$3,Parameters!$C$3) -> M-6000
A30: P-27 | B30: 09/11/2026 | C30: Level 4 curbs and islands | D30: 4A317 | E30: 14 | F30: 640 | G30: 08:10 | H30: 10:05 | I30: =IF(D30=Parameters!$B$13,Parameters!$B$3,Parameters!$C$3) -> M-4000

Sheet Samples
A1: Field sampling log, field_sampling_log_2417.csv, one line per set, as read against the placement log and the project file
A3: SET_NO | B3: FIELD_TECH | C3: DATE_CAST | D3: TIME_MOLDED | E3: LOCATION | F3: TICKET_NO | G3: MIX_DESIGN | H3: MIXTURE | I3: PLACEMENT_ID | J3: SLUMP_IN | K3: AIR_PCT | L3: CONC_TEMP_F | M3: FRESH_CONCRETE | N3: CYL_SIZE | O3: INITIAL_CURING | P3: CURING_CLASS | Q3: BOX_LOW_F | R3: BOX_HIGH_F | S3: PICKED_UP_DATE | T3: PICKED_UP_TIME | U3: HOURS_IN_BOX | V3: CURING_NOTE | W3: ENGINEER_DIRECTION | X3: MOLDED_SERIAL | Y3: USED | Z3: READING_OF_THE_FIELD_LOG
A4: S-101 | B4: R. Okafor | C4: 08/03/2026 | D4: 07:23 | E4: L2 deck bay A at pump | F4: 770418 | G4: 4A317 | H4: =IF(G4=Parameters!$B$13,Parameters!$B$3,Parameters!$C$3) -> M-4000 | I4: P-01 | J4: 4.25 | K4: 6.2 | L4: 74 | M4: =IF(AND(J4>=IF(H4=Parameters!$B$3,Parameters!$B$8,Parameters!$C$8),J4<=IF(H4=Parameters!$B$3,Parameters!$B$9,Parameters!$C$9),K4>=IF(H4=Parameters!$B$3,Parameters!$B$10,Parameters!$C$10),K4<=IF(H4=Parameters!$B$3,Parameters!$B$11,Parameters!$C$11),L4<=IF(H4=Parameters!$B$3,Parameters!$B$12,Parameters!$C$12)),"Within 2.4","Outside 2.4") -> Within 2.4 | N4: 6x12 | O4: Box 1 | P4: Standard | Q4: 63 | R4: 77 | S4: 08/04/2026 | T4: 07:52 | U4: =IF(P4="Standard",ROUND((DATE(VALUE(RIGHT(S4,4)),VALUE(LEFT(S4,2)),VALUE(MID(S4,4,2)))+VALUE(LEFT(T4,2))/Parameters!$B$28+VALUE(RIGHT(T4,2))/Parameters!$B$29-X4)*Parameters!$B$28,2),"") -> 24.48 | V4: =IF(P4<>"Standard","",IF(OR(Q4<Parameters!$B$24,R4>Parameters!$B$25),"Initial curing temperature outside 60 to 80 F",IF(U4>Parameters!$B$26,"Initial curing period over 48 hours",""))) | X4: =ROUND(DATE(VALUE(RIGHT(C4,4)),VALUE(LEFT(C4,2)),VALUE(MID(C4,4,2)))+VALUE(LEFT(D4,2))/Parameters!$B$28+VALUE(RIGHT(D4,2))/Parameters!$B$29,5) -> 46237.308 | Y4: =INDEX(Tests!$S$4:$S$31,MATCH(F4,Tests!$A$4:$A$31,0)) -> Yes
A5: S-102 | B5: R. Okafor | C5: 08/05/2026 | D5: 08:12 | E5: L2 deck bay B at pump | F5: 770653 | G5: 4A317 | H5: =IF(G5=Parameters!$B$13,Parameters!$B$3,Parameters!$C$3) -> M-4000 | I5: P-02 | J5: 5 | K5: 5.8 | L5: 76 | M5: =IF(AND(J5>=IF(H5=Parameters!$B$3,Parameters!$B$8,Parameters!$C$8),J5<=IF(H5=Parameters!$B$3,Parameters!$B$9,Parameters!$C$9),K5>=IF(H5=Parameters!$B$3,Parameters!$B$10,Parameters!$C$10),K5<=IF(H5=Parameters!$B$3,Parameters!$B$11,Parameters!$C$11),L5<=IF(H5=Parameters!$B$3,Parameters!$B$12,Parameters!$C$12)),"Within 2.4","Outside 2.4") -> Within 2.4 | N5: 6x12 | O5: Box 1 | P5: Standard | Q5: 64 | R5: 78 | S5: 08/06/2026 | T5: 07:34 | U5: =IF(P5="Standard",ROUND((DATE(VALUE(RIGHT(S5,4)),VALUE(LEFT(S5,2)),VALUE(MID(S5,4,2)))+VALUE(LEFT(T5,2))/Parameters!$B$28+VALUE(RIGHT(T5,2))/Parameters!$B$29-X5)*Parameters!$B$28,2),"") -> 23.37 | V5: =IF(P5<>"Standard","",IF(OR(Q5<Parameters!$B$24,R5>Parameters!$B$25),"Initial curing temperature outside 60 to 80 F",IF(U5>Parameters!$B$26,"Initial curing period over 48 hours",""))) | X5: =ROUND(DATE(VALUE(RIGHT(C5,4)),VALUE(LEFT(C5,2)),VALUE(MID(C5,4,2)))+VALUE(LEFT(D5,2))/Parameters!$B$28+VALUE(RIGHT(D5,2))/Parameters!$B$29,5) -> 46239.342 | Y5: =INDEX(Tests!$S$4:$S$31,MATCH(F5,Tests!$A$4:$A$31,0)) -> Yes
A6: S-103 | B6: R. Okafor | C6: 08/10/2026 | D6: 06:52 | E6: L2 deck C/D north pump | F6: 771106 | G6: 4A317 | H6: =IF(G6=Parameters!$B$13,Parameters!$B$3,Parameters!$C$3) -> M-4000 | I6: P-05 | J6: 4 | K6: 6.4 | L6: 71 | M6: =IF(AND(J6>=IF(H6=Parameters!$B$3,Parameters!$B$8,Parameters!$C$8),J6<=IF(H6=Parameters!$B$3,Parameters!$B$9,Parameters!$C$9),K6>=IF(H6=Parameters!$B$3,Parameters!$B$10,Parameters!$C$10),K6<=IF(H6=Parameters!$B$3,Parameters!$B$11,Parameters!$C$11),L6<=IF(H6=Parameters!$B$3,Parameters!$B$12,Parameters!$C$12)),"Within 2.4","Outside 2.4") -> Within 2.4 | N6: 6x12 | O6: Box 1 | P6: Standard | Q6: 62 | R6: 76 | S6: 08/11/2026 | T6: 06:56 | U6: =IF(P6="Standard",ROUND((DATE(VALUE(RIGHT(S6,4)),VALUE(LEFT(S6,2)),VALUE(MID(S6,4,2)))+VALUE(LEFT(T6,2))/Parameters!$B$28+VALUE(RIGHT(T6,2))/Parameters!$B$29-X6)*Parameters!$B$28,2),"") -> 24.07 | V6: =IF(P6<>"Standard","",IF(OR(Q6<Parameters!$B$24,R6>Parameters!$B$25),"Initial curing temperature outside 60 to 80 F",IF(U6>Parameters!$B$26,"Initial curing period over 48 hours",""))) | X6: =ROUND(DATE(VALUE(RIGHT(C6,4)),VALUE(LEFT(C6,2)),VALUE(MID(C6,4,2)))+VALUE(LEFT(D6,2))/Parameters!$B$28+VALUE(RIGHT(D6,2))/Parameters!$B$29,5) -> 46244.286 | Y6: =INDEX(Tests!$S$4:$S$31,MATCH(F6,Tests!$A$4:$A$31,0)) -> No
A7: S-104 | B7: R. Okafor | C7: 08/10/2026 | D7: 10:18 | E7: L2 deck C/D north pump | F7: 771131 | G7: 4A317 | H7: =IF(G7=Parameters!$B$13,Parameters!$B$3,Parameters!$C$3) -> M-4000 | I7: P-05 | J7: 4.25 | K7: 6.7 | L7: 77 | M7: =IF(AND(J7>=IF(H7=Parameters!$B$3,Parameters!$B$8,Parameters!$C$8),J7<=IF(H7=Parameters!$B$3,Parameters!$B$9,Parameters!$C$9),K7>=IF(H7=Parameters!$B$3,Parameters!$B$10,Parameters!$C$10),K7<=IF(H7=Parameters!$B$3,Parameters!$B$11,Parameters!$C$11),L7<=IF(H7=Parameters!$B$3,Parameters!$B$12,Parameters!$C$12)),"Within 2.4","Outside 2.4") -> Within 2.4 | N7: 6x12 | O7: Box 1 | P7: Standard | Q7: 62 | R7: 76 | S7: 08/11/2026 | T7: 06:56 | U7: =IF(P7="Standard",ROUND((DATE(VALUE(RIGHT(S7,4)),VALUE(LEFT(S7,2)),VALUE(MID(S7,4,2)))+VALUE(LEFT(T7,2))/Parameters!$B$28+VALUE(RIGHT(T7,2))/Parameters!$B$29-X7)*Parameters!$B$28,2),"") -> 20.63 | V7: =IF(P7<>"Standard","",IF(OR(Q7<Parameters!$B$24,R7>Parameters!$B$25),"Initial curing temperature outside 60 to 80 F",IF(U7>Parameters!$B$26,"Initial curing period over 48 hours",""))) | X7: =ROUND(DATE(VALUE(RIGHT(C7,4)),VALUE(LEFT(C7,2)),VALUE(MID(C7,4,2)))+VALUE(LEFT(D7,2))/Parameters!$B$28+VALUE(RIGHT(D7,2))/Parameters!$B$29,5) -> 46244.429 | Y7: =INDEX(Tests!$S$4:$S$31,MATCH(F7,Tests!$A$4:$A$31,0)) -> No
A8: S-105 | B8: R. Okafor | C8: 08/12/2026 | D8: 07:38 | E8: L3 deck bay A at pump | F8: 771342 | G8: 4A317 | H8: =IF(G8=Parameters!$B$13,Parameters!$B$3,Parameters!$C$3) -> M-4000 | I8: P-06 | J8: 5.25 | K8: 5.9 | L8: 81 | M8: =IF(AND(J8>=IF(H8=Parameters!$B$3,Parameters!$B$8,Parameters!$C$8),J8<=IF(H8=Parameters!$B$3,Parameters!$B$9,Parameters!$C$9),K8>=IF(H8=Parameters!$B$3,Parameters!$B$10,Parameters!$C$10),K8<=IF(H8=Parameters!$B$3,Parameters!$B$11,Parameters!$C$11),L8<=IF(H8=Parameters!$B$3,Parameters!$B$12,Parameters!$C$12)),"Within 2.4","Outside 2.4") -> Outside 2.4 | N8: 6x12 | O8: Box 1 | P8: Standard | Q8: 64 | R8: 78 | S8: 08/13/2026 | T8: 07:47 | U8: =IF(P8="Standard",ROUND((DATE(VALUE(RIGHT(S8,4)),VALUE(LEFT(S8,2)),VALUE(MID(S8,4,2)))+VALUE(LEFT(T8,2))/Parameters!$B$28+VALUE(RIGHT(T8,2))/Parameters!$B$29-X8)*Parameters!$B$28,2),"") -> 24.15 | V8: =IF(P8<>"Standard","",IF(OR(Q8<Parameters!$B$24,R8>Parameters!$B$25),"Initial curing temperature outside 60 to 80 F",IF(U8>Parameters!$B$26,"Initial curing period over 48 hours",""))) | X8: =ROUND(DATE(VALUE(RIGHT(C8,4)),VALUE(LEFT(C8,2)),VALUE(MID(C8,4,2)))+VALUE(LEFT(D8,2))/Parameters!$B$28+VALUE(RIGHT(D8,2))/Parameters!$B$29,5) -> 46246.318 | Y8: =INDEX(Tests!$S$4:$S$31,MATCH(F8,Tests!$A$4:$A$31,0)) -> Yes
A9: S-106 | B9: R. Okafor | C9: 08/14/2026 | D9: 07:17 | E9: L3 deck bay B at pump | F9: 771587 | G9: 4A317 | H9: =IF(G9=Parameters!$B$13,Parameters!$B$3,Parameters!$C$3) -> M-4000 | I9: P-08 | J9: 4.75 | K9: 7.8 | L9: 80 | M9: =IF(AND(J9>=IF(H9=Parameters!$B$3,Parameters!$B$8,Parameters!$C$8),J9<=IF(H9=Parameters!$B$3,Parameters!$B$9,Parameters!$C$9),K9>=IF(H9=Parameters!$B$3,Parameters!$B$10,Parameters!$C$10),K9<=IF(H9=Parameters!$B$3,Parameters!$B$11,Parameters!$C$11),L9<=IF(H9=Parameters!$B$3,Parameters!$B$12,Parameters!$C$12)),"Within 2.4","Outside 2.4") -> Outside 2.4 | N9: 6x12 | O9: Box 1 | P9: Standard | Q9: 63 | R9: 79 | S9: 08/17/2026 | T9: 09:41 | U9: =IF(P9="Standard",ROUND((DATE(VALUE(RIGHT(S9,4)),VALUE(LEFT(S9,2)),VALUE(MID(S9,4,2)))+VALUE(LEFT(T9,2))/Parameters!$B$28+VALUE(RIGHT(T9,2))/Parameters!$B$29-X9)*Parameters!$B$28,2),"") -> 74.4 | V9: =IF(P9<>"Standard","",IF(OR(Q9<Parameters!$B$24,R9>Parameters!$B$25),"Initial curing temperature outside 60 to 80 F",IF(U9>Parameters!$B$26,"Initial curing period over 48 hours",""))) -> Initial curing period over 48 hours | X9: =ROUND(DATE(VALUE(RIGHT(C9,4)),VALUE(LEFT(C9,2)),VALUE(MID(C9,4,2)))+VALUE(LEFT(D9,2))/Parameters!$B$28+VALUE(RIGHT(D9,2))/Parameters!$B$29,5) -> 46248.304 | Y9: =INDEX(Tests!$S$4:$S$31,MATCH(F9,Tests!$A$4:$A$31,0)) -> Yes
A10: S-107 | B10: R. Okafor | C10: 08/14/2026 | D10: 09:48 | E10: L3 deck bay B at pump | F10: 771604 | G10: 4A317 | H10: =IF(G10=Parameters!$B$13,Parameters!$B$3,Parameters!$C$3) -> M-4000 | I10: P-08 | J10: 4.5 | K10: 6.6 | L10: 82 | M10: =IF(AND(J10>=IF(H10=Parameters!$B$3,Parameters!$B$8,Parameters!$C$8),J10<=IF(H10=Parameters!$B$3,Parameters!$B$9,Parameters!$C$9),K10>=IF(H10=Parameters!$B$3,Parameters!$B$10,Parameters!$C$10),K10<=IF(H10=Parameters!$B$3,Parameters!$B$11,Parameters!$C$11),L10<=IF(H10=Parameters!$B$3,Parameters!$B$12,Parameters!$C$12)),"Within 2.4","Outside 2.4") -> Within 2.4 | N10: 6x12 | O10: On L3 deck at bay B under burlap and poly | P10: Field | S10: 09/11/2026 | T10: 06:41 | U10: =IF(P10="Standard",ROUND((DATE(VALUE(RIGHT(S10,4)),VALUE(LEFT(S10,2)),VALUE(MID(S10,4,2)))+VALUE(LEFT(T10,2))/Parameters!$B$28+VALUE(RIGHT(T10,2))/Parameters!$B$29-X10)*Parameters!$B$28,2),"") | V10: =IF(P10<>"Standard","",IF(OR(Q10<Parameters!$B$24,R10>Parameters!$B$25),"Initial curing temperature outside 60 to 80 F",IF(U10>Parameters!$B$26,"Initial curing period over 48 hours",""))) | X10: =ROUND(DATE(VALUE(RIGHT(C10,4)),VALUE(LEFT(C10,2)),VALUE(MID(C10,4,2)))+VALUE(LEFT(D10,2))/Parameters!$B$28+VALUE(RIGHT(D10,2))/Parameters!$B$29,5) -> 46248.408 | Y10: =INDEX(Tests!$S$4:$S$31,MATCH(F10,Tests!$A$4:$A$31,0)) -> No
A11: S-108 | B11: R. Okafor | C11: 08/15/2026 | D11: 06:43 | E11: South ramp lower run at chute | F11: 771688 | G11: 4A317 | H11: =IF(G11=Parameters!$B$13,Parameters!$B$3,Parameters!$C$3) -> M-4000 | I11: P-09 | J11: 4 | K11: 6.1 | L11: 69 | M11: =IF(AND(J11>=IF(H11=Parameters!$B$3,Parameters!$B$8,Parameters!$C$8),J11<=IF(H11=Parameters!$B$3,Parameters!$B$9,Parameters!$C$9),K11>=IF(H11=Parameters!$B$3,Parameters!$B$10,Parameters!$C$10),K11<=IF(H11=Parameters!$B$3,Parameters!$B$11,Parameters!$C$11),L11<=IF(H11=Parameters!$B$3,Parameters!$B$12,Parameters!$C$12)),"Within 2.4","Outside 2.4") -> Within 2.4 | N11: 6x12 | O11: Box 2 | P11: Standard | Q11: 62 | R11: 75 | S11: 08/16/2026 | T11: 07:36 | U11: =IF(P11="Standard",ROUND((DATE(VALUE(RIGHT(S11,4)),VALUE(LEFT(S11,2)),VALUE(MID(S11,4,2)))+VALUE(LEFT(T11,2))/Parameters!$B$28+VALUE(RIGHT(T11,2))/Parameters!$B$29-X11)*Parameters!$B$28,2),"") -> 24.88 | V11: =IF(P11<>"Standard","",IF(OR(Q11<Parameters!$B$24,R11>Parameters!$B$25),"Initial curing temperature outside 60 to 80 F",IF(U11>Parameters!$B$26,"Initial curing period over 48 hours",""))) | X11: =ROUND(DATE(VALUE(RIGHT(C11,4)),VALUE(LEFT(C11,2)),VALUE(MID(C11,4,2)))+VALUE(LEFT(D11,2))/Parameters!$B$28+VALUE(RIGHT(D11,2))/Parameters!$B$29,5) -> 46249.28 | Y11: =INDEX(Tests!$S$4:$S$31,MATCH(F11,Tests!$A$4:$A$31,0)) -> Yes
A12: S-109 | B12: R. Okafor | C12: 08/17/2026 | D12: 08:06 | E12: L3 deck bay C at pump | F12: 771842 | G12: 4A317 | H12: =IF(G12=Parameters!$B$13,Parameters!$B$3,Parameters!$C$3) -> M-4000 | I12: P-10 | J12: 4.25 | K12: 7.5 | L12: 75 | M12: =IF(AND(J12>=IF(H12=Parameters!$B$3,Parameters!$B$8,Parameters!$C$8),J12<=IF(H12=Parameters!$B$3,Parameters!$B$9,Parameters!$C$9),K12>=IF(H12=Parameters!$B$3,Parameters!$B$10,Parameters!$C$10),K12<=IF(H12=Parameters!$B$3,Parameters!$B$11,Parameters!$C$11),L12<=IF(H12=Parameters!$B$3,Parameters!$B$12,Parameters!$C$12)),"Within 2.4","Outside 2.4") -> Within 2.4 | N12: 6x12 | O12: Box 1 | P12: Standard | Q12: 63 | R12: 77 | S12: 08/19/2026 | T12: 07:51 | U12: =IF(P12="Standard",ROUND((DATE(VALUE(RIGHT(S12,4)),VALUE(LEFT(S12,2)),VALUE(MID(S12,4,2)))+VALUE(LEFT(T12,2))/Parameters!$B$28+VALUE(RIGHT(T12,2))/Parameters!$B$29-X12)*Parameters!$B$28,2),"") -> 47.75 | V12: =IF(P12<>"Standard","",IF(OR(Q12<Parameters!$B$24,R12>Parameters!$B$25),"Initial curing temperature outside 60 to 80 F",IF(U12>Parameters!$B$26,"Initial curing period over 48 hours",""))) | X12: =ROUND(DATE(VALUE(RIGHT(C12,4)),VALUE(LEFT(C12,2)),VALUE(MID(C12,4,2)))+VALUE(LEFT(D12,2))/Parameters!$B$28+VALUE(RIGHT(D12,2))/Parameters!$B$29,5) -> 46251.338 | Y12: =INDEX(Tests!$S$4:$S$31,MATCH(F12,Tests!$A$4:$A$31,0)) -> Yes
A13: S-110 | B13: R. Okafor | C13: 08/19/2026 | D13: 08:21 | E13: L3 deck bay D at pump | F13: 772071 | G13: 4A317 | H13: =IF(G13=Parameters!$B$13,Parameters!$B$3,Parameters!$C$3) -> M-4000 | I13: P-12 | J13: 4.5 | K13: 5.6 | L13: 73 | M13: =IF(AND(J13>=IF(H13=Parameters!$B$3,Parameters!$B$8,Parameters!$C$8),J13<=IF(H13=Parameters!$B$3,Parameters!$B$9,Parameters!$C$9),K13>=IF(H13=Parameters!$B$3,Parameters!$B$10,Parameters!$C$10),K13<=IF(H13=Parameters!$B$3,Parameters!$B$11,Parameters!$C$11),L13<=IF(H13=Parameters!$B$3,Parameters!$B$12,Parameters!$C$12)),"Within 2.4","Outside 2.4") -> Within 2.4 | N13: 6x12 | O13: Box 1 | P13: Standard | Q13: 62 | R13: 74 | S13: 08/20/2026 | T13: 07:18 | U13: =IF(P13="Standard",ROUND((DATE(VALUE(RIGHT(S13,4)),VALUE(LEFT(S13,2)),VALUE(MID(S13,4,2)))+VALUE(LEFT(T13,2))/Parameters!$B$28+VALUE(RIGHT(T13,2))/Parameters!$B$29-X13)*Parameters!$B$28,2),"") -> 22.95 | V13: =IF(P13<>"Standard","",IF(OR(Q13<Parameters!$B$24,R13>Parameters!$B$25),"Initial curing temperature outside 60 to 80 F",IF(U13>Parameters!$B$26,"Initial curing period over 48 hours",""))) | X13: =ROUND(DATE(VALUE(RIGHT(C13,4)),VALUE(LEFT(C13,2)),VALUE(MID(C13,4,2)))+VALUE(LEFT(D13,2))/Parameters!$B$28+VALUE(RIGHT(D13,2))/Parameters!$B$29,5) -> 46253.348 | Y13: =INDEX(Tests!$S$4:$S$31,MATCH(F13,Tests!$A$4:$A$31,0)) -> Yes
A14: S-111 | B14: R. Okafor | C14: 08/21/2026 | D14: 09:13 | E14: North ramp at chute | F14: 772316 | G14: 4A317 | H14: =IF(G14=Parameters!$B$13,Parameters!$B$3,Parameters!$C$3) -> M-4000 | I14: P-14 | J14: 4 | K14: 6 | L14: 72 | M14: =IF(AND(J14>=IF(H14=Parameters!$B$3,Parameters!$B$8,Parameters!$C$8),J14<=IF(H14=Parameters!$B$3,Parameters!$B$9,Parameters!$C$9),K14>=IF(H14=Parameters!$B$3,Parameters!$B$10,Parameters!$C$10),K14<=IF(H14=Parameters!$B$3,Parameters!$B$11,Parameters!$C$11),L14<=IF(H14=Parameters!$B$3,Parameters!$B$12,Parameters!$C$12)),"Within 2.4","Outside 2.4") -> Within 2.4 | N14: 4x8 | O14: Box 2 | P14: Standard | Q14: 61 | R14: 73 | S14: 08/22/2026 | T14: 08:16 | U14: =IF(P14="Standard",ROUND((DATE(VALUE(RIGHT(S14,4)),VALUE(LEFT(S14,2)),VALUE(MID(S14,4,2)))+VALUE(LEFT(T14,2))/Parameters!$B$28+VALUE(RIGHT(T14,2))/Parameters!$B$29-X14)*Parameters!$B$28,2),"") -> 23.05 | V14: =IF(P14<>"Standard","",IF(OR(Q14<Parameters!$B$24,R14>Parameters!$B$25),"Initial curing temperature outside 60 to 80 F",IF(U14>Parameters!$B$26,"Initial curing period over 48 hours",""))) | X14: =ROUND(DATE(VALUE(RIGHT(C14,4)),VALUE(LEFT(C14,2)),VALUE(MID(C14,4,2)))+VALUE(LEFT(D14,2))/Parameters!$B$28+VALUE(RIGHT(D14,2))/Parameters!$B$29,5) -> 46255.384 | Y14: =INDEX(Tests!$S$4:$S$31,MATCH(F14,Tests!$A$4:$A$31,0)) -> No
A15: S-112 | B15: R. Okafor | C15: 08/24/2026 | D15: 13:44 | E15: L4 deck bay A at pump | F15: 772569 | G15: 4A317 | H15: =IF(G15=Parameters!$B$13,Parameters!$B$3,Parameters!$C$3) -> M-4000 | I15: P-15 | J15: 4.5 | K15: 6.3 | L15: 79 | M15: =IF(AND(J15>=IF(H15=Parameters!$B$3,Parameters!$B$8,Parameters!$C$8),J15<=IF(H15=Parameters!$B$3,Parameters!$B$9,Parameters!$C$9),K15>=IF(H15=Parameters!$B$3,Parameters!$B$10,Parameters!$C$10),K15<=IF(H15=Parameters!$B$3,Parameters!$B$11,Parameters!$C$11),L15<=IF(H15=Parameters!$B$3,Parameters!$B$12,Parameters!$C$12)),"Within 2.4","Outside 2.4") -> Within 2.4 | N15: 6x12 | O15: Box 1 | P15: Standard | Q15: 63 | R15: 80 | S15: 08/25/2026 | T15: 07:29 | U15: =IF(P15="Standard",ROUND((DATE(VALUE(RIGHT(S15,4)),VALUE(LEFT(S15,2)),VALUE(MID(S15,4,2)))+VALUE(LEFT(T15,2))/Parameters!$B$28+VALUE(RIGHT(T15,2))/Parameters!$B$29-X15)*Parameters!$B$28,2),"") -> 17.75 | V15: =IF(P15<>"Standard","",IF(OR(Q15<Parameters!$B$24,R15>Parameters!$B$25),"Initial curing temperature outside 60 to 80 F",IF(U15>Parameters!$B$26,"Initial curing period over 48 hours",""))) | X15: =ROUND(DATE(VALUE(RIGHT(C15,4)),VALUE(LEFT(C15,2)),VALUE(MID(C15,4,2)))+VALUE(LEFT(D15,2))/Parameters!$B$28+VALUE(RIGHT(D15,2))/Parameters!$B$29,5) -> 46258.572 | Y15: =INDEX(Tests!$S$4:$S$31,MATCH(F15,Tests!$A$4:$A$31,0)) -> Yes
A16: S-113 | B16: R. Okafor | C16: 08/26/2026 | D16: 07:19 | E16: L4 deck bay B at pump | F16: 772784 | G16: 4A317 | H16: =IF(G16=Parameters!$B$13,Parameters!$B$3,Parameters!$C$3) -> M-4000 | I16: P-17 | J16: 3.75 | K16: 5.7 | L16: 71 | M16: =IF(AND(J16>=IF(H16=Parameters!$B$3,Parameters!$B$8,Parameters!$C$8),J16<=IF(H16=Parameters!$B$3,Parameters!$B$9,Parameters!$C$9),K16>=IF(H16=Parameters!$B$3,Parameters!$B$10,Parameters!$C$10),K16<=IF(H16=Parameters!$B$3,Parameters!$B$11,Parameters!$C$11),L16<=IF(H16=Parameters!$B$3,Parameters!$B$12,Parameters!$C$12)),"Within 2.4","Outside 2.4") -> Within 2.4 | N16: 6x12 | O16: Box 2 | P16: Standard | Q16: 66 | R16: 91 | S16: 08/27/2026 | T16: 16:22 | U16: =IF(P16="Standard",ROUND((DATE(VALUE(RIGHT(S16,4)),VALUE(LEFT(S16,2)),VALUE(MID(S16,4,2)))+VALUE(LEFT(T16,2))/Parameters!$B$28+VALUE(RIGHT(T16,2))/Parameters!$B$29-X16)*Parameters!$B$28,2),"") -> 33.05 | V16: =IF(P16<>"Standard","",IF(OR(Q16<Parameters!$B$24,R16>Parameters!$B$25),"Initial curing temperature outside 60 to 80 F",IF(U16>Parameters!$B$26,"Initial curing period over 48 hours",""))) -> Initial curing temperature outside 60 to 80 F | W16: Set aside, letter of October 2, 2026 | X16: =ROUND(DATE(VALUE(RIGHT(C16,4)),VALUE(LEFT(C16,2)),VALUE(MID(C16,4,2)))+VALUE(LEFT(D16,2))/Parameters!$B$28+VALUE(RIGHT(D16,2))/Parameters!$B$29,5) -> 46260.305 | Y16: =INDEX(Tests!$S$4:$S$31,MATCH(F16,Tests!$A$4:$A$31,0)) -> No
A17: S-114 | B17: R. Okafor | C17: 08/29/2026 | D17: 11:32 | E17: L4 deck bay C at pump | F17: 773127 | G17: 4A317 | H17: =IF(G17=Parameters!$B$13,Parameters!$B$3,Parameters!$C$3) -> M-4000 | I17: P-20 | J17: 4.25 | K17: 6.5 | L17: 90 | M17: =IF(AND(J17>=IF(H17=Parameters!$B$3,Parameters!$B$8,Parameters!$C$8),J17<=IF(H17=Parameters!$B$3,Parameters!$B$9,Parameters!$C$9),K17>=IF(H17=Parameters!$B$3,Parameters!$B$10,Parameters!$C$10),K17<=IF(H17=Parameters!$B$3,Parameters!$B$11,Parameters!$C$11),L17<=IF(H17=Parameters!$B$3,Parameters!$B$12,Parameters!$C$12)),"Within 2.4","Outside 2.4") -> Within 2.4 | N17: 6x12 | O17: Box 1 | P17: Standard | Q17: 66 | R17: 79 | S17: 08/31/2026 | T17: 06:33 | U17: =IF(P17="Standard",ROUND((DATE(VALUE(RIGHT(S17,4)),VALUE(LEFT(S17,2)),VALUE(MID(S17,4,2)))+VALUE(LEFT(T17,2))/Parameters!$B$28+VALUE(RIGHT(T17,2))/Parameters!$B$29-X17)*Parameters!$B$28,2),"") -> 43.02 | V17: =IF(P17<>"Standard","",IF(OR(Q17<Parameters!$B$24,R17>Parameters!$B$25),"Initial curing temperature outside 60 to 80 F",IF(U17>Parameters!$B$26,"Initial curing period over 48 hours",""))) | X17: =ROUND(DATE(VALUE(RIGHT(C17,4)),VALUE(LEFT(C17,2)),VALUE(MID(C17,4,2)))+VALUE(LEFT(D17,2))/Parameters!$B$28+VALUE(RIGHT(D17,2))/Parameters!$B$29,5) -> 46263.481 | Y17: =INDEX(Tests!$S$4:$S$31,MATCH(F17,Tests!$A$4:$A$31,0)) -> No | Z17: Date written 08/28/2026. The placement log has bay C on 08/29/2026, a Saturday, and the memo counts it among the Saturday placements.
A18: S-115 | B18: R. Okafor | C18: 08/31/2026 | D18: 11:22 | E18: L4 deck bay D at pump | F18: 773295 | G18: 4A317 | H18: =IF(G18=Parameters!$B$13,Parameters!$B$3,Parameters!$C$3) -> M-4000 | I18: P-21 | J18: 4.5 | K18: 6 | L18: 77 | M18: =IF(AND(J18>=IF(H18=Parameters!$B$3,Parameters!$B$8,Parameters!$C$8),J18<=IF(H18=Parameters!$B$3,Parameters!$B$9,Parameters!$C$9),K18>=IF(H18=Parameters!$B$3,Parameters!$B$10,Parameters!$C$10),K18<=IF(H18=Parameters!$B$3,Parameters!$B$11,Parameters!$C$11),L18<=IF(H18=Parameters!$B$3,Parameters!$B$12,Parameters!$C$12)),"Within 2.4","Outside 2.4") -> Within 2.4 | N18: 6x12 | O18: Box 1 | P18: Standard | Q18: 64 | R18: 78 | S18: 09/01/2026 | T18: 07:14 | U18: =IF(P18="Standard",ROUND((DATE(VALUE(RIGHT(S18,4)),VALUE(LEFT(S18,2)),VALUE(MID(S18,4,2)))+VALUE(LEFT(T18,2))/Parameters!$B$28+VALUE(RIGHT(T18,2))/Parameters!$B$29-X18)*Parameters!$B$28,2),"") -> 19.87 | V18: =IF(P18<>"Standard","",IF(OR(Q18<Parameters!$B$24,R18>Parameters!$B$25),"Initial curing temperature outside 60 to 80 F",IF(U18>Parameters!$B$26,"Initial curing period over 48 hours",""))) | X18: =ROUND(DATE(VALUE(RIGHT(C18,4)),VALUE(LEFT(C18,2)),VALUE(MID(C18,4,2)))+VALUE(LEFT(D18,2))/Parameters!$B$28+VALUE(RIGHT(D18,2))/Parameters!$B$29,5) -> 46265.474 | Y18: =INDEX(Tests!$S$4:$S$31,MATCH(F18,Tests!$A$4:$A$31,0)) -> Yes
A19: S-116 | B19: R. Okafor | C19: 09/08/2026 | D19: 08:31 | E19: South ramp upper run at chute | F19: 773902 | G19: 4A317 | H19: =IF(G19=Parameters!$B$13,Parameters!$B$3,Parameters!$C$3) -> M-4000 | I19: P-24 | J19: 3.5 | K19: 5.5 | L19: 64 | M19: =IF(AND(J19>=IF(H19=Parameters!$B$3,Parameters!$B$8,Parameters!$C$8),J19<=IF(H19=Parameters!$B$3,Parameters!$B$9,Parameters!$C$9),K19>=IF(H19=Parameters!$B$3,Parameters!$B$10,Parameters!$C$10),K19<=IF(H19=Parameters!$B$3,Parameters!$B$11,Parameters!$C$11),L19<=IF(H19=Parameters!$B$3,Parameters!$B$12,Parameters!$C$12)),"Within 2.4","Outside 2.4") -> Within 2.4 | N19: 6x12 | O19: Box 2 | P19: Standard | Q19: 57 | R19: 74 | S19: 09/09/2026 | T19: 07:42 | U19: =IF(P19="Standard",ROUND((DATE(VALUE(RIGHT(S19,4)),VALUE(LEFT(S19,2)),VALUE(MID(S19,4,2)))+VALUE(LEFT(T19,2))/Parameters!$B$28+VALUE(RIGHT(T19,2))/Parameters!$B$29-X19)*Parameters!$B$28,2),"") -> 23.18 | V19: =IF(P19<>"Standard","",IF(OR(Q19<Parameters!$B$24,R19>Parameters!$B$25),"Initial curing temperature outside 60 to 80 F",IF(U19>Parameters!$B$26,"Initial curing period over 48 hours",""))) -> Initial curing temperature outside 60 to 80 F | X19: =ROUND(DATE(VALUE(RIGHT(C19,4)),VALUE(LEFT(C19,2)),VALUE(MID(C19,4,2)))+VALUE(LEFT(D19,2))/Parameters!$B$28+VALUE(RIGHT(D19,2))/Parameters!$B$29,5) -> 46273.355 | Y19: =INDEX(Tests!$S$4:$S$31,MATCH(F19,Tests!$A$4:$A$31,0)) -> Yes
A20: S-201 | B20: L. Brandvold | C20: 08/06/2026 | D20: 09:36 | E20: Cols L2 grid 1-4 at bucket | F20: 770812 | G20: 6S224 | H20: =IF(G20=Parameters!$B$13,Parameters!$B$3,Parameters!$C$3) -> M-6000 | I20: P-04 | J20: 6 | K20: 3.1 | L20: 78 | M20: =IF(AND(J20>=IF(H20=Parameters!$B$3,Parameters!$B$8,Parameters!$C$8),J20<=IF(H20=Parameters!$B$3,Parameters!$B$9,Parameters!$C$9),K20>=IF(H20=Parameters!$B$3,Parameters!$B$10,Parameters!$C$10),K20<=IF(H20=Parameters!$B$3,Parameters!$B$11,Parameters!$C$11),L20<=IF(H20=Parameters!$B$3,Parameters!$B$12,Parameters!$C$12)),"Within 2.4","Outside 2.4") -> Within 2.4 | N20: 4x8 | O20: Box 2 | P20: Standard | Q20: 65 | R20: 78 | S20: 08/07/2026 | T20: 07:06 | U20: =IF(P20="Standard",ROUND((DATE(VALUE(RIGHT(S20,4)),VALUE(LEFT(S20,2)),VALUE(MID(S20,4,2)))+VALUE(LEFT(T20,2))/Parameters!$B$28+VALUE(RIGHT(T20,2))/Parameters!$B$29-X20)*Parameters!$B$28,2),"") -> 21.5 | V20: =IF(P20<>"Standard","",IF(OR(Q20<Parameters!$B$24,R20>Parameters!$B$25),"Initial curing temperature outside 60 to 80 F",IF(U20>Parameters!$B$26,"Initial curing period over 48 hours",""))) | X20: =ROUND(DATE(VALUE(RIGHT(C20,4)),VALUE(LEFT(C20,2)),VALUE(MID(C20,4,2)))+VALUE(LEFT(D20,2))/Parameters!$B$28+VALUE(RIGHT(D20,2))/Parameters!$B$29,5) -> 46240.4 | Y20: =INDEX(Tests!$S$4:$S$31,MATCH(F20,Tests!$A$4:$A$31,0)) -> Yes
A21: S-202 | B21: L. Brandvold | C21: 08/10/2026 | D21: 14:37 | E21: L2 deck C/D south pump | F21: 771163 | G21: 4A317 | H21: =IF(G21=Parameters!$B$13,Parameters!$B$3,Parameters!$C$3) -> M-4000 | I21: P-05 | J21: 4.75 | K21: 5.4 | L21: 83 | M21: =IF(AND(J21>=IF(H21=Parameters!$B$3,Parameters!$B$8,Parameters!$C$8),J21<=IF(H21=Parameters!$B$3,Parameters!$B$9,Parameters!$C$9),K21>=IF(H21=Parameters!$B$3,Parameters!$B$10,Parameters!$C$10),K21<=IF(H21=Parameters!$B$3,Parameters!$B$11,Parameters!$C$11),L21<=IF(H21=Parameters!$B$3,Parameters!$B$12,Parameters!$C$12)),"Within 2.4","Outside 2.4") -> Within 2.4 | N21: 6x12 | O21: Box 2 | P21: Standard | Q21: 65 | R21: 79 | S21: 08/11/2026 | T21: 07:11 | U21: =IF(P21="Standard",ROUND((DATE(VALUE(RIGHT(S21,4)),VALUE(LEFT(S21,2)),VALUE(MID(S21,4,2)))+VALUE(LEFT(T21,2))/Parameters!$B$28+VALUE(RIGHT(T21,2))/Parameters!$B$29-X21)*Parameters!$B$28,2),"") -> 16.57 | V21: =IF(P21<>"Standard","",IF(OR(Q21<Parameters!$B$24,R21>Parameters!$B$25),"Initial curing temperature outside 60 to 80 F",IF(U21>Parameters!$B$26,"Initial curing period over 48 hours",""))) | X21: =ROUND(DATE(VALUE(RIGHT(C21,4)),VALUE(LEFT(C21,2)),VALUE(MID(C21,4,2)))+VALUE(LEFT(D21,2))/Parameters!$B$28+VALUE(RIGHT(D21,2))/Parameters!$B$29,5) -> 46244.609 | Y21: =INDEX(Tests!$S$4:$S$31,MATCH(F21,Tests!$A$4:$A$31,0)) -> Yes | Z21: Written 2:37 with the batch at 1:47. The placement ran 05:50 to 16:10, which puts the molding at 14:37.
A22: S-203 | B22: L. Brandvold | C22: 08/13/2026 | D22: 09:04 | E22: Cols L2 grid 5-8 at bucket | F22: 771469 | G22: 6S224 | H22: =IF(G22=Parameters!$B$13,Parameters!$B$3,Parameters!$C$3) -> M-6000 | I22: P-07 | J22: 5.5 | K22: 2.8 | L22: 77 | M22: =IF(AND(J22>=IF(H22=Parameters!$B$3,Parameters!$B$8,Parameters!$C$8),J22<=IF(H22=Parameters!$B$3,Parameters!$B$9,Parameters!$C$9),K22>=IF(H22=Parameters!$B$3,Parameters!$B$10,Parameters!$C$10),K22<=IF(H22=Parameters!$B$3,Parameters!$B$11,Parameters!$C$11),L22<=IF(H22=Parameters!$B$3,Parameters!$B$12,Parameters!$C$12)),"Within 2.4","Outside 2.4") -> Within 2.4 | N22: 4x8 | O22: Box 2 | P22: Standard | Q22: 64 | R22: 77 | S22: 08/14/2026 | T22: 07:27 | U22: =IF(P22="Standard",ROUND((DATE(VALUE(RIGHT(S22,4)),VALUE(LEFT(S22,2)),VALUE(MID(S22,4,2)))+VALUE(LEFT(T22,2))/Parameters!$B$28+VALUE(RIGHT(T22,2))/Parameters!$B$29-X22)*Parameters!$B$28,2),"") -> 22.38 | V22: =IF(P22<>"Standard","",IF(OR(Q22<Parameters!$B$24,R22>Parameters!$B$25),"Initial curing temperature outside 60 to 80 F",IF(U22>Parameters!$B$26,"Initial curing period over 48 hours",""))) | X22: =ROUND(DATE(VALUE(RIGHT(C22,4)),VALUE(LEFT(C22,2)),VALUE(MID(C22,4,2)))+VALUE(LEFT(D22,2))/Parameters!$B$28+VALUE(RIGHT(D22,2))/Parameters!$B$29,5) -> 46247.378 | Y22: =INDEX(Tests!$S$4:$S$31,MATCH(F22,Tests!$A$4:$A$31,0)) -> Yes
A23: S-204 | B23: L. Brandvold | C23: 08/18/2026 | D23: 09:53 | E23: Cols L3 grid 1-4 at bucket | F23: 771955 | G23: 6S224 | H23: =IF(G23=Parameters!$B$13,Parameters!$B$3,Parameters!$C$3) -> M-6000 | I23: P-11 | J23: 7 | K23: 3.3 | L23: 79 | M23: =IF(AND(J23>=IF(H23=Parameters!$B$3,Parameters!$B$8,Parameters!$C$8),J23<=IF(H23=Parameters!$B$3,Parameters!$B$9,Parameters!$C$9),K23>=IF(H23=Parameters!$B$3,Parameters!$B$10,Parameters!$C$10),K23<=IF(H23=Parameters!$B$3,Parameters!$B$11,Parameters!$C$11),L23<=IF(H23=Parameters!$B$3,Parameters!$B$12,Parameters!$C$12)),"Within 2.4","Outside 2.4") -> Within 2.4 | N23: 4x8 | O23: Box 2 | P23: Standard | Q23: 60 | R23: 77 | S23: 08/19/2026 | T23: 08:04 | U23: =IF(P23="Standard",ROUND((DATE(VALUE(RIGHT(S23,4)),VALUE(LEFT(S23,2)),VALUE(MID(S23,4,2)))+VALUE(LEFT(T23,2))/Parameters!$B$28+VALUE(RIGHT(T23,2))/Parameters!$B$29-X23)*Parameters!$B$28,2),"") -> 22.18 | V23: =IF(P23<>"Standard","",IF(OR(Q23<Parameters!$B$24,R23>Parameters!$B$25),"Initial curing temperature outside 60 to 80 F",IF(U23>Parameters!$B$26,"Initial curing period over 48 hours",""))) | X23: =ROUND(DATE(VALUE(RIGHT(C23,4)),VALUE(LEFT(C23,2)),VALUE(MID(C23,4,2)))+VALUE(LEFT(D23,2))/Parameters!$B$28+VALUE(RIGHT(D23,2))/Parameters!$B$29,5) -> 46252.412 | Y23: =INDEX(Tests!$S$4:$S$31,MATCH(F23,Tests!$A$4:$A$31,0)) -> Yes | Z23: Thermometer written 77/60 with the high first. The low of 60 F is inside the range.
A24: S-205 | B24: L. Brandvold | C24: 08/19/2026 | D24: 08:27 | E24: L3 deck bay D at pump | F24: 772071 | G24: 4A317 | H24: =IF(G24=Parameters!$B$13,Parameters!$B$3,Parameters!$C$3) -> M-4000 | I24: P-12 | J24: 4.5 | K24: 5.6 | L24: 73 | M24: =IF(AND(J24>=IF(H24=Parameters!$B$3,Parameters!$B$8,Parameters!$C$8),J24<=IF(H24=Parameters!$B$3,Parameters!$B$9,Parameters!$C$9),K24>=IF(H24=Parameters!$B$3,Parameters!$B$10,Parameters!$C$10),K24<=IF(H24=Parameters!$B$3,Parameters!$B$11,Parameters!$C$11),L24<=IF(H24=Parameters!$B$3,Parameters!$B$12,Parameters!$C$12)),"Within 2.4","Outside 2.4") -> Within 2.4 | N24: 6x12 | O24: Box 1 | P24: Standard | Q24: 62 | R24: 74 | S24: 08/20/2026 | T24: 07:18 | U24: =IF(P24="Standard",ROUND((DATE(VALUE(RIGHT(S24,4)),VALUE(LEFT(S24,2)),VALUE(MID(S24,4,2)))+VALUE(LEFT(T24,2))/Parameters!$B$28+VALUE(RIGHT(T24,2))/Parameters!$B$29-X24)*Parameters!$B$28,2),"") -> 22.85 | V24: =IF(P24<>"Standard","",IF(OR(Q24<Parameters!$B$24,R24>Parameters!$B$25),"Initial curing temperature outside 60 to 80 F",IF(U24>Parameters!$B$26,"Initial curing period over 48 hours",""))) | X24: =ROUND(DATE(VALUE(RIGHT(C24,4)),VALUE(LEFT(C24,2)),VALUE(MID(C24,4,2)))+VALUE(LEFT(D24,2))/Parameters!$B$28+VALUE(RIGHT(D24,2))/Parameters!$B$29,5) -> 46253.352 | Y24: =INDEX(Tests!$S$4:$S$31,MATCH(F24,Tests!$A$4:$A$31,0)) -> Yes | Z24: Ticket written 772017. Truck 33 batched at 07:33 is the load of ticket 772071 on the S-110 line.
A25: S-206 | B25: L. Brandvold | C25: 08/20/2026 | D25: 09:26 | E25: Cols L3 grid 5-8 at bucket | F25: 772203 | G25: 6S224 | H25: =IF(G25=Parameters!$B$13,Parameters!$B$3,Parameters!$C$3) -> M-6000 | I25: P-13 | J25: 6.5 | K25: 3.4 | L25: 78 | M25: =IF(AND(J25>=IF(H25=Parameters!$B$3,Parameters!$B$8,Parameters!$C$8),J25<=IF(H25=Parameters!$B$3,Parameters!$B$9,Parameters!$C$9),K25>=IF(H25=Parameters!$B$3,Parameters!$B$10,Parameters!$C$10),K25<=IF(H25=Parameters!$B$3,Parameters!$B$11,Parameters!$C$11),L25<=IF(H25=Parameters!$B$3,Parameters!$B$12,Parameters!$C$12)),"Within 2.4","Outside 2.4") -> Within 2.4 | N25: 4x8 | O25: Box 2 | P25: Standard | Q25: 63 | R25: 76 | S25: 08/21/2026 | T25: 07:39 | U25: =IF(P25="Standard",ROUND((DATE(VALUE(RIGHT(S25,4)),VALUE(LEFT(S25,2)),VALUE(MID(S25,4,2)))+VALUE(LEFT(T25,2))/Parameters!$B$28+VALUE(RIGHT(T25,2))/Parameters!$B$29-X25)*Parameters!$B$28,2),"") -> 22.22 | V25: =IF(P25<>"Standard","",IF(OR(Q25<Parameters!$B$24,R25>Parameters!$B$25),"Initial curing temperature outside 60 to 80 F",IF(U25>Parameters!$B$26,"Initial curing period over 48 hours",""))) | X25: =ROUND(DATE(VALUE(RIGHT(C25,4)),VALUE(LEFT(C25,2)),VALUE(MID(C25,4,2)))+VALUE(LEFT(D25,2))/Parameters!$B$28+VALUE(RIGHT(D25,2))/Parameters!$B$29,5) -> 46254.393 | Y25: =INDEX(Tests!$S$4:$S$31,MATCH(F25,Tests!$A$4:$A$31,0)) -> Yes
A26: S-207 | B26: L. Brandvold | C26: 08/24/2026 | D26: 13:52 | E26: Cols L3 grid 9-12 at bucket | F26: 772531 | G26: 6S224 | H26: =IF(G26=Parameters!$B$13,Parameters!$B$3,Parameters!$C$3) -> M-6000 | I26: P-16 | J26: 6.25 | K26: 2.9 | L26: 81 | M26: =IF(AND(J26>=IF(H26=Parameters!$B$3,Parameters!$B$8,Parameters!$C$8),J26<=IF(H26=Parameters!$B$3,Parameters!$B$9,Parameters!$C$9),K26>=IF(H26=Parameters!$B$3,Parameters!$B$10,Parameters!$C$10),K26<=IF(H26=Parameters!$B$3,Parameters!$B$11,Parameters!$C$11),L26<=IF(H26=Parameters!$B$3,Parameters!$B$12,Parameters!$C$12)),"Within 2.4","Outside 2.4") -> Within 2.4 | N26: 4x8 | O26: Box 2 | P26: Standard | Q26: 62 | R26: 75 | S26: 08/25/2026 | T26: 07:43 | U26: =IF(P26="Standard",ROUND((DATE(VALUE(RIGHT(S26,4)),VALUE(LEFT(S26,2)),VALUE(MID(S26,4,2)))+VALUE(LEFT(T26,2))/Parameters!$B$28+VALUE(RIGHT(T26,2))/Parameters!$B$29-X26)*Parameters!$B$28,2),"") -> 17.85 | V26: =IF(P26<>"Standard","",IF(OR(Q26<Parameters!$B$24,R26>Parameters!$B$25),"Initial curing temperature outside 60 to 80 F",IF(U26>Parameters!$B$26,"Initial curing period over 48 hours",""))) | X26: =ROUND(DATE(VALUE(RIGHT(C26,4)),VALUE(LEFT(C26,2)),VALUE(MID(C26,4,2)))+VALUE(LEFT(D26,2))/Parameters!$B$28+VALUE(RIGHT(D26,2))/Parameters!$B$29,5) -> 46258.578 | Y26: =INDEX(Tests!$S$4:$S$31,MATCH(F26,Tests!$A$4:$A$31,0)) -> Yes | Z26: Written 1:52 with the batch at 1:09. The placement ran 12:40 to 15:35, which puts the molding at 13:52.
A27: S-208 | B27: L. Brandvold | C27: 08/26/2026 | D27: 10:41 | E27: Cols L4 grid 1-4 at bucket | F27: 772809 | G27: 6S224 | H27: =IF(G27=Parameters!$B$13,Parameters!$B$3,Parameters!$C$3) -> M-6000 | I27: P-18 | J27: 5.75 | K27: 3 | L27: 76 | M27: =IF(AND(J27>=IF(H27=Parameters!$B$3,Parameters!$B$8,Parameters!$C$8),J27<=IF(H27=Parameters!$B$3,Parameters!$B$9,Parameters!$C$9),K27>=IF(H27=Parameters!$B$3,Parameters!$B$10,Parameters!$C$10),K27<=IF(H27=Parameters!$B$3,Parameters!$B$11,Parameters!$C$11),L27<=IF(H27=Parameters!$B$3,Parameters!$B$12,Parameters!$C$12)),"Within 2.4","Outside 2.4") -> Within 2.4 | N27: 4x8 | O27: Box 2 | P27: Standard | Q27: 66 | R27: 91 | S27: 08/27/2026 | T27: 16:22 | U27: =IF(P27="Standard",ROUND((DATE(VALUE(RIGHT(S27,4)),VALUE(LEFT(S27,2)),VALUE(MID(S27,4,2)))+VALUE(LEFT(T27,2))/Parameters!$B$28+VALUE(RIGHT(T27,2))/Parameters!$B$29-X27)*Parameters!$B$28,2),"") -> 29.68 | V27: =IF(P27<>"Standard","",IF(OR(Q27<Parameters!$B$24,R27>Parameters!$B$25),"Initial curing temperature outside 60 to 80 F",IF(U27>Parameters!$B$26,"Initial curing period over 48 hours",""))) -> Initial curing temperature outside 60 to 80 F | X27: =ROUND(DATE(VALUE(RIGHT(C27,4)),VALUE(LEFT(C27,2)),VALUE(MID(C27,4,2)))+VALUE(LEFT(D27,2))/Parameters!$B$28+VALUE(RIGHT(D27,2))/Parameters!$B$29,5) -> 46260.445 | Y27: =INDEX(Tests!$S$4:$S$31,MATCH(F27,Tests!$A$4:$A$31,0)) -> Yes | Z27: Thermometer written 91/66 with the high first. Picked up with S-113 at 16:22, written 4:22.
A28: S-209 | B28: L. Brandvold | C28: 08/27/2026 | D28: 08:14 | E28: Stair 2 shear walls lift 1 at pump | F28: 772934 | G28: 6S224 | H28: =IF(G28=Parameters!$B$13,Parameters!$B$3,Parameters!$C$3) -> M-6000 | I28: P-19 | J28: 6.25 | K28: 2.6 | L28: 70 | M28: =IF(AND(J28>=IF(H28=Parameters!$B$3,Parameters!$B$8,Parameters!$C$8),J28<=IF(H28=Parameters!$B$3,Parameters!$B$9,Parameters!$C$9),K28>=IF(H28=Parameters!$B$3,Parameters!$B$10,Parameters!$C$10),K28<=IF(H28=Parameters!$B$3,Parameters!$B$11,Parameters!$C$11),L28<=IF(H28=Parameters!$B$3,Parameters!$B$12,Parameters!$C$12)),"Within 2.4","Outside 2.4") -> Within 2.4 | N28: 4x8 | O28: Box 1 | P28: Standard | Q28: 63 | R28: 76 | S28: 08/28/2026 | T28: 07:09 | U28: =IF(P28="Standard",ROUND((DATE(VALUE(RIGHT(S28,4)),VALUE(LEFT(S28,2)),VALUE(MID(S28,4,2)))+VALUE(LEFT(T28,2))/Parameters!$B$28+VALUE(RIGHT(T28,2))/Parameters!$B$29-X28)*Parameters!$B$28,2),"") -> 22.92 | V28: =IF(P28<>"Standard","",IF(OR(Q28<Parameters!$B$24,R28>Parameters!$B$25),"Initial curing temperature outside 60 to 80 F",IF(U28>Parameters!$B$26,"Initial curing period over 48 hours",""))) | X28: =ROUND(DATE(VALUE(RIGHT(C28,4)),VALUE(LEFT(C28,2)),VALUE(MID(C28,4,2)))+VALUE(LEFT(D28,2))/Parameters!$B$28+VALUE(RIGHT(D28,2))/Parameters!$B$29,5) -> 46261.343 | Y28: =INDEX(Tests!$S$4:$S$31,MATCH(F28,Tests!$A$4:$A$31,0)) -> Yes
A29: S-210 | B29: L. Brandvold | C29: 08/31/2026 | D29: 06:57 | E29: L4 deck bay D at pump | F29: 773248 | G29: 4A317 | H29: =IF(G29=Parameters!$B$13,Parameters!$B$3,Parameters!$C$3) -> M-4000 | I29: P-21 | J29: 4 | K29: 6.2 | L29: 68 | M29: =IF(AND(J29>=IF(H29=Parameters!$B$3,Parameters!$B$8,Parameters!$C$8),J29<=IF(H29=Parameters!$B$3,Parameters!$B$9,Parameters!$C$9),K29>=IF(H29=Parameters!$B$3,Parameters!$B$10,Parameters!$C$10),K29<=IF(H29=Parameters!$B$3,Parameters!$B$11,Parameters!$C$11),L29<=IF(H29=Parameters!$B$3,Parameters!$B$12,Parameters!$C$12)),"Within 2.4","Outside 2.4") -> Within 2.4 | N29: 6x12 | O29: Box 1 | P29: Standard | Q29: 64 | R29: 78 | S29: 09/01/2026 | T29: 07:14 | U29: =IF(P29="Standard",ROUND((DATE(VALUE(RIGHT(S29,4)),VALUE(LEFT(S29,2)),VALUE(MID(S29,4,2)))+VALUE(LEFT(T29,2))/Parameters!$B$28+VALUE(RIGHT(T29,2))/Parameters!$B$29-X29)*Parameters!$B$28,2),"") -> 24.28 | V29: =IF(P29<>"Standard","",IF(OR(Q29<Parameters!$B$24,R29>Parameters!$B$25),"Initial curing temperature outside 60 to 80 F",IF(U29>Parameters!$B$26,"Initial curing period over 48 hours",""))) | X29: =ROUND(DATE(VALUE(RIGHT(C29,4)),VALUE(LEFT(C29,2)),VALUE(MID(C29,4,2)))+VALUE(LEFT(D29,2))/Parameters!$B$28+VALUE(RIGHT(D29,2))/Parameters!$B$29,5) -> 46265.29 | Y29: =INDEX(Tests!$S$4:$S$31,MATCH(F29,Tests!$A$4:$A$31,0)) -> Yes
A30: S-211 | B30: L. Brandvold | C30: 09/02/2026 | D30: 09:19 | E30: Cols L4 grid 5-8 at bucket | F30: 773471 | G30: 6S224 | H30: =IF(G30=Parameters!$B$13,Parameters!$B$3,Parameters!$C$3) -> M-6000 | I30: P-22 | J30: 6 | K30: 4.2 | L30: 75 | M30: =IF(AND(J30>=IF(H30=Parameters!$B$3,Parameters!$B$8,Parameters!$C$8),J30<=IF(H30=Parameters!$B$3,Parameters!$B$9,Parameters!$C$9),K30>=IF(H30=Parameters!$B$3,Parameters!$B$10,Parameters!$C$10),K30<=IF(H30=Parameters!$B$3,Parameters!$B$11,Parameters!$C$11),L30<=IF(H30=Parameters!$B$3,Parameters!$B$12,Parameters!$C$12)),"Within 2.4","Outside 2.4") -> Outside 2.4 | N30: 4x8 | O30: Box 2 | P30: Standard | Q30: 62 | R30: 74 | S30: 09/03/2026 | T30: 07:01 | U30: =IF(P30="Standard",ROUND((DATE(VALUE(RIGHT(S30,4)),VALUE(LEFT(S30,2)),VALUE(MID(S30,4,2)))+VALUE(LEFT(T30,2))/Parameters!$B$28+VALUE(RIGHT(T30,2))/Parameters!$B$29-X30)*Parameters!$B$28,2),"") -> 21.7 | V30: =IF(P30<>"Standard","",IF(OR(Q30<Parameters!$B$24,R30>Parameters!$B$25),"Initial curing temperature outside 60 to 80 F",IF(U30>Parameters!$B$26,"Initial curing period over 48 hours",""))) | X30: =ROUND(DATE(VALUE(RIGHT(C30,4)),VALUE(LEFT(C30,2)),VALUE(MID(C30,4,2)))+VALUE(LEFT(D30,2))/Parameters!$B$28+VALUE(RIGHT(D30,2))/Parameters!$B$29,5) -> 46267.388 | Y30: =INDEX(Tests!$S$4:$S$31,MATCH(F30,Tests!$A$4:$A$31,0)) -> Yes
A31: S-212 | B31: L. Brandvold | C31: 09/03/2026 | D31: 08:07 | E31: Stair 2 shear walls lift 3 at pump | F31: 773586 | G31: 6S224 | H31: =IF(G31=Parameters!$B$13,Parameters!$B$3,Parameters!$C$3) -> M-6000 | I31: P-23 | J31: 6.75 | K31: 3.6 | L31: 71 | M31: =IF(AND(J31>=IF(H31=Parameters!$B$3,Parameters!$B$8,Parameters!$C$8),J31<=IF(H31=Parameters!$B$3,Parameters!$B$9,Parameters!$C$9),K31>=IF(H31=Parameters!$B$3,Parameters!$B$10,Parameters!$C$10),K31<=IF(H31=Parameters!$B$3,Parameters!$B$11,Parameters!$C$11),L31<=IF(H31=Parameters!$B$3,Parameters!$B$12,Parameters!$C$12)),"Within 2.4","Outside 2.4") -> Within 2.4 | N31: 4x8 | O31: Box 1 | P31: Standard | Q31: 61 | R31: 73 | S31: 09/04/2026 | T31: 07:32 | U31: =IF(P31="Standard",ROUND((DATE(VALUE(RIGHT(S31,4)),VALUE(LEFT(S31,2)),VALUE(MID(S31,4,2)))+VALUE(LEFT(T31,2))/Parameters!$B$28+VALUE(RIGHT(T31,2))/Parameters!$B$29-X31)*Parameters!$B$28,2),"") -> 23.42 | V31: =IF(P31<>"Standard","",IF(OR(Q31<Parameters!$B$24,R31>Parameters!$B$25),"Initial curing temperature outside 60 to 80 F",IF(U31>Parameters!$B$26,"Initial curing period over 48 hours",""))) | X31: =ROUND(DATE(VALUE(RIGHT(C31,4)),VALUE(LEFT(C31,2)),VALUE(MID(C31,4,2)))+VALUE(LEFT(D31,2))/Parameters!$B$28+VALUE(RIGHT(D31,2))/Parameters!$B$29,5) -> 46268.338 | Y31: =INDEX(Tests!$S$4:$S$31,MATCH(F31,Tests!$A$4:$A$31,0)) -> Yes
A32: S-213 | B32: L. Brandvold | C32: 09/10/2026 | D32: 12:52 | E32: Cols L4 grid 9-12 at bucket | F32: 774119 | G32: 6S224 | H32: =IF(G32=Parameters!$B$13,Parameters!$B$3,Parameters!$C$3) -> M-6000 | I32: P-26 | J32: 5.75 | K32: 2.7 | L32: 69 | M32: =IF(AND(J32>=IF(H32=Parameters!$B$3,Parameters!$B$8,Parameters!$C$8),J32<=IF(H32=Parameters!$B$3,Parameters!$B$9,Parameters!$C$9),K32>=IF(H32=Parameters!$B$3,Parameters!$B$10,Parameters!$C$10),K32<=IF(H32=Parameters!$B$3,Parameters!$B$11,Parameters!$C$11),L32<=IF(H32=Parameters!$B$3,Parameters!$B$12,Parameters!$C$12)),"Within 2.4","Outside 2.4") -> Within 2.4 | N32: 4x8 | O32: Box 2 | P32: Standard | Q32: 61 | R32: 72 | S32: 09/11/2026 | T32: 07:21 | U32: =IF(P32="Standard",ROUND((DATE(VALUE(RIGHT(S32,4)),VALUE(LEFT(S32,2)),VALUE(MID(S32,4,2)))+VALUE(LEFT(T32,2))/Parameters!$B$28+VALUE(RIGHT(T32,2))/Parameters!$B$29-X32)*Parameters!$B$28,2),"") -> 18.48 | V32: =IF(P32<>"Standard","",IF(OR(Q32<Parameters!$B$24,R32>Parameters!$B$25),"Initial curing temperature outside 60 to 80 F",IF(U32>Parameters!$B$26,"Initial curing period over 48 hours",""))) | X32: =ROUND(DATE(VALUE(RIGHT(C32,4)),VALUE(LEFT(C32,2)),VALUE(MID(C32,4,2)))+VALUE(LEFT(D32,2))/Parameters!$B$28+VALUE(RIGHT(D32,2))/Parameters!$B$29,5) -> 46275.536 | Y32: =INDEX(Tests!$S$4:$S$31,MATCH(F32,Tests!$A$4:$A$31,0)) -> Yes | Z32: Written 12:52 and read as 12:52 in the afternoon, inside the placement hours of 12:15 to 15:20.

Sheet Cylinders
A1: Every cylinder on the break record, cylinder_breaks_2417.csv, one line per cylinder, with its age and computed strength
A3: CYLINDER | B3: SET_NO | C3: MARK | D3: TICKET_NO | E3: TEST_DATE | F3: TEST_TIME | G3: DIA1_IN | H3: DIA2_IN | I3: MAX_LOAD_LBF | J3: FRACTURE | K3: DEFECT_ON_RECORD | L3: AGE_HOURS | M3: AGE_DAYS | N3: WITHIN_20_HOURS_OF_28_DAYS | O3: CURING_CLASS | P3: AREA_SQ_IN | Q3: STRENGTH_PSI | R3: ENTERS_TEST
A4: S-101-A | B4: S-101 | C4: A | D4: =INDEX(Samples!$F$4:$F$32,MATCH(B4,Samples!$A$4:$A$32,0)) -> 770418 | E4: 08/10/2026 | F4: 09:09 | G4: 5.98 | H4: 6 | I4: 85971 | J4: Type 2 | K4: No | L4: =ROUND((DATE(VALUE(RIGHT(E4,4)),VALUE(LEFT(E4,2)),VALUE(MID(E4,4,2)))+VALUE(LEFT(F4,2))/Parameters!$B$28+VALUE(RIGHT(F4,2))/Parameters!$B$29-INDEX(Samples!$X$4:$X$32,MATCH(B4,Samples!$A$4:$A$32,0)))*Parameters!$B$28,2) -> 169.77 | M4: =ROUND(L4/Parameters!$B$28,2) -> 7.07 | N4: =IF(ABS(L4-Parameters!$B$20)<=Parameters!$B$21,"Yes","No") -> No | O4: =INDEX(Samples!$P$4:$P$32,MATCH(B4,Samples!$A$4:$A$32,0)) -> Standard | P4: =ROUND(PI()*((G4+H4)/2)^2/4,4) -> 28.1802 | Q4: =ROUND(I4/(PI()*((G4+H4)/2)^2/4)/Parameters!$B$27,0)*Parameters!$B$27 -> 3050 | R4: =IF(AND(N4="Yes",O4="Standard",K4="No"),"Yes","No") -> No
A5: S-101-B | B5: S-101 | C5: B | D5: =INDEX(Samples!$F$4:$F$32,MATCH(B5,Samples!$A$4:$A$32,0)) -> 770418 | E5: 08/31/2026 | F5: 10:12 | G5: 6.02 | H5: 6.04 | I5: 125397 | J5: Type 4 | K5: No | L5: =ROUND((DATE(VALUE(RIGHT(E5,4)),VALUE(LEFT(E5,2)),VALUE(MID(E5,4,2)))+VALUE(LEFT(F5,2))/Parameters!$B$28+VALUE(RIGHT(F5,2))/Parameters!$B$29-INDEX(Samples!$X$4:$X$32,MATCH(B5,Samples!$A$4:$A$32,0)))*Parameters!$B$28,2) -> 674.82 | M5: =ROUND(L5/Parameters!$B$28,2) -> 28.12 | N5: =IF(ABS(L5-Parameters!$B$20)<=Parameters!$B$21,"Yes","No") -> Yes | O5: =INDEX(Samples!$P$4:$P$32,MATCH(B5,Samples!$A$4:$A$32,0)) -> Standard | P5: =ROUND(PI()*((G5+H5)/2)^2/4,4) -> 28.5578 | Q5: =ROUND(I5/(PI()*((G5+H5)/2)^2/4)/Parameters!$B$27,0)*Parameters!$B$27 -> 4390 | R5: =IF(AND(N5="Yes",O5="Standard",K5="No"),"Yes","No") -> Yes
A6: S-101-C | B6: S-101 | C6: C | D6: =INDEX(Samples!$F$4:$F$32,MATCH(B6,Samples!$A$4:$A$32,0)) -> 770418 | E6: 08/31/2026 | F6: 10:19 | G6: 6.01 | H6: 6.01 | I6: 116595 | J6: Type 2 | K6: No | L6: =ROUND((DATE(VALUE(RIGHT(E6,4)),VALUE(LEFT(E6,2)),VALUE(MID(E6,4,2)))+VALUE(LEFT(F6,2))/Parameters!$B$28+VALUE(RIGHT(F6,2))/Parameters!$B$29-INDEX(Samples!$X$4:$X$32,MATCH(B6,Samples!$A$4:$A$32,0)))*Parameters!$B$28,2) -> 674.93 | M6: =ROUND(L6/Parameters!$B$28,2) -> 28.12 | N6: =IF(ABS(L6-Parameters!$B$20)<=Parameters!$B$21,"Yes","No") -> Yes | O6: =INDEX(Samples!$P$4:$P$32,MATCH(B6,Samples!$A$4:$A$32,0)) -> Standard | P6: =ROUND(PI()*((G6+H6)/2)^2/4,4) -> 28.3687 | Q6: =ROUND(I6/(PI()*((G6+H6)/2)^2/4)/Parameters!$B$27,0)*Parameters!$B$27 -> 4110 | R6: =IF(AND(N6="Yes",O6="Standard",K6="No"),"Yes","No") -> Yes
A7: S-101-D | B7: S-101 | C7: D | D7: =INDEX(Samples!$F$4:$F$32,MATCH(B7,Samples!$A$4:$A$32,0)) -> 770418 | E7: 09/28/2026 | F7: 14:06 | G7: 6.01 | H7: 6.01 | I7: 131625 | J7: Type 3 | K7: No | L7: =ROUND((DATE(VALUE(RIGHT(E7,4)),VALUE(LEFT(E7,2)),VALUE(MID(E7,4,2)))+VALUE(LEFT(F7,2))/Parameters!$B$28+VALUE(RIGHT(F7,2))/Parameters!$B$29-INDEX(Samples!$X$4:$X$32,MATCH(B7,Samples!$A$4:$A$32,0)))*Parameters!$B$28,2) -> 1350.72 | M7: =ROUND(L7/Parameters!$B$28,2) -> 56.28 | N7: =IF(ABS(L7-Parameters!$B$20)<=Parameters!$B$21,"Yes","No") -> No | O7: =INDEX(Samples!$P$4:$P$32,MATCH(B7,Samples!$A$4:$A$32,0)) -> Standard | P7: =ROUND(PI()*((G7+H7)/2)^2/4,4) -> 28.3687 | Q7: =ROUND(I7/(PI()*((G7+H7)/2)^2/4)/Parameters!$B$27,0)*Parameters!$B$27 -> 4640 | R7: =IF(AND(N7="Yes",O7="Standard",K7="No"),"Yes","No") -> No
A8: S-102-A | B8: S-102 | C8: A | D8: =INDEX(Samples!$F$4:$F$32,MATCH(B8,Samples!$A$4:$A$32,0)) -> 770653 | E8: 08/12/2026 | F8: 08:36 | G8: 6 | H8: 6 | I8: 88767 | J8: Type 3 | K8: No | L8: =ROUND((DATE(VALUE(RIGHT(E8,4)),VALUE(LEFT(E8,2)),VALUE(MID(E8,4,2)))+VALUE(LEFT(F8,2))/Parameters!$B$28+VALUE(RIGHT(F8,2))/Parameters!$B$29-INDEX(Samples!$X$4:$X$32,MATCH(B8,Samples!$A$4:$A$32,0)))*Parameters!$B$28,2) -> 168.4 | M8: =ROUND(L8/Parameters!$B$28,2) -> 7.02 | N8: =IF(ABS(L8-Parameters!$B$20)<=Parameters!$B$21,"Yes","No") -> No | O8: =INDEX(Samples!$P$4:$P$32,MATCH(B8,Samples!$A$4:$A$32,0)) -> Standard | P8: =ROUND(PI()*((G8+H8)/2)^2/4,4) -> 28.2743 | Q8: =ROUND(I8/(PI()*((G8+H8)/2)^2/4)/Parameters!$B$27,0)*Parameters!$B$27 -> 3140 | R8: =IF(AND(N8="Yes",O8="Standard",K8="No"),"Yes","No") -> No
A9: S-102-B | B9: S-102 | C9: B | D9: =INDEX(Samples!$F$4:$F$32,MATCH(B9,Samples!$A$4:$A$32,0)) -> 770653 | E9: 09/02/2026 | F9: 09:48 | G9: 6.01 | H9: 6.01 | I9: 126828 | J9: Type 2 | K9: No | L9: =ROUND((DATE(VALUE(RIGHT(E9,4)),VALUE(LEFT(E9,2)),VALUE(MID(E9,4,2)))+VALUE(LEFT(F9,2))/Parameters!$B$28+VALUE(RIGHT(F9,2))/Parameters!$B$29-INDEX(Samples!$X$4:$X$32,MATCH(B9,Samples!$A$4:$A$32,0)))*Parameters!$B$28,2) -> 673.6 | M9: =ROUND(L9/Parameters!$B$28,2) -> 28.07 | N9: =IF(ABS(L9-Parameters!$B$20)<=Parameters!$B$21,"Yes","No") -> Yes | O9: =INDEX(Samples!$P$4:$P$32,MATCH(B9,Samples!$A$4:$A$32,0)) -> Standard | P9: =ROUND(PI()*((G9+H9)/2)^2/4,4) -> 28.3687 | Q9: =ROUND(I9/(PI()*((G9+H9)/2)^2/4)/Parameters!$B$27,0)*Parameters!$B$27 -> 4470 | R9: =IF(AND(N9="Yes",O9="Standard",K9="No"),"Yes","No") -> Yes
