Workbook

Sheet Findings
A1: Tract 7 boundary analysis, job 26-2214, Estate of Wendell R. Cope
A2: Prepared for Ellen Vance, who seals the plat, by the office; report prepared October 29, 2026
A3: Deed Book 412, Page 233, Putnam County, Tennessee; field work September 29 and 30, 2026
A5: Finding | B5: Value | C5: Read from
A6: Traverse closure
A7: Perimeter of the traverse (ft) | B7: =Traverse!B14 -> 2511.753 | C7: Traverse
A8: Latitude misclosure (ft) | B8: =Traverse!B15 -> -0.202 | C8: Traverse
A9: Departure misclosure (ft) | B9: =Traverse!B16 -> -0.017 | C9: Traverse
A10: Linear error of closure (ft) | B10: =Traverse!B17 -> 0.2 | C10: Traverse
A11: Precision of closure, one part in | B11: =Traverse!B18 -> 12500 | C11: Traverse
A12: Traverse shots set aside or rejected | B12: =Traverse!E11 -> 4 | C12: Traverse
A13: Tract classification on the field dates | B13: =Traverse!B19 -> Rural | C13: Parameters
A14: Firm standard for that class, one part in | B14: =Traverse!B20 -> 10000 | C14: Parameters
A15: Closure test | B15: =Traverse!B21 -> Meets the standard | C15: Traverse
A16: Notes file and ties
A17: Prism correction on every tie (ft) | B17: =Parameters!B24 -> 0.04 | C17: Parameters
A18: Offset added to the tie on point 105 (ft) | B18: =Parameters!B25 -> 0.6 | C18: Parameters
A19: Changes made to the notes file | B19: =COUNTA('Field Notes'!Z27:Z29) -> 3 | C19: Field Notes
A20: Deed comparison
A21: Deed linear misclosure on its own calls, as transcribed (ft) | B21: =Deed!B15 -> 32.13 | C21: Deed
A22: Deed misclosure per 1,000 ft of perimeter | B22: =Deed!B16 -> 12.54 | C22: Deed
A23: Deed description test | B23: =Deed!B18 -> Defect in the description | C23: Deed
A24: Deed misclosure with the 1978 distance and the 5-1 bearing restored (ft) | B24: =Deed!B29 -> 0.21 | C24: Deed
A25: Rotation line | B25: =Deed!B32 -> Stone at corner 4 to stone at corner 5, the 4-5 call | C25: Deed
A26: Rotation, deed magnetic bearings to the grid | B26: =Deed!B36 -> 2° 12' east of the deed bearings | C26: Deed
A27: Rotation the road course would give (minutes of arc) | B27: =Deed!B38 -> 135 | C27: Deed
A28: Calls out of tolerance | B28: =Deed!B42 -> 2 | C28: Deed
A29: Calls in error in the deed | B29: =Deed!B43 -> 2 | C29: Deed
A30: 3-4 call, deed distance as transcribed (ft) | B30: =Deed!B44 -> 597.2 | C30: Deed
A31: 3-4 call, measured distance the plat carries (ft) | B31: =Deed!B45 -> 592.42 | C31: Deed
A32: 3-4 call, distance in the 1978 deed of trust (ft) | B32: =Deed!B23 -> 592.7 | C32: Deed
A33: 5-1 call, rotated bearing as transcribed | B33: =Deed!B47 -> N 32° 19' W | C33: Deed
A34: 5-1 call, rotated bearing with the digits restored | B34: =Deed!B49 -> N 41° 19' W | C34: Deed
A35: 5-1 call, measured bearing the plat carries | B35: =Deed!B50 -> N 41° 15' 59" W | C35: Deed
A36: 5-1 call, measured less restored (minutes) | B36: =Deed!B51 -> 3 | C36: Deed
A37: Finding on the calls in error | B37: =Deed!B52 -> Two errors in the deed, the 3-4 distance and the 5-1 bearing; the measured courses stand | C37: Deed
A38: Monuments and corners
A39: Original monuments of the tract found and held | B39: =Corners!B35 -> 3 | C39: Corners
A40: Later monuments held as the corner | B40: =Corners!B36 -> 1 | C40: Corners
A41: Offset of the corner 1 pin from its test position (ft) | B41: =Corners!K4 -> 0.48 | C41: Corners
...

Sheet Parameters
A1: Parameters and office readings for the tract 7 analysis
A3: Parameter | B3: Value | C3: Source
A4: First station northing (ft) | B4: 5000 | C4: Firm standards 1.4
A5: First station easting (ft) | B5: 5000 | C5: Firm standards 1.4
A6: Closure standard, urban, one part in | B6: 15000 | C6: Firm standards 1.3
A7: Closure standard, rural, one part in | B7: 10000 | C7: Firm standards 1.3
A8: Tract classification on the field dates | B8: Rural | C8: Firm standards 1.3; record research: Parcel 041.00 comes inside the corporate limits under Ordinance O26-07, effective November 1, 2026, after the field work of September 29 and 30, 2026
A9: Square feet per acre | B9: 43560 | C9: Firm standards 2.1
A10: Deed acreage recited | B10: 9.89 | C10: Deed Book 412, Page 233
A11: Deed misclosure threshold (ft per 1,000 ft of perimeter) | B11: 1 | C11: Firm standards 3.1
A12: Perimeter unit for the deed misclosure rate (ft) | B12: 1000 | C12: Firm standards 3.1
A13: Tolerance of the original survey, distance (ft) | B13: 1 | C13: Firm standards 3.3
A14: Tolerance of the original survey, bearing (minutes) | B14: 10 | C14: Firm standards 3.3
A15: Later monument held within (ft) | B15: 0.5 | C15: Firm standards 3.6
A16: Occupation reported as encroachment beyond (ft) | B16: 0.25 | C16: Firm standards 3.8
A17: Minutes in a degree | B17: 60 | C17: Sexagesimal angle
A18: Seconds in a degree | B18: 3600 | C18: Sexagesimal angle
A19: Pairs on one course meaned together within (ft) | B19: 0.05 | C19: Firm standards 1.1; the same figures test a forward shot against its reverse
A20: Pairs on one course meaned together within (seconds) | B20: 20 | C20: Firm standards 1.1
... A23: Meters in a U.S. survey foot | B23: 0.3048006 | C23: Firm standards 1.5
A24: Prism correction on every tie (ft) | B24: =ROUND((B22-B21)/B29/B23,2) -> 0.04 | C24: Firm standards 1.5: the constant of the prism used less the constant set
A25: Offset added to the tie on point 105 (ft) | B25: 0.6 | C25: Field book, point 105: the pole was held 0.60 foot short of the drill hole on the line of sight
A26: Distance of the 3-4 call in the 1978 deed of trust (ft) | B26: 592.7 | C26: Record research: Trust Book 88, Page 140
A27: Distance of the rebar from the Hutchins southwest corner on the 2008 plat (ft) | B27: 588.8 | C27: Record research: Plat Cabinet D, Slide 57
A28: Length of the Ballinger west line in the Ballinger deed (ft) | B28: 806.9 | C28: Record research: Deed Book 377, Page 102
A29: Millimeters in a meter | B29: 1000 | C29: Metric conversion, for the prism constants
A30: Turn applied to every leg azimuth before the direction mean (degrees) | B30: 45 | C30: Office convention. The mean bearing of a leg is taken from summed cosines and sines, and the turn keeps those of the T7-T2 leg away from zero where it straddles north. The turn is taken off again after the mean.

Sheet Field Notes
A1: Field notes, field_notes_traverse_tract7.csv, every shot as recorded, with the office columns beside them
A3: SHOT | B3: DATE | C3: TIME | D3: AT | E3: TO | F3: NS | G3: DEG | H3: MIN | I3: SEC | J3: EW | K3: HORIZ_DIST_FT | L3: CODE | M3: STATION USED | N3: POINT USED | O3: AZIMUTH | P3: LEG | Q3: DIRECTION | R3: AZIMUTH ALONG THE LEG | S3: PAIR | T3: COSINE, LEG AZIMUTH LESS THE TURN | U3: SINE, LEG AZIMUTH LESS THE TURN | V3: USED | W3: PRISM CORRECTION (FT) | X3: OFFSET (FT) | Y3: DISTANCE USED (FT) | Z3: OFFICE NOTE
A4: 1 | B4: 09/29/2026 | C4: 08:42 | D4: T1 | E4: T7 | F4: N | G4: 31 | H4: 7 | I4: 24 | J4: E | K4: 347.42 | L4: TRAV | M4: T1 | N4: T7 | O4: =ROUND(IF(AND(F4="N",J4="E"),(G4+H4/Parameters!$B$17+I4/Parameters!$B$18),IF(AND(F4="S",J4="E"),180-(G4+H4/Parameters!$B$17+I4/Parameters!$B$18),IF(AND(F4="S",J4="W"),180+(G4+H4/Parameters!$B$17+I4/Parameters!$B$18),360-(G4+H4/Parameters!$B$17+I4/Parameters!$B$18)))),6) -> 31.123333 | P4: =IF(ISNUMBER(MATCH(M4&"-"&N4,Traverse!$A$4:$A$10,0)),M4&"-"&N4,N4&"-"&M4) -> T1-T7 | Q4: =IF(P4=M4&"-"&N4,"Forward","Reverse") -> Forward | R4: =IF(Q4="Forward",O4,ROUND(MOD(O4+180,360),6)) -> 31.123333 | S4: 1 | T4: =COS(RADIANS(R4-Parameters!$B$30)) -> 0.97081423 | U4: =SIN(RADIANS(R4-Parameters!$B$30)) -> -0.23983271 | V4: Yes | Y4: =K4 -> 347.42
A5: 2 | B5: 09/29/2026 | C5: 09:26 | D5: T7 | E5: T1 | F5: S | G5: 31 | H5: 7 | I5: 21 | J5: W | K5: 347.43 | L5: TRAV | M5: T7 | N5: T1 | O5: =ROUND(IF(AND(F5="N",J5="E"),(G5+H5/Parameters!$B$17+I5/Parameters!$B$18),IF(AND(F5="S",J5="E"),180-(G5+H5/Parameters!$B$17+I5/Parameters!$B$18),IF(AND(F5="S",J5="W"),180+(G5+H5/Parameters!$B$17+I5/Parameters!$B$18),360-(G5+H5/Parameters!$B$17+I5/Parameters!$B$18)))),6) -> 211.1225 | P5: =IF(ISNUMBER(MATCH(M5&"-"&N5,Traverse!$A$4:$A$10,0)),M5&"-"&N5,N5&"-"&M5) -> T1-T7 | Q5: =IF(P5=M5&"-"&N5,"Forward","Reverse") -> Reverse | R5: =IF(Q5="Forward",O5,ROUND(MOD(O5+180,360),6)) -> 31.1225 | S5: 1 | T5: =COS(RADIANS(R5-Parameters!$B$30)) -> 0.97081074 | U5: =SIN(RADIANS(R5-Parameters!$B$30)) -> -0.23984682 | V5: Yes | Y5: =K5 -> 347.43
A6: 3 | B6: 09/29/2026 | C6: 09:38 | D6: T7 | E6: T2 | F6: N | G6: 0 | H6: 0 | I6: 3 | J6: W | K6: 300.01 | L6: TRAV | M6: T7 | N6: T2 | O6: =ROUND(IF(AND(F6="N",J6="E"),(G6+H6/Parameters!$B$17+I6/Parameters!$B$18),IF(AND(F6="S",J6="E"),180-(G6+H6/Parameters!$B$17+I6/Parameters!$B$18),IF(AND(F6="S",J6="W"),180+(G6+H6/Parameters!$B$17+I6/Parameters!$B$18),360-(G6+H6/Parameters!$B$17+I6/Parameters!$B$18)))),6) -> 359.99917 | P6: =IF(ISNUMBER(MATCH(M6&"-"&N6,Traverse!$A$4:$A$10,0)),M6&"-"&N6,N6&"-"&M6) -> T7-T2 | Q6: =IF(P6=M6&"-"&N6,"Forward","Reverse") -> Forward | R6: =IF(Q6="Forward",O6,ROUND(MOD(O6+180,360),6)) -> 359.99917 | S6: 1 | T6: =COS(RADIANS(R6-Parameters!$B$30)) -> 0.7070965 | U6: =SIN(RADIANS(R6-Parameters!$B$30)) -> -0.70711706 | V6: Yes | Y6: =K6 -> 300.01
A7: 4 | B7: 09/29/2026 | C7: 10:04 | D7: T2 | E7: T7 | F7: S | G7: 0 | H7: 0 | I7: 1 | J7: W | K7: 299.98 | L7: TRAV | M7: T2 | N7: T7 | O7: =ROUND(IF(AND(F7="N",J7="E"),(G7+H7/Parameters!$B$17+I7/Parameters!$B$18),IF(AND(F7="S",J7="E"),180-(G7+H7/Parameters!$B$17+I7/Parameters!$B$18),IF(AND(F7="S",J7="W"),180+(G7+H7/Parameters!$B$17+I7/Parameters!$B$18),360-(G7+H7/Parameters!$B$17+I7/Parameters!$B$18)))),6) -> 180.00028 | P7: =IF(ISNUMBER(MATCH(M7&"-"&N7,Traverse!$A$4:$A$10,0)),M7&"-"&N7,N7&"-"&M7) -> T7-T2 | Q7: =IF(P7=M7&"-"&N7,"Forward","Reverse") -> Reverse | R7: =IF(Q7="Forward",O7,ROUND(MOD(O7+180,360),6)) -> 0.000278 | S7: 1 | T7: =COS(RADIANS(R7-Parameters!$B$30)) -> 0.70711021 | U7: =SIN(RADIANS(R7-Parameters!$B$30)) -> -0.70710335 | V7: Yes | Y7: =K7 -> 299.98
A8: 5 | B8: 09/29/2026 | C8: 10:31 | D8: T2 | E8: T3 | F8: S | G8: 76 | H8: 36 | I8: 15 | J8: E | K8: 285.02 | L8: TRAV | M8: T2 | N8: T3 | O8: =ROUND(IF(AND(F8="N",J8="E"),(G8+H8/Parameters!$B$17+I8/Parameters!$B$18),IF(AND(F8="S",J8="E"),180-(G8+H8/Parameters!$B$17+I8/Parameters!$B$18),IF(AND(F8="S",J8="W"),180+(G8+H8/Parameters!$B$17+I8/Parameters!$B$18),360-(G8+H8/Parameters!$B$17+I8/Parameters!$B$18)))),6) -> 103.39583 | P8: =IF(ISNUMBER(MATCH(M8&"-"&N8,Traverse!$A$4:$A$10,0)),M8&"-"&N8,N8&"-"&M8) -> T2-T3 | Q8: =IF(P8=M8&"-"&N8,"Forward","Reverse") -> Forward | R8: =IF(Q8="Forward",O8,ROUND(MOD(O8+180,360),6)) -> 103.39583 | S8: 1 | T8: =COS(RADIANS(R8-Parameters!$B$30)) -> 0.52404785 | U8: =SIN(RADIANS(R8-Parameters!$B$30)) -> 0.85168882 | V8: Yes | Y8: =K8 -> 285.02
A9: 6 | B9: 09/29/2026 | C9: 10:36 | D9: T3 | E9: T2 | F9: N | G9: 76 | H9: 36 | I9: 16 | J9: W | K9: 285.03 | L9: TRAV | M9: T3 | N9: T2 | O9: =ROUND(IF(AND(F9="N",J9="E"),(G9+H9/Parameters!$B$17+I9/Parameters!$B$18),IF(AND(F9="S",J9="E"),180-(G9+H9/Parameters!$B$17+I9/Parameters!$B$18),IF(AND(F9="S",J9="W"),180+(G9+H9/Parameters!$B$17+I9/Parameters!$B$18),360-(G9+H9/Parameters!$B$17+I9/Parameters!$B$18)))),6) -> 283.39556 | P9: =IF(ISNUMBER(MATCH(M9&"-"&N9,Traverse!$A$4:$A$10,0)),M9&"-"&N9,N9&"-"&M9) -> T2-T3 | Q9: =IF(P9=M9&"-"&N9,"Forward","Reverse") -> Reverse | R9: =IF(Q9="Forward",O9,ROUND(MOD(O9+180,360),6)) -> 103.39556 | S9: 1 | T9: =COS(RADIANS(R9-Parameters!$B$30)) -> 0.52405197 | U9: =SIN(RADIANS(R9-Parameters!$B$30)) -> 0.85168629 | V9: Yes | Y9: =K9 -> 285.03
A10: 7 | B10: 09/29/2026 | C10: 11:09 | D10: T2 | E10: T3 | F10: S | G10: 76 | H10: 36 | I10: 13 | J10: E | K10: 285.03 | L10: TRAV | M10: T2 | N10: T3 | O10: =ROUND(IF(AND(F10="N",J10="E"),(G10+H10/Parameters!$B$17+I10/Parameters!$B$18),IF(AND(F10="S",J10="E"),180-(G10+H10/Parameters!$B$17+I10/Parameters!$B$18),IF(AND(F10="S",J10="W"),180+(G10+H10/Parameters!$B$17+I10/Parameters!$B$18),360-(G10+H10/Parameters!$B$17+I10/Parameters!$B$18)))),6) -> 103.39639 | P10: =IF(ISNUMBER(MATCH(M10&"-"&N10,Traverse!$A$4:$A$10,0)),M10&"-"&N10,N10&"-"&M10) -> T2-T3 | Q10: =IF(P10=M10&"-"&N10,"Forward","Reverse") -> Forward | R10: =IF(Q10="Forward",O10,ROUND(MOD(O10+180,360),6)) -> 103.39639 | S10: 2 | T10: =COS(RADIANS(R10-Parameters!$B$30)) -> 0.52403958 | U10: =SIN(RADIANS(R10-Parameters!$B$30)) -> 0.85169391 | V10: Yes | Y10: =K10 -> 285.03
A11: 8 | B11: 09/29/2026 | C11: 11:14 | D11: T3 | E11: T2 | F11: N | G11: 76 | H11: 36 | I11: 17 | J11: W | K11: 285.03 | L11: TRAV | M11: T3 | N11: T2 | O11: =ROUND(IF(AND(F11="N",J11="E"),(G11+H11/Parameters!$B$17+I11/Parameters!$B$18),IF(AND(F11="S",J11="E"),180-(G11+H11/Parameters!$B$17+I11/Parameters!$B$18),IF(AND(F11="S",J11="W"),180+(G11+H11/Parameters!$B$17+I11/Parameters!$B$18),360-(G11+H11/Parameters!$B$17+I11/Parameters!$B$18)))),6) -> 283.39528 | P11: =IF(ISNUMBER(MATCH(M11&"-"&N11,Traverse!$A$4:$A$10,0)),M11&"-"&N11,N11&"-"&M11) -> T2-T3 | Q11: =IF(P11=M11&"-"&N11,"Forward","Reverse") -> Reverse | R11: =IF(Q11="Forward",O11,ROUND(MOD(O11+180,360),6)) -> 103.39528 | S11: 2 | T11: =COS(RADIANS(R11-Parameters!$B$30)) -> 0.5240561 | U11: =SIN(RADIANS(R11-Parameters!$B$30)) -> 0.85168375 | V11: Yes | Y11: =K11 -> 285.03
A12: 9 | B12: 09/29/2026 | C12: 11:22 | D12: T3 | E12: T4 | F12: S | G12: 81 | H12: 0 | I12: 3 | J12: E | K12: 287.39 | L12: TRAV | M12: T3 | N12: T4 | O12: =ROUND(IF(AND(F12="N",J12="E"),(G12+H12/Parameters!$B$17+I12/Parameters!$B$18),IF(AND(F12="S",J12="E"),180-(G12+H12/Parameters!$B$17+I12/Parameters!$B$18),IF(AND(F12="S",J12="W"),180+(G12+H12/Parameters!$B$17+I12/Parameters!$B$18),360-(G12+H12/Parameters!$B$17+I12/Parameters!$B$18)))),6) -> 98.999167 | P12: =IF(ISNUMBER(MATCH(M12&"-"&N12,Traverse!$A$4:$A$10,0)),M12&"-"&N12,N12&"-"&M12) -> T3-T4 | Q12: =IF(P12=M12&"-"&N12,"Forward","Reverse") -> Forward | R12: =IF(Q12="Forward",O12,ROUND(MOD(O12+180,360),6)) -> 98.999167 | S12: 1 | T12: =COS(RADIANS(R12-Parameters!$B$30)) -> 0.58779701 | U12: =SIN(RADIANS(R12-Parameters!$B$30)) -> 0.80900845 | V12: No | Y12: =K12 -> 287.39 | Z12: Pair in error under firm standards 1.1: the reverse distance of this pair reads 1.20 feet longer than the forward. The pair is rejected, and the second pair carries the T3-T4 leg
A13: 10 | B13: 09/29/2026 | C13: 13:05 | D13: T4 | E13: T3 | F13: N | G13: 81 | H13: 0 | I13: 8 | J13: W | K13: 288.59 | L13: TRAV | M13: T4 | N13: T3 | O13: =ROUND(IF(AND(F13="N",J13="E"),(G13+H13/Parameters!$B$17+I13/Parameters!$B$18),IF(AND(F13="S",J13="E"),180-(G13+H13/Parameters!$B$17+I13/Parameters!$B$18),IF(AND(F13="S",J13="W"),180+(G13+H13/Parameters!$B$17+I13/Parameters!$B$18),360-(G13+H13/Parameters!$B$17+I13/Parameters!$B$18)))),6) -> 278.99778 | P13: =IF(ISNUMBER(MATCH(M13&"-"&N13,Traverse!$A$4:$A$10,0)),M13&"-"&N13,N13&"-"&M13) -> T3-T4 | Q13: =IF(P13=M13&"-"&N13,"Forward","Reverse") -> Reverse | R13: =IF(Q13="Forward",O13,ROUND(MOD(O13+180,360),6)) -> 98.997778 | S13: 1 | T13: =COS(RADIANS(R13-Parameters!$B$30)) -> 0.58781663 | U13: =SIN(RADIANS(R13-Parameters!$B$30)) -> 0.8089942 | V13: No | Y13: =K13 -> 288.59 | Z13: Pair in error under firm standards 1.1, rejected with shot 9
A14: 11 | B14: 09/29/2026 | C14: 13:11 | D14: T3 | E14: T4 | F14: S | G14: 81 | H14: 0 | I14: 8 | J14: E | K14: 287.39 | L14: TRAV | M14: T3 | N14: T4 | O14: =ROUND(IF(AND(F14="N",J14="E"),(G14+H14/Parameters!$B$17+I14/Parameters!$B$18),IF(AND(F14="S",J14="E"),180-(G14+H14/Parameters!$B$17+I14/Parameters!$B$18),IF(AND(F14="S",J14="W"),180+(G14+H14/Parameters!$B$17+I14/Parameters!$B$18),360-(G14+H14/Parameters!$B$17+I14/Parameters!$B$18)))),6) -> 98.997778 | P14: =IF(ISNUMBER(MATCH(M14&"-"&N14,Traverse!$A$4:$A$10,0)),M14&"-"&N14,N14&"-"&M14) -> T3-T4 | Q14: =IF(P14=M14&"-"&N14,"Forward","Reverse") -> Forward | R14: =IF(Q14="Forward",O14,ROUND(MOD(O14+180,360),6)) -> 98.997778 | S14: 2 | T14: =COS(RADIANS(R14-Parameters!$B$30)) -> 0.58781663 | U14: =SIN(RADIANS(R14-Parameters!$B$30)) -> 0.8089942 | V14: Yes | Y14: =K14 -> 287.39
A15: 12 | B15: 09/29/2026 | C15: 13:17 | D15: T4 | E15: T3 | F15: N | G15: 81 | H15: 0 | I15: 5 | J15: W | K15: 287.39 | L15: TRAV | M15: T4 | N15: T3 | O15: =ROUND(IF(AND(F15="N",J15="E"),(G15+H15/Parameters!$B$17+I15/Parameters!$B$18),IF(AND(F15="S",J15="E"),180-(G15+H15/Parameters!$B$17+I15/Parameters!$B$18),IF(AND(F15="S",J15="W"),180+(G15+H15/Parameters!$B$17+I15/Parameters!$B$18),360-(G15+H15/Parameters!$B$17+I15/Parameters!$B$18)))),6) -> 278.99861 | P15: =IF(ISNUMBER(MATCH(M15&"-"&N15,Traverse!$A$4:$A$10,0)),M15&"-"&N15,N15&"-"&M15) -> T3-T4 | Q15: =IF(P15=M15&"-"&N15,"Forward","Reverse") -> Reverse | R15: =IF(Q15="Forward",O15,ROUND(MOD(O15+180,360),6)) -> 98.998611 | S15: 2 | T15: =COS(RADIANS(R15-Parameters!$B$30)) -> 0.58780486 | U15: =SIN(RADIANS(R15-Parameters!$B$30)) -> 0.80900275 | V15: Yes | Y15: =K15 -> 287.39
A16: 13 | B16: 09/29/2026 | C16: 13:26 | D16: T4 | E16: T5 | F16: S | G16: 11 | H16: 1 | I16: 13 | J16: W | K16: 575.24 | L16: TRAV | M16: T4 | N16: T5 | O16: =ROUND(IF(AND(F16="N",J16="E"),(G16+H16/Parameters!$B$17+I16/Parameters!$B$18),IF(AND(F16="S",J16="E"),180-(G16+H16/Parameters!$B$17+I16/Parameters!$B$18),IF(AND(F16="S",J16="W"),180+(G16+H16/Parameters!$B$17+I16/Parameters!$B$18),360-(G16+H16/Parameters!$B$17+I16/Parameters!$B$18)))),6) -> 191.02028 | P16: =IF(ISNUMBER(MATCH(M16&"-"&N16,Traverse!$A$4:$A$10,0)),M16&"-"&N16,N16&"-"&M16) -> T4-T5 | Q16: =IF(P16=M16&"-"&N16,"Forward","Reverse") -> Forward | R16: =IF(Q16="Forward",O16,ROUND(MOD(O16+180,360),6)) -> 191.02028 | S16: 1 | T16: =COS(RADIANS(R16-Parameters!$B$30)) -> -0.82923543 | U16: =SIN(RADIANS(R16-Parameters!$B$30)) -> 0.55889946 | V16: Yes | Y16: =K16 -> 575.24
A17: 14 | B17: 09/29/2026 | C17: 14:40 | D17: T5 | E17: T4 | F17: N | G17: 11 | H17: 1 | I17: 16 | J17: E | K17: 575.28 | L17: TRAV | M17: T5 | N17: T4 | O17: =ROUND(IF(AND(F17="N",J17="E"),(G17+H17/Parameters!$B$17+I17/Parameters!$B$18),IF(AND(F17="S",J17="E"),180-(G17+H17/Parameters!$B$17+I17/Parameters!$B$18),IF(AND(F17="S",J17="W"),180+(G17+H17/Parameters!$B$17+I17/Parameters!$B$18),360-(G17+H17/Parameters!$B$17+I17/Parameters!$B$18)))),6) -> 11.021111 | P17: =IF(ISNUMBER(MATCH(M17&"-"&N17,Traverse!$A$4:$A$10,0)),M17&"-"&N17,N17&"-"&M17) -> T4-T5 | Q17: =IF(P17=M17&"-"&N17,"Forward","Reverse") -> Reverse | R17: =IF(Q17="Forward",O17,ROUND(MOD(O17+180,360),6)) -> 191.02111 | S17: 1 | T17: =COS(RADIANS(R17-Parameters!$B$30)) -> -0.82924356 | U17: =SIN(RADIANS(R17-Parameters!$B$30)) -> 0.5588874 | V17: Yes | Y17: =K17 -> 575.28
A18: 15 | B18: 09/29/2026 | C18: 14:49 | D18: T5 | E18: T6 | F18: S | G18: 79 | H18: 55 | I18: 56 | J18: W | K18: 501.58 | L18: TRAV | M18: T5 | N18: T6 | O18: =ROUND(IF(AND(F18="N",J18="E"),(G18+H18/Parameters!$B$17+I18/Parameters!$B$18),IF(AND(F18="S",J18="E"),180-(G18+H18/Parameters!$B$17+I18/Parameters!$B$18),IF(AND(F18="S",J18="W"),180+(G18+H18/Parameters!$B$17+I18/Parameters!$B$18),360-(G18+H18/Parameters!$B$17+I18/Parameters!$B$18)))),6) -> 259.93222 | P18: =IF(ISNUMBER(MATCH(M18&"-"&N18,Traverse!$A$4:$A$10,0)),M18&"-"&N18,N18&"-"&M18) -> T5-T6 | Q18: =IF(P18=M18&"-"&N18,"Forward","Reverse") -> Forward | R18: =IF(Q18="Forward",O18,ROUND(MOD(O18+180,360),6)) -> 259.93222 | S18: 1 | T18: =COS(RADIANS(R18-Parameters!$B$30)) -> -0.81982998 | U18: =SIN(RADIANS(R18-Parameters!$B$30)) -> -0.57260702 | V18: No | Y18: =K18 -> 501.58 | Z18: Set aside: first pair on T5-T6, 0.28 foot short of the second pair, the distance of the county PK nail from the hub at T6
A19: 16 | B19: 09/29/2026 | C19: 15:33 | D19: T6 | E19: T5 | F19: N | G19: 79 | H19: 56 | I19: 0 | J19: E | K19: 501.59 | L19: TRAV | M19: T6 | N19: T5 | O19: =ROUND(IF(AND(F19="N",J19="E"),(G19+H19/Parameters!$B$17+I19/Parameters!$B$18),IF(AND(F19="S",J19="E"),180-(G19+H19/Parameters!$B$17+I19/Parameters!$B$18),IF(AND(F19="S",J19="W"),180+(G19+H19/Parameters!$B$17+I19/Parameters!$B$18),360-(G19+H19/Parameters!$B$17+I19/Parameters!$B$18)))),6) -> 79.933333 | P19: =IF(ISNUMBER(MATCH(M19&"-"&N19,Traverse!$A$4:$A$10,0)),M19&"-"&N19,N19&"-"&M19) -> T5-T6 | Q19: =IF(P19=M19&"-"&N19,"Forward","Reverse") -> Reverse | R19: =IF(Q19="Forward",O19,ROUND(MOD(O19+180,360),6)) -> 259.93333 | S19: 1 | T19: =COS(RADIANS(R19-Parameters!$B$30)) -> -0.81981888 | U19: =SIN(RADIANS(R19-Parameters!$B$30)) -> -0.57262292 | V19: No | Y19: =K19 -> 501.59 | Z19: Set aside: first pair on T5-T6, taken to the PK nail and not to the hub
A20: 17 | B20: 09/29/2026 | C20: 15:40 | D20: T5 | E20: T6 | F20: S | G20: 79 | H20: 55 | I20: 56 | J20: W | K20: 501.86 | L20: TRAV | M20: T5 | N20: T6 | O20: =ROUND(IF(AND(F20="N",J20="E"),(G20+H20/Parameters!$B$17+I20/Parameters!$B$18),IF(AND(F20="S",J20="E"),180-(G20+H20/Parameters!$B$17+I20/Parameters!$B$18),IF(AND(F20="S",J20="W"),180+(G20+H20/Parameters!$B$17+I20/Parameters!$B$18),360-(G20+H20/Parameters!$B$17+I20/Parameters!$B$18)))),6) -> 259.93222 | P20: =IF(ISNUMBER(MATCH(M20&"-"&N20,Traverse!$A$4:$A$10,0)),M20&"-"&N20,N20&"-"&M20) -> T5-T6 | Q20: =IF(P20=M20&"-"&N20,"Forward","Reverse") -> Forward | R20: =IF(Q20="Forward",O20,ROUND(MOD(O20+180,360),6)) -> 259.93222 | S20: 2 | T20: =COS(RADIANS(R20-Parameters!$B$30)) -> -0.81982998 | U20: =SIN(RADIANS(R20-Parameters!$B$30)) -> -0.57260702 | V20: Yes | Y20: =K20 -> 501.86
A21: 18 | B21: 09/29/2026 | C21: 16:27 | D21: T6 | E21: T5 | F21: N | G21: 79 | H21: 56 | I21: 0 | J21: E | K21: 501.87 | L21: TRAV | M21: T6 | N21: T5 | O21: =ROUND(IF(AND(F21="N",J21="E"),(G21+H21/Parameters!$B$17+I21/Parameters!$B$18),IF(AND(F21="S",J21="E"),180-(G21+H21/Parameters!$B$17+I21/Parameters!$B$18),IF(AND(F21="S",J21="W"),180+(G21+H21/Parameters!$B$17+I21/Parameters!$B$18),360-(G21+H21/Parameters!$B$17+I21/Parameters!$B$18)))),6) -> 79.933333 | P21: =IF(ISNUMBER(MATCH(M21&"-"&N21,Traverse!$A$4:$A$10,0)),M21&"-"&N21,N21&"-"&M21) -> T5-T6 | Q21: =IF(P21=M21&"-"&N21,"Forward","Reverse") -> Reverse | R21: =IF(Q21="Forward",O21,ROUND(MOD(O21+180,360),6)) -> 259.93333 | S21: 2 | T21: =COS(RADIANS(R21-Parameters!$B$30)) -> -0.81981888 | U21: =SIN(RADIANS(R21-Parameters!$B$30)) -> -0.57262292 | V21: Yes | Y21: =K21 -> 501.87
A22: 19 | B22: 09/29/2026 | C22: 16:48 | D22: T6 | E22: T1 | F22: N | G22: 39 | H22: 29 | I22: 43 | J22: W | K22: 214.8 | L22: TRAV | M22: T6 | N22: T1 | O22: =ROUND(IF(AND(F22="N",J22="E"),(G22+H22/Parameters!$B$17+I22/Parameters!$B$18),IF(AND(F22="S",J22="E"),180-(G22+H22/Parameters!$B$17+I22/Parameters!$B$18),IF(AND(F22="S",J22="W"),180+(G22+H22/Parameters!$B$17+I22/Parameters!$B$18),360-(G22+H22/Parameters!$B$17+I22/Parameters!$B$18)))),6) -> 320.50472 | P22: =IF(ISNUMBER(MATCH(M22&"-"&N22,Traverse!$A$4:$A$10,0)),M22&"-"&N22,N22&"-"&M22) -> T6-T1 | Q22: =IF(P22=M22&"-"&N22,"Forward","Reverse") -> Forward | R22: =IF(Q22="Forward",O22,ROUND(MOD(O22+180,360),6)) -> 320.50472 | S22: 1 | T22: =COS(RADIANS(R22-Parameters!$B$30)) -> 0.095927787 | U22: =SIN(RADIANS(R22-Parameters!$B$30)) -> -0.9953883 | V22: Yes | Y22: =K22 -> 214.8
A23: 20 | B23: 09/29/2026 | C23: 17:21 | D23: T1 | E23: T6 | F23: S | G23: 39 | H23: 29 | I23: 46 | J23: E | K23: 214.78 | L23: TRAV | M23: T1 | N23: T6 | O23: =ROUND(IF(AND(F23="N",J23="E"),(G23+H23/Parameters!$B$17+I23/Parameters!$B$18),IF(AND(F23="S",J23="E"),180-(G23+H23/Parameters!$B$17+I23/Parameters!$B$18),IF(AND(F23="S",J23="W"),180+(G23+H23/Parameters!$B$17+I23/Parameters!$B$18),360-(G23+H23/Parameters!$B$17+I23/Parameters!$B$18)))),6) -> 140.50389 | P23: =IF(ISNUMBER(MATCH(M23&"-"&N23,Traverse!$A$4:$A$10,0)),M23&"-"&N23,N23&"-"&M23) -> T6-T1 | Q23: =IF(P23=M23&"-"&N23,"Forward","Reverse") -> Reverse | R23: =IF(Q23="Forward",O23,ROUND(MOD(O23+180,360),6)) -> 320.50389 | S23: 1 | T23: =COS(RADIANS(R23-Parameters!$B$30)) -> 0.095913316 | U23: =SIN(RADIANS(R23-Parameters!$B$30)) -> -0.99538969 | V23: Yes | Y23: =K23 -> 214.78
A24: 21 | B24: 09/30/2026 | C24: 08:10 | D24: T1 | E24: 101 | F24: S | G24: 67 | H24: 54 | I24: 49 | J24: W | K24: 13.79 | L24: IPF | M24: T1 | N24: 101 | O24: =ROUND(IF(AND(F24="N",J24="E"),(G24+H24/Parameters!$B$17+I24/Parameters!$B$18),IF(AND(F24="S",J24="E"),180-(G24+H24/Parameters!$B$17+I24/Parameters!$B$18),IF(AND(F24="S",J24="W"),180+(G24+H24/Parameters!$B$17+I24/Parameters!$B$18),360-(G24+H24/Parameters!$B$17+I24/Parameters!$B$18)))),6) -> 247.91361 | W24: =Parameters!$B$24 -> 0.04 | X24: 0 | Y24: =ROUND(K24+W24+X24,2) -> 13.83
A25: 22 | B25: 09/30/2026 | C25: 08:49 | D25: T2 | E25: 102 | F25: N | G25: 29 | H25: 0 | I25: 1 | J25: W | K25: 11.16 | L25: IPF | M25: T2 | N25: 102 | O25: =ROUND(IF(AND(F25="N",J25="E"),(G25+H25/Parameters!$B$17+I25/Parameters!$B$18),IF(AND(F25="S",J25="E"),180-(G25+H25/Parameters!$B$17+I25/Parameters!$B$18),IF(AND(F25="S",J25="W"),180+(G25+H25/Parameters!$B$17+I25/Parameters!$B$18),360-(G25+H25/Parameters!$B$17+I25/Parameters!$B$18)))),6) -> 330.99972 | W25: =Parameters!$B$24 -> 0.04 | X25: 0 | Y25: =ROUND(K25+W25+X25,2) -> 11.2
A26: 23 | B26: 09/30/2026 | C26: 08:53 | D26: T2 | E26: 201 | F26: N | G26: 81 | H26: 43 | I26: 12 | J26: E | K26: 26.23 | L26: FNC | M26: T2 | N26: 201 | O26: =ROUND(IF(AND(F26="N",J26="E"),(G26+H26/Parameters!$B$17+I26/Parameters!$B$18),IF(AND(F26="S",J26="E"),180-(G26+H26/Parameters!$B$17+I26/Parameters!$B$18),IF(AND(F26="S",J26="W"),180+(G26+H26/Parameters!$B$17+I26/Parameters!$B$18),360-(G26+H26/Parameters!$B$17+I26/Parameters!$B$18)))),6) -> 81.72 | W26: =Parameters!$B$24 -> 0.04 | X26: 0 | Y26: =ROUND(K26+W26+X26,2) -> 26.27
A27: 24 | B27: 09/30/2026 | C27: 09:31 | D27: T2 | E27: 202 | F27: N | G27: 22 | H27: 48 | I27: 20 | J27: E | K27: 19.67 | L27: FNC | M27: T3 | N27: 202 | O27: =ROUND(IF(AND(F27="N",J27="E"),(G27+H27/Parameters!$B$17+I27/Parameters!$B$18),IF(AND(F27="S",J27="E"),180-(G27+H27/Parameters!$B$17+I27/Parameters!$B$18),IF(AND(F27="S",J27="W"),180+(G27+H27/Parameters!$B$17+I27/Parameters!$B$18),360-(G27+H27/Parameters!$B$17+I27/Parameters!$B$18)))),6) -> 22.805556 | W27: =Parameters!$B$24 -> 0.04 | X27: 0 | Y27: =ROUND(K27+W27+X27,2) -> 19.71 | Z27: Station changed from T2 to T3: the field book ties point 202 from T3, the shot falls between the T2 and T4 set-ups, and from T3 the post stands on the fence line
A28: 25 | B28: 09/30/2026 | C28: 10:12 | D28: T4 | E28: 103 | F28: N | G28: 55 | H28: 46 | I28: 19 | J28: E | K28: 13.78 | L28: FNC | M28: T4 | N28: 203 | O28: =ROUND(IF(AND(F28="N",J28="E"),(G28+H28/Parameters!$B$17+I28/Parameters!$B$18),IF(AND(F28="S",J28="E"),180-(G28+H28/Parameters!$B$17+I28/Parameters!$B$18),IF(AND(F28="S",J28="W"),180+(G28+H28/Parameters!$B$17+I28/Parameters!$B$18),360-(G28+H28/Parameters!$B$17+I28/Parameters!$B$18)))),6) -> 55.771944 | W28: =Parameters!$B$24 -> 0.04 | X28: 0 | Y28: =ROUND(K28+W28+X28,2) -> 13.82 | Z28: Point changed from 103 to 203: the code is FNC, and this is the fence corner post
A29: 26 | B29: 09/30/2026 | C29: 10:15 | D29: T4 | E29: 203 | F29: N | G29: 59 | H29: 27 | I29: 9 | J29: E | K29: 12.83 | L29: IRF | M29: T4 | N29: 103 | O29: =ROUND(IF(AND(F29="N",J29="E"),(G29+H29/Parameters!$B$17+I29/Parameters!$B$18),IF(AND(F29="S",J29="E"),180-(G29+H29/Parameters!$B$17+I29/Parameters!$B$18),IF(AND(F29="S",J29="W"),180+(G29+H29/Parameters!$B$17+I29/Parameters!$B$18),360-(G29+H29/Parameters!$B$17+I29/Parameters!$B$18)))),6) -> 59.4525 | W29: =Parameters!$B$24 -> 0.04 | X29: 0 | Y29: =ROUND(K29+W29+X29,2) -> 12.87 | Z29: Point changed from 203 to 103: the code is IRF, and the mark stands 588.82 feet from the pin at corner 2, the distance on the 2008 plat
A30: 27 | B30: 09/30/2026 | C30: 10:19 | D30: T4 | E30: 107 | F30: N | G30: 57 | H30: 15 | I30: 36 | J30: E | K30: 12.95 | L30: IPS | M30: T4 | N30: 107 | O30: =ROUND(IF(AND(F30="N",J30="E"),(G30+H30/Parameters!$B$17+I30/Parameters!$B$18),IF(AND(F30="S",J30="E"),180-(G30+H30/Parameters!$B$17+I30/Parameters!$B$18),IF(AND(F30="S",J30="W"),180+(G30+H30/Parameters!$B$17+I30/Parameters!$B$18),360-(G30+H30/Parameters!$B$17+I30/Parameters!$B$18)))),6) -> 57.26 | W30: =Parameters!$B$24 -> 0.04 | X30: 0 | Y30: =ROUND(K30+W30+X30,2) -> 12.99
A31: 28 | B31: 09/30/2026 | C31: 10:24 | D31: T4 | E31: 106 | F31: N | G31: 13 | H31: 29 | I31: 42 | J31: E | K31: 223.98 | L31: IP | M31: T4 | N31: 106 | O31: =ROUND(IF(AND(F31="N",J31="E"),(G31+H31/Parameters!$B$17+I31/Parameters!$B$18),IF(AND(F31="S",J31="E"),180-(G31+H31/Parameters!$B$17+I31/Parameters!$B$18),IF(AND(F31="S",J31="W"),180+(G31+H31/Parameters!$B$17+I31/Parameters!$B$18),360-(G31+H31/Parameters!$B$17+I31/Parameters!$B$18)))),6) -> 13.495 | W31: =Parameters!$B$24 -> 0.04 | X31: 0 | Y31: =ROUND(K31+W31+X31,2) -> 224.02
A32: 29 | B32: 09/30/2026 | C32: 10:31 | D32: T4 | E32: 204 | F32: S | G32: 1 | H32: 52 | I32: 10 | J32: E | K32: 43.59 | L32: FNC | M32: T4 | N32: 204 | O32: =ROUND(IF(AND(F32="N",J32="E"),(G32+H32/Parameters!$B$17+I32/Parameters!$B$18),IF(AND(F32="S",J32="E"),180-(G32+H32/Parameters!$B$17+I32/Parameters!$B$18),IF(AND(F32="S",J32="W"),180+(G32+H32/Parameters!$B$17+I32/Parameters!$B$18),360-(G32+H32/Parameters!$B$17+I32/Parameters!$B$18)))),6) -> 178.13056 | W32: =Parameters!$B$24 -> 0.04 | X32: 0 | Y32: =ROUND(K32+W32+X32,2) -> 43.63
A33: 30 | B33: 09/30/2026 | C33: 11:17 | D33: T5 | E33: 104 | F33: S | G33: 39 | H33: 29 | I33: 59 | J33: E | K33: 12.26 | L33: STN | M33: T5 | N33: 104 | O33: =ROUND(IF(AND(F33="N",J33="E"),(G33+H33/Parameters!$B$17+I33/Parameters!$B$18),IF(AND(F33="S",J33="E"),180-(G33+H33/Parameters!$B$17+I33/Parameters!$B$18),IF(AND(F33="S",J33="W"),180+(G33+H33/Parameters!$B$17+I33/Parameters!$B$18),360-(G33+H33/Parameters!$B$17+I33/Parameters!$B$18)))),6) -> 140.50028 | W33: =Parameters!$B$24 -> 0.04 | X33: 0 | Y33: =ROUND(K33+W33+X33,2) -> 12.3
A34: 31 | B34: 09/30/2026 | C34: 11:20 | D34: T5 | E34: 206 | F34: N | G34: 32 | H34: 35 | I34: 33 | J34: E | K34: 26.34 | L34: FNC | M34: T5 | N34: 206 | O34: =ROUND(IF(AND(F34="N",J34="E"),(G34+H34/Parameters!$B$17+I34/Parameters!$B$18),IF(AND(F34="S",J34="E"),180-(G34+H34/Parameters!$B$17+I34/Parameters!$B$18),IF(AND(F34="S",J34="W"),180+(G34+H34/Parameters!$B$17+I34/Parameters!$B$18),360-(G34+H34/Parameters!$B$17+I34/Parameters!$B$18)))),6) -> 32.5925 | W34: =Parameters!$B$24 -> 0.04 | X34: 0 | Y34: =ROUND(K34+W34+X34,2) -> 26.38
A35: 32 | B35: 09/30/2026 | C35: 11:26 | D35: T5 | E35: 205 | F35: N | G35: 13 | H35: 47 | I35: 21 | J35: E | K35: 204.74 | L35: FNC | M35: T5 | N35: 205 | O35: =ROUND(IF(AND(F35="N",J35="E"),(G35+H35/Parameters!$B$17+I35/Parameters!$B$18),IF(AND(F35="S",J35="E"),180-(G35+H35/Parameters!$B$17+I35/Parameters!$B$18),IF(AND(F35="S",J35="W"),180+(G35+H35/Parameters!$B$17+I35/Parameters!$B$18),360-(G35+H35/Parameters!$B$17+I35/Parameters!$B$18)))),6) -> 13.789167 | W35: =Parameters!$B$24 -> 0.04 | X35: 0 | Y35: =ROUND(K35+W35+X35,2) -> 204.78
A36: 33 | B36: 09/30/2026 | C36: 11:33 | D36: T5 | E36: 207 | F36: S | G36: 68 | H36: 2 | I36: 43 | J36: W | K36: 49.99 | L36: FNC | M36: T5 | N36: 207 | O36: =ROUND(IF(AND(F36="N",J36="E"),(G36+H36/Parameters!$B$17+I36/Parameters!$B$18),IF(AND(F36="S",J36="E"),180-(G36+H36/Parameters!$B$17+I36/Parameters!$B$18),IF(AND(F36="S",J36="W"),180+(G36+H36/Parameters!$B$17+I36/Parameters!$B$18),360-(G36+H36/Parameters!$B$17+I36/Parameters!$B$18)))),6) -> 248.04528 | W36: =Parameters!$B$24 -> 0.04 | X36: 0 | Y36: =ROUND(K36+W36+X36,2) -> 50.03
A37: 34 | B37: 09/30/2026 | C37: 13:22 | D37: T6 | E37: 105 | F37: S | G37: 5 | H37: 18 | I37: 1 | J37: W | K37: 8.19 | L37: STN | M37: T6 | N37: 105 | O37: =ROUND(IF(AND(F37="N",J37="E"),(G37+H37/Parameters!$B$17+I37/Parameters!$B$18),IF(AND(F37="S",J37="E"),180-(G37+H37/Parameters!$B$17+I37/Parameters!$B$18),IF(AND(F37="S",J37="W"),180+(G37+H37/Parameters!$B$17+I37/Parameters!$B$18),360-(G37+H37/Parameters!$B$17+I37/Parameters!$B$18)))),6) -> 185.30028 | W37: =Parameters!$B$24 -> 0.04 | X37: =Parameters!$B$25 -> 0.6 | Y37: =ROUND(K37+W37+X37,2) -> 8.83 | Z37: Pole held 0.60 foot short of the drill hole on the line of sight; the taped 0.60 foot is added
A38: 35 | B38: 09/30/2026 | C38: 13:27 | D38: T6 | E38: 209 | F38: S | G38: 83 | H38: 1 | I38: 32 | J38: E | K38: 29.15 | L38: FNC | M38: T6 | N38: 209 | O38: =ROUND(IF(AND(F38="N",J38="E"),(G38+H38/Parameters!$B$17+I38/Parameters!$B$18),IF(AND(F38="S",J38="E"),180-(G38+H38/Parameters!$B$17+I38/Parameters!$B$18),IF(AND(F38="S",J38="W"),180+(G38+H38/Parameters!$B$17+I38/Parameters!$B$18),360-(G38+H38/Parameters!$B$17+I38/Parameters!$B$18)))),6) -> 96.974444 | W38: =Parameters!$B$24 -> 0.04 | X38: 0 | Y38: =ROUND(K38+W38+X38,2) -> 29.19
A39: 36 | B39: 09/30/2026 | C39: 13:35 | D39: T6 | E39: 208 | F39: N | G39: 82 | H39: 6 | I39: 48 | J39: E | K39: 246.05 | L39: FNC | M39: T6 | N39: 208 | O39: =ROUND(IF(AND(F39="N",J39="E"),(G39+H39/Parameters!$B$17+I39/Parameters!$B$18),IF(AND(F39="S",J39="E"),180-(G39+H39/Parameters!$B$17+I39/Parameters!$B$18),IF(AND(F39="S",J39="W"),180+(G39+H39/Parameters!$B$17+I39/Parameters!$B$18),360-(G39+H39/Parameters!$B$17+I39/Parameters!$B$18)))),6) -> 82.113333 | W39: =Parameters!$B$24 -> 0.04 | X39: 0 | Y39: =ROUND(K39+W39+X39,2) -> 246.09
A41: Columns A to L are the notes file as recorded. STATION USED and POINT USED carry the three changes the office made on reading the file against the field book, each with its reason in the note beside it. USED marks the traverse shots that enter the mean under firm standards 1.1: a pair in error is rejected, and the pair at fault on a doubled leg is set aside. The mean bearing of a leg is taken as a direction, from the summed cosines and sines of the azimuths turned by 45 degrees, because the T7-T2 leg straddles north.

Sheet Traverse
A1: Traverse reduction: mean of the pairs that stand, latitudes and departures, closure, compass rule, station coordinates
A3: Leg | B3: From | C3: To | D3: Shots used | E3: Shots set aside | F3: Mean azimuth | G3: Mean bearing | H3: Mean distance (ft) | I3: Latitude (ft) | J3: Departure (ft) | K3: Latitude correction | L3: Departure correction | M3: Adjusted latitude | N3: Adjusted departure | O3: Northing of To (ft) | P3: Easting of To (ft)
A4: T1-T7 | B4: T1 | C4: T7 | D4: =COUNTIFS('Field Notes'!$P$4:$P$39,A4,'Field Notes'!$V$4:$V$39,"Yes") -> 2 | E4: =COUNTIFS('Field Notes'!$P$4:$P$39,A4,'Field Notes'!$V$4:$V$39,"No") -> 0 | F4: =ROUND(MOD(DEGREES(ATAN2(SUMIFS('Field Notes'!$T$4:$T$39,'Field Notes'!$P$4:$P$39,A4,'Field Notes'!$V$4:$V$39,"Yes"),SUMIFS('Field Notes'!$U$4:$U$39,'Field Notes'!$P$4:$P$39,A4,'Field Notes'!$V$4:$V$39,"Yes")))+Parameters!$B$30,360),6) -> 31.122917 | G4: =IF(OR(F4<=90,F4>270),"N","S")&" "&TEXT(INT(ROUND((IF(F4<=90,F4,IF(F4<=180,180-F4,IF(F4<=270,F4-180,360-F4))))*Parameters!$B$18,0)/Parameters!$B$18),"0")&"° "&TEXT(INT(MOD(ROUND((IF(F4<=90,F4,IF(F4<=180,180-F4,IF(F4<=270,F4-180,360-F4))))*Parameters!$B$18,0),Parameters!$B$18)/Parameters!$B$17),"00")&"' "&TEXT(MOD(ROUND((IF(F4<=90,F4,IF(F4<=180,180-F4,IF(F4<=270,F4-180,360-F4))))*Parameters!$B$18,0),Parameters!$B$17),"00")&""""&" "&IF(F4<=180,"E","W") -> N 31° 07' 23" E | H4: =ROUND(AVERAGEIFS('Field Notes'!$K$4:$K$39,'Field Notes'!$P$4:$P$39,A4,'Field Notes'!$V$4:$V$39,"Yes"),3) -> 347.425 | I4: =ROUND(H4*COS(RADIANS(F4)),3) -> 297.417 | J4: =ROUND(H4*SIN(RADIANS(F4)),3) -> 179.576 | K4: =ROUND(-$I$11*H4/$H$11,3) -> 0.028 | L4: =ROUND(-$J$11*H4/$H$11,3) -> 0.002 | M4: =ROUND(I4+K4,3) -> 297.445 | N4: =ROUND(J4+L4,3) -> 179.578 | O4: =ROUND(Parameters!$B$4+M4,3) -> 5297.445 | P4: =ROUND(Parameters!$B$5+N4,3) -> 5179.578
A5: T7-T2 | B5: T7 | C5: T2 | D5: =COUNTIFS('Field Notes'!$P$4:$P$39,A5,'Field Notes'!$V$4:$V$39,"Yes") -> 2 | E5: =COUNTIFS('Field Notes'!$P$4:$P$39,A5,'Field Notes'!$V$4:$V$39,"No") -> 0 | F5: =ROUND(MOD(DEGREES(ATAN2(SUMIFS('Field Notes'!$T$4:$T$39,'Field Notes'!$P$4:$P$39,A5,'Field Notes'!$V$4:$V$39,"Yes"),SUMIFS('Field Notes'!$U$4:$U$39,'Field Notes'!$P$4:$P$39,A5,'Field Notes'!$V$4:$V$39,"Yes")))+Parameters!$B$30,360),6) -> 359.99972 | G5: =IF(OR(F5<=90,F5>270),"N","S")&" "&TEXT(INT(ROUND((IF(F5<=90,F5,IF(F5<=180,180-F5,IF(F5<=270,F5-180,360-F5))))*Parameters!$B$18,0)/Parameters!$B$18),"0")&"° "&TEXT(INT(MOD(ROUND((IF(F5<=90,F5,IF(F5<=180,180-F5,IF(F5<=270,F5-180,360-F5))))*Parameters!$B$18,0),Parameters!$B$18)/Parameters!$B$17),"00")&"' "&TEXT(MOD(ROUND((IF(F5<=90,F5,IF(F5<=180,180-F5,IF(F5<=270,F5-180,360-F5))))*Parameters!$B$18,0),Parameters!$B$17),"00")&""""&" "&IF(F5<=180,"E","W") -> N 0° 00' 01" W | H5: =ROUND(AVERAGEIFS('Field Notes'!$K$4:$K$39,'Field Notes'!$P$4:$P$39,A5,'Field Notes'!$V$4:$V$39,"Yes"),3) -> 299.995 | I5: =ROUND(H5*COS(RADIANS(F5)),3) -> 299.995 | J5: =ROUND(H5*SIN(RADIANS(F5)),3) -> -0.001 | K5: =ROUND(-$I$11*H5/$H$11,3) -> 0.024 | L5: =ROUND(-$J$11*H5/$H$11,3) -> 0.002 | M5: =ROUND(I5+K5,3) -> 300.019 | N5: =ROUND(J5+L5,3) -> 0.001 | O5: =ROUND(O4+M5,3) -> 5597.464 | P5: =ROUND(P4+N5,3) -> 5179.579
A6: T2-T3 | B6: T2 | C6: T3 | D6: =COUNTIFS('Field Notes'!$P$4:$P$39,A6,'Field Notes'!$V$4:$V$39,"Yes") -> 4 | E6: =COUNTIFS('Field Notes'!$P$4:$P$39,A6,'Field Notes'!$V$4:$V$39,"No") -> 0 | F6: =ROUND(MOD(DEGREES(ATAN2(SUMIFS('Field Notes'!$T$4:$T$39,'Field Notes'!$P$4:$P$39,A6,'Field Notes'!$V$4:$V$39,"Yes"),SUMIFS('Field Notes'!$U$4:$U$39,'Field Notes'!$P$4:$P$39,A6,'Field Notes'!$V$4:$V$39,"Yes")))+Parameters!$B$30,360),6) -> 103.39576 | G6: =IF(OR(F6<=90,F6>270),"N","S")&" "&TEXT(INT(ROUND((IF(F6<=90,F6,IF(F6<=180,180-F6,IF(F6<=270,F6-180,360-F6))))*Parameters!$B$18,0)/Parameters!$B$18),"0")&"° "&TEXT(INT(MOD(ROUND((IF(F6<=90,F6,IF(F6<=180,180-F6,IF(F6<=270,F6-180,360-F6))))*Parameters!$B$18,0),Parameters!$B$18)/Parameters!$B$17),"00")&"' "&TEXT(MOD(ROUND((IF(F6<=90,F6,IF(F6<=180,180-F6,IF(F6<=270,F6-180,360-F6))))*Parameters!$B$18,0),Parameters!$B$17),"00")&""""&" "&IF(F6<=180,"E","W") -> S 76° 36' 15" E | H6: =ROUND(AVERAGEIFS('Field Notes'!$K$4:$K$39,'Field Notes'!$P$4:$P$39,A6,'Field Notes'!$V$4:$V$39,"Yes"),3) -> 285.028 | I6: =ROUND(H6*COS(RADIANS(F6)),3) -> -66.034 | J6: =ROUND(H6*SIN(RADIANS(F6)),3) -> 277.273 | K6: =ROUND(-$I$11*H6/$H$11,3) -> 0.023 | L6: =ROUND(-$J$11*H6/$H$11,3) -> 0.002 | M6: =ROUND(I6+K6,3) -> -66.011 | N6: =ROUND(J6+L6,3) -> 277.275 | O6: =ROUND(O5+M6,3) -> 5531.453 | P6: =ROUND(P5+N6,3) -> 5456.854
A7: T3-T4 | B7: T3 | C7: T4 | D7: =COUNTIFS('Field Notes'!$P$4:$P$39,A7,'Field Notes'!$V$4:$V$39,"Yes") -> 2 | E7: =COUNTIFS('Field Notes'!$P$4:$P$39,A7,'Field Notes'!$V$4:$V$39,"No") -> 2 | F7: =ROUND(MOD(DEGREES(ATAN2(SUMIFS('Field Notes'!$T$4:$T$39,'Field Notes'!$P$4:$P$39,A7,'Field Notes'!$V$4:$V$39,"Yes"),SUMIFS('Field Notes'!$U$4:$U$39,'Field Notes'!$P$4:$P$39,A7,'Field Notes'!$V$4:$V$39,"Yes")))+Parameters!$B$30,360),6) -> 98.998195 | G7: =IF(OR(F7<=90,F7>270),"N","S")&" "&TEXT(INT(ROUND((IF(F7<=90,F7,IF(F7<=180,180-F7,IF(F7<=270,F7-180,360-F7))))*Parameters!$B$18,0)/Parameters!$B$18),"0")&"° "&TEXT(INT(MOD(ROUND((IF(F7<=90,F7,IF(F7<=180,180-F7,IF(F7<=270,F7-180,360-F7))))*Parameters!$B$18,0),Parameters!$B$18)/Parameters!$B$17),"00")&"' "&TEXT(MOD(ROUND((IF(F7<=90,F7,IF(F7<=180,180-F7,IF(F7<=270,F7-180,360-F7))))*Parameters!$B$18,0),Parameters!$B$17),"00")&""""&" "&IF(F7<=180,"E","W") -> S 81° 00' 06" E | H7: =ROUND(AVERAGEIFS('Field Notes'!$K$4:$K$39,'Field Notes'!$P$4:$P$39,A7,'Field Notes'!$V$4:$V$39,"Yes"),3) -> 287.39 | I7: =ROUND(H7*COS(RADIANS(F7)),3) -> -44.949 | J7: =ROUND(H7*SIN(RADIANS(F7)),3) -> 283.853 | K7: =ROUND(-$I$11*H7/$H$11,3) -> 0.023 | L7: =ROUND(-$J$11*H7/$H$11,3) -> 0.002 | M7: =ROUND(I7+K7,3) -> -44.926 | N7: =ROUND(J7+L7,3) -> 283.855 | O7: =ROUND(O6+M7,3) -> 5486.527 | P7: =ROUND(P6+N7,3) -> 5740.709
A8: T4-T5 | B8: T4 | C8: T5 | D8: =COUNTIFS('Field Notes'!$P$4:$P$39,A8,'Field Notes'!$V$4:$V$39,"Yes") -> 2 | E8: =COUNTIFS('Field Notes'!$P$4:$P$39,A8,'Field Notes'!$V$4:$V$39,"No") -> 0 | F8: =ROUND(MOD(DEGREES(ATAN2(SUMIFS('Field Notes'!$T$4:$T$39,'Field Notes'!$P$4:$P$39,A8,'Field Notes'!$V$4:$V$39,"Yes"),SUMIFS('Field Notes'!$U$4:$U$39,'Field Notes'!$P$4:$P$39,A8,'Field Notes'!$V$4:$V$39,"Yes")))+Parameters!$B$30,360),6) -> 191.02069 | G8: =IF(OR(F8<=90,F8>270),"N","S")&" "&TEXT(INT(ROUND((IF(F8<=90,F8,IF(F8<=180,180-F8,IF(F8<=270,F8-180,360-F8))))*Parameters!$B$18,0)/Parameters!$B$18),"0")&"° "&TEXT(INT(MOD(ROUND((IF(F8<=90,F8,IF(F8<=180,180-F8,IF(F8<=270,F8-180,360-F8))))*Parameters!$B$18,0),Parameters!$B$18)/Parameters!$B$17),"00")&"' "&TEXT(MOD(ROUND((IF(F8<=90,F8,IF(F8<=180,180-F8,IF(F8<=270,F8-180,360-F8))))*Parameters!$B$18,0),Parameters!$B$17),"00")&""""&" "&IF(F8<=180,"E","W") -> S 11° 01' 15" W | H8: =ROUND(AVERAGEIFS('Field Notes'!$K$4:$K$39,'Field Notes'!$P$4:$P$39,A8,'Field Notes'!$V$4:$V$39,"Yes"),3) -> 575.26 | I8: =ROUND(H8*COS(RADIANS(F8)),3) -> -564.651 | J8: =ROUND(H8*SIN(RADIANS(F8)),3) -> -109.969 | K8: =ROUND(-$I$11*H8/$H$11,3) -> 0.046 | L8: =ROUND(-$J$11*H8/$H$11,3) -> 0.004 | M8: =ROUND(I8+K8,3) -> -564.605 | N8: =ROUND(J8+L8,3) -> -109.965 | O8: =ROUND(O7+M8,3) -> 4921.922 | P8: =ROUND(P7+N8,3) -> 5630.744
A9: T5-T6 | B9: T5 | C9: T6 | D9: =COUNTIFS('Field Notes'!$P$4:$P$39,A9,'Field Notes'!$V$4:$V$39,"Yes") -> 2 | E9: =COUNTIFS('Field Notes'!$P$4:$P$39,A9,'Field Notes'!$V$4:$V$39,"No") -> 2 | F9: =ROUND(MOD(DEGREES(ATAN2(SUMIFS('Field Notes'!$T$4:$T$39,'Field Notes'!$P$4:$P$39,A9,'Field Notes'!$V$4:$V$39,"Yes"),SUMIFS('Field Notes'!$U$4:$U$39,'Field Notes'!$P$4:$P$39,A9,'Field Notes'!$V$4:$V$39,"Yes")))+Parameters!$B$30,360),6) -> 259.93278 | G9: =IF(OR(F9<=90,F9>270),"N","S")&" "&TEXT(INT(ROUND((IF(F9<=90,F9,IF(F9<=180,180-F9,IF(F9<=270,F9-180,360-F9))))*Parameters!$B$18,0)/Parameters!$B$18),"0")&"° "&TEXT(INT(MOD(ROUND((IF(F9<=90,F9,IF(F9<=180,180-F9,IF(F9<=270,F9-180,360-F9))))*Parameters!$B$18,0),Parameters!$B$18)/Parameters!$B$17),"00")&"' "&TEXT(MOD(ROUND((IF(F9<=90,F9,IF(F9<=180,180-F9,IF(F9<=270,F9-180,360-F9))))*Parameters!$B$18,0),Parameters!$B$17),"00")&""""&" "&IF(F9<=180,"E","W") -> S 79° 55' 58" W | H9: =ROUND(AVERAGEIFS('Field Notes'!$K$4:$K$39,'Field Notes'!$P$4:$P$39,A9,'Field Notes'!$V$4:$V$39,"Yes"),3) -> 501.865 | I9: =ROUND(H9*COS(RADIANS(F9)),3) -> -87.728 | J9: =ROUND(H9*SIN(RADIANS(F9)),3) -> -494.138 | K9: =ROUND(-$I$11*H9/$H$11,3) -> 0.04 | L9: =ROUND(-$J$11*H9/$H$11,3) -> 0.003 | M9: =ROUND(I9+K9,3) -> -87.688 | N9: =ROUND(J9+L9,3) -> -494.135 | O9: =ROUND(O8+M9,3) -> 4834.234 | P9: =ROUND(P8+N9,3) -> 5136.609
A10: T6-T1 | B10: T6 | C10: T1 | D10: =COUNTIFS('Field Notes'!$P$4:$P$39,A10,'Field Notes'!$V$4:$V$39,"Yes") -> 2 | E10: =COUNTIFS('Field Notes'!$P$4:$P$39,A10,'Field Notes'!$V$4:$V$39,"No") -> 0 | F10: =ROUND(MOD(DEGREES(ATAN2(SUMIFS('Field Notes'!$T$4:$T$39,'Field Notes'!$P$4:$P$39,A10,'Field Notes'!$V$4:$V$39,"Yes"),SUMIFS('Field Notes'!$U$4:$U$39,'Field Notes'!$P$4:$P$39,A10,'Field Notes'!$V$4:$V$39,"Yes")))+Parameters!$B$30,360),6) -> 320.50431 | G10: =IF(OR(F10<=90,F10>270),"N","S")&" "&TEXT(INT(ROUND((IF(F10<=90,F10,IF(F10<=180,180-F10,IF(F10<=270,F10-180,360-F10))))*Parameters!$B$18,0)/Parameters!$B$18),"0")&"° "&TEXT(INT(MOD(ROUND((IF(F10<=90,F10,IF(F10<=180,180-F10,IF(F10<=270,F10-180,360-F10))))*Parameters!$B$18,0),Parameters!$B$18)/Parameters!$B$17),"00")&"' "&TEXT(MOD(ROUND((IF(F10<=90,F10,IF(F10<=180,180-F10,IF(F10<=270,F10-180,360-F10))))*Parameters!$B$18,0),Parameters!$B$17),"00")&""""&" "&IF(F10<=180,"E","W") -> N 39° 29' 44" W | H10: =ROUND(AVERAGEIFS('Field Notes'!$K$4:$K$39,'Field Notes'!$P$4:$P$39,A10,'Field Notes'!$V$4:$V$39,"Yes"),3) -> 214.79 | I10: =ROUND(H10*COS(RADIANS(F10)),3) -> 165.748 | J10: =ROUND(H10*SIN(RADIANS(F10)),3) -> -136.611 | K10: =ROUND(-$I$11*H10/$H$11,3) -> 0.017 | L10: =ROUND(-$J$11*H10/$H$11,3) -> 0.001 | M10: =ROUND(I10+K10,3) -> 165.765 | N10: =ROUND(J10+L10,3) -> -136.61 | O10: =ROUND(O9+M10,3) -> 4999.999 | P10: =ROUND(P9+N10,3) -> 4999.999
A11: Totals | D11: =SUM(D4:D10) -> 16 | E11: =SUM(E4:E10) -> 4 | H11: =ROUND(SUM(H4:H10),3) -> 2511.753 | I11: =ROUND(SUM(I4:I10),3) -> -0.202 | J11: =ROUND(SUM(J4:J10),3) -> -0.017 | K11: =ROUND(SUM(K4:K10),3) -> 0.201 | L11: =ROUND(SUM(L4:L10),3) -> 0.016 | M11: =ROUND(SUM(M4:M10),3) -> -0.001 | N11: =ROUND(SUM(N4:N10),3) -> -0.001
A13: Closure, unadjusted
A14: Perimeter (ft) | B14: =H11 -> 2511.753
A15: Latitude misclosure (ft) | B15: =I11 -> -0.202
A16: Departure misclosure (ft) | B16: =J11 -> -0.017
A17: Linear error of closure (ft) | B17: =ROUND(SQRT(B15^2+B16^2),2) -> 0.2
A18: Precision of closure, one part in | B18: =ROUNDDOWN(B14/B17,-2) -> 12500
A19: Tract classification on the field dates | B19: =Parameters!B8 -> Rural
A20: Firm standard for that class, one part in | B20: =IF(B19="Urban",Parameters!B6,Parameters!B7) -> 10000
A21: Closure test | B21: =IF(B18>=B20,"Meets the standard","Does not meet the standard") -> Meets the standard
A23: Station coordinates, adjusted
A24: Station | B24: Northing (ft) | C24: Easting (ft)
A25: T1 | B25: =Parameters!B4 -> 5000 | C25: =Parameters!B5 -> 5000
A26: T7 | B26: =O4 -> 5297.445 | C26: =P4 -> 5179.578
A27: T2 | B27: =O5 -> 5597.464 | C27: =P5 -> 5179.579
A28: T3 | B28: =O6 -> 5531.453 | C28: =P6 -> 5456.854
A29: T4 | B29: =O7 -> 5486.527 | C29: =P7 -> 5740.709
A30: T5 | B30: =O8 -> 4921.922 | C30: =P8 -> 5630.744
A31: T6 | B31: =O9 -> 4834.234 | C31: =P9 -> 5136.609
A32: T1 on return | B32: =O10 -> 4999.999 | C32: =P10 -> 4999.999
A34: Every pair, the forward shot against its reverse under firm standards 1.1
A35: Leg | B35: Pair | C35: Forward distance (ft) | D35: Reverse distance (ft) | E35: Difference in distance (ft) | F35: Forward azimuth | G35: Reverse azimuth, turned | H35: Difference in bearing (seconds) | I35: Test
A36: T1-T7 | B36: 1 | C36: =AVERAGEIFS('Field Notes'!$K$4:$K$39,'Field Notes'!$P$4:$P$39,A36,'Field Notes'!$S$4:$S$39,B36,'Field Notes'!$Q$4:$Q$39,"Forward") -> 347.42 | D36: =AVERAGEIFS('Field Notes'!$K$4:$K$39,'Field Notes'!$P$4:$P$39,A36,'Field Notes'!$S$4:$S$39,B36,'Field Notes'!$Q$4:$Q$39,"Reverse") -> 347.43 | E36: =ROUND(ABS(C36-D36),3) -> 0.01 | F36: =AVERAGEIFS('Field Notes'!$R$4:$R$39,'Field Notes'!$P$4:$P$39,A36,'Field Notes'!$S$4:$S$39,B36,'Field Notes'!$Q$4:$Q$39,"Forward") -> 31.123333 | G36: =AVERAGEIFS('Field Notes'!$R$4:$R$39,'Field Notes'!$P$4:$P$39,A36,'Field Notes'!$S$4:$S$39,B36,'Field Notes'!$Q$4:$Q$39,"Reverse") -> 31.1225 | H36: =ROUND(MIN(ABS(F36-G36),360-ABS(F36-G36))*Parameters!$B$18,0) -> 3 | I36: =IF(OR(E36>Parameters!$B$19,H36>Parameters!$B$20),"Pair in error","Pair stands") -> Pair stands
A37: T7-T2 | B37: 1 | C37: =AVERAGEIFS('Field Notes'!$K$4:$K$39,'Field Notes'!$P$4:$P$39,A37,'Field Notes'!$S$4:$S$39,B37,'Field Notes'!$Q$4:$Q$39,"Forward") -> 300.01 | D37: =AVERAGEIFS('Field Notes'!$K$4:$K$39,'Field Notes'!$P$4:$P$39,A37,'Field Notes'!$S$4:$S$39,B37,'Field Notes'!$Q$4:$Q$39,"Reverse") -> 299.98 | E37: =ROUND(ABS(C37-D37),3) -> 0.03 | F37: =AVERAGEIFS('Field Notes'!$R$4:$R$39,'Field Notes'!$P$4:$P$39,A37,'Field Notes'!$S$4:$S$39,B37,'Field Notes'!$Q$4:$Q$39,"Forward") -> 359.99917 | G37: =AVERAGEIFS('Field Notes'!$R$4:$R$39,'Field Notes'!$P$4:$P$39,A37,'Field Notes'!$S$4:$S$39,B37,'Field Notes'!$Q$4:$Q$39,"Reverse") -> 0.000278 | H37: =ROUND(MIN(ABS(F37-G37),360-ABS(F37-G37))*Parameters!$B$18,0) -> 4 | I37: =IF(OR(E37>Parameters!$B$19,H37>Parameters!$B$20),"Pair in error","Pair stands") -> Pair stands
A38: T2-T3 | B38: 1 | C38: =AVERAGEIFS('Field Notes'!$K$4:$K$39,'Field Notes'!$P$4:$P$39,A38,'Field Notes'!$S$4:$S$39,B38,'Field Notes'!$Q$4:$Q$39,"Forward") -> 285.02 | D38: =AVERAGEIFS('Field Notes'!$K$4:$K$39,'Field Notes'!$P$4:$P$39,A38,'Field Notes'!$S$4:$S$39,B38,'Field Notes'!$Q$4:$Q$39,"Reverse") -> 285.03 | E38: =ROUND(ABS(C38-D38),3) -> 0.01 | F38: =AVERAGEIFS('Field Notes'!$R$4:$R$39,'Field Notes'!$P$4:$P$39,A38,'Field Notes'!$S$4:$S$39,B38,'Field Notes'!$Q$4:$Q$39,"Forward") -> 103.39583 | G38: =AVERAGEIFS('Field Notes'!$R$4:$R$39,'Field Notes'!$P$4:$P$39,A38,'Field Notes'!$S$4:$S$39,B38,'Field Notes'!$Q$4:$Q$39,"Reverse") -> 103.39556 | H38: =ROUND(MIN(ABS(F38-G38),360-ABS(F38-G38))*Parameters!$B$18,0) -> 1 | I38: =IF(OR(E38>Parameters!$B$19,H38>Parameters!$B$20),"Pair in error","Pair stands") -> Pair stands
A39: T2-T3 | B39: 2 | C39: =AVERAGEIFS('Field Notes'!$K$4:$K$39,'Field Notes'!$P$4:$P$39,A39,'Field Notes'!$S$4:$S$39,B39,'Field Notes'!$Q$4:$Q$39,"Forward") -> 285.03 | D39: =AVERAGEIFS('Field Notes'!$K$4:$K$39,'Field Notes'!$P$4:$P$39,A39,'Field Notes'!$S$4:$S$39,B39,'Field Notes'!$Q$4:$Q$39,"Reverse") -> 285.03 | E39: =ROUND(ABS(C39-D39),3) -> 0 | F39: =AVERAGEIFS('Field Notes'!$R$4:$R$39,'Field Notes'!$P$4:$P$39,A39,'Field Notes'!$S$4:$S$39,B39,'Field Notes'!$Q$4:$Q$39,"Forward") -> 103.39639 | G39: =AVERAGEIFS('Field Notes'!$R$4:$R$39,'Field Notes'!$P$4:$P$39,A39,'Field Notes'!$S$4:$S$39,B39,'Field Notes'!$Q$4:$Q$39,"Reverse") -> 103.39528 | H39: =ROUND(MIN(ABS(F39-G39),360-ABS(F39-G39))*Parameters!$B$18,0) -> 4 | I39: =IF(OR(E39>Parameters!$B$19,H39>Parameters!$B$20),"Pair in error","Pair stands") -> Pair stands
A40: T3-T4 | B40: 1 | C40: =AVERAGEIFS('Field Notes'!$K$4:$K$39,'Field Notes'!$P$4:$P$39,A40,'Field Notes'!$S$4:$S$39,B40,'Field Notes'!$Q$4:$Q$39,"Forward") -> 287.39 | D40: =AVERAGEIFS('Field Notes'!$K$4:$K$39,'Field Notes'!$P$4:$P$39,A40,'Field Notes'!$S$4:$S$39,B40,'Field Notes'!$Q$4:$Q$39,"Reverse") -> 288.59 | E40: =ROUND(ABS(C40-D40),3) -> 1.2 | F40: =AVERAGEIFS('Field Notes'!$R$4:$R$39,'Field Notes'!$P$4:$P$39,A40,'Field Notes'!$S$4:$S$39,B40,'Field Notes'!$Q$4:$Q$39,"Forward") -> 98.999167 | G40: =AVERAGEIFS('Field Notes'!$R$4:$R$39,'Field Notes'!$P$4:$P$39,A40,'Field Notes'!$S$4:$S$39,B40,'Field Notes'!$Q$4:$Q$39,"Reverse") -> 98.997778 | H40: =ROUND(MIN(ABS(F40-G40),360-ABS(F40-G40))*Parameters!$B$18,0) -> 5 | I40: =IF(OR(E40>Parameters!$B$19,H40>Parameters!$B$20),"Pair in error","Pair stands") -> Pair in error
A41: T3-T4 | B41: 2 | C41: =AVERAGEIFS('Field Notes'!$K$4:$K$39,'Field Notes'!$P$4:$P$39,A41,'Field Notes'!$S$4:$S$39,B41,'Field Notes'!$Q$4:$Q$39,"Forward") -> 287.39 | D41: =AVERAGEIFS('Field Notes'!$K$4:$K$39,'Field Notes'!$P$4:$P$39,A41,'Field Notes'!$S$4:$S$39,B41,'Field Notes'!$Q$4:$Q$39,"Reverse") -> 287.39 | E41: =ROUND(ABS(C41-D41),3) -> 0 | F41: =AVERAGEIFS('Field Notes'!$R$4:$R$39,'Field Notes'!$P$4:$P$39,A41,'Field Notes'!$S$4:$S$39,B41,'Field Notes'!$Q$4:$Q$39,"Forward") -> 98.997778 | G41: =AVERAGEIFS('Field Notes'!$R$4:$R$39,'Field Notes'!$P$4:$P$39,A41,'Field Notes'!$S$4:$S$39,B41,'Field Notes'!$Q$4:$Q$39,"Reverse") -> 98.998611 | H41: =ROUND(MIN(ABS(F41-G41),360-ABS(F41-G41))*Parameters!$B$18,0) -> 3 | I41: =IF(OR(E41>Parameters!$B$19,H41>Parameters!$B$20),"Pair in error","Pair stands") -> Pair stands
A42: T4-T5 | B42: 1 | C42: =AVERAGEIFS('Field Notes'!$K$4:$K$39,'Field Notes'!$P$4:$P$39,A42,'Field Notes'!$S$4:$S$39,B42,'Field Notes'!$Q$4:$Q$39,"Forward") -> 575.24 | D42: =AVERAGEIFS('Field Notes'!$K$4:$K$39,'Field Notes'!$P$4:$P$39,A42,'Field Notes'!$S$4:$S$39,B42,'Field Notes'!$Q$4:$Q$39,"Reverse") -> 575.28 | E42: =ROUND(ABS(C42-D42),3) -> 0.04 | F42: =AVERAGEIFS('Field Notes'!$R$4:$R$39,'Field Notes'!$P$4:$P$39,A42,'Field Notes'!$S$4:$S$39,B42,'Field Notes'!$Q$4:$Q$39,"Forward") -> 191.02028 | G42: =AVERAGEIFS('Field Notes'!$R$4:$R$39,'Field Notes'!$P$4:$P$39,A42,'Field Notes'!$S$4:$S$39,B42,'Field Notes'!$Q$4:$Q$39,"Reverse") -> 191.02111 | H42: =ROUND(MIN(ABS(F42-G42),360-ABS(F42-G42))*Parameters!$B$18,0) -> 3 | I42: =IF(OR(E42>Parameters!$B$19,H42>Parameters!$B$20),"Pair in error","Pair stands") -> Pair stands
A43: T5-T6 | B43: 1 | C43: =AVERAGEIFS('Field Notes'!$K$4:$K$39,'Field Notes'!$P$4:$P$39,A43,'Field Notes'!$S$4:$S$39,B43,'Field Notes'!$Q$4:$Q$39,"Forward") -> 501.58 | D43: =AVERAGEIFS('Field Notes'!$K$4:$K$39,'Field Notes'!$P$4:$P$39,A43,'Field Notes'!$S$4:$S$39,B43,'Field Notes'!$Q$4:$Q$39,"Reverse") -> 501.59 | E43: =ROUND(ABS(C43-D43),3) -> 0.01 | F43: =AVERAGEIFS('Field Notes'!$R$4:$R$39,'Field Notes'!$P$4:$P$39,A43,'Field Notes'!$S$4:$S$39,B43,'Field Notes'!$Q$4:$Q$39,"Forward") -> 259.93222 | G43: =AVERAGEIFS('Field Notes'!$R$4:$R$39,'Field Notes'!$P$4:$P$39,A43,'Field Notes'!$S$4:$S$39,B43,'Field Notes'!$Q$4:$Q$39,"Reverse") -> 259.93333 | H43: =ROUND(MIN(ABS(F43-G43),360-ABS(F43-G43))*Parameters!$B$18,0) -> 4 | I43: =IF(OR(E43>Parameters!$B$19,H43>Parameters!$B$20),"Pair in error","Pair stands") -> Pair stands
A44: T5-T6 | B44: 2 | C44: =AVERAGEIFS('Field Notes'!$K$4:$K$39,'Field Notes'!$P$4:$P$39,A44,'Field Notes'!$S$4:$S$39,B44,'Field Notes'!$Q$4:$Q$39,"Forward") -> 501.86 | D44: =AVERAGEIFS('Field Notes'!$K$4:$K$39,'Field Notes'!$P$4:$P$39,A44,'Field Notes'!$S$4:$S$39,B44,'Field Notes'!$Q$4:$Q$39,"Reverse") -> 501.87 | E44: =ROUND(ABS(C44-D44),3) -> 0.01 | F44: =AVERAGEIFS('Field Notes'!$R$4:$R$39,'Field Notes'!$P$4:$P$39,A44,'Field Notes'!$S$4:$S$39,B44,'Field Notes'!$Q$4:$Q$39,"Forward") -> 259.93222 | G44: =AVERAGEIFS('Field Notes'!$R$4:$R$39,'Field Notes'!$P$4:$P$39,A44,'Field Notes'!$S$4:$S$39,B44,'Field Notes'!$Q$4:$Q$39,"Reverse") -> 259.93333 | H44: =ROUND(MIN(ABS(F44-G44),360-ABS(F44-G44))*Parameters!$B$18,0) -> 4 | I44: =IF(OR(E44>Parameters!$B$19,H44>Parameters!$B$20),"Pair in error","Pair stands") -> Pair stands
...

Sheet Ties
A1: Monument and fence ties, reduced from the adjusted station coordinates
A3: Point | B3: What was tied | C3: Station | D3: Shot | E3: Azimuth | F3: Distance used (ft) | G3: Station northing | H3: Station easting | I3: Latitude (ft) | J3: Departure (ft) | K3: Northing (ft) | L3: Easting (ft)
A4: 101 | B4: Iron pin, cap PLS 1188, southwest corner at Stanhope Road | C4: =INDEX('Field Notes'!$M$4:$M$39,MATCH(A4,'Field Notes'!$N$4:$N$39,0)) -> T1 | D4: =INDEX('Field Notes'!$A$4:$A$39,MATCH(A4,'Field Notes'!$N$4:$N$39,0)) -> 21 | E4: =INDEX('Field Notes'!$O$4:$O$39,MATCH(A4,'Field Notes'!$N$4:$N$39,0)) -> 247.91361 | F4: =INDEX('Field Notes'!$Y$4:$Y$39,MATCH(A4,'Field Notes'!$N$4:$N$39,0)) -> 13.83 | G4: =INDEX(Traverse!$B$25:$B$31,MATCH(C4,Traverse!$A$25:$A$31,0)) -> 5000 | H4: =INDEX(Traverse!$C$25:$C$31,MATCH(C4,Traverse!$A$25:$A$31,0)) -> 5000 | I4: =ROUND(F4*COS(RADIANS(E4)),3) -> -5.2 | J4: =ROUND(F4*SIN(RADIANS(E4)),3) -> -12.815 | K4: =ROUND(G4+I4,3) -> 4994.8 | L4: =ROUND(H4+J4,3) -> 4987.185
A5: 102 | B5: Iron pin, cap PLS 2207, northwest corner at the Hutchins line | C5: =INDEX('Field Notes'!$M$4:$M$39,MATCH(A5,'Field Notes'!$N$4:$N$39,0)) -> T2 | D5: =INDEX('Field Notes'!$A$4:$A$39,MATCH(A5,'Field Notes'!$N$4:$N$39,0)) -> 22 | E5: =INDEX('Field Notes'!$O$4:$O$39,MATCH(A5,'Field Notes'!$N$4:$N$39,0)) -> 330.99972 | F5: =INDEX('Field Notes'!$Y$4:$Y$39,MATCH(A5,'Field Notes'!$N$4:$N$39,0)) -> 11.2 | G5: =INDEX(Traverse!$B$25:$B$31,MATCH(C5,Traverse!$A$25:$A$31,0)) -> 5597.464 | H5: =INDEX(Traverse!$C$25:$C$31,MATCH(C5,Traverse!$A$25:$A$31,0)) -> 5179.579 | I5: =ROUND(F5*COS(RADIANS(E5)),3) -> 9.796 | J5: =ROUND(F5*SIN(RADIANS(E5)),3) -> -5.43 | K5: =ROUND(G5+I5,3) -> 5607.26 | L5: =ROUND(H5+J5,3) -> 5174.149
A6: 103 | B6: Rebar, cap PLS 2207, at the northeast corner | C6: =INDEX('Field Notes'!$M$4:$M$39,MATCH(A6,'Field Notes'!$N$4:$N$39,0)) -> T4 | D6: =INDEX('Field Notes'!$A$4:$A$39,MATCH(A6,'Field Notes'!$N$4:$N$39,0)) -> 26 | E6: =INDEX('Field Notes'!$O$4:$O$39,MATCH(A6,'Field Notes'!$N$4:$N$39,0)) -> 59.4525 | F6: =INDEX('Field Notes'!$Y$4:$Y$39,MATCH(A6,'Field Notes'!$N$4:$N$39,0)) -> 12.87 | G6: =INDEX(Traverse!$B$25:$B$31,MATCH(C6,Traverse!$A$25:$A$31,0)) -> 5486.527 | H6: =INDEX(Traverse!$C$25:$C$31,MATCH(C6,Traverse!$A$25:$A$31,0)) -> 5740.709 | I6: =ROUND(F6*COS(RADIANS(E6)),3) -> 6.541 | J6: =ROUND(F6*SIN(RADIANS(E6)),3) -> 11.084 | K6: =ROUND(G6+I6,3) -> 5493.068 | L6: =ROUND(H6+J6,3) -> 5751.793
A7: 104 | B7: Stone with chiseled cross, southeast corner | C7: =INDEX('Field Notes'!$M$4:$M$39,MATCH(A7,'Field Notes'!$N$4:$N$39,0)) -> T5 | D7: =INDEX('Field Notes'!$A$4:$A$39,MATCH(A7,'Field Notes'!$N$4:$N$39,0)) -> 30 | E7: =INDEX('Field Notes'!$O$4:$O$39,MATCH(A7,'Field Notes'!$N$4:$N$39,0)) -> 140.50028 | F7: =INDEX('Field Notes'!$Y$4:$Y$39,MATCH(A7,'Field Notes'!$N$4:$N$39,0)) -> 12.3 | G7: =INDEX(Traverse!$B$25:$B$31,MATCH(C7,Traverse!$A$25:$A$31,0)) -> 4921.922 | H7: =INDEX(Traverse!$C$25:$C$31,MATCH(C7,Traverse!$A$25:$A$31,0)) -> 5630.744 | I7: =ROUND(F7*COS(RADIANS(E7)),3) -> -9.491 | J7: =ROUND(F7*SIN(RADIANS(E7)),3) -> 7.824 | K7: =ROUND(G7+I7,3) -> 4912.431 | L7: =ROUND(H7+J7,3) -> 5638.568
A8: 105 | B8: Stone with drill hole, angle point in the Farley line | C8: =INDEX('Field Notes'!$M$4:$M$39,MATCH(A8,'Field Notes'!$N$4:$N$39,0)) -> T6 | D8: =INDEX('Field Notes'!$A$4:$A$39,MATCH(A8,'Field Notes'!$N$4:$N$39,0)) -> 34 | E8: =INDEX('Field Notes'!$O$4:$O$39,MATCH(A8,'Field Notes'!$N$4:$N$39,0)) -> 185.30028 | F8: =INDEX('Field Notes'!$Y$4:$Y$39,MATCH(A8,'Field Notes'!$N$4:$N$39,0)) -> 8.83 | G8: =INDEX(Traverse!$B$25:$B$31,MATCH(C8,Traverse!$A$25:$A$31,0)) -> 4834.234 | H8: =INDEX(Traverse!$C$25:$C$31,MATCH(C8,Traverse!$A$25:$A$31,0)) -> 5136.609 | I8: =ROUND(F8*COS(RADIANS(E8)),3) -> -8.792 | J8: =ROUND(F8*SIN(RADIANS(E8)),3) -> -0.816 | K8: =ROUND(G8+I8,3) -> 4825.442 | L8: =ROUND(H8+J8,3) -> 5135.793
A9: 106 | B9: Iron pipe, northwest corner of the Ballinger tract | C9: =INDEX('Field Notes'!$M$4:$M$39,MATCH(A9,'Field Notes'!$N$4:$N$39,0)) -> T4 | D9: =INDEX('Field Notes'!$A$4:$A$39,MATCH(A9,'Field Notes'!$N$4:$N$39,0)) -> 28 | E9: =INDEX('Field Notes'!$O$4:$O$39,MATCH(A9,'Field Notes'!$N$4:$N$39,0)) -> 13.495 | F9: =INDEX('Field Notes'!$Y$4:$Y$39,MATCH(A9,'Field Notes'!$N$4:$N$39,0)) -> 224.02 | G9: =INDEX(Traverse!$B$25:$B$31,MATCH(C9,Traverse!$A$25:$A$31,0)) -> 5486.527 | H9: =INDEX(Traverse!$C$25:$C$31,MATCH(C9,Traverse!$A$25:$A$31,0)) -> 5740.709 | I9: =ROUND(F9*COS(RADIANS(E9)),3) -> 217.835 | J9: =ROUND(F9*SIN(RADIANS(E9)),3) -> 52.277 | K9: =ROUND(G9+I9,3) -> 5704.362 | L9: =ROUND(H9+J9,3) -> 5792.986
A10: 107 | B10: Iron pin, cap PLS 2641, set by the crew at the northeast corner on September 30 | C10: =INDEX('Field Notes'!$M$4:$M$39,MATCH(A10,'Field Notes'!$N$4:$N$39,0)) -> T4 | D10: =INDEX('Field Notes'!$A$4:$A$39,MATCH(A10,'Field Notes'!$N$4:$N$39,0)) -> 27 | E10: =INDEX('Field Notes'!$O$4:$O$39,MATCH(A10,'Field Notes'!$N$4:$N$39,0)) -> 57.26 | F10: =INDEX('Field Notes'!$Y$4:$Y$39,MATCH(A10,'Field Notes'!$N$4:$N$39,0)) -> 12.99 | G10: =INDEX(Traverse!$B$25:$B$31,MATCH(C10,Traverse!$A$25:$A$31,0)) -> 5486.527 | H10: =INDEX(Traverse!$C$25:$C$31,MATCH(C10,Traverse!$A$25:$A$31,0)) -> 5740.709 | I10: =ROUND(F10*COS(RADIANS(E10)),3) -> 7.025 | J10: =ROUND(F10*SIN(RADIANS(E10)),3) -> 10.926 | K10: =ROUND(G10+I10,3) -> 5493.552 | L10: =ROUND(H10+J10,3) -> 5751.635
A11: 201 | B11: Hutchins fence post | C11: =INDEX('Field Notes'!$M$4:$M$39,MATCH(A11,'Field Notes'!$N$4:$N$39,0)) -> T2 | D11: =INDEX('Field Notes'!$A$4:$A$39,MATCH(A11,'Field Notes'!$N$4:$N$39,0)) -> 23 | E11: =INDEX('Field Notes'!$O$4:$O$39,MATCH(A11,'Field Notes'!$N$4:$N$39,0)) -> 81.72 | F11: =INDEX('Field Notes'!$Y$4:$Y$39,MATCH(A11,'Field Notes'!$N$4:$N$39,0)) -> 26.27 | G11: =INDEX(Traverse!$B$25:$B$31,MATCH(C11,Traverse!$A$25:$A$31,0)) -> 5597.464 | H11: =INDEX(Traverse!$C$25:$C$31,MATCH(C11,Traverse!$A$25:$A$31,0)) -> 5179.579 | I11: =ROUND(F11*COS(RADIANS(E11)),3) -> 3.783 | J11: =ROUND(F11*SIN(RADIANS(E11)),3) -> 25.996 | K11: =ROUND(G11+I11,3) -> 5601.247 | L11: =ROUND(H11+J11,3) -> 5205.575
A12: 202 | B12: Hutchins fence post | C12: =INDEX('Field Notes'!$M$4:$M$39,MATCH(A12,'Field Notes'!$N$4:$N$39,0)) -> T3 | D12: =INDEX('Field Notes'!$A$4:$A$39,MATCH(A12,'Field Notes'!$N$4:$N$39,0)) -> 24 | E12: =INDEX('Field Notes'!$O$4:$O$39,MATCH(A12,'Field Notes'!$N$4:$N$39,0)) -> 22.805556 | F12: =INDEX('Field Notes'!$Y$4:$Y$39,MATCH(A12,'Field Notes'!$N$4:$N$39,0)) -> 19.71 | G12: =INDEX(Traverse!$B$25:$B$31,MATCH(C12,Traverse!$A$25:$A$31,0)) -> 5531.453 | H12: =INDEX(Traverse!$C$25:$C$31,MATCH(C12,Traverse!$A$25:$A$31,0)) -> 5456.854 | I12: =ROUND(F12*COS(RADIANS(E12)),3) -> 18.169 | J12: =ROUND(F12*SIN(RADIANS(E12)),3) -> 7.64 | K12: =ROUND(G12+I12,3) -> 5549.622 | L12: =ROUND(H12+J12,3) -> 5464.494
