Workbook

Sheet Summary
A1: Recorded claims of mechanics lien, Larkspur Crossing Building B, 2210 Pleasant Grove Boulevard, Roseville: analysis for the refinance
A2: Prepared for Marguerite Okonjo for Piedmont Ridge Properties, LLC, from the recorder's copies of the fifteen claims, the owner's project file, the direct contractor's payment ledger, and the close-out file
A4: The two answers for Nadia
A5: Answer | B5: Value | C5: Read from
A6: Release bonds required, total penal sum at 125 percent | B6: =SUM(K25:K39) -> 578094.11 | C6: Claim by claim in the table below
A7: Line the surety has approved for release bonds | B7: =Parameters!$B$24 -> 575000 | C7: Nadia Ferris email of October 2, 2026
A8: Bonds required over the surety's line | B8: =ROUND(B6-B7,2) -> 3094.11 | C8: Bonds required less the line
A9: Do the bonds fit inside the surety's line | B9: =IF(B6<=B7,"Yes, the bonds are inside the line","No, the bonds are over the line") -> No, the bonds are over the line | C9: section 8424(b), 125 percent of each recorded claim
A10: Enforceable by claimants under the Dunmore-Kettle contract | B10: =Claims!D23 -> 286087.47 | C10: Every enforceable claim except the claimant that contracted with the owner itself
A11: Held by the owner on the Dunmore-Kettle contract | B11: =Parameters!$B$44 -> 283135.5 | C11: Adjusted contract sum less payments: unpaid application 8 and the retention
A12: Enforceable claims over what the owner holds | B12: =ROUND(B10-B11,2) -> 2951.97 | C12: Enforceable under the contract less the money held
A13: Does what the owner holds cover those claims | B13: =IF(B10<=B11,"Yes, the money held covers them","No, the money held falls short") -> No, the money held falls short | C13: PN-14, what the owner holds on a direct contract
A15: Totals
A16: Total | B16: Value
A17: Amount of the fifteen claims as recorded | B17: =SUM(C25:C39) -> 561561.79
A18: Amount the claimants could enforce against the property | B18: =SUM(I25:I39) -> 311167.47
A19: Claims to bond or settle | B19: =Claims!D20 -> 10
A20: Claims to demand released | B20: =Claims!D21 -> 5
A21: Recorded amount of the claims to demand released | B21: =Claims!D22 -> 99086.5
A23: The fifteen recorded claims
A24: CLAIMANT | B24: RECORDED | C24: AMOUNT_AS_RECORDED | D24: LIEN_RIGHTS | E24: TIMELY | F24: SERVED_ON_OWNER | G24: EXPIRED | H24: STANDING | I24: ENFORCEABLE_AMOUNT | J24: WHAT_WE_DO | K24: RELEASE_BOND | L24: WAIVERS_ON_FILE | M24: WHAT_DECIDES_IT
A25: =Claims!A4 -> Tallac Concrete, Inc. | B25: =Claims!B4 -> 06/26/2026 | C25: =Claims!D4 -> 33275 | D25: =Claims!F4 -> Yes | E25: =Claims!G4 -> Yes | F25: =Claims!H4 -> Yes | G25: =Claims!I4 -> Yes | H25: =Claims!J4 -> Expired | I25: =Claims!K4 -> 0 | J25: =Claims!M4 -> Demand a release under section 8482, then petition under sections 8480 to 8488 after 10 days | K25: =Claims!N4 -> 0 | L25: Progress waivers through 04/30/2026; the May letter is not a statutory form | M25: No action by 09/24/2026; the search of 10/02/2026 is later
A26: =Claims!A5 -> Foothill Ready Mix, Inc. | B26: =Claims!B5 -> 07/06/2026 | C26: =Claims!D5 -> 17204.84 | D26: =Claims!F5 -> Yes | E26: =Claims!G5 -> Yes | F26: =Claims!H5 -> Yes | G26: =Claims!I5 -> Not shown | H26: =Claims!J5 -> Enforceable | I26: =Claims!K5 -> 17204.84 | J26: =Claims!M5 -> Bond at 125 percent until a new index search shows no action, then demand a release | K26: =Claims!N5 -> 21506.05 | L26: None on file | M26: Last day to sue 10/05/2026 is after the 10/02/2026 search
A27: =Claims!A6 -> Norcal Rebar & Mesh, LLC | B27: =Claims!B6 -> 09/14/2026 | C27: =Claims!D6 -> 27640 | D27: =Claims!F6 -> No | E27: =Claims!G6 -> Yes | F27: =Claims!H6 -> Yes | G27: =Claims!I6 -> No | H27: =Claims!J6 -> No lien rights | I27: =Claims!K6 -> 0 | J27: =Claims!M6 -> Demand a recorded release, the defect being no preliminary notice to the owner | K27: =Claims!N6 -> 0 | L27: None on file | M27: Preliminary notice never given to the owner
A28: =Claims!A7 -> Hedrick & Sons Building Supply | B28: =Claims!B7 -> 09/16/2026 | C28: =Claims!D7 -> 54230.81 | D28: =Claims!F7 -> Yes | E28: =Claims!G7 -> Yes | F28: =Claims!H7 -> Yes | G28: =Claims!I7 -> No | H28: =Claims!J7 -> Enforceable | I28: =Claims!K7 -> 29091.69 | J28: =Claims!M7 -> Bond at 125 percent of the recorded claim, or take an amended claim at the enforceable amount | K28: =Claims!N7 -> 67788.51 | L28: None on file | M28: Late notice deposited 05/29/2026 reaches back to 05/09/2026
A29: =Claims!A8 -> Abrego Glass & Glazing | B29: =Claims!B8 -> 09/17/2026 | C29: =Claims!D8 -> 9345 | D29: =Claims!F8 -> Yes | E29: =Claims!G8 -> Yes | F29: =Claims!H8 -> No | G29: =Claims!I8 -> No | H29: =Claims!J8 -> Not served on the owner | I29: =Claims!K8 -> 0 | J29: =Claims!M8 -> Demand a recorded release, the defect being no service on the owner | K29: =Claims!N8 -> 0 | L29: Progress waivers through 06/30/2026; retention is saved | M29: Claim mailed to Dunmore-Kettle, not to the owner
A30: =Claims!A9 -> Kastner Mechanical Contractors, Inc. | B30: =Claims!B9 -> 09/21/2026 | C30: =Claims!D9 -> 159145 | D30: =Claims!F9 -> Yes | E30: =Claims!G9 -> Yes | F30: =Claims!H9 -> Yes | G30: =Claims!I9 -> No | H30: =Claims!J9 -> Enforceable | I30: =Claims!K9 -> 85235 | J30: =Claims!M9 -> Bond at 125 percent of the recorded claim, or take an amended claim at the enforceable amount | K30: =Claims!N9 -> 198931.25 | L30: July waiver rests on stopped check 4460; July was paid by check 4474 | M30: Replacement check 4474 paid at the bank on 09/23/2026
A31: =Claims!A10 -> Bautista Painting Co. | B31: =Claims!B10 -> 09/22/2026 | C31: =Claims!D10 -> 46600 | D31: =Claims!F10 -> Yes | E31: =Claims!G10 -> Yes | F31: =Claims!H10 -> Yes | G31: =Claims!I10 -> No | H31: =Claims!J10 -> Enforceable | I31: =Claims!K10 -> 8125 | J31: =Claims!M10 -> Bond at 125 percent of the recorded claim, or take an amended claim at the enforceable amount | K31: =Claims!N10 -> 58250 | L31: Unconditional through 07/31/2026 releases the unpaid July draw | M31: Unconditional waiver effective when signed
A32: =Claims!A11 -> Fenwick Roofing, Inc. | B32: =Claims!B11 -> 09/23/2026 | C32: =Claims!D11 -> 14937.5 | D32: =Claims!F11 -> Yes | E32: =Claims!G11 -> Yes | F32: =Claims!H11 -> Yes | G32: =Claims!I11 -> No | H32: =Claims!J11 -> Waived in full | I32: =Claims!K11 -> 0 | J32: =Claims!M11 -> Demand a recorded release, the defect being a final waiver of the whole claim | K32: =Claims!N11 -> 0 | L32: Conditional final waiver, check 4448 paid; releases the retention too | M32: A final form releases every lien right, retention included
A33: =Claims!A12 -> Lindqvist Fire Protection | B33: =Claims!B12 -> 09/24/2026 | C33: =Claims!D12 -> 16600 | D33: =Claims!F12 -> Yes | E33: =Claims!G12 -> Yes | F33: =Claims!H12 -> Yes | G33: =Claims!I12 -> No | H33: =Claims!J12 -> Enforceable | I33: =Claims!K12 -> 7132.5 | J33: =Claims!M12 -> Bond at 125 percent of the recorded claim, or take an amended claim at the enforceable amount | K33: =Claims!N12 -> 20750 | L33: Unconditional through 06/30/2026; retention saved, request 3 never approved | M33: Change order request 3 is not part of the price agreed
A34: =Claims!A13 -> Sierra Pipe & Supply, Inc. | B34: =Claims!B13 -> 09/24/2026 | C34: =Claims!D13 -> 19742.64 | D34: =Claims!F13 -> Yes | E34: =Claims!G13 -> Yes | F34: =Claims!H13 -> Yes | G34: =Claims!I13 -> No | H34: =Claims!J13 -> Enforceable | I34: =Claims!K13 -> 15426.44 | J34: =Claims!M13 -> Bond at 125 percent of the recorded claim, or take an amended claim at the enforceable amount | K34: =Claims!N13 -> 24678.3 | L34: None on file | M34: Late notice deposited 03/16/2026 reaches back to 02/24/2026
A35: =Claims!A14 -> Ostrowski Electric, Inc. | B35: =Claims!B14 -> 09/28/2026 | C35: =Claims!D14 -> 61477 | D35: =Claims!F14 -> Yes | E35: =Claims!G14 -> Yes | F35: =Claims!H14 -> Yes | G35: =Claims!I14 -> No | H35: =Claims!J14 -> Enforceable | I35: =Claims!K14 -> 61477 | J35: =Claims!M14 -> Bond at 125 percent, or pay from the money held against an unconditional final release | K35: =Claims!N14 -> 76846.25 | L35: July released on check 4461; check 4479 has not paid at the bank | M35: Recorded on the extended last day, 09/28/2026
A36: =Claims!A15 -> Calder Drywall & Plaster, LLC | B36: =Claims!B15 -> 09/29/2026 | C36: =Claims!D15 -> 38915 | D36: =Claims!F15 -> Yes | E36: =Claims!G15 -> Yes | F36: =Claims!H15 -> Yes | G36: =Claims!I15 -> No | H36: =Claims!J15 -> Enforceable | I36: =Claims!K15 -> 38915 | J36: =Claims!M15 -> Bond at 125 percent, or pay from the money held against an unconditional final release | K36: =Claims!N15 -> 48643.75 | L36: July release is on the contractor's form S-9; releases nothing | M36: No copy of the notice of completion; last day 11/09/2026
... A39: =Claims!A18 -> Capitol Wire & Lighting, Inc. | B39: =Claims!B18 -> 10/01/2026 | C39: =Claims!D18 -> 23480 | D39: =Claims!F18 -> Yes | E39: =Claims!G18 -> Yes | F39: =Claims!H18 -> Yes | G39: =Claims!I18 -> No | H39: =Claims!J18 -> Enforceable | I39: =Claims!K18 -> 23480 | J39: =Claims!M18 -> Bond at 125 percent, or pay from the money held against an unconditional final release | K39: =Claims!N18 -> 29350 | L39: None on file | M39: Copy mailed 09/09/2026, a day late; last day 11/09/2026
A41: Dates that govern every claim
A42: Date | B42: Value | C42: Read from
A43: Completion of the work of improvement | B43: =Parameters!B4 -> 08/11/2026 | C43: Completion memorandum and notice of completion item 5
A44: Notice of completion recorded | B44: =Parameters!B5 -> 08/26/2026 | C44: Document No. 2026-0081562
A45: Days from completion to recording | B45: =Parameters!B34 -> 15 | C45: The fifteenth day, the last that section 8182(a) allows
A46: Notice of completion effective | B46: =Parameters!B35 -> Yes, recorded within 15 days of completion | C46: section 8182(a)
...

Sheet Parameters
A1: Dates, rule constants, and money figures the analysis applies, with the source of each
A3: PARAMETER | B3: VALUE | C3: SERIAL | D3: SOURCE
A4: Completion of the work of improvement | B4: 08/11/2026 | C4: =DATE(VALUE(RIGHT(B4,4)),VALUE(LEFT(B4,2)),VALUE(MID(B4,4,2))) -> 46245 | D4: Completion memorandum of August 19, 2026, final inspection and last labor; notice of completion item 5
A5: Notice of completion recorded | B5: 08/26/2026 | C5: =DATE(VALUE(RIGHT(B5,4)),VALUE(LEFT(B5,2)),VALUE(MID(B5,4,2))) -> 46260 | D5: Notice of completion, Document No. 2026-0081562
A6: Holiday, Labor Day | B6: 09/07/2026 | C6: =DATE(VALUE(RIGHT(B6,4)),VALUE(LEFT(B6,2)),VALUE(MID(B6,4,2))) -> 46272 | D6: Memorandum of September 10, 2026 on the copies of the notice of completion
A7: Holiday under Code of Civil Procedure section 12b, county offices closed the whole day | B7: 09/25/2026 | C7: =DATE(VALUE(RIGHT(B7,4)),VALUE(LEFT(B7,2)),VALUE(MID(B7,4,2))) -> 46290 | D7: Close-out file, part D, civil index search
A8: Days allowed to record a notice of completion after completion | B8: 15 | D8: section 8182(a)
A9: Days allowed to give a copy of the notice of completion | B9: 10 | D9: section 8190(a)
A10: Days after the notice of completion to record, claimants other than the direct contractor | B10: 30 | D10: section 8414
A11: Days after the notice of completion to record, direct contractor | B11: 60 | D11: section 8412
A12: Days after completion to record where the notice does not shorten the time | B12: 90 | D12: section 8190(d) with sections 8412 and 8414
A13: Days after first furnishing for a timely preliminary notice | B13: 20 | D13: section 8204(a)
A14: Days a late preliminary notice reaches back | B14: 20 | D14: section 8204(b)
A15: Days after recording to commence an action | B15: 90 | D15: section 8460(a)
A16: Release bond, percent of the recorded claim | B16: 125 | D16: section 8424(b)
A17: Days between the demand for release and a petition | B17: 10 | D17: section 8482
A18: Days after completion for payment of retention | B18: 45 | D18: section 8812(a)
A19: Percent of a disputed amount the owner may withhold from retention | B19: 150 | D19: section 8812(c)
A20: Civil index and recorder searches run | B20: 10/02/2026 | C20: =DATE(VALUE(RIGHT(B20,4)),VALUE(LEFT(B20,2)),VALUE(MID(B20,4,2))) -> 46297 | D20: Close-out file, part D
A21: Date the analysis is due | B21: 10/20/2026 | C21: =DATE(VALUE(RIGHT(B21,4)),VALUE(LEFT(B21,2)),VALUE(MID(B21,4,2))) -> 46315 | D21: The handoff, Tuesday, October 20
A22: Refinance closing | B22: 11/20/2026 | C22: =DATE(VALUE(RIGHT(B22,4)),VALUE(LEFT(B22,2)),VALUE(MID(B22,4,2))) -> 46346 | D22: Nadia Ferris email of October 2, 2026
A23: Bank's date for releases and bonds of record | B23: 11/06/2026 | C23: =DATE(VALUE(RIGHT(B23,4)),VALUE(LEFT(B23,2)),VALUE(MID(B23,4,2))) -> 46332 | D23: Nadia Ferris email of October 2, 2026
A24: Line the surety has approved for release bonds | B24: 575000 | D24: Nadia Ferris email of October 2, 2026
A25: Contract sum, Dunmore-Kettle Builders, Inc., as signed | B25: 3748250 | D25: Owner Payments tab of the project file; completion memorandum of August 19, 2026
A26: Change orders 1 to 6 approved by the owner | B26: 46000 | D26: Owner Payments tab of the project file; completion memorandum of August 19, 2026
A27: Adjusted contract sum | B27: =ROUND(B25+B26,2) -> 3794250 | D27: PN-14 on what the owner holds, the contract sum as adjusted by the approved change orders
A28: Paid to the direct contractor to date | B28: 3511114.5 | D28: Owner Payments tab, applications 1 through 7; application 8 is unpaid
A29: Retention withheld from the direct contractor | B29: 189712.5 | D29: Owner Payments tab of the project file; completion memorandum
A30: Direct contractor's estimate to correct the two rooftop units | B30: 22000 | D30: Completion memorandum of August 19, 2026
A32: Derived dates and figures
A33: PARAMETER | B33: VALUE | C33: SERIAL | D33: SOURCE
A34: Days from completion to the recording of the notice of completion | B34: =Parameters!$C$5-Parameters!$C$4 -> 15 | D34: Completion and recording rows above
A35: Notice of completion effective under section 8182 | B35: =IF((Parameters!$C$5-Parameters!$C$4)<=Parameters!$B$8,"Yes, recorded within 15 days of completion","No, recorded more than 15 days after completion") -> Yes, recorded within 15 days of completion | D35: section 8182(a), the fifteenth day counted with the day of completion excluded
A36: Tenth day after the notice of completion was recorded | B36: =TEXT(C36,"mm/dd/yyyy") -> 09/05/2026 | C36: =Parameters!$C$5+Parameters!$B$9 -> 46270 | D36: section 8190(a), before the section 12a extension
A37: Weekday of the tenth day | B37: =TEXT(Parameters!$C$5+Parameters!$B$9,"dddd") -> Saturday | D37: A Saturday, followed by the Sunday and by Labor Day
A38: Last day to give a copy of the notice of completion | B38: =TEXT(C38,"mm/dd/yyyy") -> 09/08/2026 | C38: =IF(OR(WEEKDAY(Parameters!$C$5+Parameters!$B$9,2)>5,COUNTIF(Parameters!$C$6:$C$7,Parameters!$C$5+Parameters!$B$9)>0),WORKDAY(Parameters!$C$5+Parameters!$B$9,1,Parameters!$C$6:$C$7),Parameters!$C$5+Parameters!$B$9) -> 46273 | D38: section 8190(a) with the section 12a extension
A39: Thirtieth day after the notice of completion | B39: =TEXT(C39,"mm/dd/yyyy") -> 09/25/2026 | C39: =Parameters!$C$5+Parameters!$B$10 -> 46290 | D39: section 8414, before the section 12a extension
A40: Weekday of the thirtieth day | B40: =TEXT(Parameters!$C$5+Parameters!$B$10,"dddd") -> Friday | D40: A Friday on which the county offices were closed for the whole day
A41: Last day to record, claimant given its copy in time | B41: =TEXT(C41,"mm/dd/yyyy") -> 09/28/2026 | C41: =IF(OR(WEEKDAY(Parameters!$C$5+Parameters!$B$10,2)>5,COUNTIF(Parameters!$C$6:$C$7,Parameters!$C$5+Parameters!$B$10)>0),WORKDAY(Parameters!$C$5+Parameters!$B$10,1,Parameters!$C$6:$C$7),Parameters!$C$5+Parameters!$B$10) -> 46293 | D41: section 8414 with the section 12a extension
A42: Last day to record, direct contractor given its copy in time | B42: =TEXT(C42,"mm/dd/yyyy") -> 10/26/2026 | C42: =IF(OR(WEEKDAY(Parameters!$C$5+Parameters!$B$11,2)>5,COUNTIF(Parameters!$C$6:$C$7,Parameters!$C$5+Parameters!$B$11)>0),WORKDAY(Parameters!$C$5+Parameters!$B$11,1,Parameters!$C$6:$C$7),Parameters!$C$5+Parameters!$B$11) -> 46321 | D42: section 8412 with the section 12a extension
...

Sheet DK Ledger
A1: Dunmore-Kettle Builders subcontractor payment ledger, dk_subcontractor_payments.csv, copied line for line
A3: ENTRY_DATE | B3: CHECK_NO | C3: TYPE | D3: PAYEE | E3: TRADE | F3: PAY_APP | G3: AMOUNT | H3: BANK_CLEARED
A4: 03/27/2026 | B4: 4390 | C4: CHK | D4: Ostrowski Electric Inc | E4: Electrical | F4: 2 | G4: 152950 | H4: 04/01/2026
A5: 03/27/2026 | B5: 4391 | C5: CHK | D5: Tallac Concrete Inc | E5: Site concrete | F5: 2 | G5: 71250 | H5: 03/31/2026
A6: 03/27/2026 | B6: 4393 | C6: CHK | D6: Petrakis Plumbing Inc | E6: Plumbing | F6: 2 | G6: 61370 | H6: 04/02/2026
A7: 04/28/2026 | B7: 4402 | C7: CHK | D7: Ostrowski Electric Inc | E7: Electrical | F7: 3 | G7: 121600 | H7: 05/01/2026
A8: 04/28/2026 | B8: 4403 | C8: CHK | D8: Tallac Concrete Inc | E8: Site concrete | F8: 3 | G8: 158650 | H8: 04/30/2026
A9: 04/28/2026 | B9: 4404 | C9: CHK | D9: R Nakamura Framing Inc | E9: Rough carpentry | F9: 3 | G9: 164730 | H9: 05/04/2026
A10: 04/28/2026 | B10: 4405 | C10: CHK | D10: Fenwick Roofing Inc | E10: Roofing | F10: 3 | G10: 95410 | H10: 05/01/2026
A11: 04/29/2026 | B11: 4407 | C11: CHK | D11: Kastner Mechanical Contractors Inc | E11: HVAC | F11: 3 | G11: 32110 | H11: 05/04/2026
A12: 04/29/2026 | B12: 4409 | C12: CHK | D12: Petrakis Plumbing Inc | E12: Plumbing | F12: 3 | G12: 48830 | H12: 05/05/2026
A13: 05/29/2026 | B13: 4418 | C13: CHK | D13: Ostrowski Electric Inc | E13: Electrical | F13: 4 | G13: 98325 | H13: 06/03/2026
A14: 05/29/2026 | B14: 4419 | C14: CHK | D14: R Nakamura Framing Inc | E14: Rough carpentry | F14: 4 | G14: 194370 | H14: 06/02/2026
A15: 05/29/2026 | B15: 4420 | C15: CHK | D15: Kastner Mechanical Contractors Inc | E15: HVAC | F15: 4 | G15: 97565 | H15: 06/03/2026
... A36: 07/30/2026 | B36: 4456 | C36: CHK | D36: Calder Drywall and Plaster LLC | E36: Drywall and plaster | F36: 6 | G36: 100515 | H36: 08/04/2026
A37: 08/18/2026 | B37: 4460 | C37: CHK | D37: Kastner Mechanical Contractors Inc | E37: HVAC | F37: 7 | G37: 73910
A38: 08/19/2026 | B38: 4461 | C38: CHK | D38: Ostrowski Electric Inc | E38: Electrical | F38: 7 | G38: 41230 | H38: 08/24/2026
A39: 08/19/2026 | B39: 4463 | C39: CHK | D39: Petrakis Plumbing Inc | E39: Plumbing | F39: 7 | G39: 37166 | H39: 08/25/2026
A40: 08/24/2026 | B40: 4460 | C40: STP | D40: Kastner Mechanical Contractors Inc | E40: HVAC | F40: 7 | G40: -73910
A41: 09/18/2026 | B41: 4474 | C41: CHK | D41: Kastner Mechanical Contractors Inc | E41: HVAC | F41: 7 | G41: 73910 | H41: 09/23/2026
A42: 09/30/2026 | B42: 4479 | C42: CHK | D42: Ostrowski Electric Inc | E42: Electrical | F42: 8 | G42: 27227

Sheet Notices
A1: Preliminary notice by claimant: whether one was owed, when it was given, what it covers, and whether the owner was given it
A3: CLAIMANT | B3: CONTRACTED_WITH | C3: CLASS | D3: FIRST_FURNISHED | E3: FIRST_SERIAL | F3: NOTICE_GIVEN | G3: NOTICE_SERIAL | H3: DAYS_TO_NOTICE | I3: GIVEN_TO_OWNER | J3: NOTICE_OWED | K3: TIMELY_NOTICE | L3: COVERAGE_FROM | M3: COVERAGE_SERIAL | N3: LIEN_RIGHTS | O3: READ_FROM
A4: Tallac Concrete, Inc. | B4: Dunmore-Kettle Builders, Inc. | C4: Other claimant | D4: 02/02/2026 | E4: =DATE(VALUE(RIGHT(D4,4)),VALUE(LEFT(D4,2)),VALUE(MID(D4,4,2))) -> 46055 | F4: 02/09/2026 | G4: =IF(F4="","",DATE(VALUE(RIGHT(F4,4)),VALUE(LEFT(F4,2)),VALUE(MID(F4,4,2)))) -> 46062 | H4: =IF(F4="","",G4-E4) -> 7 | I4: Yes, owner log entry mailed 02/09/2026 | J4: =IF(C4="Direct contractor","No","Yes") -> Yes | K4: =IF(J4="No","Not owed",IF(F4="","No notice",IF(H4<=Parameters!$B$13,"Yes","No"))) -> Yes | L4: =TEXT(M4,"mm/dd/yyyy") -> 02/02/2026 | M4: =IF(OR(J4="No",F4="",K4="Yes"),E4,G4-Parameters!$B$14) -> 46055 | N4: =IF(J4="No","Yes",IF(LEFT(I4,3)="Yes","Yes","No")) -> Yes | O4: Claim 1 item 7; Prelim Log row for Tallac Concrete
A5: Foothill Ready Mix, Inc. | B5: Tallac Concrete, Inc. | C5: Other claimant | D5: 02/05/2026 | E5: =DATE(VALUE(RIGHT(D5,4)),VALUE(LEFT(D5,2)),VALUE(MID(D5,4,2))) -> 46058 | F5: 02/11/2026 | G5: =IF(F5="","",DATE(VALUE(RIGHT(F5,4)),VALUE(LEFT(F5,2)),VALUE(MID(F5,4,2)))) -> 46064 | H5: =IF(F5="","",G5-E5) -> 6 | I5: Yes, owner log entry mailed 02/11/2026 | J5: =IF(C5="Direct contractor","No","Yes") -> Yes | K5: =IF(J5="No","Not owed",IF(F5="","No notice",IF(H5<=Parameters!$B$13,"Yes","No"))) -> Yes | L5: =TEXT(M5,"mm/dd/yyyy") -> 02/05/2026 | M5: =IF(OR(J5="No",F5="",K5="Yes"),E5,G5-Parameters!$B$14) -> 46058 | N5: =IF(J5="No","Yes",IF(LEFT(I5,3)="Yes","Yes","No")) -> Yes | O5: Claim 2 item 7; Prelim Log row for Foothill Ready Mix
A6: Norcal Rebar & Mesh, LLC | B6: Tallac Concrete, Inc. | C6: Other claimant | D6: 02/03/2026 | E6: =DATE(VALUE(RIGHT(D6,4)),VALUE(LEFT(D6,2)),VALUE(MID(D6,4,2))) -> 46056 | F6: 02/17/2026 | G6: =IF(F6="","",DATE(VALUE(RIGHT(F6,4)),VALUE(LEFT(F6,2)),VALUE(MID(F6,4,2)))) -> 46070 | H6: =IF(F6="","",G6-E6) -> 14 | I6: No, Exhibit A names Dunmore-Kettle and Tallac, and the owner log has no entry | J6: =IF(C6="Direct contractor","No","Yes") -> Yes | K6: =IF(J6="No","Not owed",IF(F6="","No notice",IF(H6<=Parameters!$B$13,"Yes","No"))) -> Yes | L6: =TEXT(M6,"mm/dd/yyyy") -> 02/03/2026 | M6: =IF(OR(J6="No",F6="",K6="Yes"),E6,G6-Parameters!$B$14) -> 46056 | N6: =IF(J6="No","Yes",IF(LEFT(I6,3)="Yes","Yes","No")) -> No | O6: Claim 3 item 7 and Exhibit A; Prelim Log, no entry
A7: Hedrick & Sons Building Supply | B7: R. Nakamura Framing, Inc. | C7: Other claimant | D7: 04/06/2026 | E7: =DATE(VALUE(RIGHT(D7,4)),VALUE(LEFT(D7,2)),VALUE(MID(D7,4,2))) -> 46118 | F7: 05/29/2026 | G7: =IF(F7="","",DATE(VALUE(RIGHT(F7,4)),VALUE(LEFT(F7,2)),VALUE(MID(F7,4,2)))) -> 46171 | H7: =IF(F7="","",G7-E7) -> 53 | I7: Yes, owner log entry mailed 05/29/2026 | J7: =IF(C7="Direct contractor","No","Yes") -> Yes | K7: =IF(J7="No","Not owed",IF(F7="","No notice",IF(H7<=Parameters!$B$13,"Yes","No"))) -> No | L7: =TEXT(M7,"mm/dd/yyyy") -> 05/09/2026 | M7: =IF(OR(J7="No",F7="",K7="Yes"),E7,G7-Parameters!$B$14) -> 46151 | N7: =IF(J7="No","Yes",IF(LEFT(I7,3)="Yes","Yes","No")) -> Yes | O7: Claim 4 item 7 and Exhibit A, first delivery 04/06/2026; Prelim Log DATE_MAILED
A8: Abrego Glass & Glazing | B8: Dunmore-Kettle Builders, Inc. | C8: Other claimant | D8: 04/27/2026 | E8: =DATE(VALUE(RIGHT(D8,4)),VALUE(LEFT(D8,2)),VALUE(MID(D8,4,2))) -> 46139 | F8: 05/04/2026 | G8: =IF(F8="","",DATE(VALUE(RIGHT(F8,4)),VALUE(LEFT(F8,2)),VALUE(MID(F8,4,2)))) -> 46146 | H8: =IF(F8="","",G8-E8) -> 7 | I8: Yes, owner log entry mailed 05/04/2026 | J8: =IF(C8="Direct contractor","No","Yes") -> Yes | K8: =IF(J8="No","Not owed",IF(F8="","No notice",IF(H8<=Parameters!$B$13,"Yes","No"))) -> Yes | L8: =TEXT(M8,"mm/dd/yyyy") -> 04/27/2026 | M8: =IF(OR(J8="No",F8="",K8="Yes"),E8,G8-Parameters!$B$14) -> 46139 | N8: =IF(J8="No","Yes",IF(LEFT(I8,3)="Yes","Yes","No")) -> Yes | O8: Claim 5 item 7; Prelim Log row for Abrego Glass & Glazing
A9: Kastner Mechanical Contractors, Inc. | B9: Dunmore-Kettle Builders, Inc. | C9: Other claimant | D9: 03/16/2026 | E9: =DATE(VALUE(RIGHT(D9,4)),VALUE(LEFT(D9,2)),VALUE(MID(D9,4,2))) -> 46097 | F9: 03/20/2026 | G9: =IF(F9="","",DATE(VALUE(RIGHT(F9,4)),VALUE(LEFT(F9,2)),VALUE(MID(F9,4,2)))) -> 46101 | H9: =IF(F9="","",G9-E9) -> 4 | I9: Yes, owner log entry mailed 03/20/2026 | J9: =IF(C9="Direct contractor","No","Yes") -> Yes | K9: =IF(J9="No","Not owed",IF(F9="","No notice",IF(H9<=Parameters!$B$13,"Yes","No"))) -> Yes | L9: =TEXT(M9,"mm/dd/yyyy") -> 03/16/2026 | M9: =IF(OR(J9="No",F9="",K9="Yes"),E9,G9-Parameters!$B$14) -> 46097 | N9: =IF(J9="No","Yes",IF(LEFT(I9,3)="Yes","Yes","No")) -> Yes | O9: Claim 6 item 7; Prelim Log row for Kastner Mechanical Contractors
A10: Bautista Painting Co. | B10: Dunmore-Kettle Builders, Inc. | C10: Other claimant | D10: 05/18/2026 | E10: =DATE(VALUE(RIGHT(D10,4)),VALUE(LEFT(D10,2)),VALUE(MID(D10,4,2))) -> 46160 | F10: 05/27/2026 | G10: =IF(F10="","",DATE(VALUE(RIGHT(F10,4)),VALUE(LEFT(F10,2)),VALUE(MID(F10,4,2)))) -> 46169 | H10: =IF(F10="","",G10-E10) -> 9 | I10: Yes, owner log entry mailed 05/27/2026 | J10: =IF(C10="Direct contractor","No","Yes") -> Yes | K10: =IF(J10="No","Not owed",IF(F10="","No notice",IF(H10<=Parameters!$B$13,"Yes","No"))) -> Yes | L10: =TEXT(M10,"mm/dd/yyyy") -> 05/18/2026 | M10: =IF(OR(J10="No",F10="",K10="Yes"),E10,G10-Parameters!$B$14) -> 46160 | N10: =IF(J10="No","Yes",IF(LEFT(I10,3)="Yes","Yes","No")) -> Yes | O10: Claim 7 item 7; Prelim Log row for Bautista Painting Co.
A11: Fenwick Roofing, Inc. | B11: Dunmore-Kettle Builders, Inc. | C11: Other claimant | D11: 03/09/2026 | E11: =DATE(VALUE(RIGHT(D11,4)),VALUE(LEFT(D11,2)),VALUE(MID(D11,4,2))) -> 46090 | F11: 03/12/2026 | G11: =IF(F11="","",DATE(VALUE(RIGHT(F11,4)),VALUE(LEFT(F11,2)),VALUE(MID(F11,4,2)))) -> 46093 | H11: =IF(F11="","",G11-E11) -> 3 | I11: Yes, owner log entry mailed 03/12/2026 | J11: =IF(C11="Direct contractor","No","Yes") -> Yes | K11: =IF(J11="No","Not owed",IF(F11="","No notice",IF(H11<=Parameters!$B$13,"Yes","No"))) -> Yes | L11: =TEXT(M11,"mm/dd/yyyy") -> 03/09/2026 | M11: =IF(OR(J11="No",F11="",K11="Yes"),E11,G11-Parameters!$B$14) -> 46090 | N11: =IF(J11="No","Yes",IF(LEFT(I11,3)="Yes","Yes","No")) -> Yes | O11: Claim 8 item 7; Prelim Log row for Fenwick Roofing
A12: Lindqvist Fire Protection | B12: Dunmore-Kettle Builders, Inc. | C12: Other claimant | D12: 03/02/2026 | E12: =DATE(VALUE(RIGHT(D12,4)),VALUE(LEFT(D12,2)),VALUE(MID(D12,4,2))) -> 46083 | F12: 03/09/2026 | G12: =IF(F12="","",DATE(VALUE(RIGHT(F12,4)),VALUE(LEFT(F12,2)),VALUE(MID(F12,4,2)))) -> 46090 | H12: =IF(F12="","",G12-E12) -> 7 | I12: Yes, owner log entry mailed 03/09/2026 | J12: =IF(C12="Direct contractor","No","Yes") -> Yes | K12: =IF(J12="No","Not owed",IF(F12="","No notice",IF(H12<=Parameters!$B$13,"Yes","No"))) -> Yes | L12: =TEXT(M12,"mm/dd/yyyy") -> 03/02/2026 | M12: =IF(OR(J12="No",F12="",K12="Yes"),E12,G12-Parameters!$B$14) -> 46083 | N12: =IF(J12="No","Yes",IF(LEFT(I12,3)="Yes","Yes","No")) -> Yes | O12: Claim 9 item 7; Prelim Log row for Lindqvist Fire Protection
A13: Sierra Pipe & Supply, Inc. | B13: Petrakis Plumbing, Inc. | C13: Other claimant | D13: 02/23/2026 | E13: =DATE(VALUE(RIGHT(D13,4)),VALUE(LEFT(D13,2)),VALUE(MID(D13,4,2))) -> 46076 | F13: 03/16/2026 | G13: =IF(F13="","",DATE(VALUE(RIGHT(F13,4)),VALUE(LEFT(F13,2)),VALUE(MID(F13,4,2)))) -> 46097 | H13: =IF(F13="","",G13-E13) -> 21 | I13: Yes, owner log entry mailed 03/16/2026 | J13: =IF(C13="Direct contractor","No","Yes") -> Yes | K13: =IF(J13="No","Not owed",IF(F13="","No notice",IF(H13<=Parameters!$B$13,"Yes","No"))) -> No | L13: =TEXT(M13,"mm/dd/yyyy") -> 02/24/2026 | M13: =IF(OR(J13="No",F13="",K13="Yes"),E13,G13-Parameters!$B$14) -> 46077 | N13: =IF(J13="No","Yes",IF(LEFT(I13,3)="Yes","Yes","No")) -> Yes | O13: Claim 10 Exhibit A, ticket R-51022 delivered 02/23/2026; Prelim Log DATE_MAILED
A14: Ostrowski Electric, Inc. | B14: Dunmore-Kettle Builders, Inc. | C14: Other claimant | D14: 01/19/2026 | E14: =DATE(VALUE(RIGHT(D14,4)),VALUE(LEFT(D14,2)),VALUE(MID(D14,4,2))) -> 46041 | F14: 01/30/2026 | G14: =IF(F14="","",DATE(VALUE(RIGHT(F14,4)),VALUE(LEFT(F14,2)),VALUE(MID(F14,4,2)))) -> 46052 | H14: =IF(F14="","",G14-E14) -> 11 | I14: Yes, owner log entry mailed 01/30/2026 | J14: =IF(C14="Direct contractor","No","Yes") -> Yes | K14: =IF(J14="No","Not owed",IF(F14="","No notice",IF(H14<=Parameters!$B$13,"Yes","No"))) -> Yes | L14: =TEXT(M14,"mm/dd/yyyy") -> 01/19/2026 | M14: =IF(OR(J14="No",F14="",K14="Yes"),E14,G14-Parameters!$B$14) -> 46041 | N14: =IF(J14="No","Yes",IF(LEFT(I14,3)="Yes","Yes","No")) -> Yes | O14: Claim 11 item 7; Prelim Log row for Ostrowski Electric
A15: Calder Drywall & Plaster, LLC | B15: Dunmore-Kettle Builders, Inc. | C15: Other claimant | D15: 04/20/2026 | E15: =DATE(VALUE(RIGHT(D15,4)),VALUE(LEFT(D15,2)),VALUE(MID(D15,4,2))) -> 46132 | F15: 04/24/2026 | G15: =IF(F15="","",DATE(VALUE(RIGHT(F15,4)),VALUE(LEFT(F15,2)),VALUE(MID(F15,4,2)))) -> 46136 | H15: =IF(F15="","",G15-E15) -> 4 | I15: Yes, owner log entry mailed 04/24/2026 | J15: =IF(C15="Direct contractor","No","Yes") -> Yes | K15: =IF(J15="No","Not owed",IF(F15="","No notice",IF(H15<=Parameters!$B$13,"Yes","No"))) -> Yes | L15: =TEXT(M15,"mm/dd/yyyy") -> 04/20/2026 | M15: =IF(OR(J15="No",F15="",K15="Yes"),E15,G15-Parameters!$B$14) -> 46132 | N15: =IF(J15="No","Yes",IF(LEFT(I15,3)="Yes","Yes","No")) -> Yes | O15: Claim 12 item 7; Prelim Log row for Calder Drywall & Plaster
A16: Petrakis Plumbing, Inc. | B16: Dunmore-Kettle Builders, Inc. | C16: Other claimant | D16: 02/09/2026 | E16: =DATE(VALUE(RIGHT(D16,4)),VALUE(LEFT(D16,2)),VALUE(MID(D16,4,2))) -> 46062 | F16: 02/12/2026 | G16: =IF(F16="","",DATE(VALUE(RIGHT(F16,4)),VALUE(LEFT(F16,2)),VALUE(MID(F16,4,2)))) -> 46065 | H16: =IF(F16="","",G16-E16) -> 3 | I16: Yes, owner log entry mailed 02/12/2026 | J16: =IF(C16="Direct contractor","No","Yes") -> Yes | K16: =IF(J16="No","Not owed",IF(F16="","No notice",IF(H16<=Parameters!$B$13,"Yes","No"))) -> Yes | L16: =TEXT(M16,"mm/dd/yyyy") -> 02/09/2026 | M16: =IF(OR(J16="No",F16="",K16="Yes"),E16,G16-Parameters!$B$14) -> 46062 | N16: =IF(J16="No","Yes",IF(LEFT(I16,3)="Yes","Yes","No")) -> Yes | O16: Claim 13 item 7; Prelim Log row for Petrakis Plumbing
A17: Sorensen Landscape Co. | B17: Piedmont Ridge Properties, LLC | C17: Direct contractor | D17: 06/08/2026 | E17: =DATE(VALUE(RIGHT(D17,4)),VALUE(LEFT(D17,2)),VALUE(MID(D17,4,2))) -> 46181 | G17: =IF(F17="","",DATE(VALUE(RIGHT(F17,4)),VALUE(LEFT(F17,2)),VALUE(MID(F17,4,2)))) | H17: =IF(F17="","",G17-E17) | I17: None given and none owed, the claimant contracted with the owner itself | J17: =IF(C17="Direct contractor","No","Yes") -> No | K17: =IF(J17="No","Not owed",IF(F17="","No notice",IF(H17<=Parameters!$B$13,"Yes","No"))) -> Not owed | L17: =TEXT(M17,"mm/dd/yyyy") -> 06/08/2026 | M17: =IF(OR(J17="No",F17="",K17="Yes"),E17,G17-Parameters!$B$14) -> 46181 | N17: =IF(J17="No","Yes",IF(LEFT(I17,3)="Yes","Yes","No")) -> Yes | O17: Claim 14 items 5, 7 and 8; Owner Payments tab, the owner's own agreements
A18: Capitol Wire & Lighting, Inc. | B18: Ostrowski Electric, Inc. | C18: Other claimant | D18: 01/27/2026 | E18: =DATE(VALUE(RIGHT(D18,4)),VALUE(LEFT(D18,2)),VALUE(MID(D18,4,2))) -> 46049 | F18: 02/16/2026 | G18: =IF(F18="","",DATE(VALUE(RIGHT(F18,4)),VALUE(LEFT(F18,2)),VALUE(MID(F18,4,2)))) -> 46069 | H18: =IF(F18="","",G18-E18) -> 20 | I18: Yes, owner log entry mailed 02/16/2026 | J18: =IF(C18="Direct contractor","No","Yes") -> Yes | K18: =IF(J18="No","Not owed",IF(F18="","No notice",IF(H18<=Parameters!$B$13,"Yes","No"))) -> Yes | L18: =TEXT(M18,"mm/dd/yyyy") -> 01/27/2026 | M18: =IF(OR(J18="No",F18="",K18="Yes"),E18,G18-Parameters!$B$14) -> 46049 | N18: =IF(J18="No","Yes",IF(LEFT(I18,3)="Yes","Yes","No")) -> Yes | O18: Claim 15 Exhibit A, ticket D-30117 delivered 01/27/2026; Prelim Log DATE_MAILED
A20: Notice given is the date of deposit (section 8116), read from DATE_MAILED on the owner's log or from the exhibit to the claim, never from the date typed on the notice, the date received, or the recital in the claim. First furnishing is read from the claim and the statement of account attached to it, never from the preliminary notice form. A late notice covers work furnished from the twentieth day before it was given, the day of giving not counted. A direct contractor owes no preliminary notice on a job with no construction lender (section 8200(e)).

Sheet NOC Copies
A1: Copy of the notice of completion by person: who was entitled to one, when it was mailed, and the last day to record that follows
A3: PERSON | B3: CLASS | C3: ENTITLED_TO_COPY | D3: ADDRESSEE_ON_MAIL_LOG | E3: COPY_MAILED | F3: MAILED_SERIAL | G3: GIVEN_IN_TIME | H3: NOTICE_SHORTENS_TIME | I3: LAST_DAY_TO_RECORD | J3: LAST_DAY_SERIAL | K3: READ_FROM
A4: Tallac Concrete, Inc. | B4: =Notices!C4 -> Other claimant | C4: =IF(OR(Notices!C4="Direct contractor",LEFT(Notices!I4,3)="Yes"),"Yes","No") -> Yes | D4: Tallac Concrete Inc | E4: 08/31/2026 | F4: =IF(E4="","",DATE(VALUE(RIGHT(E4,4)),VALUE(LEFT(E4,2)),VALUE(MID(E4,4,2)))) -> 46265 | G4: =IF(C4="No","Not entitled",IF(E4="","No",IF(F4<=Parameters!$C$38,"Yes","No"))) -> Yes | H4: =IF(G4="No","No","Yes") -> Yes | I4: =TEXT(J4,"mm/dd/yyyy") -> 09/28/2026 | J4: =IF(H4="No",Parameters!$C$43,IF(B4="Direct contractor",Parameters!$C$42,Parameters!$C$41)) -> 46293 | K4: Certified Mail tab, Tallac Concrete Inc, mailed 08/31/2026
A5: Foothill Ready Mix, Inc. | B5: =Notices!C5 -> Other claimant | C5: =IF(OR(Notices!C5="Direct contractor",LEFT(Notices!I5,3)="Yes"),"Yes","No") -> Yes | D5: Foothill Ready Mix | E5: 08/31/2026 | F5: =IF(E5="","",DATE(VALUE(RIGHT(E5,4)),VALUE(LEFT(E5,2)),VALUE(MID(E5,4,2)))) -> 46265 | G5: =IF(C5="No","Not entitled",IF(E5="","No",IF(F5<=Parameters!$C$38,"Yes","No"))) -> Yes | H5: =IF(G5="No","No","Yes") -> Yes | I5: =TEXT(J5,"mm/dd/yyyy") -> 09/28/2026 | J5: =IF(H5="No",Parameters!$C$43,IF(B5="Direct contractor",Parameters!$C$42,Parameters!$C$41)) -> 46293 | K5: Certified Mail tab, Foothill Ready Mix, mailed 08/31/2026
A6: Norcal Rebar & Mesh, LLC | B6: =Notices!C6 -> Other claimant | C6: =IF(OR(Notices!C6="Direct contractor",LEFT(Notices!I6,3)="Yes"),"Yes","No") -> No | D6: Not on the log | F6: =IF(E6="","",DATE(VALUE(RIGHT(E6,4)),VALUE(LEFT(E6,2)),VALUE(MID(E6,4,2)))) | G6: =IF(C6="No","Not entitled",IF(E6="","No",IF(F6<=Parameters!$C$38,"Yes","No"))) -> Not entitled | H6: =IF(G6="No","No","Yes") -> Yes | I6: =TEXT(J6,"mm/dd/yyyy") -> 09/28/2026 | J6: =IF(H6="No",Parameters!$C$43,IF(B6="Direct contractor",Parameters!$C$42,Parameters!$C$41)) -> 46293 | K6: Certified Mail tab, no entry; no preliminary notice to the owner, so no copy was owed
A7: Hedrick & Sons Building Supply | B7: =Notices!C7 -> Other claimant | C7: =IF(OR(Notices!C7="Direct contractor",LEFT(Notices!I7,3)="Yes"),"Yes","No") -> Yes | D7: Hedrick and Sons Bldg Supply | E7: 09/08/2026 | F7: =IF(E7="","",DATE(VALUE(RIGHT(E7,4)),VALUE(LEFT(E7,2)),VALUE(MID(E7,4,2)))) -> 46273 | G7: =IF(C7="No","Not entitled",IF(E7="","No",IF(F7<=Parameters!$C$38,"Yes","No"))) -> Yes | H7: =IF(G7="No","No","Yes") -> Yes | I7: =TEXT(J7,"mm/dd/yyyy") -> 09/28/2026 | J7: =IF(H7="No",Parameters!$C$43,IF(B7="Direct contractor",Parameters!$C$42,Parameters!$C$41)) -> 46293 | K7: Certified Mail tab, Hedrick and Sons Bldg Supply, mailed 09/08/2026
A8: Abrego Glass & Glazing | B8: =Notices!C8 -> Other claimant | C8: =IF(OR(Notices!C8="Direct contractor",LEFT(Notices!I8,3)="Yes"),"Yes","No") -> Yes | D8: Abrego Glass and Glazing | E8: 08/31/2026 | F8: =IF(E8="","",DATE(VALUE(RIGHT(E8,4)),VALUE(LEFT(E8,2)),VALUE(MID(E8,4,2)))) -> 46265 | G8: =IF(C8="No","Not entitled",IF(E8="","No",IF(F8<=Parameters!$C$38,"Yes","No"))) -> Yes | H8: =IF(G8="No","No","Yes") -> Yes | I8: =TEXT(J8,"mm/dd/yyyy") -> 09/28/2026 | J8: =IF(H8="No",Parameters!$C$43,IF(B8="Direct contractor",Parameters!$C$42,Parameters!$C$41)) -> 46293 | K8: Certified Mail tab, Abrego Glass and Glazing, mailed 08/31/2026
A9: Kastner Mechanical Contractors, Inc. | B9: =Notices!C9 -> Other claimant | C9: =IF(OR(Notices!C9="Direct contractor",LEFT(Notices!I9,3)="Yes"),"Yes","No") -> Yes | D9: Kastner Mechanical | E9: 08/31/2026 | F9: =IF(E9="","",DATE(VALUE(RIGHT(E9,4)),VALUE(LEFT(E9,2)),VALUE(MID(E9,4,2)))) -> 46265 | G9: =IF(C9="No","Not entitled",IF(E9="","No",IF(F9<=Parameters!$C$38,"Yes","No"))) -> Yes | H9: =IF(G9="No","No","Yes") -> Yes | I9: =TEXT(J9,"mm/dd/yyyy") -> 09/28/2026 | J9: =IF(H9="No",Parameters!$C$43,IF(B9="Direct contractor",Parameters!$C$42,Parameters!$C$41)) -> 46293 | K9: Certified Mail tab, Kastner Mechanical, mailed 08/31/2026
A10: Bautista Painting Co. | B10: =Notices!C10 -> Other claimant | C10: =IF(OR(Notices!C10="Direct contractor",LEFT(Notices!I10,3)="Yes"),"Yes","No") -> Yes | D10: Bautista Painting | E10: 09/08/2026 | F10: =IF(E10="","",DATE(VALUE(RIGHT(E10,4)),VALUE(LEFT(E10,2)),VALUE(MID(E10,4,2)))) -> 46273 | G10: =IF(C10="No","Not entitled",IF(E10="","No",IF(F10<=Parameters!$C$38,"Yes","No"))) -> Yes | H10: =IF(G10="No","No","Yes") -> Yes | I10: =TEXT(J10,"mm/dd/yyyy") -> 09/28/2026 | J10: =IF(H10="No",Parameters!$C$43,IF(B10="Direct contractor",Parameters!$C$42,Parameters!$C$41)) -> 46293 | K10: Certified Mail tab, Bautista Painting, mailed 09/08/2026
A11: Fenwick Roofing, Inc. | B11: =Notices!C11 -> Other claimant | C11: =IF(OR(Notices!C11="Direct contractor",LEFT(Notices!I11,3)="Yes"),"Yes","No") -> Yes | D11: Fenwick Roofing Inc | E11: 08/31/2026 | F11: =IF(E11="","",DATE(VALUE(RIGHT(E11,4)),VALUE(LEFT(E11,2)),VALUE(MID(E11,4,2)))) -> 46265 | G11: =IF(C11="No","Not entitled",IF(E11="","No",IF(F11<=Parameters!$C$38,"Yes","No"))) -> Yes | H11: =IF(G11="No","No","Yes") -> Yes | I11: =TEXT(J11,"mm/dd/yyyy") -> 09/28/2026 | J11: =IF(H11="No",Parameters!$C$43,IF(B11="Direct contractor",Parameters!$C$42,Parameters!$C$41)) -> 46293 | K11: Certified Mail tab, Fenwick Roofing Inc, mailed 08/31/2026
A12: Lindqvist Fire Protection | B12: =Notices!C12 -> Other claimant | C12: =IF(OR(Notices!C12="Direct contractor",LEFT(Notices!I12,3)="Yes"),"Yes","No") -> Yes | D12: Lindqvist Fire Protection | E12: 08/31/2026 | F12: =IF(E12="","",DATE(VALUE(RIGHT(E12,4)),VALUE(LEFT(E12,2)),VALUE(MID(E12,4,2)))) -> 46265 | G12: =IF(C12="No","Not entitled",IF(E12="","No",IF(F12<=Parameters!$C$38,"Yes","No"))) -> Yes | H12: =IF(G12="No","No","Yes") -> Yes | I12: =TEXT(J12,"mm/dd/yyyy") -> 09/28/2026 | J12: =IF(H12="No",Parameters!$C$43,IF(B12="Direct contractor",Parameters!$C$42,Parameters!$C$41)) -> 46293 | K12: Certified Mail tab, Lindqvist Fire Protection, mailed 08/31/2026
A13: Sierra Pipe & Supply, Inc. | B13: =Notices!C13 -> Other claimant | C13: =IF(OR(Notices!C13="Direct contractor",LEFT(Notices!I13,3)="Yes"),"Yes","No") -> Yes | D13: Sierra Pipe and Supply | E13: 09/08/2026 | F13: =IF(E13="","",DATE(VALUE(RIGHT(E13,4)),VALUE(LEFT(E13,2)),VALUE(MID(E13,4,2)))) -> 46273 | G13: =IF(C13="No","Not entitled",IF(E13="","No",IF(F13<=Parameters!$C$38,"Yes","No"))) -> Yes | H13: =IF(G13="No","No","Yes") -> Yes | I13: =TEXT(J13,"mm/dd/yyyy") -> 09/28/2026 | J13: =IF(H13="No",Parameters!$C$43,IF(B13="Direct contractor",Parameters!$C$42,Parameters!$C$41)) -> 46293 | K13: Certified Mail tab, Sierra Pipe and Supply, mailed 09/08/2026
A14: Ostrowski Electric, Inc. | B14: =Notices!C14 -> Other claimant | C14: =IF(OR(Notices!C14="Direct contractor",LEFT(Notices!I14,3)="Yes"),"Yes","No") -> Yes | D14: Ostrowski Electric Inc | E14: 08/31/2026 | F14: =IF(E14="","",DATE(VALUE(RIGHT(E14,4)),VALUE(LEFT(E14,2)),VALUE(MID(E14,4,2)))) -> 46265 | G14: =IF(C14="No","Not entitled",IF(E14="","No",IF(F14<=Parameters!$C$38,"Yes","No"))) -> Yes | H14: =IF(G14="No","No","Yes") -> Yes | I14: =TEXT(J14,"mm/dd/yyyy") -> 09/28/2026 | J14: =IF(H14="No",Parameters!$C$43,IF(B14="Direct contractor",Parameters!$C$42,Parameters!$C$41)) -> 46293 | K14: Certified Mail tab, Ostrowski Electric Inc, mailed 08/31/2026
A15: Calder Drywall & Plaster, LLC | B15: =Notices!C15 -> Other claimant | C15: =IF(OR(Notices!C15="Direct contractor",LEFT(Notices!I15,3)="Yes"),"Yes","No") -> Yes | D15: Not on the log | F15: =IF(E15="","",DATE(VALUE(RIGHT(E15,4)),VALUE(LEFT(E15,2)),VALUE(MID(E15,4,2)))) | G15: =IF(C15="No","Not entitled",IF(E15="","No",IF(F15<=Parameters!$C$38,"Yes","No"))) -> No | H15: =IF(G15="No","No","Yes") -> No | I15: =TEXT(J15,"mm/dd/yyyy") -> 11/09/2026 | J15: =IF(H15="No",Parameters!$C$43,IF(B15="Direct contractor",Parameters!$C$42,Parameters!$C$41)) -> 46335 | K15: Certified Mail tab, no entry for Calder Drywall & Plaster; the 08/31/2026 entry is Calder Bros Masonry of Penryn
A16: Petrakis Plumbing, Inc. | B16: =Notices!C16 -> Other claimant | C16: =IF(OR(Notices!C16="Direct contractor",LEFT(Notices!I16,3)="Yes"),"Yes","No") -> Yes | D16: Petrakis Plumbing | E16: 09/08/2026 | F16: =IF(E16="","",DATE(VALUE(RIGHT(E16,4)),VALUE(LEFT(E16,2)),VALUE(MID(E16,4,2)))) -> 46273 | G16: =IF(C16="No","Not entitled",IF(E16="","No",IF(F16<=Parameters!$C$38,"Yes","No"))) -> Yes | H16: =IF(G16="No","No","Yes") -> Yes | I16: =TEXT(J16,"mm/dd/yyyy") -> 09/28/2026 | J16: =IF(H16="No",Parameters!$C$43,IF(B16="Direct contractor",Parameters!$C$42,Parameters!$C$41)) -> 46293 | K16: Certified Mail tab, Petrakis Plumbing, mailed 09/08/2026
A17: Sorensen Landscape Co. | B17: =Notices!C17 -> Direct contractor | C17: =IF(OR(Notices!C17="Direct contractor",LEFT(Notices!I17,3)="Yes"),"Yes","No") -> Yes | D17: Not on the log | F17: =IF(E17="","",DATE(VALUE(RIGHT(E17,4)),VALUE(LEFT(E17,2)),VALUE(MID(E17,4,2)))) | G17: =IF(C17="No","Not entitled",IF(E17="","No",IF(F17<=Parameters!$C$38,"Yes","No"))) -> No | H17: =IF(G17="No","No","Yes") -> No | I17: =TEXT(J17,"mm/dd/yyyy") -> 11/09/2026 | J17: =IF(H17="No",Parameters!$C$43,IF(B17="Direct contractor",Parameters!$C$42,Parameters!$C$41)) -> 46335 | K17: Certified Mail tab, no entry; memorandum of September 10, 2026
A18: Capitol Wire & Lighting, Inc. | B18: =Notices!C18 -> Other claimant | C18: =IF(OR(Notices!C18="Direct contractor",LEFT(Notices!I18,3)="Yes"),"Yes","No") -> Yes | D18: Capitol Wire and Lighting | E18: 09/09/2026 | F18: =IF(E18="","",DATE(VALUE(RIGHT(E18,4)),VALUE(LEFT(E18,2)),VALUE(MID(E18,4,2)))) -> 46274 | G18: =IF(C18="No","Not entitled",IF(E18="","No",IF(F18<=Parameters!$C$38,"Yes","No"))) -> No | H18: =IF(G18="No","No","Yes") -> No | I18: =TEXT(J18,"mm/dd/yyyy") -> 11/09/2026 | J18: =IF(H18="No",Parameters!$C$43,IF(B18="Direct contractor",Parameters!$C$42,Parameters!$C$41)) -> 46335 | K18: Certified Mail tab, Capitol Wire and Lighting, mailed 09/09/2026
A20: The direct contractor on the notice of completion, which has not recorded a claim
A21: PERSON | B21: CLASS | C21: ENTITLED_TO_COPY | D21: ADDRESSEE_ON_MAIL_LOG | E21: COPY_MAILED | F21: MAILED_SERIAL | G21: GIVEN_IN_TIME | H21: NOTICE_SHORTENS_TIME | I21: LAST_DAY_TO_RECORD | J21: LAST_DAY_SERIAL | K21: READ_FROM
A22: Dunmore-Kettle Builders, Inc. | B22: Direct contractor | C22: Yes | D22: Dunmore-Kettle Builders | E22: 09/09/2026 | F22: =IF(E22="","",DATE(VALUE(RIGHT(E22,4)),VALUE(LEFT(E22,2)),VALUE(MID(E22,4,2)))) -> 46274 | G22: =IF(C22="No","Not entitled",IF(E22="","No",IF(F22<=Parameters!$C$38,"Yes","No"))) -> No | H22: =IF(G22="No","No","Yes") -> No | I22: =TEXT(J22,"mm/dd/yyyy") -> 11/09/2026 | J22: =IF(H22="No",Parameters!$C$43,IF(B22="Direct contractor",Parameters!$C$42,Parameters!$C$41)) -> 46335 | K22: Certified Mail tab, Dunmore-Kettle Builders, mailed 09/09/2026
A24: A copy is owed to the direct contractor and to every claimant that gave the owner a preliminary notice, within 10 days after the notice of completion was recorded (section 8190(a)). The tenth day was a Saturday and the Monday after it was Labor Day, so a copy deposited on Tuesday 09/08/2026 was given in time and one deposited on Wednesday 09/09/2026 was not. Where no copy was given in time, the notice of completion does not shorten that person's time, and the last day is 90 days after completion (section 8190(d)).

Sheet Deadlines
A1: Recording, service, and enforcement by claim, counted under Code of Civil Procedure sections 12, 12a and 12b
A3: CLAIMANT | B3: RECORDED | C3: RECORDED_SERIAL | D3: LAST_DAY_TO_RECORD | E3: TIMELY | F3: COPY_OF_CLAIM_MAILED_TO | G3: SERVED_ON_OWNER | H3: ACTION_DUE_BY | I3: ACTION_DUE_SERIAL | J3: ACTION_ON_INDEX | K3: EXPIRED | L3: DOC_NO
A4: Tallac Concrete, Inc. | B4: 06/26/2026 | C4: =DATE(VALUE(RIGHT(B4,4)),VALUE(LEFT(B4,2)),VALUE(MID(B4,4,2))) -> 46199 | D4: ='NOC Copies'!I4 -> 09/28/2026 | E4: =IF(C4<='NOC Copies'!J4,"Yes","No") -> Yes | F4: Owner, 3100 Douglas Boulevard, Roseville | G4: =IF(LEFT(F4,5)="Owner","Yes","No") -> Yes | H4: =TEXT(I4,"mm/dd/yyyy") -> 09/24/2026 | I4: =IF(OR(WEEKDAY(C4+Parameters!$B$15,2)>5,COUNTIF(Parameters!$C$6:$C$7,C4+Parameters!$B$15)>0),WORKDAY(C4+Parameters!$B$15,1,Parameters!$C$6:$C$7),C4+Parameters!$B$15) -> 46289 | J4: None | K4: =IF(J4<>"None","No",IF(Parameters!$C$20>I4,"Yes",IF(Parameters!$C$21>I4,"Not shown","No"))) -> Yes | L4: 2026-0060418
A5: Foothill Ready Mix, Inc. | B5: 07/06/2026 | C5: =DATE(VALUE(RIGHT(B5,4)),VALUE(LEFT(B5,2)),VALUE(MID(B5,4,2))) -> 46209 | D5: ='NOC Copies'!I5 -> 09/28/2026 | E5: =IF(C5<='NOC Copies'!J5,"Yes","No") -> Yes | F5: Owner, 3100 Douglas Boulevard, Roseville | G5: =IF(LEFT(F5,5)="Owner","Yes","No") -> Yes | H5: =TEXT(I5,"mm/dd/yyyy") -> 10/05/2026 | I5: =IF(OR(WEEKDAY(C5+Parameters!$B$15,2)>5,COUNTIF(Parameters!$C$6:$C$7,C5+Parameters!$B$15)>0),WORKDAY(C5+Parameters!$B$15,1,Parameters!$C$6:$C$7),C5+Parameters!$B$15) -> 46300 | J5: None | K5: =IF(J5<>"None","No",IF(Parameters!$C$20>I5,"Yes",IF(Parameters!$C$21>I5,"Not shown","No"))) -> Not shown | L5: 2026-0063905
A6: Norcal Rebar & Mesh, LLC | B6: 09/14/2026 | C6: =DATE(VALUE(RIGHT(B6,4)),VALUE(LEFT(B6,2)),VALUE(MID(B6,4,2))) -> 46279 | D6: ='NOC Copies'!I6 -> 09/28/2026 | E6: =IF(C6<='NOC Copies'!J6,"Yes","No") -> Yes | F6: Owner, 3100 Douglas Boulevard, Roseville | G6: =IF(LEFT(F6,5)="Owner","Yes","No") -> Yes | H6: =TEXT(I6,"mm/dd/yyyy") -> 12/14/2026 | I6: =IF(OR(WEEKDAY(C6+Parameters!$B$15,2)>5,COUNTIF(Parameters!$C$6:$C$7,C6+Parameters!$B$15)>0),WORKDAY(C6+Parameters!$B$15,1,Parameters!$C$6:$C$7),C6+Parameters!$B$15) -> 46370 | J6: None | K6: =IF(J6<>"None","No",IF(Parameters!$C$20>I6,"Yes",IF(Parameters!$C$21>I6,"Not shown","No"))) -> No | L6: 2026-0095207
A7: Hedrick & Sons Building Supply | B7: 09/16/2026 | C7: =DATE(VALUE(RIGHT(B7,4)),VALUE(LEFT(B7,2)),VALUE(MID(B7,4,2))) -> 46281 | D7: ='NOC Copies'!I7 -> 09/28/2026 | E7: =IF(C7<='NOC Copies'!J7,"Yes","No") -> Yes | F7: Owner, 3100 Douglas Boulevard, Roseville | G7: =IF(LEFT(F7,5)="Owner","Yes","No") -> Yes | H7: =TEXT(I7,"mm/dd/yyyy") -> 12/15/2026 | I7: =IF(OR(WEEKDAY(C7+Parameters!$B$15,2)>5,COUNTIF(Parameters!$C$6:$C$7,C7+Parameters!$B$15)>0),WORKDAY(C7+Parameters!$B$15,1,Parameters!$C$6:$C$7),C7+Parameters!$B$15) -> 46371 | J7: None | K7: =IF(J7<>"None","No",IF(Parameters!$C$20>I7,"Yes",IF(Parameters!$C$21>I7,"Not shown","No"))) -> No | L7: 2026-0096088
A8: Abrego Glass & Glazing | B8: 09/17/2026 | C8: =DATE(VALUE(RIGHT(B8,4)),VALUE(LEFT(B8,2)),VALUE(MID(B8,4,2))) -> 46282 | D8: ='NOC Copies'!I8 -> 09/28/2026 | E8: =IF(C8<='NOC Copies'!J8,"Yes","No") -> Yes | F8: Dunmore-Kettle Builders, 2140 Sunset Boulevard, Rocklin | G8: =IF(LEFT(F8,5)="Owner","Yes","No") -> No | H8: =TEXT(I8,"mm/dd/yyyy") -> 12/16/2026 | I8: =IF(OR(WEEKDAY(C8+Parameters!$B$15,2)>5,COUNTIF(Parameters!$C$6:$C$7,C8+Parameters!$B$15)>0),WORKDAY(C8+Parameters!$B$15,1,Parameters!$C$6:$C$7),C8+Parameters!$B$15) -> 46372 | J8: None | K8: =IF(J8<>"None","No",IF(Parameters!$C$20>I8,"Yes",IF(Parameters!$C$21>I8,"Not shown","No"))) -> No | L8: 2026-0096531
A9: Kastner Mechanical Contractors, Inc. | B9: 09/21/2026 | C9: =DATE(VALUE(RIGHT(B9,4)),VALUE(LEFT(B9,2)),VALUE(MID(B9,4,2))) -> 46286 | D9: ='NOC Copies'!I9 -> 09/28/2026 | E9: =IF(C9<='NOC Copies'!J9,"Yes","No") -> Yes | F9: Owner, 3100 Douglas Boulevard, Roseville | G9: =IF(LEFT(F9,5)="Owner","Yes","No") -> Yes | H9: =TEXT(I9,"mm/dd/yyyy") -> 12/21/2026 | I9: =IF(OR(WEEKDAY(C9+Parameters!$B$15,2)>5,COUNTIF(Parameters!$C$6:$C$7,C9+Parameters!$B$15)>0),WORKDAY(C9+Parameters!$B$15,1,Parameters!$C$6:$C$7),C9+Parameters!$B$15) -> 46377 | J9: None | K9: =IF(J9<>"None","No",IF(Parameters!$C$20>I9,"Yes",IF(Parameters!$C$21>I9,"Not shown","No"))) -> No | L9: 2026-0097644
A10: Bautista Painting Co. | B10: 09/22/2026 | C10: =DATE(VALUE(RIGHT(B10,4)),VALUE(LEFT(B10,2)),VALUE(MID(B10,4,2))) -> 46287 | D10: ='NOC Copies'!I10 -> 09/28/2026 | E10: =IF(C10<='NOC Copies'!J10,"Yes","No") -> Yes | F10: Owner, 3100 Douglas Boulevard, Roseville | G10: =IF(LEFT(F10,5)="Owner","Yes","No") -> Yes | H10: =TEXT(I10,"mm/dd/yyyy") -> 12/21/2026 | I10: =IF(OR(WEEKDAY(C10+Parameters!$B$15,2)>5,COUNTIF(Parameters!$C$6:$C$7,C10+Parameters!$B$15)>0),WORKDAY(C10+Parameters!$B$15,1,Parameters!$C$6:$C$7),C10+Parameters!$B$15) -> 46377 | J10: None | K10: =IF(J10<>"None","No",IF(Parameters!$C$20>I10,"Yes",IF(Parameters!$C$21>I10,"Not shown","No"))) -> No | L10: 2026-0098120
A11: Fenwick Roofing, Inc. | B11: 09/23/2026 | C11: =DATE(VALUE(RIGHT(B11,4)),VALUE(LEFT(B11,2)),VALUE(MID(B11,4,2))) -> 46288 | D11: ='NOC Copies'!I11 -> 09/28/2026 | E11: =IF(C11<='NOC Copies'!J11,"Yes","No") -> Yes | F11: Owner, 3100 Douglas Boulevard, Roseville | G11: =IF(LEFT(F11,5)="Owner","Yes","No") -> Yes | H11: =TEXT(I11,"mm/dd/yyyy") -> 12/22/2026 | I11: =IF(OR(WEEKDAY(C11+Parameters!$B$15,2)>5,COUNTIF(Parameters!$C$6:$C$7,C11+Parameters!$B$15)>0),WORKDAY(C11+Parameters!$B$15,1,Parameters!$C$6:$C$7),C11+Parameters!$B$15) -> 46378 | J11: None | K11: =IF(J11<>"None","No",IF(Parameters!$C$20>I11,"Yes",IF(Parameters!$C$21>I11,"Not shown","No"))) -> No | L11: 2026-0098577
A12: Lindqvist Fire Protection | B12: 09/24/2026 | C12: =DATE(VALUE(RIGHT(B12,4)),VALUE(LEFT(B12,2)),VALUE(MID(B12,4,2))) -> 46289 | D12: ='NOC Copies'!I12 -> 09/28/2026 | E12: =IF(C12<='NOC Copies'!J12,"Yes","No") -> Yes | F12: Owner, 1440 Eureka Road, Roseville, the address on building permit B25-1187 | G12: =IF(LEFT(F12,5)="Owner","Yes","No") -> Yes | H12: =TEXT(I12,"mm/dd/yyyy") -> 12/23/2026 | I12: =IF(OR(WEEKDAY(C12+Parameters!$B$15,2)>5,COUNTIF(Parameters!$C$6:$C$7,C12+Parameters!$B$15)>0),WORKDAY(C12+Parameters!$B$15,1,Parameters!$C$6:$C$7),C12+Parameters!$B$15) -> 46379 | J12: None | K12: =IF(J12<>"None","No",IF(Parameters!$C$20>I12,"Yes",IF(Parameters!$C$21>I12,"Not shown","No"))) -> No | L12: 2026-0098901
A13: Sierra Pipe & Supply, Inc. | B13: 09/24/2026 | C13: =DATE(VALUE(RIGHT(B13,4)),VALUE(LEFT(B13,2)),VALUE(MID(B13,4,2))) -> 46289 | D13: ='NOC Copies'!I13 -> 09/28/2026 | E13: =IF(C13<='NOC Copies'!J13,"Yes","No") -> Yes | F13: Owner, 3100 Douglas Boulevard, Roseville | G13: =IF(LEFT(F13,5)="Owner","Yes","No") -> Yes | H13: =TEXT(I13,"mm/dd/yyyy") -> 12/23/2026 | I13: =IF(OR(WEEKDAY(C13+Parameters!$B$15,2)>5,COUNTIF(Parameters!$C$6:$C$7,C13+Parameters!$B$15)>0),WORKDAY(C13+Parameters!$B$15,1,Parameters!$C$6:$C$7),C13+Parameters!$B$15) -> 46379 | J13: None | K13: =IF(J13<>"None","No",IF(Parameters!$C$20>I13,"Yes",IF(Parameters!$C$21>I13,"Not shown","No"))) -> No | L13: 2026-0098955
A14: Ostrowski Electric, Inc. | B14: 09/28/2026 | C14: =DATE(VALUE(RIGHT(B14,4)),VALUE(LEFT(B14,2)),VALUE(MID(B14,4,2))) -> 46293 | D14: ='NOC Copies'!I14 -> 09/28/2026 | E14: =IF(C14<='NOC Copies'!J14,"Yes","No") -> Yes | F14: Owner, 3100 Douglas Boulevard, Roseville | G14: =IF(LEFT(F14,5)="Owner","Yes","No") -> Yes | H14: =TEXT(I14,"mm/dd/yyyy") -> 12/28/2026 | I14: =IF(OR(WEEKDAY(C14+Parameters!$B$15,2)>5,COUNTIF(Parameters!$C$6:$C$7,C14+Parameters!$B$15)>0),WORKDAY(C14+Parameters!$B$15,1,Parameters!$C$6:$C$7),C14+Parameters!$B$15) -> 46384 | J14: None | K14: =IF(J14<>"None","No",IF(Parameters!$C$20>I14,"Yes",IF(Parameters!$C$21>I14,"Not shown","No"))) -> No | L14: 2026-0100263
A15: Calder Drywall & Plaster, LLC | B15: 09/29/2026 | C15: =DATE(VALUE(RIGHT(B15,4)),VALUE(LEFT(B15,2)),VALUE(MID(B15,4,2))) -> 46294 | D15: ='NOC Copies'!I15 -> 11/09/2026 | E15: =IF(C15<='NOC Copies'!J15,"Yes","No") -> Yes | F15: Owner, 3100 Douglas Boulevard, Roseville | G15: =IF(LEFT(F15,5)="Owner","Yes","No") -> Yes | H15: =TEXT(I15,"mm/dd/yyyy") -> 12/28/2026 | I15: =IF(OR(WEEKDAY(C15+Parameters!$B$15,2)>5,COUNTIF(Parameters!$C$6:$C$7,C15+Parameters!$B$15)>0),WORKDAY(C15+Parameters!$B$15,1,Parameters!$C$6:$C$7),C15+Parameters!$B$15) -> 46384 | J15: None | K15: =IF(J15<>"None","No",IF(Parameters!$C$20>I15,"Yes",IF(Parameters!$C$21>I15,"Not shown","No"))) -> No | L15: 2026-0100719
... A18: Capitol Wire & Lighting, Inc. | B18: 10/01/2026 | C18: =DATE(VALUE(RIGHT(B18,4)),VALUE(LEFT(B18,2)),VALUE(MID(B18,4,2))) -> 46296 | D18: ='NOC Copies'!I18 -> 11/09/2026 | E18: =IF(C18<='NOC Copies'!J18,"Yes","No") -> Yes | F18: Owner, 3100 Douglas Boulevard, Roseville | G18: =IF(LEFT(F18,5)="Owner","Yes","No") -> Yes | H18: =TEXT(I18,"mm/dd/yyyy") -> 12/30/2026 | I18: =IF(OR(WEEKDAY(C18+Parameters!$B$15,2)>5,COUNTIF(Parameters!$C$6:$C$7,C18+Parameters!$B$15)>0),WORKDAY(C18+Parameters!$B$15,1,Parameters!$C$6:$C$7),C18+Parameters!$B$15) -> 46386 | J18: None | K18: =IF(J18<>"None","No",IF(Parameters!$C$20>I18,"Yes",IF(Parameters!$C$21>I18,"Not shown","No"))) -> No | L18: 2026-0101655
A20: LAST_DAY_TO_RECORD is read from the NOC Copies tab. A claim is served on the owner when its copy was mailed to the owner at its place of business or at the address the building permit shows for it (section 8416(c)(1)); a copy mailed to the direct contractor alone is no service. ACTION_ON_INDEX is read from the civil index search of 10/02/2026, which found no action by any claimant. A lien is expired only where that search was run after its ACTION_DUE_BY date (section 8460(a) and PN-14). Not shown marks a lien whose last day to sue has passed since the search, so that the search cannot show whether an action was filed in time.

Sheet Waivers
A1: Every waiver on file from a claimant, read against the payment ledger
A3: CLAIMANT | B3: FORM_TITLE | C3: THROUGH_DATE | D3: THROUGH_SERIAL | E3: AMOUNT | F3: EXCEPTIONS | G3: CHECK_REF | H3: CHECK_NO | I3: CHECK_AT_THE_BANK | J3: STATUTORY_FORM | K3: FORM_KIND | L3: EFFECTIVE | M3: WHY
A4: Tallac Concrete, Inc. | B4: Unconditional Waiver and Release on Progress Payment | C4: 02/28/2026 | D4: =IF(C4="","",DATE(VALUE(RIGHT(C4,4)),VALUE(LEFT(C4,2)),VALUE(MID(C4,4,2)))) -> 46081 | E4: 71250 | F4: None | H4: =IF(G4="","",VALUE(RIGHT(G4,4))) | I4: =IF(G4="","No check named",IF(COUNTIFS('DK Ledger'!$B$4:$B$42,H4,'DK Ledger'!$C$4:$C$42,"STP")>0,"Stopped",IF(INDEX('DK Ledger'!$H$4:$H$42,MATCH(H4,'DK Ledger'!$B$4:$B$42,0))="","Not paid by the bank","Paid "&INDEX('DK Ledger'!$H$4:$H$42,MATCH(H4,'DK Ledger'!$B$4:$B$42,0))))) -> No check named | J4: =IF(OR(LEFT(B4,32)="Unconditional Waiver and Release",LEFT(B4,30)="Conditional Waiver and Release"),"Yes","No") -> Yes | K4: =IF(J4="No","None",IF(ISNUMBER(SEARCH("Final Payment",B4)),"Final","Progress")) -> Progress | L4: =IF(J4="No","No",IF(LEFT(B4,13)="Unconditional","Yes",IF(LEFT(I4,4)="Paid","Yes","No"))) -> Yes | M4: =IF(J4="No","Not one of the four statutory forms, releases nothing",IF(LEFT(B4,13)="Unconditional",IF(K4="Final","Effective when signed whether or not paid, section 8138","Effective when signed whether or not paid, section 8134"),IF(LEFT(I4,4)="Paid","Check paid by the bank, effective under section 8124(b)","No evidence of payment under section 8124(b), releases nothing until payment is shown"))) -> Effective when signed whether or not paid, section 8134
A5: Tallac Concrete, Inc. | B5: Unconditional Waiver and Release on Progress Payment | C5: 03/31/2026 | D5: =IF(C5="","",DATE(VALUE(RIGHT(C5,4)),VALUE(LEFT(C5,2)),VALUE(MID(C5,4,2)))) -> 46112 | E5: 158650 | F5: None | H5: =IF(G5="","",VALUE(RIGHT(G5,4))) | I5: =IF(G5="","No check named",IF(COUNTIFS('DK Ledger'!$B$4:$B$42,H5,'DK Ledger'!$C$4:$C$42,"STP")>0,"Stopped",IF(INDEX('DK Ledger'!$H$4:$H$42,MATCH(H5,'DK Ledger'!$B$4:$B$42,0))="","Not paid by the bank","Paid "&INDEX('DK Ledger'!$H$4:$H$42,MATCH(H5,'DK Ledger'!$B$4:$B$42,0))))) -> No check named | J5: =IF(OR(LEFT(B5,32)="Unconditional Waiver and Release",LEFT(B5,30)="Conditional Waiver and Release"),"Yes","No") -> Yes | K5: =IF(J5="No","None",IF(ISNUMBER(SEARCH("Final Payment",B5)),"Final","Progress")) -> Progress | L5: =IF(J5="No","No",IF(LEFT(B5,13)="Unconditional","Yes",IF(LEFT(I5,4)="Paid","Yes","No"))) -> Yes | M5: =IF(J5="No","Not one of the four statutory forms, releases nothing",IF(LEFT(B5,13)="Unconditional",IF(K5="Final","Effective when signed whether or not paid, section 8138","Effective when signed whether or not paid, section 8134"),IF(LEFT(I5,4)="Paid","Check paid by the bank, effective under section 8124(b)","No evidence of payment under section 8124(b), releases nothing until payment is shown"))) -> Effective when signed whether or not paid, section 8134
A6: Tallac Concrete, Inc. | B6: Unconditional Waiver and Release on Progress Payment | C6: 04/30/2026 | D6: =IF(C6="","",DATE(VALUE(RIGHT(C6,4)),VALUE(LEFT(C6,2)),VALUE(MID(C6,4,2)))) -> 46142 | E6: 143710 | F6: None | H6: =IF(G6="","",VALUE(RIGHT(G6,4))) | I6: =IF(G6="","No check named",IF(COUNTIFS('DK Ledger'!$B$4:$B$42,H6,'DK Ledger'!$C$4:$C$42,"STP")>0,"Stopped",IF(INDEX('DK Ledger'!$H$4:$H$42,MATCH(H6,'DK Ledger'!$B$4:$B$42,0))="","Not paid by the bank","Paid "&INDEX('DK Ledger'!$H$4:$H$42,MATCH(H6,'DK Ledger'!$B$4:$B$42,0))))) -> No check named | J6: =IF(OR(LEFT(B6,32)="Unconditional Waiver and Release",LEFT(B6,30)="Conditional Waiver and Release"),"Yes","No") -> Yes | K6: =IF(J6="No","None",IF(ISNUMBER(SEARCH("Final Payment",B6)),"Final","Progress")) -> Progress | L6: =IF(J6="No","No",IF(LEFT(B6,13)="Unconditional","Yes",IF(LEFT(I6,4)="Paid","Yes","No"))) -> Yes | M6: =IF(J6="No","Not one of the four statutory forms, releases nothing",IF(LEFT(B6,13)="Unconditional",IF(K6="Final","Effective when signed whether or not paid, section 8138","Effective when signed whether or not paid, section 8134"),IF(LEFT(I6,4)="Paid","Check paid by the bank, effective under section 8124(b)","No evidence of payment under section 8124(b), releases nothing until payment is shown"))) -> Effective when signed whether or not paid, section 8134
A7: Tallac Concrete, Inc. | B7: Lien release letter on Tallac Concrete letterhead | C7: 05/08/2026 | D7: =IF(C7="","",DATE(VALUE(RIGHT(C7,4)),VALUE(LEFT(C7,2)),VALUE(MID(C7,4,2)))) -> 46150 | E7: 12675 | F7: Letter says all claims for the May billing and retention are released on payment of the balance | H7: =IF(G7="","",VALUE(RIGHT(G7,4))) | I7: =IF(G7="","No check named",IF(COUNTIFS('DK Ledger'!$B$4:$B$42,H7,'DK Ledger'!$C$4:$C$42,"STP")>0,"Stopped",IF(INDEX('DK Ledger'!$H$4:$H$42,MATCH(H7,'DK Ledger'!$B$4:$B$42,0))="","Not paid by the bank","Paid "&INDEX('DK Ledger'!$H$4:$H$42,MATCH(H7,'DK Ledger'!$B$4:$B$42,0))))) -> No check named | J7: =IF(OR(LEFT(B7,32)="Unconditional Waiver and Release",LEFT(B7,30)="Conditional Waiver and Release"),"Yes","No") -> No | K7: =IF(J7="No","None",IF(ISNUMBER(SEARCH("Final Payment",B7)),"Final","Progress")) -> None | L7: =IF(J7="No","No",IF(LEFT(B7,13)="Unconditional","Yes",IF(LEFT(I7,4)="Paid","Yes","No"))) -> No | M7: =IF(J7="No","Not one of the four statutory forms, releases nothing",IF(LEFT(B7,13)="Unconditional",IF(K7="Final","Effective when signed whether or not paid, section 8138","Effective when signed whether or not paid, section 8134"),IF(LEFT(I7,4)="Paid","Check paid by the bank, effective under section 8124(b)","No evidence of payment under section 8124(b), releases nothing until payment is shown"))) -> Not one of the four statutory forms, releases nothing
