Workbook

Sheet Recommendation
A1: Award recommendation, ITB 2026-17, corrugated shipping cartons, annual requirement
A2: Prepared for Torsten Nordvik, vice president of operations, under PP-3.5; recommendation prepared October 23, 2026
A4: Bidder | B4: =Evaluation!B3 -> Brannock Box Company | C4: =Evaluation!C3 -> Dahlgren Paper Box Co. | D4: =Evaluation!D3 -> Halvard Corrugated | E4: =Evaluation!E3 -> Kessel Container Corp. | F4: =Evaluation!F3 -> Loken & Vik Container | G4: =Evaluation!G3 -> Mesabi Container Co. | H4: =Evaluation!H3 -> Otter Tail Corrugated | I4: =Evaluation!I3 -> Pemberton Container | ... L4: =Evaluation!L3 -> Wenzel & Krause Corrugated | M4: Read from
A5: Plant | B5: =Terms!B4&", "&Terms!C4 -> Rockford, IL | C5: =Terms!B5&", "&Terms!C5 -> St. Cloud, MN | D5: =Terms!B6&", "&Terms!C6 -> Fargo, ND | E5: =Terms!B7&", "&Terms!C7 -> Des Moines, IA | F5: =Terms!B8&", "&Terms!C8 -> Sioux Falls, SD | G5: =Terms!B9&", "&Terms!C9 -> Duluth, MN | H5: =Terms!B10&", "&Terms!C10 -> Fergus Falls, MN | I5: =Terms!B11&", "&Terms!C11 -> Neenah, WI | J5: =Terms!B12&", "&Terms!C12 -> Cedar Rapids, IA | K5: =Terms!B13&", "&Terms!C13 -> Moorhead, MN | L5: =Terms!B14&", "&Terms!C14 -> La Crosse, WI | M5: Terms
A6: Responsiveness | B6: =Responsiveness!K4 -> Non-responsive | C6: =Responsiveness!K5 -> Non-responsive | D6: =Responsiveness!K6 -> Non-responsive | E6: =Responsiveness!K7 -> Non-responsive | F6: =Responsiveness!K8 -> Responsive | G6: =Responsiveness!K9 -> Non-responsive | H6: =Responsiveness!K10 -> Non-responsive | I6: =Responsiveness!K11 -> Responsive | J6: =Responsiveness!K12 -> Responsive | K6: =Responsiveness!K13 -> Non-responsive | L6: =Responsiveness!K14 -> Responsive | M6: Responsiveness
A7: Reason set aside | B7: =Responsiveness!L4 -> Addendum 2 not acknowledged, section 3.2; bid on the superseded item 3 quantity and item 5 grade, PP-3.4.5. | C7: =Responsiveness!L5 -> Bid security under five percent of the total bid as written, section 3.2 and addendum 2. | D7: =Responsiveness!L6 -> Exception to a material term, Price hold, section 4.3, section 5.2 and PP-3.4.4. | E7: =Responsiveness!L7 -> Bid on a superseded specification, item 2 as 18 x 12 x 12, PP-3.4.5. | F7: =Responsiveness!L8 | G7: =Responsiveness!L9 -> Item 4 offered only as an alternate, with no bid on the item as specified, section 5.2 and 4.4. | H7: =Responsiveness!L10 -> Exception to a material term, Quantity, releases in pallet multiples, section 1, section 5.2 and PP-3.4.4. | I7: =Responsiveness!L11 | J7: =Responsiveness!L12 | K7: =Responsiveness!L13 -> Exception to a material term, Price hold, section 4.3, section 5.2 and PP-3.4.4. | L7: =Responsiveness!L14 | M7: Responsiveness
A8: Responsibility of the bidder in line, PP-3.7.1 | B8: =IFERROR(INDEX(Responsibility!$G$4:$G$14,MATCH(B4,Responsibility!$B$4:$B$14,0)),"Set aside before price") -> Set aside before price | C8: =IFERROR(INDEX(Responsibility!$G$4:$G$14,MATCH(C4,Responsibility!$B$4:$B$14,0)),"Set aside before price") -> Set aside before price | D8: =IFERROR(INDEX(Responsibility!$G$4:$G$14,MATCH(D4,Responsibility!$B$4:$B$14,0)),"Set aside before price") -> Set aside before price | E8: =IFERROR(INDEX(Responsibility!$G$4:$G$14,MATCH(E4,Responsibility!$B$4:$B$14,0)),"Set aside before price") -> Set aside before price | F8: =IFERROR(INDEX(Responsibility!$G$4:$G$14,MATCH(F4,Responsibility!$B$4:$B$14,0)),"Set aside before price") -> Not responsible, open quality hold, PP-3.7.1 | G8: =IFERROR(INDEX(Responsibility!$G$4:$G$14,MATCH(G4,Responsibility!$B$4:$B$14,0)),"Set aside before price") -> Set aside before price | H8: =IFERROR(INDEX(Responsibility!$G$4:$G$14,MATCH(H4,Responsibility!$B$4:$B$14,0)),"Set aside before price") -> Set aside before price | I8: =IFERROR(INDEX(Responsibility!$G$4:$G$14,MATCH(I4,Responsibility!$B$4:$B$14,0)),"Set aside before price") -> Responsible | ... L8: =IFERROR(INDEX(Responsibility!$G$4:$G$14,MATCH(L4,Responsibility!$B$4:$B$14,0)),"Set aside before price") -> Not decided, PP-3.7.1 | M8: Responsibility
A9: Total bid as written | B9: =Evaluation!B22 -> 100058 | C9: =Evaluation!C22 -> 100045 | D9: =Evaluation!D22 -> 100608 | E9: =Evaluation!E22 -> 99876 | F9: =Evaluation!F22 -> 101214 | G9: =Evaluation!G22 -> 94902 | H9: =Evaluation!H22 -> 99567 | I9: =Evaluation!I22 -> 101839 | ... L9: =Evaluation!L22 -> 105877 | M9: Bids as Written
A10: Corrected extensions | B10: =Evaluation!B14 -> 96074 | C10: =Evaluation!C14 -> 98095 | D10: =Evaluation!D14 -> 99008 | E10: =Evaluation!E14 -> 98076 | F10: =Evaluation!F14 -> 99164 | G10: =Evaluation!G14 -> 93002 | H10: =Evaluation!H14 -> 97842 | I10: =Evaluation!I14 -> 98109 | ... L10: =Evaluation!L14 -> 104177 | M10: Evaluation
A11: Tooling | B11: =Evaluation!B15 -> 1500 | C11: =Evaluation!C15 -> 1950 | D11: =Evaluation!D15 -> 1600 | E11: =Evaluation!E15 -> 1800 | F11: =Evaluation!F15 -> 2050 | G11: =Evaluation!G15 -> 1900 | H11: =Evaluation!H15 -> 1725 | I11: =Evaluation!I15 -> 1850 | ... L11: =Evaluation!L15 -> 1700 | M11: Evaluation
A12: Freight added, FOB origin | B12: =Evaluation!B17 -> 0 | C12: =Evaluation!C17 -> 0 | D12: =Evaluation!D17 -> 0 | E12: =Evaluation!E17 -> 0 | F12: =Evaluation!F17 -> 0 | G12: =Evaluation!G17 -> 4991.2 | H12: =Evaluation!H17 -> 0 | I12: =Evaluation!I17 -> 0 | ... L12: =Evaluation!L17 -> 0 | M12: Evaluation
A13: Payment discount credit | B13: =Evaluation!B20 -> 0 | C13: =Evaluation!C20 -> 980.95 | D13: =Evaluation!D20 -> 1980.16 | E13: =Evaluation!E20 -> 980.76 | F13: =Evaluation!F20 -> 1983.28 | G13: =Evaluation!G20 -> 930.02 | H13: =Evaluation!H20 -> 0 | I13: =Evaluation!I20 -> 0 | ... L13: =Evaluation!L20 -> 2083.54 | M13: Evaluation
A14: Total evaluated price | B14: =Evaluation!B21 -> 97574 | C14: =Evaluation!C21 -> 99064.05 | D14: =Evaluation!D21 -> 98627.84 | E14: =Evaluation!E21 -> 98895.24 | F14: =Evaluation!F21 -> 99230.72 | G14: =Evaluation!G21 -> 98963.18 | H14: =Evaluation!H21 -> 99567 | I14: =Evaluation!I21 -> 99959 | ... L14: =Evaluation!L21 -> 103793.46 | M14: Evaluation
A15: Order in line among responsive bids, 5.1 and 5.6 | B15: =Evaluation!B25 -> Set aside | C15: =Evaluation!C25 -> Set aside | D15: =Evaluation!D25 -> Set aside | E15: =Evaluation!E25 -> Set aside | F15: =Evaluation!F25 -> 1 | G15: =Evaluation!G25 -> Set aside | H15: =Evaluation!H25 -> Set aside | I15: =Evaluation!I25 -> 2 | ... L15: =Evaluation!L25 -> 4 | M15: Evaluation
A16: Bid received | B16: =INDEX('Bid Receipt'!$D$4:$D$14,1)&" "&INDEX('Bid Receipt'!$E$4:$E$14,1) -> 10/05/2026 16:02 | C16: =INDEX('Bid Receipt'!$D$4:$D$14,2)&" "&INDEX('Bid Receipt'!$E$4:$E$14,2) -> 10/06/2026 09:33 | D16: =INDEX('Bid Receipt'!$D$4:$D$14,3)&" "&INDEX('Bid Receipt'!$E$4:$E$14,3) -> 10/06/2026 09:58 | E16: =INDEX('Bid Receipt'!$D$4:$D$14,4)&" "&INDEX('Bid Receipt'!$E$4:$E$14,4) -> 10/02/2026 09:47 | F16: =INDEX('Bid Receipt'!$D$4:$D$14,5)&" "&INDEX('Bid Receipt'!$E$4:$E$14,5) -> 10/06/2026 10:00 | G16: =INDEX('Bid Receipt'!$D$4:$D$14,6)&" "&INDEX('Bid Receipt'!$E$4:$E$14,6) -> 10/06/2026 09:05 | H16: =INDEX('Bid Receipt'!$D$4:$D$14,7)&" "&INDEX('Bid Receipt'!$E$4:$E$14,7) -> 10/06/2026 08:52 | I16: =INDEX('Bid Receipt'!$D$4:$D$14,8)&" "&INDEX('Bid Receipt'!$E$4:$E$14,8) -> 10/05/2026 11:37 | J16: =INDEX('Bid Receipt'!$D$4:$D$14,9)&" "&INDEX('Bid Receipt'!$E$4:$E$14,9) -> 10/06/2026 08:15 | K16: =INDEX('Bid Receipt'!$D$4:$D$14,10)&" "&INDEX('Bid Receipt'!$E$4:$E$14,10) -> 10/06/2026 09:27 | L16: =INDEX('Bid Receipt'!$D$4:$D$14,11)&" "&INDEX('Bid Receipt'!$E$4:$E$14,11) -> 10/06/2026 09:41 | M16: Bid Receipt
A18: Award
A19: Recommended award | B19: =Responsibility!B18 -> Pemberton Container | M19: Responsibility
A20: Recommended award, total evaluated price | B20: =Responsibility!B19 -> 99959 | M20: Responsibility
A21: Approver required by PP-3.5.3 | B21: =Evaluation!B32 -> Director of supply chain | M21: Evaluation
A22: Next responsive bidder in line | B22: =Responsibility!B20 -> Ridgecrest Packaging | M22: Responsibility
A23: Next bidder in line, total evaluated price | B23: =Responsibility!B21 -> 99927.25 | M23: Responsibility
A24: Recommended award above the next bid in line by | B24: =Responsibility!B22 -> 31.75 | M24: Responsibility
A25: Order between the two bids rests on | B25: =Responsibility!B23 -> 5.6, within $100 of each other, the bid received first prevails | M25: Responsibility
A26: Recommended bid received | B26: =Responsibility!B24 -> 10/05/2026 11:37 | M26: Bid Receipt
A27: Next bid in line received | B27: =Responsibility!B25 -> 10/06/2026 08:15 | M27: Bid Receipt
A28: Responsive bids | B28: =Responsiveness!B16 -> 4 | M28: Responsiveness
A29: Bids set aside as non-responsive | B29: =Responsiveness!B17 -> 7 | M29: Responsiveness
A30: Responsive bid passed over, open quality hold | B30: =Responsibility!B26 -> Loken & Vik Container | M30: Responsibility
A31: Passed-over bid, total evaluated price | B31: =Responsibility!B27 -> 99230.72 | M31: Responsibility
A32: Passed-over bid below the recommended award by | B32: =Responsibility!B28 -> 728.28 | M32: Responsibility
A33: Lowest bid as written | B33: =Evaluation!B31 -> Ridgecrest Packaging | M33: Evaluation
A34: Extensions corrected for arithmetic or quantity | B34: =Extensions!H59 -> 2 | M34: Extensions
A35: Extension corrected on the recommended bid, as written | B35: =Extensions!F40 -> 26912 | M35: Extensions
A36: Extension corrected on the recommended bid, corrected | B36: =Extensions!G40 -> 26112 | M36: Extensions
A37: Unit price changes applied from a timely signed modification | B37: ='Later Writings'!B21 -> 1 | M37: Later Writings
A38: Unit price changes not considered under section 3.4 | B38: ='Later Writings'!B22 -> 6 | M38: Later Writings
A40: Award is by lot to the responsive and responsible bidder first in the order of 5.1 and 5.6, checked under PP-3.7.1; every figure on this page reads from the tab named beside it.
A41: The award value is at or under one hundred thousand dollars, so PP-3.5.3 places the approval with the director of supply chain; the signature line below follows the policy.
A43: Recommended by | B43: Purchasing manager | C43: Signature: ______________________ | D43: Date: ____________
A44: Approved | B44: Director of supply chain | C44: Signature: ______________________ | D44: Date: ____________

Sheet Parameters
A1: Terms the evaluation applies, from ITB 2026-17 as amended and policy PP-3
A3: Term | B3: Value | C3: Source
A4: Discount period floor for a credit (days) | B4: 20 | C4: section 5.5
A5: Approval threshold, vice president above (dollars) | B5: 100000 | C5: PP-3.5.3
A6: Price hold required (months from award) | B6: 12 | C6: section 4.3
A7: Band on total evaluated price inside which the bid received first prevails (dollars) | B7: 100 | C7: 5.6
A8: Pounds per hundredweight | B8: 100 | C8: section 5.4
A9: Addendum that must be acknowledged | B9: 2 | C9: Addendum 2; section 3.2
A10: Item 3 quantity superseded by addendum 2 | B10: 36000 | C10: section 2; Addendum 2 change 1
A11: Bid security, share of the total bid as written | B11: 0.05 | C11: section 3.2; Addendum 2
A12: Bid due time as a log key, year month day hour minute | B12: 202610061000 | C12: section 3.1; section 3.4
A14: Item | B14: Quantity, addendum 2 | C14: Source
A15: 1 | B15: 45000 | C15: section 2
A16: 2 | B16: 64000 | C16: section 2
A17: 3 | B17: 27000 | C17: Addendum 2 change 1
A18: 4 | B18: 9000 | C18: section 2
A19: 5 | B19: 24000 | C19: section 2

Sheet Bids as Written
A1: Bids as written on the signed bid forms in bid_forms_itb_2026_17.docx; eleven bids in alphabetical order
A4: ITEM | B4: DESCRIPTION | C4: BRANNOCK_UNIT | D4: BRANNOCK_EXTENSION | E4: DAHLGREN_UNIT | F4: DAHLGREN_EXTENSION | G4: HALVARD_UNIT | H4: HALVARD_EXTENSION | I4: KESSEL_UNIT | J4: KESSEL_EXTENSION | K4: LOKEN_VIK_UNIT | L4: LOKEN_VIK_EXTENSION | M4: MESABI_UNIT | N4: MESABI_EXTENSION | O4: OTTER_TAIL_UNIT | P4: OTTER_TAIL_EXTENSION | Q4: PEMBERTON_UNIT | R4: PEMBERTON_EXTENSION | S4: RIDGECREST_UNIT | T4: RIDGECREST_EXTENSION | U4: THORSGARD_UNIT | V4: THORSGARD_EXTENSION | W4: WENZEL_KRAUSE_UNIT | X4: WENZEL_KRAUSE_EXTENSION
A5: 1 | B5: RSC 24 x 18 x 12, 200 lb test C flute, kraft, unprinted | C5: 0.571 | D5: 25695 | E5: 0.591 | F5: 26595 | G5: 0.594 | H5: 26730 | I5: 0.59 | J5: 26550 | K5: 0.598 | L5: 26910 | M5: 0.562 | N5: 25290 | O5: 0.583 | P5: 26235 | Q5: 0.602 | R5: 27090 | S5: 0.546 | T5: 24570 | U5: 0.604 | V5: 27180 | W5: 0.628 | X5: 28260
A6: 2 | B6: RSC 18 x 12 x 10, 32 ECT B flute, kraft, unprinted | C6: 0.398 | D6: 25472 | E6: 0.397 | F6: 25408 | G6: 0.404 | H6: 25856 | I6: 0.402 | J6: 25728 | K6: 0.401 | L6: 25664 | M6: 0.386 | N6: 24704 | O6: 0.399 | P6: 25536 | Q6: 0.408 | R6: 26912 | S6: 0.37 | T6: 23680 | U6: 0.407 | V6: 26048 | W6: 0.428 | X6: 27392
A7: 3 | B7: Die-cut mailer 12 x 9 x 4, 32 ECT E flute, white, unprinted | C7: 0.276 | D7: 9936 | E7: 0.284 | F7: 7668 | G7: 0.288 | H7: 7776 | I7: 0.285 | J7: 7695 | K7: 0.287 | L7: 7749 | M7: 0.268 | N7: 7236 | O7: 0.283 | P7: 7641 | Q7: 0.289 | R7: 7803 | S7: 0.262 | T7: 7074 | U7: 0.281 | V7: 7587 | W7: 0.301 | X7: 8127
A8: 4 | B8: RSC 36 x 24 x 24, 275 lb test doublewall, kraft, unprinted | C8: 1.655 | D8: 14895 | E8: 1.688 | F8: 15192 | G8: 1.702 | H8: 15318 | I8: 1.679 | J8: 15111 | K8: 1.713 | L8: 15417 | M8: 1.548 | N8: 13932 | O8: 1.694 | P8: 15246 | Q8: 1.704 | R8: 15336 | S8: 1.575 | T8: 14175 | U8: 1.699 | V8: 15291 | W8: 1.79 | X8: 16110
A9: 5 | B9: RSC 20 x 20 x 20, 44 ECT C flute, kraft, two-color print | C9: 0.94 | D9: 22560 | E9: 0.968 | F9: 23232 | G9: 0.972 | H9: 23328 | I9: 0.958 | J9: 22992 | K9: 0.976 | L9: 23424 | M9: 0.91 | N9: 21840 | O9: 0.966 | P9: 23184 | Q9: 0.952 | R9: 22848 | S9: 0.9 | T9: 21600 | U9: 0.963 | V9: 23112 | W9: 1.012 | X9: 24288
A10: Tooling, plates and dies, one time | D10: 1500 | F10: 1950 | H10: 1600 | J10: 1800 | L10: 2050 | N10: 1900 | P10: 1725 | R10: 1850 | T10: 2400 | V10: 1650 | X10: 1700
A11: Total bid as written | D11: =SUM(D5:D10) -> 100058 | F11: =SUM(F5:F10) -> 100045 | H11: =SUM(H5:H10) -> 100608 | J11: =SUM(J5:J10) -> 99876 | L11: =SUM(L5:L10) -> 101214 | N11: =SUM(N5:N10) -> 94902 | P11: =SUM(P5:P10) -> 99567 | R11: =SUM(R5:R10) -> 101839 | T11: =SUM(T5:T10) -> 93499 | V11: =SUM(V5:V10) -> 100868 | X11: =SUM(X5:X10) -> 105877
A13: The unit prices are read from the signed forms, which PP-3.4.2 makes the bid. The tabulation as opened keys Ridgecrest's item 4 unit price as 1.557 where the signed form reads 1.575; the form's extension of 14,175.00 agrees with 1.575, and the form governs.

Sheet Terms
A1: Bidder terms and submittals as marked on the bid forms, with the plant that ships each item
A3: BIDDER | B3: PLANT_CITY | C3: PLANT_STATE | D3: FOB_TERMS | E3: PAYMENT_TERMS | F3: BID_SECURITY_ENCLOSED | G3: SECURITY_FORM | H3: ADDENDA_ACKNOWLEDGED | I3: SAMPLES_RECEIVED | J3: SHIPPING_PLANT_BY_ITEM
A4: Brannock Box Company | B4: Rockford | C4: IL | D4: Destination | E4: Net 30 | F4: Yes | G4: Surety bond | H4: 1 | I4: Yes | J4: All items Rockford, IL
A5: Dahlgren Paper Box Co. | B5: St. Cloud | C5: MN | D5: Destination | E5: 1% 30, net 45 | F5: Yes | G5: Cashier's check, $4,904.75, no. 20871 | H5: 1, 2 | I5: Yes | J5: All items St. Cloud, MN
A6: Halvard Corrugated | B6: Fargo | C6: ND | D6: Destination | E6: 2% 30, net 60 | F6: Yes | G6: Surety bond | H6: 1, 2 | I6: Yes | J6: All items Fargo, ND
A7: Kessel Container Corp. | B7: Des Moines | C7: IA | D7: Destination | E7: 1% 20, net 30 | F7: Yes | G7: Surety bond | H7: 1, 2 | I7: Yes | J7: All items Des Moines, IA
A8: Loken & Vik Container | B8: Sioux Falls | C8: SD | D8: Destination | E8: 2% 20, net 45 | F8: Yes | G8: Cashier's check, $5,060.70, no. 4471820 | H8: 1, 2 | I8: Yes | J8: All items Sioux Falls, SD
A9: Mesabi Container Co. | B9: Duluth | C9: MN | D9: Origin, Duluth plant | E9: 1% 20, net 30 | F9: Yes | G9: Surety bond | H9: 1, 2 | I9: Yes | J9: All items Duluth, MN (FOB origin)
A10: Otter Tail Corrugated | B10: Fergus Falls | C10: MN | D10: Destination | E10: 1% 15, net 30 | F10: Yes | G10: Surety bond | H10: 1, 2 | I10: Yes | J10: All items Fergus Falls, MN
A11: Pemberton Container | B11: Neenah | C11: WI | D11: Destination | E11: 2% 10, net 30 | F11: Yes | G11: Surety bond | H11: 1, 2 | I11: Yes | J11: All items Neenah, WI
A12: Ridgecrest Packaging | B12: Cedar Rapids | C12: IA | D12: Origin, shipping plant | E12: 1% 20, net 45 | F12: Yes | G12: Surety bond | H12: 1, 2 | I12: Yes | J12: Items 1 to 4 Cedar Rapids, IA; item 5 Omaha, NE
A13: Thorsgard Box & Label | B13: Moorhead | C13: MN | D13: Destination | E13: 2% 25, net 45 | F13: Yes | G13: Surety bond | H13: 1, 2 | I13: Yes | J13: All items Moorhead, MN
A14: Wenzel & Krause Corrugated | B14: La Crosse | C14: WI | D14: Destination | E14: 2% 20, net 30 | F14: Yes | G14: Cashier's check, $5,300.00, no. 553106 | H14: 1, 2 | I14: Yes | J14: All items La Crosse, WI

Sheet Bid Conditions
A1: Pricing conditions, exceptions and alternates read from each bid form and letter in bid_forms_itb_2026_17.docx
A3: BIDDER | B3: CONDITION_AS_STATED | C3: TERM_AFFECTED | D3: MATERIAL_TERM_EXCEPTION | E3: RULE_APPLIED | F3: PRICES_FIRM_THROUGH
A4: =Terms!A4 -> Brannock Box Company | B4: None stated; the form acknowledges addendum 1 only and prices item 3 at 36,000 with item 5 on 32 ECT board | C4: Quantity and specification as amended | D4: No | E4: Handled under addendum 2 and PP-3.4.5 on the Responsiveness tab, not as an exception | F4: Twelve months from award
A5: =Terms!A5 -> Dahlgren Paper Box Co. | B5: None; releases taken in any pallet quantity | C5: None | D5: No | E5: No condition on price, quantity, quality, delivery or FOB terms; the bid security is tested on the Bid Security tab | F5: Twelve months from award
A6: =Terms!A6 -> Halvard Corrugated | B6: Prices held firm for six months from award, then adjusted quarterly to the Pulp and Paper Week 42 lb kraft linerboard index | C6: Price hold, section 4.3 | D6: Yes | E6: section 4.3; section 5.2; addendum 2 answer on a shorter hold or an index; PP-3.4.4 | F6: Twelve months from award
A7: =Terms!A7 -> Kessel Container Corp. | B7: None; prices hold through December 31, 2027, which runs past twelve months from any award this year | C7: None | D7: No | E7: The hold meets section 4.3; the item 2 description is tested on the Responsiveness tab under PP-3.4.5 | F7: 12/31/2027
A8: =Terms!A8 -> Loken & Vik Container | B8: None; releases requested at least ten working days ahead of delivery | C8: None | D8: No | E8: A scheduling request, not a condition on price, quantity, quality, delivery or FOB terms | F8: Twelve months from award
A9: =Terms!A9 -> Mesabi Container Co. | B9: Item 4 offered on 200 lb test doublewall only, the Duluth plant not running 275 lb test; FOB origin, all five items from Duluth | C9: Item as specified, section 5.2; alternate under 4.4 | D9: No | E9: No bid on item 4 as specified; the alternate cannot stand alone under 4.4 and the addendum 2 answer, tested on the Responsiveness tab under 5.2. Freight is added under section 5.4 at the Minnesota rate | F9: Twelve months from award
A10: =Terms!A10 -> Otter Tail Corrugated | B10: Pricing assumes releases in full truckload quantities of 26 pallets; a release below a full truckload carries a $185 stop charge; the form box reads None | C10: Quantity, releases in pallet multiples, section 1 | D10: Yes | E10: section 5.2; addendum 2 answer on truckload releases; PP-3.4.4; the letter of October 8 reached the office after the due time, section 3.4 | F10: Twelve months from award
A11: =Terms!A11 -> Pemberton Container | B11: Alternate for item 4 at 200 lb test doublewall, $1.512 per carton, beside the bid on the item as specified | C11: None; an alternate under section 4.4 | D11: No | E11: section 4.4; the alternate is not evaluated for award | F11: Twelve months from award
A12: =Terms!A12 -> Ridgecrest Packaging | B12: None; FOB origin, items 1 to 4 shipped from Cedar Rapids and item 5 from Omaha; tooling credited back if the award arrives by October 30 | C12: FOB terms as permitted by 3.3 | D12: No | E12: 3.3; freight added under section 5.4; the tooling credit is not an adjustment the invitation names, so tooling is added in full, 4.2 and PP-3.4.3 | F12: Twelve months from award
A13: =Terms!A13 -> Thorsgard Box & Label | B13: Prices firm through September 30, 2027; the form box reads Yes to twelve months from award | C13: Price hold, section 4.3 | D13: Yes | E13: section 4.3; section 5.2; PP-3.4.4; twelve months from an award made after the October 6, 2026 opening runs past September 30, 2027 | F13: 09/30/2027
A14: =Terms!A14 -> Wenzel & Krause Corrugated | B14: None; the letter follows the linerboard index and holds prices firm for twelve months whatever the index does, and offers stock holding after award that the prices do not depend on | C14: None | D14: No | E14: Prices are not conditioned on the index or on the stock offer, section 4.3 | F14: Twelve months from award
A16: A condition is a material term exception where it would change price, price hold, quantity, quality, delivery or FOB terms, PP-3.4.4; the buyer does not negotiate it away before award.

Sheet Later Writings
A1: Writings and messages received on the bids other than the bids themselves, from bid_correspondence_itb_2026_17.docx and bid_receipt_log_itb_2026_17.xlsx
A3: BIDDER | B3: WRITING | C3: DATED | D3: LOG_NO | E3: RECEIVED_DATE | F3: RECEIVED_TIME | G3: RECEIVED_KEY | H3: BEFORE_THE_DUE_TIME | I3: SIGNED_WRITING | J3: EFFECT_ON_THE_EVALUATION
A4: Ridgecrest Packaging | B4: Letter withdrawing the bid delivered October 2 | C4: 10/05/2026 | D4: R-1048 | E4: 10/05/2026 | F4: 15:52 | G4: =VALUE(RIGHT(E4,4)&LEFT(E4,2)&MID(E4,4,2)&LEFT(F4,2)&RIGHT(F4,2)) -> 202610051552 | H4: =IF(G4<Parameters!$B$12,"Yes","No") -> Yes | I4: Yes | J4: Bid withdrawn and resubmitted; the bid opened is the one received October 6 at 08:15, section 3.4
A5: Wenzel & Krause Corrugated | B5: Facsimile changing the five unit prices | C5: 10/05/2026 | D5: R-1060 | E5: 10/06/2026 | F5: 10:07 | G5: =VALUE(RIGHT(E5,4)&LEFT(E5,2)&MID(E5,4,2)&LEFT(F5,2)&RIGHT(F5,2)) -> 202610061007 | H5: =IF(G5<Parameters!$B$12,"Yes","No") -> No | I5: Yes | J5: Not considered; the bid stands at its sealed prices, section 3.4
A6: Pemberton Container | B6: Facsimile changing the item 1 unit price | C6: 10/06/2026 | D6: R-1053 | E6: 10/06/2026 | F6: 09:12 | G6: =VALUE(RIGHT(E6,4)&LEFT(E6,2)&MID(E6,4,2)&LEFT(F6,2)&RIGHT(F6,2)) -> 202610060912 | H6: =IF(G6<Parameters!$B$12,"Yes","No") -> Yes | I6: Yes | J6: Applied; item 1 is evaluated at 0.578, and the bid keeps its receipt time, section 3.4
A7: Ridgecrest Packaging | B7: Telephone message asking that item 3 be read at 0.255 | C7: 10/06/2026 | D7: R-1056 | E7: 10/06/2026 | F7: 09:35 | G7: =VALUE(RIGHT(E7,4)&LEFT(E7,2)&MID(E7,4,2)&LEFT(F7,2)&RIGHT(F7,2)) -> 202610060935 | H7: =IF(G7<Parameters!$B$12,"Yes","No") -> Yes | I7: No | J7: Not considered; a modification is a signed writing, section 3.4; item 3 stands at 0.262 on the signed form
A8: Otter Tail Corrugated | B8: Letter withdrawing the stop charge | C8: 10/08/2026 | D8: R-1062 | E8: 10/09/2026 | F8: 11:46 | G8: =VALUE(RIGHT(E8,4)&LEFT(E8,2)&MID(E8,4,2)&LEFT(F8,2)&RIGHT(F8,2)) -> 202610091146 | H8: =IF(G8<Parameters!$B$12,"Yes","No") -> No | I8: Yes | J8: Not considered; the exception in the bid stands, section 3.4 and PP-3.4.4
A9: Loken & Vik Container | B9: Letter on the edge crush complaint, hold QH-26-031 | C9: 10/12/2026 | D9: R-1063 | E9: 10/12/2026 | F9: 16:44 | G9: =VALUE(RIGHT(E9,4)&LEFT(E9,2)&MID(E9,4,2)&LEFT(F9,2)&RIGHT(F9,2)) -> 202610121644 | H9: =IF(G9<Parameters!$B$12,"Yes","No") -> No | I9: Yes | J9: Not a change to the bid; the hold is cleared only by quality engineering, PP-3.7.1
A12: BIDDER | B12: ITEM | C12: UNIT_AS_BID | D12: UNIT_AS_CHANGED | E12: WRITING_ROW | F12: APPLIED | G12: CHANGE_IN_EXTENSION
A13: Pemberton Container | B13: 1 | C13: 0.602 | D13: 0.578 | E13: 6 | F13: =IF(AND(INDEX($H$4:$H$9,E13-3)="Yes",INDEX($I$4:$I$9,E13-3)="Yes"),"Yes","No") -> Yes | G13: =ROUND((D13-C13)*INDEX(Parameters!$B$15:$B$19,B13),2) -> -1080
A14: Ridgecrest Packaging | B14: 3 | C14: 0.262 | D14: 0.255 | E14: 7 | F14: =IF(AND(INDEX($H$4:$H$9,E14-3)="Yes",INDEX($I$4:$I$9,E14-3)="Yes"),"Yes","No") -> No | G14: =ROUND((D14-C14)*INDEX(Parameters!$B$15:$B$19,B14),2) -> -189
A15: Wenzel & Krause Corrugated | B15: 1 | C15: 0.628 | D15: 0.598 | E15: 5 | F15: =IF(AND(INDEX($H$4:$H$9,E15-3)="Yes",INDEX($I$4:$I$9,E15-3)="Yes"),"Yes","No") -> No | G15: =ROUND((D15-C15)*INDEX(Parameters!$B$15:$B$19,B15),2) -> -1350
A16: Wenzel & Krause Corrugated | B16: 2 | C16: 0.428 | D16: 0.403 | E16: 5 | F16: =IF(AND(INDEX($H$4:$H$9,E16-3)="Yes",INDEX($I$4:$I$9,E16-3)="Yes"),"Yes","No") -> No | G16: =ROUND((D16-C16)*INDEX(Parameters!$B$15:$B$19,B16),2) -> -1600
A17: Wenzel & Krause Corrugated | B17: 3 | C17: 0.301 | D17: 0.286 | E17: 5 | F17: =IF(AND(INDEX($H$4:$H$9,E17-3)="Yes",INDEX($I$4:$I$9,E17-3)="Yes"),"Yes","No") -> No | G17: =ROUND((D17-C17)*INDEX(Parameters!$B$15:$B$19,B17),2) -> -405
A18: Wenzel & Krause Corrugated | B18: 4 | C18: 1.79 | D18: 1.7 | E18: 5 | F18: =IF(AND(INDEX($H$4:$H$9,E18-3)="Yes",INDEX($I$4:$I$9,E18-3)="Yes"),"Yes","No") -> No | G18: =ROUND((D18-C18)*INDEX(Parameters!$B$15:$B$19,B18),2) -> -810
A19: Wenzel & Krause Corrugated | B19: 5 | C19: 1.012 | D19: 0.962 | E19: 5 | F19: =IF(AND(INDEX($H$4:$H$9,E19-3)="Yes",INDEX($I$4:$I$9,E19-3)="Yes"),"Yes","No") -> No | G19: =ROUND((D19-C19)*INDEX(Parameters!$B$15:$B$19,B19),2) -> -1200
A21: Unit price changes applied | B21: =COUNTIF(F13:F19,"Yes") -> 1
A22: Unit price changes not considered | B22: =COUNTIF(F13:F19,"No") -> 6
A24: A modification counts when it is a signed writing that reaches the purchasing office before 10:00 on October 6, whatever date it carries, section 3.4. The Wenzel & Krause facsimile is dated October 5 and came off the machine at 10:07 on October 6. The telephone message from Ridgecrest at 09:35 is not a writing. The log enters the facsimiles and the message under the names of the people who sent them.

Sheet Bid Security
A1: Bid security against five percent of the total bid as written, section 3.2 and addendum 2
A3: BIDDER | B3: SECURITY_FORM | C3: AMOUNT_STATED | D3: TOTAL_BID_AS_WRITTEN | E3: FIVE_PERCENT_REQUIRED | F3: SHORT_BY | G3: MEETS_SECTION_3.2
A4: =Terms!A4 -> Brannock Box Company | B4: =Terms!G4 -> Surety bond | D4: ='Bids as Written'!D11 -> 100058 | E4: =ROUND(D4*Parameters!$B$11,2) -> 5002.9 | F4: =IF(C4="",0,MAX(0,ROUND(E4-C4,2))) -> 0 | G4: =IF(Terms!F4<>"Yes","No",IF(F4>0,"No, short","Yes")) -> Yes
A5: =Terms!A5 -> Dahlgren Paper Box Co. | B5: =Terms!G5 -> Cashier's check, $4,904.75, no. 20871 | C5: 4904.75 | D5: ='Bids as Written'!F11 -> 100045 | E5: =ROUND(D5*Parameters!$B$11,2) -> 5002.25 | F5: =IF(C5="",0,MAX(0,ROUND(E5-C5,2))) -> 97.5 | G5: =IF(Terms!F5<>"Yes","No",IF(F5>0,"No, short","Yes")) -> No, short
A6: =Terms!A6 -> Halvard Corrugated | B6: =Terms!G6 -> Surety bond | D6: ='Bids as Written'!H11 -> 100608 | E6: =ROUND(D6*Parameters!$B$11,2) -> 5030.4 | F6: =IF(C6="",0,MAX(0,ROUND(E6-C6,2))) -> 0 | G6: =IF(Terms!F6<>"Yes","No",IF(F6>0,"No, short","Yes")) -> Yes
A7: =Terms!A7 -> Kessel Container Corp. | B7: =Terms!G7 -> Surety bond | D7: ='Bids as Written'!J11 -> 99876 | E7: =ROUND(D7*Parameters!$B$11,2) -> 4993.8 | F7: =IF(C7="",0,MAX(0,ROUND(E7-C7,2))) -> 0 | G7: =IF(Terms!F7<>"Yes","No",IF(F7>0,"No, short","Yes")) -> Yes
A8: =Terms!A8 -> Loken & Vik Container | B8: =Terms!G8 -> Cashier's check, $5,060.70, no. 4471820 | C8: 5060.7 | D8: ='Bids as Written'!L11 -> 101214 | E8: =ROUND(D8*Parameters!$B$11,2) -> 5060.7 | F8: =IF(C8="",0,MAX(0,ROUND(E8-C8,2))) -> 0 | G8: =IF(Terms!F8<>"Yes","No",IF(F8>0,"No, short","Yes")) -> Yes
A9: =Terms!A9 -> Mesabi Container Co. | B9: =Terms!G9 -> Surety bond | D9: ='Bids as Written'!N11 -> 94902 | E9: =ROUND(D9*Parameters!$B$11,2) -> 4745.1 | F9: =IF(C9="",0,MAX(0,ROUND(E9-C9,2))) -> 0 | G9: =IF(Terms!F9<>"Yes","No",IF(F9>0,"No, short","Yes")) -> Yes
A10: =Terms!A10 -> Otter Tail Corrugated | B10: =Terms!G10 -> Surety bond | D10: ='Bids as Written'!P11 -> 99567 | E10: =ROUND(D10*Parameters!$B$11,2) -> 4978.35 | F10: =IF(C10="",0,MAX(0,ROUND(E10-C10,2))) -> 0 | G10: =IF(Terms!F10<>"Yes","No",IF(F10>0,"No, short","Yes")) -> Yes
A11: =Terms!A11 -> Pemberton Container | B11: =Terms!G11 -> Surety bond | D11: ='Bids as Written'!R11 -> 101839 | E11: =ROUND(D11*Parameters!$B$11,2) -> 5091.95 | F11: =IF(C11="",0,MAX(0,ROUND(E11-C11,2))) -> 0 | G11: =IF(Terms!F11<>"Yes","No",IF(F11>0,"No, short","Yes")) -> Yes
A12: =Terms!A12 -> Ridgecrest Packaging | B12: =Terms!G12 -> Surety bond | D12: ='Bids as Written'!T11 -> 93499 | E12: =ROUND(D12*Parameters!$B$11,2) -> 4674.95 | F12: =IF(C12="",0,MAX(0,ROUND(E12-C12,2))) -> 0 | G12: =IF(Terms!F12<>"Yes","No",IF(F12>0,"No, short","Yes")) -> Yes
A13: =Terms!A13 -> Thorsgard Box & Label | B13: =Terms!G13 -> Surety bond | D13: ='Bids as Written'!V11 -> 100868 | E13: =ROUND(D13*Parameters!$B$11,2) -> 5043.4 | F13: =IF(C13="",0,MAX(0,ROUND(E13-C13,2))) -> 0 | G13: =IF(Terms!F13<>"Yes","No",IF(F13>0,"No, short","Yes")) -> Yes
A14: =Terms!A14 -> Wenzel & Krause Corrugated | B14: =Terms!G14 -> Cashier's check, $5,300.00, no. 553106 | C14: 5300 | D14: ='Bids as Written'!X11 -> 105877 | E14: =ROUND(D14*Parameters!$B$11,2) -> 5293.85 | F14: =IF(C14="",0,MAX(0,ROUND(E14-C14,2))) -> 0 | G14: =IF(Terms!F14<>"Yes","No",IF(F14>0,"No, short","Yes")) -> Yes
A16: A surety bond is written at five percent of the total bid and meets section 3.2 at any total. A cashier's check is a fixed amount and is tested against five percent of the total bid as written, tooling included, per addendum 2.

Sheet Bid Receipt
A1: When each bid that was opened reached the purchasing office, from bid_receipt_log_itb_2026_17.xlsx
A3: BIDDER | B3: NAME_IN_THE_LOG | C3: LOG_NO | D3: RECEIVED_DATE | E3: RECEIVED_TIME | F3: RECEIVED_KEY | G3: NOTE
A4: =Terms!A4 -> Brannock Box Company | B4: Brannock Box | C4: R-1049 | D4: 10/05/2026 | E4: 16:02 | F4: =VALUE(RIGHT(D4,4)&LEFT(D4,2)&MID(D4,4,2)&LEFT(E4,2)&RIGHT(E4,2)) -> 202610051602
A5: =Terms!A5 -> Dahlgren Paper Box Co. | B5: Dahlgren Box, St. Cloud | C5: R-1055 | D5: 10/06/2026 | E5: 09:33 | F5: =VALUE(RIGHT(D5,4)&LEFT(D5,2)&MID(D5,4,2)&LEFT(E5,2)&RIGHT(E5,2)) -> 202610060933
A6: =Terms!A6 -> Halvard Corrugated | B6: Halvard | C6: R-1058 | D6: 10/06/2026 | E6: 09:58 | F6: =VALUE(RIGHT(D6,4)&LEFT(D6,2)&MID(D6,4,2)&LEFT(E6,2)&RIGHT(E6,2)) -> 202610060958
A7: =Terms!A7 -> Kessel Container Corp. | B7: Kessel Container, Des Moines | C7: R-1040 | D7: 10/02/2026 | E7: 09:47 | F7: =VALUE(RIGHT(D7,4)&LEFT(D7,2)&MID(D7,4,2)&LEFT(E7,2)&RIGHT(E7,2)) -> 202610020947
A8: =Terms!A8 -> Loken & Vik Container | B8: Loken & Vik | C8: R-1059 | D8: 10/06/2026 | E8: 10:00 | F8: =VALUE(RIGHT(D8,4)&LEFT(D8,2)&MID(D8,4,2)&LEFT(E8,2)&RIGHT(E8,2)) -> 202610061000 | G8: Handed over at 10:00, the due time; a bid is due by 10:00 and only a bid received after that time goes back unopened, section 3.1
A9: =Terms!A9 -> Mesabi Container Co. | B9: Mesabi Container, Duluth | C9: R-1052 | D9: 10/06/2026 | E9: 09:05 | F9: =VALUE(RIGHT(D9,4)&LEFT(D9,2)&MID(D9,4,2)&LEFT(E9,2)&RIGHT(E9,2)) -> 202610060905
A10: =Terms!A10 -> Otter Tail Corrugated | B10: Otter Tail Corr. | C10: R-1051 | D10: 10/06/2026 | E10: 08:52 | F10: =VALUE(RIGHT(D10,4)&LEFT(D10,2)&MID(D10,4,2)&LEFT(E10,2)&RIGHT(E10,2)) -> 202610060852
A11: =Terms!A11 -> Pemberton Container | B11: Pemberton, Neenah | C11: R-1047 | D11: 10/05/2026 | E11: 11:37 | F11: =VALUE(RIGHT(D11,4)&LEFT(D11,2)&MID(D11,4,2)&LEFT(E11,2)&RIGHT(E11,2)) -> 202610051137 | G11: The facsimile of October 6 changes the bid and leaves this receipt time, section 3.4
A12: =Terms!A12 -> Ridgecrest Packaging | B12: A. Delaney | C12: R-1050 | D12: 10/06/2026 | E12: 08:15 | F12: =VALUE(RIGHT(D12,4)&LEFT(D12,2)&MID(D12,4,2)&LEFT(E12,2)&RIGHT(E12,2)) -> 202610060815 | G12: The envelope logged R-1041 on 10/02/2026 was withdrawn and handed back under R-1048; the bid opened is the resubmitted one, section 3.4
A13: =Terms!A13 -> Thorsgard Box & Label | B13: Thorsgard, Moorhead | C13: R-1054 | D13: 10/06/2026 | E13: 09:27 | F13: =VALUE(RIGHT(D13,4)&LEFT(D13,2)&MID(D13,4,2)&LEFT(E13,2)&RIGHT(E13,2)) -> 202610060927
A14: =Terms!A14 -> Wenzel & Krause Corrugated | B14: W & K Corrugated, La Crosse | C14: R-1057 | D14: 10/06/2026 | E14: 09:41 | F14: =VALUE(RIGHT(D14,4)&LEFT(D14,2)&MID(D14,4,2)&LEFT(E14,2)&RIGHT(E14,2)) -> 202610060941
A16: Bids received by the due time | B16: =COUNTIF(F4:F14,"<="&Parameters!$B$12) -> 11
A18: A twelfth envelope, from Siouxland Container, reached the office at 10:22 on October 6 and went back unopened under section 3.1; it is not a bid in this evaluation. Loken & Vik's envelope was handed over at 10:00, which section 3.1 makes the last minute a bid is due, and it was opened.

Sheet Holds on Bidders
A1: Quality holds recorded against any bidder in supplier_quality_holds_2026.xlsx, matched to the bidder by name, with clearances since the extract
A3: HOLD_NO | B3: SUPPLIER_AS_REGISTERED | C3: BIDDER | D3: COMMODITY | E3: OPENED | F3: STATUS_IN_THE_EXTRACT | G3: CLEARED | H3: SOURCE_OF_THE_CLEARANCE | I3: STATUS_AT_RECOMMENDATION
A4: QH-25-024 | B4: Halvard Corrugated | C4: Halvard Corrugated | D4: Corrugated, RSC 30 x 20 x 16 | E4: 10/08/2025 | F4: Cleared | G4: 11/04/2025 | H4: Register extract of October 7 | I4: =IF(G4="","Open","Cleared") -> Cleared
A5: QH-26-009 | B5: Pemberton Container | C5: Pemberton Container | D5: Corrugated, RSC 24 x 18 x 12 | E5: 03/04/2026 | F5: Cleared | G5: 05/12/2026 | H5: Register extract of October 7 | I5: =IF(G5="","Open","Cleared") -> Cleared
A6: QH-26-031 | B6: Loken & Vik Container Corp. | C6: Loken & Vik Container | D6: Corrugated, RSC 16 x 12 x 8 | E6: 08/27/2026 | F6: Open | H6: None; verification lot not yet run | I6: =IF(G6="","Open","Cleared") -> Open
A7: QH-26-034 | B7: Pemberton Container, Neenah plant | C7: Pemberton Container | D7: Corrugated, RSC 24 x 18 x 12 | E7: 09/10/2026 | F7: Open | G7: 10/15/2026 | H7: Quality engineering clearance notice of October 15 | I7: =IF(G7="","Open","Cleared") -> Cleared
A9: Loken Bros. Pallet & Crate carries an open hold in the register and is a different supplier from Loken & Vik Container. Loken & Vik's letter of October 12 reports its own tests and a verification lot to ship October 27; quality engineering has recorded no clearance of QH-26-031.

Sheet Freight
A1: Freight on the FOB origin bid under 5.4: current item weights, the plant that ships each item, and the schedule rate for that plant's state
A3: ITEM | B3: DRAWING_REV | C3: LB_PER_CARTON | D3: QUANTITY | E3: SHIPPING_LB | F3: HUNDREDWEIGHT | G3: SHIPPING_PLANT | H3: STATE | I3: RATE_PER_CWT | J3: FREIGHT | K3: FOB_ORIGIN_BIDDER | M3: ORIGIN_STATE | N3: RATE_PER_CWT
A4: 1 | B4: NM-CTN-26-01 rev A | C4: 0.9 | D4: =Parameters!B15 -> 45000 | E4: =ROUND(C4*D4,2) -> 40500 | F4: =ROUND(E4/Parameters!$B$8,2) -> 405 | G4: Cedar Rapids | H4: IA | I4: =INDEX($N$4:$N$10,MATCH(H4,$M$4:$M$10,0)) -> 4.87 | J4: =ROUND(F4*I4,2) -> 1972.35 | K4: Ridgecrest Packaging | M4: MN | N4: 3.4
A5: 2 | B5: NM-CTN-26-02 rev B | C5: 0.55 | D5: =Parameters!B16 -> 64000 | E5: =ROUND(C5*D5,2) -> 35200 | F5: =ROUND(E5/Parameters!$B$8,2) -> 352 | G5: Cedar Rapids | H5: IA | I5: =INDEX($N$4:$N$10,MATCH(H5,$M$4:$M$10,0)) -> 4.87 | J5: =ROUND(F5*I5,2) -> 1714.24 | K5: Ridgecrest Packaging | M5: IA | N5: 4.87
A6: 3 | B6: NM-CTN-26-03 rev A | C6: 0.3 | D6: =Parameters!B17 -> 27000 | E6: =ROUND(C6*D6,2) -> 8100 | F6: =ROUND(E6/Parameters!$B$8,2) -> 81 | G6: Cedar Rapids | H6: IA | I6: =INDEX($N$4:$N$10,MATCH(H6,$M$4:$M$10,0)) -> 4.87 | J6: =ROUND(F6*I6,2) -> 394.47 | K6: Ridgecrest Packaging | M6: WI | N6: 5.1
A7: 4 | B7: NM-CTN-26-04 rev A | C7: 2.6 | D7: =Parameters!B18 -> 9000 | E7: =ROUND(C7*D7,2) -> 23400 | F7: =ROUND(E7/Parameters!$B$8,2) -> 234 | G7: Cedar Rapids | H7: IA | I7: =INDEX($N$4:$N$10,MATCH(H7,$M$4:$M$10,0)) -> 4.87 | J7: =ROUND(F7*I7,2) -> 1139.58 | K7: Ridgecrest Packaging | M7: IL | N7: 5.6
A8: 5 | B8: NM-CTN-26-05 rev B | C8: 1.65 | D8: =Parameters!B19 -> 24000 | E8: =ROUND(C8*D8,2) -> 39600 | F8: =ROUND(E8/Parameters!$B$8,2) -> 396 | G8: Omaha | H8: NE | I8: =INDEX($N$4:$N$10,MATCH(H8,$M$4:$M$10,0)) -> 5.35 | J8: =ROUND(F8*I8,2) -> 2118.6 | K8: Ridgecrest Packaging | M8: ND | N8: 4.2
A9: 1 | B9: NM-CTN-26-01 rev A | C9: 0.9 | D9: =Parameters!B15 -> 45000 | E9: =ROUND(C9*D9,2) -> 40500 | F9: =ROUND(E9/Parameters!$B$8,2) -> 405 | G9: Duluth | H9: MN | I9: =INDEX($N$4:$N$10,MATCH(H9,$M$4:$M$10,0)) -> 3.4 | J9: =ROUND(F9*I9,2) -> 1377 | K9: Mesabi Container Co. | M9: SD | N9: 4.6
A10: 2 | B10: NM-CTN-26-02 rev B | C10: 0.55 | D10: =Parameters!B16 -> 64000 | E10: =ROUND(C10*D10,2) -> 35200 | F10: =ROUND(E10/Parameters!$B$8,2) -> 352 | G10: Duluth | H10: MN | I10: =INDEX($N$4:$N$10,MATCH(H10,$M$4:$M$10,0)) -> 3.4 | J10: =ROUND(F10*I10,2) -> 1196.8 | K10: Mesabi Container Co. | M10: NE | N10: 5.35
A11: 3 | B11: NM-CTN-26-03 rev A | C11: 0.3 | D11: =Parameters!B17 -> 27000 | E11: =ROUND(C11*D11,2) -> 8100 | F11: =ROUND(E11/Parameters!$B$8,2) -> 81 | G11: Duluth | H11: MN | I11: =INDEX($N$4:$N$10,MATCH(H11,$M$4:$M$10,0)) -> 3.4 | J11: =ROUND(F11*I11,2) -> 275.4 | K11: Mesabi Container Co.
A12: 4 | B12: NM-CTN-26-04 rev A | C12: 2.6 | D12: =Parameters!B18 -> 9000 | E12: =ROUND(C12*D12,2) -> 23400 | F12: =ROUND(E12/Parameters!$B$8,2) -> 234 | G12: Duluth | H12: MN | I12: =INDEX($N$4:$N$10,MATCH(H12,$M$4:$M$10,0)) -> 3.4 | J12: =ROUND(F12*I12,2) -> 795.6 | K12: Mesabi Container Co.
A13: 5 | B13: NM-CTN-26-05 rev B | C13: 1.65 | D13: =Parameters!B19 -> 24000 | E13: =ROUND(C13*D13,2) -> 39600 | F13: =ROUND(E13/Parameters!$B$8,2) -> 396 | G13: Duluth | H13: MN | I13: =INDEX($N$4:$N$10,MATCH(H13,$M$4:$M$10,0)) -> 3.4 | J13: =ROUND(F13*I13,2) -> 1346.4 | K13: Mesabi Container Co.
A14: Freight on the Ridgecrest bid | J14: =SUMIFS(J4:J13,K4:K13,"Ridgecrest Packaging") -> 7339.24
A15: Freight on the Mesabi bid | J15: =SUMIFS(J4:J13,K4:K13,"Mesabi Container Co.") -> 4991.2
A16: Hundredweight from Cedar Rapids, Iowa | F16: =SUMIFS(F4:F13,H4:H13,"IA") -> 1072
A17: Hundredweight from Omaha, Nebraska | F17: =SUMIFS(F4:F13,H4:H13,"NE") -> 396
A18: Hundredweight from Duluth, Minnesota | F18: =SUMIFS(F4:F13,H4:H13,"MN") -> 1468
A20: Freight for a bid offered FOB origin is each item's hundredweight at the rate for the state of the plant that ships it, per section 5.4; no truckload allowance applies, per addendum 2.
A21: Item 2 is weighed at drawing NM-CTN-26-02 revision B and item 5 at NM-CTN-26-05 revision B, the revisions addenda 1 and 2 put in place; revision A of each, at 0.61 lb and 1.40 lb, is superseded.
A22: Ridgecrest's letter ships items 1 to 4 from Cedar Rapids and item 5 from Omaha, so 1,072 hundredweight is rated at the Iowa rate and 396 hundredweight at the Nebraska rate. Mesabi ships all five items from Duluth, so its 1,468 hundredweight is rated at the Minnesota rate.

Sheet Responsiveness
A1: Responsiveness of each bid under section 3.2, section 4.3, section 4.4, section 5.2 and PP-3.4, decided before price
A3: BIDDER | B3: BID_SECURITY | C3: ADDENDUM_2_ACKNOWLEDGED | D3: SAMPLES | E3: ITEM_3_PRICED_AT_THE_AMENDED_QUANTITY | F3: ITEMS_DESCRIBED_AS_AMENDED | G3: EVERY_ITEM_BID_AS_SPECIFIED | H3: EXCEPTION_TO_A_MATERIAL_TERM | I3: CONDITION_STATED | J3: ALTERNATE_OFFERED | K3: STATUS | L3: REASON
A4: =Terms!A4 -> Brannock Box Company | B4: ='Bid Security'!G4 -> Yes | C4: =IF(ISNUMBER(SEARCH(Parameters!$B$9,Terms!H4)),"Yes","No") -> No | D4: =IF(Terms!I4="Yes","Yes","No") -> Yes | E4: =IF(ROUND('Bids as Written'!D7,2)=ROUND('Bids as Written'!C7*Parameters!$B$10,2),"No, superseded 36,000","Yes") -> No, superseded 36,000 | F4: No, item 5 on 32 ECT | G4: Yes | H4: ='Bid Conditions'!D4 -> No | I4: ='Bid Conditions'!B4 -> None stated; the form acknowledges addendum 1 only and prices item 3 at 36,000 with item 5 on 32 ECT board | J4: =IF(ISNUMBER(SEARCH("lternate",'Bid Conditions'!B4)),"Yes, not evaluated","No") -> No | K4: =IF(AND(B4="Yes",C4="Yes",D4="Yes",LEFT(E4,3)="Yes",F4="Yes",G4="Yes",H4="No"),"Responsive","Non-responsive") -> Non-responsive | L4: =TRIM(IF(B4="No","No bid security, section 3.2. ","")&IF(B4="No, short","Bid security under five percent of the total bid as written, section 3.2 and addendum 2. ","")&IF(C4="No","Addendum 2 not acknowledged, section 3.2; bid on the superseded item 3 quantity and item 5 grade, PP-3.4.5. ","")&IF(D4="No","Samples not received, section 3.2. ","")&IF(AND(C4="Yes",LEFT(E4,2)="No"),"Item 3 priced at the superseded quantity, PP-3.4.5. ","")&IF(AND(C4="Yes",LEFT(F4,2)="No"),"Bid on a superseded specification, "&MID(F4,5,40)&", PP-3.4.5. ","")&IF(LEFT(G4,2)="No","Item 4 offered only as an alternate, with no bid on the item as specified, section 5.2 and 4.4. ","")&IF(H4="Yes","Exception to a material term, "&'Bid Conditions'!C4&", section 5.2 and PP-3.4.4. ","")) -> Addendum 2 not acknowledged, section 3.2; bid on the superseded item 3 quantity and item 5 grade, PP-3.4.5.
A5: =Terms!A5 -> Dahlgren Paper Box Co. | B5: ='Bid Security'!G5 -> No, short | C5: =IF(ISNUMBER(SEARCH(Parameters!$B$9,Terms!H5)),"Yes","No") -> Yes | D5: =IF(Terms!I5="Yes","Yes","No") -> Yes | E5: =IF(ROUND('Bids as Written'!F7,2)=ROUND('Bids as Written'!E7*Parameters!$B$10,2),"No, superseded 36,000","Yes") -> Yes | F5: Yes | G5: Yes | H5: ='Bid Conditions'!D5 -> No | I5: ='Bid Conditions'!B5 -> None; releases taken in any pallet quantity | J5: =IF(ISNUMBER(SEARCH("lternate",'Bid Conditions'!B5)),"Yes, not evaluated","No") -> No | K5: =IF(AND(B5="Yes",C5="Yes",D5="Yes",LEFT(E5,3)="Yes",F5="Yes",G5="Yes",H5="No"),"Responsive","Non-responsive") -> Non-responsive | L5: =TRIM(IF(B5="No","No bid security, section 3.2. ","")&IF(B5="No, short","Bid security under five percent of the total bid as written, section 3.2 and addendum 2. ","")&IF(C5="No","Addendum 2 not acknowledged, section 3.2; bid on the superseded item 3 quantity and item 5 grade, PP-3.4.5. ","")&IF(D5="No","Samples not received, section 3.2. ","")&IF(AND(C5="Yes",LEFT(E5,2)="No"),"Item 3 priced at the superseded quantity, PP-3.4.5. ","")&IF(AND(C5="Yes",LEFT(F5,2)="No"),"Bid on a superseded specification, "&MID(F5,5,40)&", PP-3.4.5. ","")&IF(LEFT(G5,2)="No","Item 4 offered only as an alternate, with no bid on the item as specified, section 5.2 and 4.4. ","")&IF(H5="Yes","Exception to a material term, "&'Bid Conditions'!C5&", section 5.2 and PP-3.4.4. ","")) -> Bid security under five percent of the total bid as written, section 3.2 and addendum 2.
A6: =Terms!A6 -> Halvard Corrugated | B6: ='Bid Security'!G6 -> Yes | C6: =IF(ISNUMBER(SEARCH(Parameters!$B$9,Terms!H6)),"Yes","No") -> Yes | D6: =IF(Terms!I6="Yes","Yes","No") -> Yes | E6: =IF(ROUND('Bids as Written'!H7,2)=ROUND('Bids as Written'!G7*Parameters!$B$10,2),"No, superseded 36,000","Yes") -> Yes | F6: Yes | G6: Yes | H6: ='Bid Conditions'!D6 -> Yes | I6: ='Bid Conditions'!B6 -> Prices held firm for six months from award, then adjusted quarterly to the Pulp and Paper Week 42 lb kraft linerboard index | J6: =IF(ISNUMBER(SEARCH("lternate",'Bid Conditions'!B6)),"Yes, not evaluated","No") -> No | K6: =IF(AND(B6="Yes",C6="Yes",D6="Yes",LEFT(E6,3)="Yes",F6="Yes",G6="Yes",H6="No"),"Responsive","Non-responsive") -> Non-responsive | L6: =TRIM(IF(B6="No","No bid security, section 3.2. ","")&IF(B6="No, short","Bid security under five percent of the total bid as written, section 3.2 and addendum 2. ","")&IF(C6="No","Addendum 2 not acknowledged, section 3.2; bid on the superseded item 3 quantity and item 5 grade, PP-3.4.5. ","")&IF(D6="No","Samples not received, section 3.2. ","")&IF(AND(C6="Yes",LEFT(E6,2)="No"),"Item 3 priced at the superseded quantity, PP-3.4.5. ","")&IF(AND(C6="Yes",LEFT(F6,2)="No"),"Bid on a superseded specification, "&MID(F6,5,40)&", PP-3.4.5. ","")&IF(LEFT(G6,2)="No","Item 4 offered only as an alternate, with no bid on the item as specified, section 5.2 and 4.4. ","")&IF(H6="Yes","Exception to a material term, "&'Bid Conditions'!C6&", section 5.2 and PP-3.4.4. ","")) -> Exception to a material term, Price hold, section 4.3, section 5.2 and PP-3.4.4.
A7: =Terms!A7 -> Kessel Container Corp. | B7: ='Bid Security'!G7 -> Yes | C7: =IF(ISNUMBER(SEARCH(Parameters!$B$9,Terms!H7)),"Yes","No") -> Yes | D7: =IF(Terms!I7="Yes","Yes","No") -> Yes | E7: =IF(ROUND('Bids as Written'!J7,2)=ROUND('Bids as Written'!I7*Parameters!$B$10,2),"No, superseded 36,000","Yes") -> Yes | F7: No, item 2 as 18 x 12 x 12 | G7: Yes | H7: ='Bid Conditions'!D7 -> No | I7: ='Bid Conditions'!B7 -> None; prices hold through December 31, 2027, which runs past twelve months from any award this year | J7: =IF(ISNUMBER(SEARCH("lternate",'Bid Conditions'!B7)),"Yes, not evaluated","No") -> No | K7: =IF(AND(B7="Yes",C7="Yes",D7="Yes",LEFT(E7,3)="Yes",F7="Yes",G7="Yes",H7="No"),"Responsive","Non-responsive") -> Non-responsive | L7: =TRIM(IF(B7="No","No bid security, section 3.2. ","")&IF(B7="No, short","Bid security under five percent of the total bid as written, section 3.2 and addendum 2. ","")&IF(C7="No","Addendum 2 not acknowledged, section 3.2; bid on the superseded item 3 quantity and item 5 grade, PP-3.4.5. ","")&IF(D7="No","Samples not received, section 3.2. ","")&IF(AND(C7="Yes",LEFT(E7,2)="No"),"Item 3 priced at the superseded quantity, PP-3.4.5. ","")&IF(AND(C7="Yes",LEFT(F7,2)="No"),"Bid on a superseded specification, "&MID(F7,5,40)&", PP-3.4.5. ","")&IF(LEFT(G7,2)="No","Item 4 offered only as an alternate, with no bid on the item as specified, section 5.2 and 4.4. ","")&IF(H7="Yes","Exception to a material term, "&'Bid Conditions'!C7&", section 5.2 and PP-3.4.4. ","")) -> Bid on a superseded specification, item 2 as 18 x 12 x 12, PP-3.4.5.
A8: =Terms!A8 -> Loken & Vik Container | B8: ='Bid Security'!G8 -> Yes | C8: =IF(ISNUMBER(SEARCH(Parameters!$B$9,Terms!H8)),"Yes","No") -> Yes | D8: =IF(Terms!I8="Yes","Yes","No") -> Yes | E8: =IF(ROUND('Bids as Written'!L7,2)=ROUND('Bids as Written'!K7*Parameters!$B$10,2),"No, superseded 36,000","Yes") -> Yes | F8: Yes | G8: Yes | H8: ='Bid Conditions'!D8 -> No | I8: ='Bid Conditions'!B8 -> None; releases requested at least ten working days ahead of delivery | J8: =IF(ISNUMBER(SEARCH("lternate",'Bid Conditions'!B8)),"Yes, not evaluated","No") -> No | K8: =IF(AND(B8="Yes",C8="Yes",D8="Yes",LEFT(E8,3)="Yes",F8="Yes",G8="Yes",H8="No"),"Responsive","Non-responsive") -> Responsive | L8: =TRIM(IF(B8="No","No bid security, section 3.2. ","")&IF(B8="No, short","Bid security under five percent of the total bid as written, section 3.2 and addendum 2. ","")&IF(C8="No","Addendum 2 not acknowledged, section 3.2; bid on the superseded item 3 quantity and item 5 grade, PP-3.4.5. ","")&IF(D8="No","Samples not received, section 3.2. ","")&IF(AND(C8="Yes",LEFT(E8,2)="No"),"Item 3 priced at the superseded quantity, PP-3.4.5. ","")&IF(AND(C8="Yes",LEFT(F8,2)="No"),"Bid on a superseded specification, "&MID(F8,5,40)&", PP-3.4.5. ","")&IF(LEFT(G8,2)="No","Item 4 offered only as an alternate, with no bid on the item as specified, section 5.2 and 4.4. ","")&IF(H8="Yes","Exception to a material term, "&'Bid Conditions'!C8&", section 5.2 and PP-3.4.4. ",""))
A9: =Terms!A9 -> Mesabi Container Co. | B9: ='Bid Security'!G9 -> Yes | C9: =IF(ISNUMBER(SEARCH(Parameters!$B$9,Terms!H9)),"Yes","No") -> Yes | D9: =IF(Terms!I9="Yes","Yes","No") -> Yes | E9: =IF(ROUND('Bids as Written'!N7,2)=ROUND('Bids as Written'!M7*Parameters!$B$10,2),"No, superseded 36,000","Yes") -> Yes | F9: Yes | G9: No, item 4 as an alternate only | H9: ='Bid Conditions'!D9 -> No | I9: ='Bid Conditions'!B9 -> Item 4 offered on 200 lb test doublewall only, the Duluth plant not running 275 lb test; FOB origin, all five items from Duluth | J9: =IF(ISNUMBER(SEARCH("lternate",'Bid Conditions'!B9)),"Yes, not evaluated","No") -> No | K9: =IF(AND(B9="Yes",C9="Yes",D9="Yes",LEFT(E9,3)="Yes",F9="Yes",G9="Yes",H9="No"),"Responsive","Non-responsive") -> Non-responsive | L9: =TRIM(IF(B9="No","No bid security, section 3.2. ","")&IF(B9="No, short","Bid security under five percent of the total bid as written, section 3.2 and addendum 2. ","")&IF(C9="No","Addendum 2 not acknowledged, section 3.2; bid on the superseded item 3 quantity and item 5 grade, PP-3.4.5. ","")&IF(D9="No","Samples not received, section 3.2. ","")&IF(AND(C9="Yes",LEFT(E9,2)="No"),"Item 3 priced at the superseded quantity, PP-3.4.5. ","")&IF(AND(C9="Yes",LEFT(F9,2)="No"),"Bid on a superseded specification, "&MID(F9,5,40)&", PP-3.4.5. ","")&IF(LEFT(G9,2)="No","Item 4 offered only as an alternate, with no bid on the item as specified, section 5.2 and 4.4. ","")&IF(H9="Yes","Exception to a material term, "&'Bid Conditions'!C9&", section 5.2 and PP-3.4.4. ","")) -> Item 4 offered only as an alternate, with no bid on the item as specified, section 5.2 and 4.4.
A10: =Terms!A10 -> Otter Tail Corrugated | B10: ='Bid Security'!G10 -> Yes | C10: =IF(ISNUMBER(SEARCH(Parameters!$B$9,Terms!H10)),"Yes","No") -> Yes | D10: =IF(Terms!I10="Yes","Yes","No") -> Yes | E10: =IF(ROUND('Bids as Written'!P7,2)=ROUND('Bids as Written'!O7*Parameters!$B$10,2),"No, superseded 36,000","Yes") -> Yes | F10: Yes | G10: Yes | H10: ='Bid Conditions'!D10 -> Yes | I10: ='Bid Conditions'!B10 -> Pricing assumes releases in full truckload quantities of 26 pallets; a release below a full truckload carries a $185 stop charge; the form box reads None | J10: =IF(ISNUMBER(SEARCH("lternate",'Bid Conditions'!B10)),"Yes, not evaluated","No") -> No | K10: =IF(AND(B10="Yes",C10="Yes",D10="Yes",LEFT(E10,3)="Yes",F10="Yes",G10="Yes",H10="No"),"Responsive","Non-responsive") -> Non-responsive | L10: =TRIM(IF(B10="No","No bid security, section 3.2. ","")&IF(B10="No, short","Bid security under five percent of the total bid as written, section 3.2 and addendum 2. ","")&IF(C10="No","Addendum 2 not acknowledged, section 3.2; bid on the superseded item 3 quantity and item 5 grade, PP-3.4.5. ","")&IF(D10="No","Samples not received, section 3.2. ","")&IF(AND(C10="Yes",LEFT(E10,2)="No"),"Item 3 priced at the superseded quantity, PP-3.4.5. ","")&IF(AND(C10="Yes",LEFT(F10,2)="No"),"Bid on a superseded specification, "&MID(F10,5,40)&", PP-3.4.5. ","")&IF(LEFT(G10,2)="No","Item 4 offered only as an alternate, with no bid on the item as specified, section 5.2 and 4.4. ","")&IF(H10="Yes","Exception to a material term, "&'Bid Conditions'!C10&", section 5.2 and PP-3.4.4. ","")) -> Exception to a material term, Quantity, releases in pallet multiples, section 1, section 5.2 and PP-3.4.4.
A11: =Terms!A11 -> Pemberton Container | B11: ='Bid Security'!G11 -> Yes | C11: =IF(ISNUMBER(SEARCH(Parameters!$B$9,Terms!H11)),"Yes","No") -> Yes | D11: =IF(Terms!I11="Yes","Yes","No") -> Yes | E11: =IF(ROUND('Bids as Written'!R7,2)=ROUND('Bids as Written'!Q7*Parameters!$B$10,2),"No, superseded 36,000","Yes") -> Yes | F11: Yes | G11: Yes | H11: ='Bid Conditions'!D11 -> No | I11: ='Bid Conditions'!B11 -> Alternate for item 4 at 200 lb test doublewall, $1.512 per carton, beside the bid on the item as specified | J11: =IF(ISNUMBER(SEARCH("lternate",'Bid Conditions'!B11)),"Yes, not evaluated","No") -> Yes, not evaluated | K11: =IF(AND(B11="Yes",C11="Yes",D11="Yes",LEFT(E11,3)="Yes",F11="Yes",G11="Yes",H11="No"),"Responsive","Non-responsive") -> Responsive | L11: =TRIM(IF(B11="No","No bid security, section 3.2. ","")&IF(B11="No, short","Bid security under five percent of the total bid as written, section 3.2 and addendum 2. ","")&IF(C11="No","Addendum 2 not acknowledged, section 3.2; bid on the superseded item 3 quantity and item 5 grade, PP-3.4.5. ","")&IF(D11="No","Samples not received, section 3.2. ","")&IF(AND(C11="Yes",LEFT(E11,2)="No"),"Item 3 priced at the superseded quantity, PP-3.4.5. ","")&IF(AND(C11="Yes",LEFT(F11,2)="No"),"Bid on a superseded specification, "&MID(F11,5,40)&", PP-3.4.5. ","")&IF(LEFT(G11,2)="No","Item 4 offered only as an alternate, with no bid on the item as specified, section 5.2 and 4.4. ","")&IF(H11="Yes","Exception to a material term, "&'Bid Conditions'!C11&", section 5.2 and PP-3.4.4. ",""))
A12: =Terms!A12 -> Ridgecrest Packaging | B12: ='Bid Security'!G12 -> Yes | C12: =IF(ISNUMBER(SEARCH(Parameters!$B$9,Terms!H12)),"Yes","No") -> Yes | D12: =IF(Terms!I12="Yes","Yes","No") -> Yes | E12: =IF(ROUND('Bids as Written'!T7,2)=ROUND('Bids as Written'!S7*Parameters!$B$10,2),"No, superseded 36,000","Yes") -> Yes | F12: Yes | G12: Yes | H12: ='Bid Conditions'!D12 -> No | I12: ='Bid Conditions'!B12 -> None; FOB origin, items 1 to 4 shipped from Cedar Rapids and item 5 from Omaha; tooling credited back if the award arrives by October 30 | J12: =IF(ISNUMBER(SEARCH("lternate",'Bid Conditions'!B12)),"Yes, not evaluated","No") -> No | K12: =IF(AND(B12="Yes",C12="Yes",D12="Yes",LEFT(E12,3)="Yes",F12="Yes",G12="Yes",H12="No"),"Responsive","Non-responsive") -> Responsive | L12: =TRIM(IF(B12="No","No bid security, section 3.2. ","")&IF(B12="No, short","Bid security under five percent of the total bid as written, section 3.2 and addendum 2. ","")&IF(C12="No","Addendum 2 not acknowledged, section 3.2; bid on the superseded item 3 quantity and item 5 grade, PP-3.4.5. ","")&IF(D12="No","Samples not received, section 3.2. ","")&IF(AND(C12="Yes",LEFT(E12,2)="No"),"Item 3 priced at the superseded quantity, PP-3.4.5. ","")&IF(AND(C12="Yes",LEFT(F12,2)="No"),"Bid on a superseded specification, "&MID(F12,5,40)&", PP-3.4.5. ","")&IF(LEFT(G12,2)="No","Item 4 offered only as an alternate, with no bid on the item as specified, section 5.2 and 4.4. ","")&IF(H12="Yes","Exception to a material term, "&'Bid Conditions'!C12&", section 5.2 and PP-3.4.4. ",""))
A13: =Terms!A13 -> Thorsgard Box & Label | B13: ='Bid Security'!G13 -> Yes | C13: =IF(ISNUMBER(SEARCH(Parameters!$B$9,Terms!H13)),"Yes","No") -> Yes | D13: =IF(Terms!I13="Yes","Yes","No") -> Yes | E13: =IF(ROUND('Bids as Written'!V7,2)=ROUND('Bids as Written'!U7*Parameters!$B$10,2),"No, superseded 36,000","Yes") -> Yes | F13: Yes | G13: Yes | H13: ='Bid Conditions'!D13 -> Yes | I13: ='Bid Conditions'!B13 -> Prices firm through September 30, 2027; the form box reads Yes to twelve months from award | J13: =IF(ISNUMBER(SEARCH("lternate",'Bid Conditions'!B13)),"Yes, not evaluated","No") -> No | K13: =IF(AND(B13="Yes",C13="Yes",D13="Yes",LEFT(E13,3)="Yes",F13="Yes",G13="Yes",H13="No"),"Responsive","Non-responsive") -> Non-responsive | L13: =TRIM(IF(B13="No","No bid security, section 3.2. ","")&IF(B13="No, short","Bid security under five percent of the total bid as written, section 3.2 and addendum 2. ","")&IF(C13="No","Addendum 2 not acknowledged, section 3.2; bid on the superseded item 3 quantity and item 5 grade, PP-3.4.5. ","")&IF(D13="No","Samples not received, section 3.2. ","")&IF(AND(C13="Yes",LEFT(E13,2)="No"),"Item 3 priced at the superseded quantity, PP-3.4.5. ","")&IF(AND(C13="Yes",LEFT(F13,2)="No"),"Bid on a superseded specification, "&MID(F13,5,40)&", PP-3.4.5. ","")&IF(LEFT(G13,2)="No","Item 4 offered only as an alternate, with no bid on the item as specified, section 5.2 and 4.4. ","")&IF(H13="Yes","Exception to a material term, "&'Bid Conditions'!C13&", section 5.2 and PP-3.4.4. ","")) -> Exception to a material term, Price hold, section 4.3, section 5.2 and PP-3.4.4.
A14: =Terms!A14 -> Wenzel & Krause Corrugated | B14: ='Bid Security'!G14 -> Yes | C14: =IF(ISNUMBER(SEARCH(Parameters!$B$9,Terms!H14)),"Yes","No") -> Yes | D14: =IF(Terms!I14="Yes","Yes","No") -> Yes | E14: =IF(ROUND('Bids as Written'!X7,2)=ROUND('Bids as Written'!W7*Parameters!$B$10,2),"No, superseded 36,000","Yes") -> Yes | F14: Yes | G14: Yes | H14: ='Bid Conditions'!D14 -> No | I14: ='Bid Conditions'!B14 -> None; the letter follows the linerboard index and holds prices firm for twelve months whatever the index does, and offers stock holding after award that the prices do not depend on | J14: =IF(ISNUMBER(SEARCH("lternate",'Bid Conditions'!B14)),"Yes, not evaluated","No") -> No | K14: =IF(AND(B14="Yes",C14="Yes",D14="Yes",LEFT(E14,3)="Yes",F14="Yes",G14="Yes",H14="No"),"Responsive","Non-responsive") -> Responsive | L14: =TRIM(IF(B14="No","No bid security, section 3.2. ","")&IF(B14="No, short","Bid security under five percent of the total bid as written, section 3.2 and addendum 2. ","")&IF(C14="No","Addendum 2 not acknowledged, section 3.2; bid on the superseded item 3 quantity and item 5 grade, PP-3.4.5. ","")&IF(D14="No","Samples not received, section 3.2. ","")&IF(AND(C14="Yes",LEFT(E14,2)="No"),"Item 3 priced at the superseded quantity, PP-3.4.5. ","")&IF(AND(C14="Yes",LEFT(F14,2)="No"),"Bid on a superseded specification, "&MID(F14,5,40)&", PP-3.4.5. ","")&IF(LEFT(G14,2)="No","Item 4 offered only as an alternate, with no bid on the item as specified, section 5.2 and 4.4. ","")&IF(H14="Yes","Exception to a material term, "&'Bid Conditions'!C14&", section 5.2 and PP-3.4.4. ",""))
A16: Responsive bids | B16: =COUNTIF(K4:K14,"Responsive") -> 4
A17: Bids set aside as non-responsive | B17: =COUNTIF(K4:K14,"Non-responsive") -> 7
A19: Responsiveness is decided on the invitation as amended before any price is compared, per PP-3.4.1; a bid set aside is shown on the Evaluation tab for the record and does not compete for award. Responsibility under PP-3.7 is decided afterwards, for the bidder in line, on the Responsibility tab.
A20: The description column of each form is read against the items as amended. Kessel's form acknowledges both addenda and describes item 2 as 18 x 12 x 12, the size addendum 1 replaced with 18 x 12 x 10. Mesabi's form carries item 4 on 200 lb test doublewall as an alternate with no line on the 275 lb test board as specified; 4.4 lets an alternate stand only alongside a bid on the item as specified.

Sheet Responsibility
A1: Responsibility of the bidder in line for award under PP-3.7.1, checked in the order 5.1 and 5.6 give among the responsive bids
A3: IN_LINE_ORDER | B3: BIDDER | C3: TOTAL_EVALUATED_PRICE | D3: BID_RECEIVED | E3: OPEN_HOLDS | F3: DECISION | G3: RESPONSIBILITY | H3: RULE
A4: 1 | B4: =IFERROR(INDEX(Evaluation!$B$3:$L$3,MATCH(A4,Evaluation!$B$25:$L$25,0)),"") -> Loken & Vik Container | C4: =IF(B4="","",INDEX(Evaluation!$B$21:$L$21,MATCH(A4,Evaluation!$B$25:$L$25,0))) -> 99230.72 | D4: =IF(B4="","",INDEX('Bid Receipt'!$D$4:$D$14,MATCH(B4,'Bid Receipt'!$A$4:$A$14,0))&" "&INDEX('Bid Receipt'!$E$4:$E$14,MATCH(B4,'Bid Receipt'!$A$4:$A$14,0))) -> 10/06/2026 10:00 | E4: =IF(B4="","",COUNTIFS('Holds on Bidders'!$C$4:$C$7,B4,'Holds on Bidders'!$I$4:$I$7,"Open")) -> 1 | F4: =IF(B4="","",IF(FALSE,"Not reached",IF(E4=0,"Award","Passed over"))) -> Passed over | G4: =IF(B4="","",IF(F4="Not reached","Not decided, PP-3.7.1",IF(E4=0,"Responsible","Not responsible, open quality hold, PP-3.7.1"))) -> Not responsible, open quality hold, PP-3.7.1 | H4: =IF(B4="","",IF(F4="Award","Responsive and responsible, first in the order of 5.1 and 5.6",IF(F4="Passed over","Open hold in the register; PP-3.7.1 passes the bid over","Responsibility decided only for the bidder in line, PP-3.7.1"))) -> Open hold in the register; PP-3.7.1 passes the bid over
