Workbook

Sheet SMR Q3
A1: SELF-MONITORING REPORT, THIRD QUARTER 2026 (JULY 1 THROUGH SEPTEMBER 30, 2026)
A2: Permittee: Vandeveer Plating LLC, 2140 Chicago Drive SW, Wyoming, Michigan 49519
A3: Wastewater Discharge Permit No. IP-0421, City of Wyoming Clean Water Plant, Industrial Pretreatment Program
A4: Report prepared October 12, 2026 for the Plant Manager's signature. Sampling point: Outfall 001, pretreatment system effluent. Report format per Attachment B; due to the City by October 15, 2026 under Section 3.1.
A6: JULY 2026
A7: PARAMETER | B7: DAILY MAXIMUM LIMIT MG/L | C7: MONTHLY AVERAGE LIMIT MG/L | D7: VALID SAMPLES | E7: REQUIRED | F7: MONTHLY AVERAGE MG/L | G7: DAILY MAXIMUM MG/L | H7: MONTHLY AVERAGE MET | I7: DAILY MAXIMUM MET | J7: FREQUENCY MET
A8: Cadmium, total | B8: ='Monthly Stats'!C23 -> 0.11 | C8: ='Monthly Stats'!D23 -> 0.07 | D8: ='Monthly Stats'!E23 -> 1 | E8: ='Monthly Stats'!F23 -> 2 | F8: ='Monthly Stats'!G23 -> 0 | G8: ='Monthly Stats'!H23 -> 0 | H8: ='Monthly Stats'!I23 -> Met | I8: ='Monthly Stats'!J23 -> Met | J8: ='Monthly Stats'!K23 -> Below frequency
A9: Chromium, total | B9: ='Monthly Stats'!C24 -> 2.77 | C9: ='Monthly Stats'!D24 -> 1.71 | D9: ='Monthly Stats'!E24 -> 1 | E9: ='Monthly Stats'!F24 -> 2 | F9: ='Monthly Stats'!G24 -> 1.21 | G9: ='Monthly Stats'!H24 -> 1.21 | H9: ='Monthly Stats'!I24 -> Met | I9: ='Monthly Stats'!J24 -> Met | J9: ='Monthly Stats'!K24 -> Below frequency
A10: Copper, total | B10: ='Monthly Stats'!C25 -> 3.38 | C10: ='Monthly Stats'!D25 -> 2.07 | D10: ='Monthly Stats'!E25 -> 1 | E10: ='Monthly Stats'!F25 -> 2 | F10: ='Monthly Stats'!G25 -> 4.09 | G10: ='Monthly Stats'!H25 -> 4.09 | H10: ='Monthly Stats'!I25 -> Exceeded | I10: ='Monthly Stats'!J25 -> Exceeded | J10: ='Monthly Stats'!K25 -> Below frequency
A11: Nickel, total | B11: ='Monthly Stats'!C26 -> 3.98 | C11: ='Monthly Stats'!D26 -> 2.38 | D11: ='Monthly Stats'!E26 -> 1 | E11: ='Monthly Stats'!F26 -> 2 | F11: ='Monthly Stats'!G26 -> 1.57 | G11: ='Monthly Stats'!H26 -> 1.57 | H11: ='Monthly Stats'!I26 -> Met | I11: ='Monthly Stats'!J26 -> Met | J11: ='Monthly Stats'!K26 -> Below frequency
A12: Zinc, total | B12: ='Monthly Stats'!C27 -> 2.61 | C12: ='Monthly Stats'!D27 -> 1.48 | D12: ='Monthly Stats'!E27 -> 1 | E12: ='Monthly Stats'!F27 -> 2 | F12: ='Monthly Stats'!G27 -> 1.27 | G12: ='Monthly Stats'!H27 -> 1.27 | H12: ='Monthly Stats'!I27 -> Met | I12: ='Monthly Stats'!J27 -> Met | J12: ='Monthly Stats'!K27 -> Below frequency
A13: Cyanide, total | B13: ='Monthly Stats'!C28 -> 1.2 | C13: ='Monthly Stats'!D28 -> 0.65 | D13: ='Monthly Stats'!E28 -> 2 | E13: ='Monthly Stats'!F28 -> 2 | F13: ='Monthly Stats'!G28 -> 0.31 | G13: ='Monthly Stats'!H28 -> 0.35 | H13: ='Monthly Stats'!I28 -> Met | I13: ='Monthly Stats'!J28 -> Met | J13: ='Monthly Stats'!K28 -> Met
A14: pH, standard units, grabs at sampling | B14: 6.0 to 9.0 | C14: not applicable | D14: =COUNTIFS('Lab Data'!$C$5:$C$17,"Jul") -> 2 | E14: =Parameters!$B$15 -> 2 | F14: =_xlfn.MINIFS('Lab Data'!$AC$5:$AC$17,'Lab Data'!$C$5:$C$17,"Jul") -> 7.2 | G14: =_xlfn.MAXIFS('Lab Data'!$AC$5:$AC$17,'Lab Data'!$C$5:$C$17,"Jul") -> 8.4 | H14: In-line meter: none reported | I14: Met | J14: Met
A15: Flow, gallons per day | B15: =Parameters!$B$12 -> 45000 | C15: not applicable | D15: daily | E15: daily | G15: no day above the limit per the plant manager's review of the operator logs | H15: not applicable | I15: Met | J15: Met
A17: AUGUST 2026
A18: PARAMETER | B18: DAILY MAXIMUM LIMIT MG/L | C18: MONTHLY AVERAGE LIMIT MG/L | D18: VALID SAMPLES | E18: REQUIRED | F18: MONTHLY AVERAGE MG/L | G18: DAILY MAXIMUM MG/L | H18: MONTHLY AVERAGE MET | I18: DAILY MAXIMUM MET | J18: FREQUENCY MET
A19: Cadmium, total | B19: ='Monthly Stats'!C29 -> 0.11 | C19: ='Monthly Stats'!D29 -> 0.07 | D19: ='Monthly Stats'!E29 -> 2 | E19: ='Monthly Stats'!F29 -> 2 | F19: ='Monthly Stats'!G29 -> 0.007 | G19: ='Monthly Stats'!H29 -> 0.014 | H19: ='Monthly Stats'!I29 -> Met | I19: ='Monthly Stats'!J29 -> Met | J19: ='Monthly Stats'!K29 -> Met
A20: Chromium, total | B20: ='Monthly Stats'!C30 -> 2.77 | C20: ='Monthly Stats'!D30 -> 1.71 | D20: ='Monthly Stats'!E30 -> 2 | E20: ='Monthly Stats'!F30 -> 2 | F20: ='Monthly Stats'!G30 -> 0.7 | G20: ='Monthly Stats'!H30 -> 0.74 | H20: ='Monthly Stats'!I30 -> Met | I20: ='Monthly Stats'!J30 -> Met | J20: ='Monthly Stats'!K30 -> Met
A21: Copper, total | B21: ='Monthly Stats'!C31 -> 3.38 | C21: ='Monthly Stats'!D31 -> 2.07 | D21: ='Monthly Stats'!E31 -> 2 | E21: ='Monthly Stats'!F31 -> 2 | F21: ='Monthly Stats'!G31 -> 4.24 | G21: ='Monthly Stats'!H31 -> 4.33 | H21: ='Monthly Stats'!I31 -> Exceeded | I21: ='Monthly Stats'!J31 -> Exceeded | J21: ='Monthly Stats'!K31 -> Met
A22: Nickel, total | B22: ='Monthly Stats'!C32 -> 3.98 | C22: ='Monthly Stats'!D32 -> 2.38 | D22: ='Monthly Stats'!E32 -> 1 | E22: ='Monthly Stats'!F32 -> 2 | F22: ='Monthly Stats'!G32 -> 2.61 | G22: ='Monthly Stats'!H32 -> 2.61 | H22: ='Monthly Stats'!I32 -> Exceeded | I22: ='Monthly Stats'!J32 -> Met | J22: ='Monthly Stats'!K32 -> Below frequency
A23: Zinc, total | B23: ='Monthly Stats'!C33 -> 2.61 | C23: ='Monthly Stats'!D33 -> 1.48 | D23: ='Monthly Stats'!E33 -> 2 | E23: ='Monthly Stats'!F33 -> 2 | F23: ='Monthly Stats'!G33 -> 1.035 | G23: ='Monthly Stats'!H33 -> 1.18 | H23: ='Monthly Stats'!I33 -> Met | I23: ='Monthly Stats'!J33 -> Met | J23: ='Monthly Stats'!K33 -> Met
A24: Cyanide, total | B24: ='Monthly Stats'!C34 -> 1.2 | C24: ='Monthly Stats'!D34 -> 0.65 | D24: ='Monthly Stats'!E34 -> 2 | E24: ='Monthly Stats'!F34 -> 2 | F24: ='Monthly Stats'!G34 -> 0.24 | G24: ='Monthly Stats'!H34 -> 0.29 | H24: ='Monthly Stats'!I34 -> Met | I24: ='Monthly Stats'!J34 -> Met | J24: ='Monthly Stats'!K34 -> Met
A25: pH, standard units, grabs at sampling | B25: 6.0 to 9.0 | C25: not applicable | D25: =COUNTIFS('Lab Data'!$C$5:$C$17,"Aug") -> 2 | E25: =Parameters!$B$15 -> 2 | F25: =_xlfn.MINIFS('Lab Data'!$AC$5:$AC$17,'Lab Data'!$C$5:$C$17,"Aug") -> 6.8 | G25: =_xlfn.MAXIFS('Lab Data'!$AC$5:$AC$17,'Lab Data'!$C$5:$C$17,"Aug") -> 7.5 | H25: In-line meter: none reported | I25: Met | J25: Met
A26: Flow, gallons per day | B26: =Parameters!$B$12 -> 45000 | C26: not applicable | D26: daily | E26: daily | G26: no day above the limit per the plant manager's review of the operator logs | H26: not applicable | I26: Met | J26: Met
A28: SEPTEMBER 2026
A29: PARAMETER | B29: DAILY MAXIMUM LIMIT MG/L | C29: MONTHLY AVERAGE LIMIT MG/L | D29: VALID SAMPLES | E29: REQUIRED | F29: MONTHLY AVERAGE MG/L | G29: DAILY MAXIMUM MG/L | H29: MONTHLY AVERAGE MET | I29: DAILY MAXIMUM MET | J29: FREQUENCY MET
A30: Cadmium, total | B30: ='Monthly Stats'!C35 -> 0.11 | C30: ='Monthly Stats'!D35 -> 0.07 | D30: ='Monthly Stats'!E35 -> 3 | E30: ='Monthly Stats'!F35 -> 2 | F30: ='Monthly Stats'!G35 -> 0.004 | G30: ='Monthly Stats'!H35 -> 0.012 | H30: ='Monthly Stats'!I35 -> Met | I30: ='Monthly Stats'!J35 -> Met | J30: ='Monthly Stats'!K35 -> Met
A31: Chromium, total | B31: ='Monthly Stats'!C36 -> 2.77 | C31: ='Monthly Stats'!D36 -> 1.71 | D31: ='Monthly Stats'!E36 -> 3 | E31: ='Monthly Stats'!F36 -> 2 | F31: ='Monthly Stats'!G36 -> 0.697 | G31: ='Monthly Stats'!H36 -> 1.02 | H31: ='Monthly Stats'!I36 -> Met | I31: ='Monthly Stats'!J36 -> Met | J31: ='Monthly Stats'!K36 -> Met
A32: Copper, total | B32: ='Monthly Stats'!C37 -> 3.38 | C32: ='Monthly Stats'!D37 -> 2.07 | D32: ='Monthly Stats'!E37 -> 3 | E32: ='Monthly Stats'!F37 -> 2 | F32: ='Monthly Stats'!G37 -> 2.053 | G32: ='Monthly Stats'!H37 -> 2.96 | H32: ='Monthly Stats'!I37 -> Met | I32: ='Monthly Stats'!J37 -> Met | J32: ='Monthly Stats'!K37 -> Met
A33: Nickel, total | B33: ='Monthly Stats'!C38 -> 3.98 | C33: ='Monthly Stats'!D38 -> 2.38 | D33: ='Monthly Stats'!E38 -> 3 | E33: ='Monthly Stats'!F38 -> 2 | F33: ='Monthly Stats'!G38 -> 1.15 | G33: ='Monthly Stats'!H38 -> 1.36 | H33: ='Monthly Stats'!I38 -> Met | I33: ='Monthly Stats'!J38 -> Met | J33: ='Monthly Stats'!K38 -> Met
A34: Zinc, total | B34: ='Monthly Stats'!C39 -> 2.61 | C34: ='Monthly Stats'!D39 -> 1.48 | D34: ='Monthly Stats'!E39 -> 3 | E34: ='Monthly Stats'!F39 -> 2 | F34: ='Monthly Stats'!G39 -> 1.653 | G34: ='Monthly Stats'!H39 -> 3.14 | H34: ='Monthly Stats'!I39 -> Exceeded | I34: ='Monthly Stats'!J39 -> Exceeded | J34: ='Monthly Stats'!K39 -> Met
A35: Cyanide, total | B35: ='Monthly Stats'!C40 -> 1.2 | C35: ='Monthly Stats'!D40 -> 0.65 | D35: ='Monthly Stats'!E40 -> 2 | E35: ='Monthly Stats'!F40 -> 2 | F35: ='Monthly Stats'!G40 -> 0.325 | G35: ='Monthly Stats'!H40 -> 0.41 | H35: ='Monthly Stats'!I40 -> Met | I35: ='Monthly Stats'!J40 -> Met | J35: ='Monthly Stats'!K40 -> Met
A36: pH, standard units, grabs at sampling | B36: 6.0 to 9.0 | C36: not applicable | D36: =COUNTIFS('Lab Data'!$C$5:$C$17,"Sep") -> 3 | E36: =Parameters!$B$15 -> 2 | F36: =_xlfn.MINIFS('Lab Data'!$AC$5:$AC$17,'Lab Data'!$C$5:$C$17,"Sep") -> 7.3 | G36: =_xlfn.MAXIFS('Lab Data'!$AC$5:$AC$17,'Lab Data'!$C$5:$C$17,"Sep") -> 7.9 | H36: In-line meter: one excursion, 09/17/2026; the 6.0 low of 09/11/2026 is inside the range | I36: Exceeded | J36: Met
A37: Flow, gallons per day | B37: =Parameters!$B$12 -> 45000 | C37: not applicable | D37: daily | E37: daily | G37: ='Flow Sep'!$B$36 -> 47300 | H37: not applicable | I37: =IF(G37>B37,"Exceeded","Met") -> Exceeded | J37: Met
A39: VIOLATIONS IN THE QUARTER
A40: DATE | B40: PARAMETER OR CONDITION | C40: VALUE | D40: LIMITATION | E40: PERMIT SECTION | F40: CAUSE AS KNOWN
A41: 07/21/2026 | B41: Copper, daily maximum, sample VP-260721 | C41: ='Monthly Stats'!H25 -> 4.09 | D41: 3.38 mg/L | E41: Part I | F41: Copper carryover from the plating line; treatment chemistry under review by the plant
A42: July 2026 | B42: Copper, monthly average, one valid sample | C42: ='Monthly Stats'!G25 -> 4.09 | D42: 2.07 mg/L | E42: Part I | F42: The July 21 result stands alone after the July 7 sample's metals were analyzed outside the holding period
A43: July 2026 | B43: Cadmium, chromium, copper, nickel and zinc, monitoring frequency | C43: ='Monthly Stats'!E25 -> 1 | D43: 2 valid samples | E43: Section 2.3 | F43: Metals of sample VP-260707 analyzed 08/06/2026, 30 days after collection, outside the 28-day holding period; the laboratory reported the month on 08/07/2026 after it had ended, so no replacement could be collected
A44: 08/11/2026 | B44: Copper, daily maximum, sample VP-260811 | C44: ='Monthly Stats'!H31 -> 4.33 | D44: 3.38 mg/L | E44: Part I | F44: Copper carryover from the plating line
...

Sheet Parameters
A1: Permit limitations and computation parameters, Wastewater Discharge Permit IP-0421
A3: PARAMETER | B3: DAILY MAXIMUM MG/L | C3: MONTHLY AVERAGE MG/L | D3: MDL MG/L | E3: SOURCE
A4: Cadmium, total | B4: 0.11 | C4: 0.07 | D4: 0.005 | E4: Part I of the permit; MDL from the laboratory's Methods tab
A5: Chromium, total | B5: 2.77 | C5: 1.71 | D5: 0.01 | E5: Part I of the permit; MDL from the laboratory's Methods tab
A6: Copper, total | B6: 3.38 | C6: 2.07 | D6: 0.01 | E6: Part I of the permit; MDL from the laboratory's Methods tab
A7: Nickel, total | B7: 3.98 | C7: 2.38 | D7: 0.02 | E7: Part I of the permit; MDL from the laboratory's Methods tab
A8: Zinc, total | B8: 2.61 | C8: 1.48 | D8: 0.02 | E8: Part I of the permit; MDL from the laboratory's Methods tab
A9: Cyanide, total | B9: 1.2 | C9: 0.65 | D9: 0.005 | E9: Part I of the permit; MDL from the laboratory's Methods tab
A11: OTHER PARAMETER | B11: VALUE | E11: SOURCE
A12: Daily flow limit, gallons per day | B12: 45000 | E12: Part I of the permit
A13: pH range, standard units, lower bound | B13: 6 | E13: Part I of the permit
A14: pH range, standard units, upper bound | B14: 9 | E14: Part I of the permit
A15: Required valid samples per parameter per month | B15: 2 | E15: Section 2.1 of the permit
A16: Technical review criterion for metals and cyanide | B16: 1.2 | E16: Section 3.4 of the permit
A17: Chronic significant noncompliance threshold, percent of measurements | B17: 66 | E17: Section 3.4 of the permit
A18: Technical review criterion significant noncompliance threshold, percent of measurements | B18: 33 | E18: Section 3.4 of the permit
A19: Telephone notice, hours after becoming aware | B19: 24 | E19: Section 3.2 of the permit
A20: Written report, days after the event | B20: 5 | E20: Section 3.2 of the permit
A21: Resample, days after becoming aware of a daily maximum exceedance | B21: 30 | E21: Section 3.3 of the permit
A22: Self-monitoring report due, day of the month after the quarter | B22: 15 | E22: Section 3.1 of the permit
A23: Holding period, total metals, days from collection | B23: 28 | E23: Section 2.3 of the permit (40 CFR Part 136); the period the laboratory's chain of custody log states
A24: Holding period, total cyanide, days from collection | B24: 14 | E24: Section 2.3 of the permit (40 CFR Part 136); the period the laboratory's chain of custody log states

Sheet Lab Data
A1: Laboratory results April through September 2026, Outfall 001, as reported (lab_results_apr_sep2026.xlsx)
A2: RESULT and QUAL are the laboratory's figures as typed; the ANALYZED dates are from the laboratory's chain of custody log, and the SERIAL columns carry the same dates as Excel serials for the day count. VALID is N for a result not sampled (NS) or analyzed more than the holding period after collection, Section 2.3 and Parameters rows 23 and 24. TREATED carries a U result at zero for averaging, Section 2.2.
A4: SAMPLE ID | B4: COLLECTED | C4: MONTH | D4: TYPE | E4: Cd RESULT | F4: Cd QUAL | G4: Cd VALID | H4: Cd TREATED | I4: Cr RESULT | J4: Cr QUAL | K4: Cr VALID | L4: Cr TREATED | M4: Cu RESULT | N4: Cu QUAL | O4: Cu VALID | P4: Cu TREATED | Q4: Ni RESULT | R4: Ni QUAL | S4: Ni VALID | T4: Ni TREATED | U4: Zn RESULT | V4: Zn QUAL | W4: Zn VALID | X4: Zn TREATED | Y4: CN RESULT | Z4: CN QUAL | AA4: CN VALID | AB4: CN TREATED | AC4: FIELD PH | AD4: LAB REPORT DATE | AE4: METALS ANALYZED | AF4: NICKEL ANALYZED | AG4: CYANIDE ANALYZED | AH4: METALS HOLD DAYS | AI4: NICKEL HOLD DAYS | AJ4: CYANIDE HOLD DAYS | AK4: COLLECTED, SERIAL | AL4: METALS ANALYZED, SERIAL | AM4: NICKEL ANALYZED, SERIAL | AN4: CYANIDE ANALYZED, SERIAL
A5: VP-260407 | B5: 04/07/2026 | C5: Apr | D5: Routine | E5: 0.005 | F5: U | G5: =IF(F5="NS","N",IF($AH5>Parameters!$B$23,"N","Y")) -> Y | H5: =IF(F5="U",0,E5) -> 0 | I5: 0.62 | K5: =IF(J5="NS","N",IF($AH5>Parameters!$B$23,"N","Y")) -> Y | L5: =IF(J5="U",0,I5) -> 0.62 | M5: 1.84 | O5: =IF(N5="NS","N",IF($AH5>Parameters!$B$23,"N","Y")) -> Y | P5: =IF(N5="U",0,M5) -> 1.84 | Q5: 0.91 | S5: =IF(R5="NS","N",IF($AI5>Parameters!$B$23,"N","Y")) -> Y | T5: =IF(R5="U",0,Q5) -> 0.91 | U5: 0.74 | W5: =IF(V5="NS","N",IF($AH5>Parameters!$B$23,"N","Y")) -> Y | X5: =IF(V5="U",0,U5) -> 0.74 | Y5: 0.18 | AA5: =IF(Z5="NS","N",IF($AJ5>Parameters!$B$24,"N","Y")) -> Y | AB5: =IF(Z5="U",0,Y5) -> 0.18 | AC5: 7.4 | AD5: 04/17/2026 | AE5: 04/11/2026 | AF5: 04/11/2026 | AG5: 04/12/2026 | AH5: =_xlfn.DAYS(AL5,AK5) -> 4 | AI5: =_xlfn.DAYS(AM5,AK5) -> 4 | AJ5: =_xlfn.DAYS(AN5,AK5) -> 5 | AK5: =DATE(VALUE(RIGHT(B5,4)),VALUE(LEFT(B5,2)),VALUE(MID(B5,4,2))) -> 46119 | AL5: =DATE(VALUE(RIGHT(AE5,4)),VALUE(LEFT(AE5,2)),VALUE(MID(AE5,4,2))) -> 46123 | AM5: =DATE(VALUE(RIGHT(AF5,4)),VALUE(LEFT(AF5,2)),VALUE(MID(AF5,4,2))) -> 46123 | AN5: =DATE(VALUE(RIGHT(AG5,4)),VALUE(LEFT(AG5,2)),VALUE(MID(AG5,4,2))) -> 46124
A6: VP-260421 | B6: 04/21/2026 | C6: Apr | D6: Routine | E6: 0.012 | G6: =IF(F6="NS","N",IF($AH6>Parameters!$B$23,"N","Y")) -> Y | H6: =IF(F6="U",0,E6) -> 0.012 | I6: 0.48 | K6: =IF(J6="NS","N",IF($AH6>Parameters!$B$23,"N","Y")) -> Y | L6: =IF(J6="U",0,I6) -> 0.48 | M6: 3.62 | O6: =IF(N6="NS","N",IF($AH6>Parameters!$B$23,"N","Y")) -> Y | P6: =IF(N6="U",0,M6) -> 3.62 | Q6: 1.44 | S6: =IF(R6="NS","N",IF($AI6>Parameters!$B$23,"N","Y")) -> Y | T6: =IF(R6="U",0,Q6) -> 1.44 | U6: 1.12 | W6: =IF(V6="NS","N",IF($AH6>Parameters!$B$23,"N","Y")) -> Y | X6: =IF(V6="U",0,U6) -> 1.12 | Y6: 0.31 | AA6: =IF(Z6="NS","N",IF($AJ6>Parameters!$B$24,"N","Y")) -> Y | AB6: =IF(Z6="U",0,Y6) -> 0.31 | AC6: 7.1 | AD6: 04/30/2026 | AE6: 04/25/2026 | AF6: 04/25/2026 | AG6: 04/23/2026 | AH6: =_xlfn.DAYS(AL6,AK6) -> 4 | AI6: =_xlfn.DAYS(AM6,AK6) -> 4 | AJ6: =_xlfn.DAYS(AN6,AK6) -> 2 | AK6: =DATE(VALUE(RIGHT(B6,4)),VALUE(LEFT(B6,2)),VALUE(MID(B6,4,2))) -> 46133 | AL6: =DATE(VALUE(RIGHT(AE6,4)),VALUE(LEFT(AE6,2)),VALUE(MID(AE6,4,2))) -> 46137 | AM6: =DATE(VALUE(RIGHT(AF6,4)),VALUE(LEFT(AF6,2)),VALUE(MID(AF6,4,2))) -> 46137 | AN6: =DATE(VALUE(RIGHT(AG6,4)),VALUE(LEFT(AG6,2)),VALUE(MID(AG6,4,2))) -> 46135
A7: VP-260505 | B7: 05/05/2026 | C7: May | D7: Routine | E7: 0.005 | F7: U | G7: =IF(F7="NS","N",IF($AH7>Parameters!$B$23,"N","Y")) -> Y | H7: =IF(F7="U",0,E7) -> 0 | I7: 1.13 | K7: =IF(J7="NS","N",IF($AH7>Parameters!$B$23,"N","Y")) -> Y | L7: =IF(J7="U",0,I7) -> 1.13 | M7: 4.21 | O7: =IF(N7="NS","N",IF($AH7>Parameters!$B$23,"N","Y")) -> Y | P7: =IF(N7="U",0,M7) -> 4.21 | Q7: 0.77 | S7: =IF(R7="NS","N",IF($AI7>Parameters!$B$23,"N","Y")) -> Y | T7: =IF(R7="U",0,Q7) -> 0.77 | U7: 0.68 | W7: =IF(V7="NS","N",IF($AH7>Parameters!$B$23,"N","Y")) -> Y | X7: =IF(V7="U",0,U7) -> 0.68 | Y7: 0.22 | AA7: =IF(Z7="NS","N",IF($AJ7>Parameters!$B$24,"N","Y")) -> Y | AB7: =IF(Z7="U",0,Y7) -> 0.22 | AC7: 8.2 | AD7: 05/14/2026 | AE7: 05/08/2026 | AF7: 05/08/2026 | AG7: 05/10/2026 | AH7: =_xlfn.DAYS(AL7,AK7) -> 3 | AI7: =_xlfn.DAYS(AM7,AK7) -> 3 | AJ7: =_xlfn.DAYS(AN7,AK7) -> 5 | AK7: =DATE(VALUE(RIGHT(B7,4)),VALUE(LEFT(B7,2)),VALUE(MID(B7,4,2))) -> 46147 | AL7: =DATE(VALUE(RIGHT(AE7,4)),VALUE(LEFT(AE7,2)),VALUE(MID(AE7,4,2))) -> 46150 | AM7: =DATE(VALUE(RIGHT(AF7,4)),VALUE(LEFT(AF7,2)),VALUE(MID(AF7,4,2))) -> 46150 | AN7: =DATE(VALUE(RIGHT(AG7,4)),VALUE(LEFT(AG7,2)),VALUE(MID(AG7,4,2))) -> 46152
A8: VP-260519 | B8: 05/19/2026 | C8: May | D8: Routine | E8: 0.005 | F8: U | G8: =IF(F8="NS","N",IF($AH8>Parameters!$B$23,"N","Y")) -> Y | H8: =IF(F8="U",0,E8) -> 0 | I8: 0.71 | K8: =IF(J8="NS","N",IF($AH8>Parameters!$B$23,"N","Y")) -> Y | L8: =IF(J8="U",0,I8) -> 0.71 | M8: 1.95 | O8: =IF(N8="NS","N",IF($AH8>Parameters!$B$23,"N","Y")) -> Y | P8: =IF(N8="U",0,M8) -> 1.95 | Q8: 1.68 | S8: =IF(R8="NS","N",IF($AI8>Parameters!$B$23,"N","Y")) -> Y | T8: =IF(R8="U",0,Q8) -> 1.68 | U8: 0.95 | W8: =IF(V8="NS","N",IF($AH8>Parameters!$B$23,"N","Y")) -> Y | X8: =IF(V8="U",0,U8) -> 0.95 | Y8: 0.008 | Z8: J | AA8: =IF(Z8="NS","N",IF($AJ8>Parameters!$B$24,"N","Y")) -> Y | AB8: =IF(Z8="U",0,Y8) -> 0.008 | AC8: 7.6 | AD8: 05/29/2026 | AE8: 05/26/2026 | AF8: 05/26/2026 | AG8: 05/25/2026 | AH8: =_xlfn.DAYS(AL8,AK8) -> 7 | AI8: =_xlfn.DAYS(AM8,AK8) -> 7 | AJ8: =_xlfn.DAYS(AN8,AK8) -> 6 | AK8: =DATE(VALUE(RIGHT(B8,4)),VALUE(LEFT(B8,2)),VALUE(MID(B8,4,2))) -> 46161 | AL8: =DATE(VALUE(RIGHT(AE8,4)),VALUE(LEFT(AE8,2)),VALUE(MID(AE8,4,2))) -> 46168 | AM8: =DATE(VALUE(RIGHT(AF8,4)),VALUE(LEFT(AF8,2)),VALUE(MID(AF8,4,2))) -> 46168 | AN8: =DATE(VALUE(RIGHT(AG8,4)),VALUE(LEFT(AG8,2)),VALUE(MID(AG8,4,2))) -> 46167
A9: VP-260602 | B9: 06/02/2026 | C9: Jun | D9: Routine | E9: 0.019 | G9: =IF(F9="NS","N",IF($AH9>Parameters!$B$23,"N","Y")) -> Y | H9: =IF(F9="U",0,E9) -> 0.019 | I9: 0.55 | K9: =IF(J9="NS","N",IF($AH9>Parameters!$B$23,"N","Y")) -> Y | L9: =IF(J9="U",0,I9) -> 0.55 | M9: 2.4 | O9: =IF(N9="NS","N",IF($AH9>Parameters!$B$23,"N","Y")) -> Y | P9: =IF(N9="U",0,M9) -> 2.4 | Q9: 1.05 | S9: =IF(R9="NS","N",IF($AI9>Parameters!$B$23,"N","Y")) -> Y | T9: =IF(R9="U",0,Q9) -> 1.05 | U9: 1.31 | W9: =IF(V9="NS","N",IF($AH9>Parameters!$B$23,"N","Y")) -> Y | X9: =IF(V9="U",0,U9) -> 1.31 | Y9: 0.71 | AA9: =IF(Z9="NS","N",IF($AJ9>Parameters!$B$24,"N","Y")) -> Y | AB9: =IF(Z9="U",0,Y9) -> 0.71 | AC9: 6.9 | AD9: 06/12/2026 | AE9: 06/08/2026 | AF9: 06/08/2026 | AG9: 06/07/2026 | AH9: =_xlfn.DAYS(AL9,AK9) -> 6 | AI9: =_xlfn.DAYS(AM9,AK9) -> 6 | AJ9: =_xlfn.DAYS(AN9,AK9) -> 5 | AK9: =DATE(VALUE(RIGHT(B9,4)),VALUE(LEFT(B9,2)),VALUE(MID(B9,4,2))) -> 46175 | AL9: =DATE(VALUE(RIGHT(AE9,4)),VALUE(LEFT(AE9,2)),VALUE(MID(AE9,4,2))) -> 46181 | AM9: =DATE(VALUE(RIGHT(AF9,4)),VALUE(LEFT(AF9,2)),VALUE(MID(AF9,4,2))) -> 46181 | AN9: =DATE(VALUE(RIGHT(AG9,4)),VALUE(LEFT(AG9,2)),VALUE(MID(AG9,4,2))) -> 46180
A10: VP-260616 | B10: 06/16/2026 | C10: Jun | D10: Routine | E10: 0.005 | F10: U | G10: =IF(F10="NS","N",IF($AH10>Parameters!$B$23,"N","Y")) -> Y | H10: =IF(F10="U",0,E10) -> 0 | I10: 0.93 | K10: =IF(J10="NS","N",IF($AH10>Parameters!$B$23,"N","Y")) -> Y | L10: =IF(J10="U",0,I10) -> 0.93 | M10: 3.97 | O10: =IF(N10="NS","N",IF($AH10>Parameters!$B$23,"N","Y")) -> Y | P10: =IF(N10="U",0,M10) -> 3.97 | Q10: 0.83 | S10: =IF(R10="NS","N",IF($AI10>Parameters!$B$23,"N","Y")) -> Y | T10: =IF(R10="U",0,Q10) -> 0.83 | U10: 0.82 | W10: =IF(V10="NS","N",IF($AH10>Parameters!$B$23,"N","Y")) -> Y | X10: =IF(V10="U",0,U10) -> 0.82 | Y10: 0.44 | AA10: =IF(Z10="NS","N",IF($AJ10>Parameters!$B$24,"N","Y")) -> Y | AB10: =IF(Z10="U",0,Y10) -> 0.44 | AC10: 7.8 | AD10: 06/26/2026 | AE10: 07/13/2026 | AF10: 07/13/2026 | AG10: 06/18/2026 | AH10: =_xlfn.DAYS(AL10,AK10) -> 27 | AI10: =_xlfn.DAYS(AM10,AK10) -> 27 | AJ10: =_xlfn.DAYS(AN10,AK10) -> 2 | AK10: =DATE(VALUE(RIGHT(B10,4)),VALUE(LEFT(B10,2)),VALUE(MID(B10,4,2))) -> 46189 | AL10: =DATE(VALUE(RIGHT(AE10,4)),VALUE(LEFT(AE10,2)),VALUE(MID(AE10,4,2))) -> 46216 | AM10: =DATE(VALUE(RIGHT(AF10,4)),VALUE(LEFT(AF10,2)),VALUE(MID(AF10,4,2))) -> 46216 | AN10: =DATE(VALUE(RIGHT(AG10,4)),VALUE(LEFT(AG10,2)),VALUE(MID(AG10,4,2))) -> 46191
A11: VP-260707 | B11: 07/07/2026 | C11: Jul | D11: Routine | E11: 0.005 | F11: U | G11: =IF(F11="NS","N",IF($AH11>Parameters!$B$23,"N","Y")) -> N | H11: =IF(F11="U",0,E11) -> 0 | I11: 0.87 | K11: =IF(J11="NS","N",IF($AH11>Parameters!$B$23,"N","Y")) -> N | L11: =IF(J11="U",0,I11) -> 0.87 | M11: 1.77 | O11: =IF(N11="NS","N",IF($AH11>Parameters!$B$23,"N","Y")) -> N | P11: =IF(N11="U",0,M11) -> 1.77 | Q11: 1.22 | S11: =IF(R11="NS","N",IF($AI11>Parameters!$B$23,"N","Y")) -> N | T11: =IF(R11="U",0,Q11) -> 1.22 | U11: 1.06 | W11: =IF(V11="NS","N",IF($AH11>Parameters!$B$23,"N","Y")) -> N | X11: =IF(V11="U",0,U11) -> 1.06 | Y11: 0.27 | AA11: =IF(Z11="NS","N",IF($AJ11>Parameters!$B$24,"N","Y")) -> Y | AB11: =IF(Z11="U",0,Y11) -> 0.27 | AC11: 7.2 | AD11: 08/07/2026 | AE11: 08/06/2026 | AF11: 08/06/2026 | AG11: 07/13/2026 | AH11: =_xlfn.DAYS(AL11,AK11) -> 30 | AI11: =_xlfn.DAYS(AM11,AK11) -> 30 | AJ11: =_xlfn.DAYS(AN11,AK11) -> 6 | AK11: =DATE(VALUE(RIGHT(B11,4)),VALUE(LEFT(B11,2)),VALUE(MID(B11,4,2))) -> 46210 | AL11: =DATE(VALUE(RIGHT(AE11,4)),VALUE(LEFT(AE11,2)),VALUE(MID(AE11,4,2))) -> 46240 | AM11: =DATE(VALUE(RIGHT(AF11,4)),VALUE(LEFT(AF11,2)),VALUE(MID(AF11,4,2))) -> 46240 | AN11: =DATE(VALUE(RIGHT(AG11,4)),VALUE(LEFT(AG11,2)),VALUE(MID(AG11,4,2))) -> 46216
A12: VP-260721 | B12: 07/21/2026 | C12: Jul | D12: Routine | E12: 0.005 | F12: U | G12: =IF(F12="NS","N",IF($AH12>Parameters!$B$23,"N","Y")) -> Y | H12: =IF(F12="U",0,E12) -> 0 | I12: 1.21 | K12: =IF(J12="NS","N",IF($AH12>Parameters!$B$23,"N","Y")) -> Y | L12: =IF(J12="U",0,I12) -> 1.21 | M12: 4.09 | O12: =IF(N12="NS","N",IF($AH12>Parameters!$B$23,"N","Y")) -> Y | P12: =IF(N12="U",0,M12) -> 4.09 | Q12: 1.57 | S12: =IF(R12="NS","N",IF($AI12>Parameters!$B$23,"N","Y")) -> Y | T12: =IF(R12="U",0,Q12) -> 1.57 | U12: 1.27 | W12: =IF(V12="NS","N",IF($AH12>Parameters!$B$23,"N","Y")) -> Y | X12: =IF(V12="U",0,U12) -> 1.27 | Y12: 0.35 | AA12: =IF(Z12="NS","N",IF($AJ12>Parameters!$B$24,"N","Y")) -> Y | AB12: =IF(Z12="U",0,Y12) -> 0.35 | AC12: 8.4 | AD12: 07/30/2026 | AE12: 07/26/2026 | AF12: 07/26/2026 | AG12: 07/25/2026 | AH12: =_xlfn.DAYS(AL12,AK12) -> 5 | AI12: =_xlfn.DAYS(AM12,AK12) -> 5 | AJ12: =_xlfn.DAYS(AN12,AK12) -> 4 | AK12: =DATE(VALUE(RIGHT(B12,4)),VALUE(LEFT(B12,2)),VALUE(MID(B12,4,2))) -> 46224 | AL12: =DATE(VALUE(RIGHT(AE12,4)),VALUE(LEFT(AE12,2)),VALUE(MID(AE12,4,2))) -> 46229 | AM12: =DATE(VALUE(RIGHT(AF12,4)),VALUE(LEFT(AF12,2)),VALUE(MID(AF12,4,2))) -> 46229 | AN12: =DATE(VALUE(RIGHT(AG12,4)),VALUE(LEFT(AG12,2)),VALUE(MID(AG12,4,2))) -> 46228
A13: VP-260811 | B13: 08/11/2026 | C13: Aug | D13: Routine | E13: 0.014 | G13: =IF(F13="NS","N",IF($AH13>Parameters!$B$23,"N","Y")) -> Y | H13: =IF(F13="U",0,E13) -> 0.014 | I13: 0.66 | K13: =IF(J13="NS","N",IF($AH13>Parameters!$B$23,"N","Y")) -> Y | L13: =IF(J13="U",0,I13) -> 0.66 | M13: 4.33 | O13: =IF(N13="NS","N",IF($AH13>Parameters!$B$23,"N","Y")) -> Y | P13: =IF(N13="U",0,M13) -> 4.33 | Q13: 2.61 | S13: =IF(R13="NS","N",IF($AI13>Parameters!$B$23,"N","Y")) -> Y | T13: =IF(R13="U",0,Q13) -> 2.61 | U13: 0.89 | W13: =IF(V13="NS","N",IF($AH13>Parameters!$B$23,"N","Y")) -> Y | X13: =IF(V13="U",0,U13) -> 0.89 | Y13: 0.19 | AA13: =IF(Z13="NS","N",IF($AJ13>Parameters!$B$24,"N","Y")) -> Y | AB13: =IF(Z13="U",0,Y13) -> 0.19 | AC13: 6.8 | AD13: 08/20/2026 | AE13: 08/15/2026 | AF13: 08/15/2026 | AG13: 08/14/2026 | AH13: =_xlfn.DAYS(AL13,AK13) -> 4 | AI13: =_xlfn.DAYS(AM13,AK13) -> 4 | AJ13: =_xlfn.DAYS(AN13,AK13) -> 3 | AK13: =DATE(VALUE(RIGHT(B13,4)),VALUE(LEFT(B13,2)),VALUE(MID(B13,4,2))) -> 46245 | AL13: =DATE(VALUE(RIGHT(AE13,4)),VALUE(LEFT(AE13,2)),VALUE(MID(AE13,4,2))) -> 46249 | AM13: =DATE(VALUE(RIGHT(AF13,4)),VALUE(LEFT(AF13,2)),VALUE(MID(AF13,4,2))) -> 46249 | AN13: =DATE(VALUE(RIGHT(AG13,4)),VALUE(LEFT(AG13,2)),VALUE(MID(AG13,4,2))) -> 46248
A14: VP-260825 | B14: 08/25/2026 | C14: Aug | D14: Routine | E14: 0.005 | F14: U | G14: =IF(F14="NS","N",IF($AH14>Parameters!$B$23,"N","Y")) -> Y | H14: =IF(F14="U",0,E14) -> 0 | I14: 0.74 | K14: =IF(J14="NS","N",IF($AH14>Parameters!$B$23,"N","Y")) -> Y | L14: =IF(J14="U",0,I14) -> 0.74 | M14: 4.15 | O14: =IF(N14="NS","N",IF($AH14>Parameters!$B$23,"N","Y")) -> Y | P14: =IF(N14="U",0,M14) -> 4.15 | Q14: 1.9 | S14: =IF(R14="NS","N",IF($AI14>Parameters!$B$23,"N","Y")) -> N | T14: =IF(R14="U",0,Q14) -> 1.9 | U14: 1.18 | W14: =IF(V14="NS","N",IF($AH14>Parameters!$B$23,"N","Y")) -> Y | X14: =IF(V14="U",0,U14) -> 1.18 | Y14: 0.29 | AA14: =IF(Z14="NS","N",IF($AJ14>Parameters!$B$24,"N","Y")) -> Y | AB14: =IF(Z14="U",0,Y14) -> 0.29 | AC14: 7.5 | AD14: 09/04/2026 | AE14: 08/29/2026 | AF14: 09/28/2026 | AG14: 08/27/2026 | AH14: =_xlfn.DAYS(AL14,AK14) -> 4 | AI14: =_xlfn.DAYS(AM14,AK14) -> 34 | AJ14: =_xlfn.DAYS(AN14,AK14) -> 2 | AK14: =DATE(VALUE(RIGHT(B14,4)),VALUE(LEFT(B14,2)),VALUE(MID(B14,4,2))) -> 46259 | AL14: =DATE(VALUE(RIGHT(AE14,4)),VALUE(LEFT(AE14,2)),VALUE(MID(AE14,4,2))) -> 46263 | AM14: =DATE(VALUE(RIGHT(AF14,4)),VALUE(LEFT(AF14,2)),VALUE(MID(AF14,4,2))) -> 46293 | AN14: =DATE(VALUE(RIGHT(AG14,4)),VALUE(LEFT(AG14,2)),VALUE(MID(AG14,4,2))) -> 46261
A15: VP-260909 | B15: 09/09/2026 | C15: Sep | D15: Routine | E15: 0.012 | G15: =IF(F15="NS","N",IF($AH15>Parameters!$B$23,"N","Y")) -> Y | H15: =IF(F15="U",0,E15) -> 0.012 | I15: 1.02 | K15: =IF(J15="NS","N",IF($AH15>Parameters!$B$23,"N","Y")) -> Y | L15: =IF(J15="U",0,I15) -> 1.02 | M15: 2.96 | O15: =IF(N15="NS","N",IF($AH15>Parameters!$B$23,"N","Y")) -> Y | P15: =IF(N15="U",0,M15) -> 2.96 | Q15: 1.36 | S15: =IF(R15="NS","N",IF($AI15>Parameters!$B$23,"N","Y")) -> Y | T15: =IF(R15="U",0,Q15) -> 1.36 | U15: 3.14 | W15: =IF(V15="NS","N",IF($AH15>Parameters!$B$23,"N","Y")) -> Y | X15: =IF(V15="U",0,U15) -> 3.14 | Y15: 0.41 | AA15: =IF(Z15="NS","N",IF($AJ15>Parameters!$B$24,"N","Y")) -> Y | AB15: =IF(Z15="U",0,Y15) -> 0.41 | AC15: 7.9 | AD15: 09/15/2026 | AE15: 09/12/2026 | AF15: 09/12/2026 | AG15: 09/22/2026 | AH15: =_xlfn.DAYS(AL15,AK15) -> 3 | AI15: =_xlfn.DAYS(AM15,AK15) -> 3 | AJ15: =_xlfn.DAYS(AN15,AK15) -> 13 | AK15: =DATE(VALUE(RIGHT(B15,4)),VALUE(LEFT(B15,2)),VALUE(MID(B15,4,2))) -> 46274 | AL15: =DATE(VALUE(RIGHT(AE15,4)),VALUE(LEFT(AE15,2)),VALUE(MID(AE15,4,2))) -> 46277 | AM15: =DATE(VALUE(RIGHT(AF15,4)),VALUE(LEFT(AF15,2)),VALUE(MID(AF15,4,2))) -> 46277 | AN15: =DATE(VALUE(RIGHT(AG15,4)),VALUE(LEFT(AG15,2)),VALUE(MID(AG15,4,2))) -> 46287
A16: VP-260922 | B16: 09/22/2026 | C16: Sep | D16: Routine | E16: 0.005 | F16: U | G16: =IF(F16="NS","N",IF($AH16>Parameters!$B$23,"N","Y")) -> Y | H16: =IF(F16="U",0,E16) -> 0 | I16: 0.58 | K16: =IF(J16="NS","N",IF($AH16>Parameters!$B$23,"N","Y")) -> Y | L16: =IF(J16="U",0,I16) -> 0.58 | M16: 1.68 | O16: =IF(N16="NS","N",IF($AH16>Parameters!$B$23,"N","Y")) -> Y | P16: =IF(N16="U",0,M16) -> 1.68 | Q16: 0.98 | S16: =IF(R16="NS","N",IF($AI16>Parameters!$B$23,"N","Y")) -> Y | T16: =IF(R16="U",0,Q16) -> 0.98 | U16: 0.94 | W16: =IF(V16="NS","N",IF($AH16>Parameters!$B$23,"N","Y")) -> Y | X16: =IF(V16="U",0,U16) -> 0.94 | Y16: 0.24 | AA16: =IF(Z16="NS","N",IF($AJ16>Parameters!$B$24,"N","Y")) -> Y | AB16: =IF(Z16="U",0,Y16) -> 0.24 | AC16: 7.3 | AD16: 10/01/2026 | AE16: 09/30/2026 | AF16: 09/30/2026 | AG16: 09/28/2026 | AH16: =_xlfn.DAYS(AL16,AK16) -> 8 | AI16: =_xlfn.DAYS(AM16,AK16) -> 8 | AJ16: =_xlfn.DAYS(AN16,AK16) -> 6 | AK16: =DATE(VALUE(RIGHT(B16,4)),VALUE(LEFT(B16,2)),VALUE(MID(B16,4,2))) -> 46287 | AL16: =DATE(VALUE(RIGHT(AE16,4)),VALUE(LEFT(AE16,2)),VALUE(MID(AE16,4,2))) -> 46295 | AM16: =DATE(VALUE(RIGHT(AF16,4)),VALUE(LEFT(AF16,2)),VALUE(MID(AF16,4,2))) -> 46295 | AN16: =DATE(VALUE(RIGHT(AG16,4)),VALUE(LEFT(AG16,2)),VALUE(MID(AG16,4,2))) -> 46293
A17: VP-260923 | B17: 09/23/2026 | C17: Sep | D17: Resample | E17: 0.005 | F17: U | G17: =IF(F17="NS","N",IF($AH17>Parameters!$B$23,"N","Y")) -> Y | H17: =IF(F17="U",0,E17) -> 0 | I17: 0.49 | K17: =IF(J17="NS","N",IF($AH17>Parameters!$B$23,"N","Y")) -> Y | L17: =IF(J17="U",0,I17) -> 0.49 | M17: 1.52 | O17: =IF(N17="NS","N",IF($AH17>Parameters!$B$23,"N","Y")) -> Y | P17: =IF(N17="U",0,M17) -> 1.52 | Q17: 1.11 | S17: =IF(R17="NS","N",IF($AI17>Parameters!$B$23,"N","Y")) -> Y | T17: =IF(R17="U",0,Q17) -> 1.11 | U17: 0.88 | W17: =IF(V17="NS","N",IF($AH17>Parameters!$B$23,"N","Y")) -> Y | X17: =IF(V17="U",0,U17) -> 0.88 | Z17: NS | AA17: =IF(Z17="NS","N",IF($AJ17>Parameters!$B$24,"N","Y")) -> N | AB17: =IF(Z17="U",0,Y17) -> 0 | AC17: 7.4 | AD17: 10/01/2026 | AE17: 09/26/2026 | AF17: 09/26/2026 | AG17: not collected | AH17: =_xlfn.DAYS(AL17,AK17) -> 3 | AI17: =_xlfn.DAYS(AM17,AK17) -> 3 | AJ17: not collected | AK17: =DATE(VALUE(RIGHT(B17,4)),VALUE(LEFT(B17,2)),VALUE(MID(B17,4,2))) -> 46288 | AL17: =DATE(VALUE(RIGHT(AE17,4)),VALUE(LEFT(AE17,2)),VALUE(MID(AE17,4,2))) -> 46291 | AM17: =DATE(VALUE(RIGHT(AF17,4)),VALUE(LEFT(AF17,2)),VALUE(MID(AF17,4,2))) -> 46291 | AN17: not collected

Sheet Monthly Stats
A1: Monthly averages and daily maximums by parameter, April through September 2026
A2: Monthly average is the arithmetic mean of the valid results in the month, resamples included, non-detects at zero (Section 2.2); daily maximum is the highest valid result in the month. A result analyzed outside its holding period is not a valid sample, and a month with fewer valid samples than required is monitored below frequency (Section 2.3).
A4: MONTH | B4: PARAMETER | C4: DAILY MAXIMUM LIMIT | D4: MONTHLY AVERAGE LIMIT | E4: VALID SAMPLES | F4: REQUIRED | G4: MONTHLY AVERAGE | H4: DAILY MAXIMUM | I4: MONTHLY AVERAGE STATUS | J4: DAILY MAXIMUM STATUS | K4: FREQUENCY STATUS
A5: Apr | B5: Cadmium, total | C5: =Parameters!$B$4 -> 0.11 | D5: =Parameters!$C$4 -> 0.07 | E5: =COUNTIFS('Lab Data'!$C$5:$C$17,"Apr",'Lab Data'!$G$5:$G$17,"Y") -> 2 | F5: =Parameters!$B$15 -> 2 | G5: =ROUND(AVERAGEIFS('Lab Data'!$H$5:$H$17,'Lab Data'!$C$5:$C$17,"Apr",'Lab Data'!$G$5:$G$17,"Y"),3) -> 0.006 | H5: =_xlfn.MAXIFS('Lab Data'!$H$5:$H$17,'Lab Data'!$C$5:$C$17,"Apr",'Lab Data'!$G$5:$G$17,"Y") -> 0.012 | I5: =IF(G5<=D5,"Met","Exceeded") -> Met | J5: =IF(H5<=C5,"Met","Exceeded") -> Met | K5: =IF(E5>=F5,"Met","Below frequency") -> Met
A6: Apr | B6: Chromium, total | C6: =Parameters!$B$5 -> 2.77 | D6: =Parameters!$C$5 -> 1.71 | E6: =COUNTIFS('Lab Data'!$C$5:$C$17,"Apr",'Lab Data'!$K$5:$K$17,"Y") -> 2 | F6: =Parameters!$B$15 -> 2 | G6: =ROUND(AVERAGEIFS('Lab Data'!$L$5:$L$17,'Lab Data'!$C$5:$C$17,"Apr",'Lab Data'!$K$5:$K$17,"Y"),3) -> 0.55 | H6: =_xlfn.MAXIFS('Lab Data'!$L$5:$L$17,'Lab Data'!$C$5:$C$17,"Apr",'Lab Data'!$K$5:$K$17,"Y") -> 0.62 | I6: =IF(G6<=D6,"Met","Exceeded") -> Met | J6: =IF(H6<=C6,"Met","Exceeded") -> Met | K6: =IF(E6>=F6,"Met","Below frequency") -> Met
A7: Apr | B7: Copper, total | C7: =Parameters!$B$6 -> 3.38 | D7: =Parameters!$C$6 -> 2.07 | E7: =COUNTIFS('Lab Data'!$C$5:$C$17,"Apr",'Lab Data'!$O$5:$O$17,"Y") -> 2 | F7: =Parameters!$B$15 -> 2 | G7: =ROUND(AVERAGEIFS('Lab Data'!$P$5:$P$17,'Lab Data'!$C$5:$C$17,"Apr",'Lab Data'!$O$5:$O$17,"Y"),3) -> 2.73 | H7: =_xlfn.MAXIFS('Lab Data'!$P$5:$P$17,'Lab Data'!$C$5:$C$17,"Apr",'Lab Data'!$O$5:$O$17,"Y") -> 3.62 | I7: =IF(G7<=D7,"Met","Exceeded") -> Exceeded | J7: =IF(H7<=C7,"Met","Exceeded") -> Exceeded | K7: =IF(E7>=F7,"Met","Below frequency") -> Met
A8: Apr | B8: Nickel, total | C8: =Parameters!$B$7 -> 3.98 | D8: =Parameters!$C$7 -> 2.38 | E8: =COUNTIFS('Lab Data'!$C$5:$C$17,"Apr",'Lab Data'!$S$5:$S$17,"Y") -> 2 | F8: =Parameters!$B$15 -> 2 | G8: =ROUND(AVERAGEIFS('Lab Data'!$T$5:$T$17,'Lab Data'!$C$5:$C$17,"Apr",'Lab Data'!$S$5:$S$17,"Y"),3) -> 1.175 | H8: =_xlfn.MAXIFS('Lab Data'!$T$5:$T$17,'Lab Data'!$C$5:$C$17,"Apr",'Lab Data'!$S$5:$S$17,"Y") -> 1.44 | I8: =IF(G8<=D8,"Met","Exceeded") -> Met | J8: =IF(H8<=C8,"Met","Exceeded") -> Met | K8: =IF(E8>=F8,"Met","Below frequency") -> Met
A9: Apr | B9: Zinc, total | C9: =Parameters!$B$8 -> 2.61 | D9: =Parameters!$C$8 -> 1.48 | E9: =COUNTIFS('Lab Data'!$C$5:$C$17,"Apr",'Lab Data'!$W$5:$W$17,"Y") -> 2 | F9: =Parameters!$B$15 -> 2 | G9: =ROUND(AVERAGEIFS('Lab Data'!$X$5:$X$17,'Lab Data'!$C$5:$C$17,"Apr",'Lab Data'!$W$5:$W$17,"Y"),3) -> 0.93 | H9: =_xlfn.MAXIFS('Lab Data'!$X$5:$X$17,'Lab Data'!$C$5:$C$17,"Apr",'Lab Data'!$W$5:$W$17,"Y") -> 1.12 | I9: =IF(G9<=D9,"Met","Exceeded") -> Met | J9: =IF(H9<=C9,"Met","Exceeded") -> Met | K9: =IF(E9>=F9,"Met","Below frequency") -> Met
A10: Apr | B10: Cyanide, total | C10: =Parameters!$B$9 -> 1.2 | D10: =Parameters!$C$9 -> 0.65 | E10: =COUNTIFS('Lab Data'!$C$5:$C$17,"Apr",'Lab Data'!$AA$5:$AA$17,"Y") -> 2 | F10: =Parameters!$B$15 -> 2 | G10: =ROUND(AVERAGEIFS('Lab Data'!$AB$5:$AB$17,'Lab Data'!$C$5:$C$17,"Apr",'Lab Data'!$AA$5:$AA$17,"Y"),3) -> 0.245 | H10: =_xlfn.MAXIFS('Lab Data'!$AB$5:$AB$17,'Lab Data'!$C$5:$C$17,"Apr",'Lab Data'!$AA$5:$AA$17,"Y") -> 0.31 | I10: =IF(G10<=D10,"Met","Exceeded") -> Met | J10: =IF(H10<=C10,"Met","Exceeded") -> Met | K10: =IF(E10>=F10,"Met","Below frequency") -> Met
A11: May | B11: Cadmium, total | C11: =Parameters!$B$4 -> 0.11 | D11: =Parameters!$C$4 -> 0.07 | E11: =COUNTIFS('Lab Data'!$C$5:$C$17,"May",'Lab Data'!$G$5:$G$17,"Y") -> 2 | F11: =Parameters!$B$15 -> 2 | G11: =ROUND(AVERAGEIFS('Lab Data'!$H$5:$H$17,'Lab Data'!$C$5:$C$17,"May",'Lab Data'!$G$5:$G$17,"Y"),3) -> 0 | H11: =_xlfn.MAXIFS('Lab Data'!$H$5:$H$17,'Lab Data'!$C$5:$C$17,"May",'Lab Data'!$G$5:$G$17,"Y") -> 0 | I11: =IF(G11<=D11,"Met","Exceeded") -> Met | J11: =IF(H11<=C11,"Met","Exceeded") -> Met | K11: =IF(E11>=F11,"Met","Below frequency") -> Met
A12: May | B12: Chromium, total | C12: =Parameters!$B$5 -> 2.77 | D12: =Parameters!$C$5 -> 1.71 | E12: =COUNTIFS('Lab Data'!$C$5:$C$17,"May",'Lab Data'!$K$5:$K$17,"Y") -> 2 | F12: =Parameters!$B$15 -> 2 | G12: =ROUND(AVERAGEIFS('Lab Data'!$L$5:$L$17,'Lab Data'!$C$5:$C$17,"May",'Lab Data'!$K$5:$K$17,"Y"),3) -> 0.92 | H12: =_xlfn.MAXIFS('Lab Data'!$L$5:$L$17,'Lab Data'!$C$5:$C$17,"May",'Lab Data'!$K$5:$K$17,"Y") -> 1.13 | I12: =IF(G12<=D12,"Met","Exceeded") -> Met | J12: =IF(H12<=C12,"Met","Exceeded") -> Met | K12: =IF(E12>=F12,"Met","Below frequency") -> Met
A13: May | B13: Copper, total | C13: =Parameters!$B$6 -> 3.38 | D13: =Parameters!$C$6 -> 2.07 | E13: =COUNTIFS('Lab Data'!$C$5:$C$17,"May",'Lab Data'!$O$5:$O$17,"Y") -> 2 | F13: =Parameters!$B$15 -> 2 | G13: =ROUND(AVERAGEIFS('Lab Data'!$P$5:$P$17,'Lab Data'!$C$5:$C$17,"May",'Lab Data'!$O$5:$O$17,"Y"),3) -> 3.08 | H13: =_xlfn.MAXIFS('Lab Data'!$P$5:$P$17,'Lab Data'!$C$5:$C$17,"May",'Lab Data'!$O$5:$O$17,"Y") -> 4.21 | I13: =IF(G13<=D13,"Met","Exceeded") -> Exceeded | J13: =IF(H13<=C13,"Met","Exceeded") -> Exceeded | K13: =IF(E13>=F13,"Met","Below frequency") -> Met
A14: May | B14: Nickel, total | C14: =Parameters!$B$7 -> 3.98 | D14: =Parameters!$C$7 -> 2.38 | E14: =COUNTIFS('Lab Data'!$C$5:$C$17,"May",'Lab Data'!$S$5:$S$17,"Y") -> 2 | F14: =Parameters!$B$15 -> 2 | G14: =ROUND(AVERAGEIFS('Lab Data'!$T$5:$T$17,'Lab Data'!$C$5:$C$17,"May",'Lab Data'!$S$5:$S$17,"Y"),3) -> 1.225 | H14: =_xlfn.MAXIFS('Lab Data'!$T$5:$T$17,'Lab Data'!$C$5:$C$17,"May",'Lab Data'!$S$5:$S$17,"Y") -> 1.68 | I14: =IF(G14<=D14,"Met","Exceeded") -> Met | J14: =IF(H14<=C14,"Met","Exceeded") -> Met | K14: =IF(E14>=F14,"Met","Below frequency") -> Met
A15: May | B15: Zinc, total | C15: =Parameters!$B$8 -> 2.61 | D15: =Parameters!$C$8 -> 1.48 | E15: =COUNTIFS('Lab Data'!$C$5:$C$17,"May",'Lab Data'!$W$5:$W$17,"Y") -> 2 | F15: =Parameters!$B$15 -> 2 | G15: =ROUND(AVERAGEIFS('Lab Data'!$X$5:$X$17,'Lab Data'!$C$5:$C$17,"May",'Lab Data'!$W$5:$W$17,"Y"),3) -> 0.815 | H15: =_xlfn.MAXIFS('Lab Data'!$X$5:$X$17,'Lab Data'!$C$5:$C$17,"May",'Lab Data'!$W$5:$W$17,"Y") -> 0.95 | I15: =IF(G15<=D15,"Met","Exceeded") -> Met | J15: =IF(H15<=C15,"Met","Exceeded") -> Met | K15: =IF(E15>=F15,"Met","Below frequency") -> Met
A16: May | B16: Cyanide, total | C16: =Parameters!$B$9 -> 1.2 | D16: =Parameters!$C$9 -> 0.65 | E16: =COUNTIFS('Lab Data'!$C$5:$C$17,"May",'Lab Data'!$AA$5:$AA$17,"Y") -> 2 | F16: =Parameters!$B$15 -> 2 | G16: =ROUND(AVERAGEIFS('Lab Data'!$AB$5:$AB$17,'Lab Data'!$C$5:$C$17,"May",'Lab Data'!$AA$5:$AA$17,"Y"),3) -> 0.114 | H16: =_xlfn.MAXIFS('Lab Data'!$AB$5:$AB$17,'Lab Data'!$C$5:$C$17,"May",'Lab Data'!$AA$5:$AA$17,"Y") -> 0.22 | I16: =IF(G16<=D16,"Met","Exceeded") -> Met | J16: =IF(H16<=C16,"Met","Exceeded") -> Met | K16: =IF(E16>=F16,"Met","Below frequency") -> Met
A17: Jun | B17: Cadmium, total | C17: =Parameters!$B$4 -> 0.11 | D17: =Parameters!$C$4 -> 0.07 | E17: =COUNTIFS('Lab Data'!$C$5:$C$17,"Jun",'Lab Data'!$G$5:$G$17,"Y") -> 2 | F17: =Parameters!$B$15 -> 2 | G17: =ROUND(AVERAGEIFS('Lab Data'!$H$5:$H$17,'Lab Data'!$C$5:$C$17,"Jun",'Lab Data'!$G$5:$G$17,"Y"),3) -> 0.01 | H17: =_xlfn.MAXIFS('Lab Data'!$H$5:$H$17,'Lab Data'!$C$5:$C$17,"Jun",'Lab Data'!$G$5:$G$17,"Y") -> 0.019 | I17: =IF(G17<=D17,"Met","Exceeded") -> Met | J17: =IF(H17<=C17,"Met","Exceeded") -> Met | K17: =IF(E17>=F17,"Met","Below frequency") -> Met
A18: Jun | B18: Chromium, total | C18: =Parameters!$B$5 -> 2.77 | D18: =Parameters!$C$5 -> 1.71 | E18: =COUNTIFS('Lab Data'!$C$5:$C$17,"Jun",'Lab Data'!$K$5:$K$17,"Y") -> 2 | F18: =Parameters!$B$15 -> 2 | G18: =ROUND(AVERAGEIFS('Lab Data'!$L$5:$L$17,'Lab Data'!$C$5:$C$17,"Jun",'Lab Data'!$K$5:$K$17,"Y"),3) -> 0.74 | H18: =_xlfn.MAXIFS('Lab Data'!$L$5:$L$17,'Lab Data'!$C$5:$C$17,"Jun",'Lab Data'!$K$5:$K$17,"Y") -> 0.93 | I18: =IF(G18<=D18,"Met","Exceeded") -> Met | J18: =IF(H18<=C18,"Met","Exceeded") -> Met | K18: =IF(E18>=F18,"Met","Below frequency") -> Met
A19: Jun | B19: Copper, total | C19: =Parameters!$B$6 -> 3.38 | D19: =Parameters!$C$6 -> 2.07 | E19: =COUNTIFS('Lab Data'!$C$5:$C$17,"Jun",'Lab Data'!$O$5:$O$17,"Y") -> 2 | F19: =Parameters!$B$15 -> 2 | G19: =ROUND(AVERAGEIFS('Lab Data'!$P$5:$P$17,'Lab Data'!$C$5:$C$17,"Jun",'Lab Data'!$O$5:$O$17,"Y"),3) -> 3.185 | H19: =_xlfn.MAXIFS('Lab Data'!$P$5:$P$17,'Lab Data'!$C$5:$C$17,"Jun",'Lab Data'!$O$5:$O$17,"Y") -> 3.97 | I19: =IF(G19<=D19,"Met","Exceeded") -> Exceeded | J19: =IF(H19<=C19,"Met","Exceeded") -> Exceeded | K19: =IF(E19>=F19,"Met","Below frequency") -> Met
A20: Jun | B20: Nickel, total | C20: =Parameters!$B$7 -> 3.98 | D20: =Parameters!$C$7 -> 2.38 | E20: =COUNTIFS('Lab Data'!$C$5:$C$17,"Jun",'Lab Data'!$S$5:$S$17,"Y") -> 2 | F20: =Parameters!$B$15 -> 2 | G20: =ROUND(AVERAGEIFS('Lab Data'!$T$5:$T$17,'Lab Data'!$C$5:$C$17,"Jun",'Lab Data'!$S$5:$S$17,"Y"),3) -> 0.94 | H20: =_xlfn.MAXIFS('Lab Data'!$T$5:$T$17,'Lab Data'!$C$5:$C$17,"Jun",'Lab Data'!$S$5:$S$17,"Y") -> 1.05 | I20: =IF(G20<=D20,"Met","Exceeded") -> Met | J20: =IF(H20<=C20,"Met","Exceeded") -> Met | K20: =IF(E20>=F20,"Met","Below frequency") -> Met
A21: Jun | B21: Zinc, total | C21: =Parameters!$B$8 -> 2.61 | D21: =Parameters!$C$8 -> 1.48 | E21: =COUNTIFS('Lab Data'!$C$5:$C$17,"Jun",'Lab Data'!$W$5:$W$17,"Y") -> 2 | F21: =Parameters!$B$15 -> 2 | G21: =ROUND(AVERAGEIFS('Lab Data'!$X$5:$X$17,'Lab Data'!$C$5:$C$17,"Jun",'Lab Data'!$W$5:$W$17,"Y"),3) -> 1.065 | H21: =_xlfn.MAXIFS('Lab Data'!$X$5:$X$17,'Lab Data'!$C$5:$C$17,"Jun",'Lab Data'!$W$5:$W$17,"Y") -> 1.31 | I21: =IF(G21<=D21,"Met","Exceeded") -> Met | J21: =IF(H21<=C21,"Met","Exceeded") -> Met | K21: =IF(E21>=F21,"Met","Below frequency") -> Met
A22: Jun | B22: Cyanide, total | C22: =Parameters!$B$9 -> 1.2 | D22: =Parameters!$C$9 -> 0.65 | E22: =COUNTIFS('Lab Data'!$C$5:$C$17,"Jun",'Lab Data'!$AA$5:$AA$17,"Y") -> 2 | F22: =Parameters!$B$15 -> 2 | G22: =ROUND(AVERAGEIFS('Lab Data'!$AB$5:$AB$17,'Lab Data'!$C$5:$C$17,"Jun",'Lab Data'!$AA$5:$AA$17,"Y"),3) -> 0.575 | H22: =_xlfn.MAXIFS('Lab Data'!$AB$5:$AB$17,'Lab Data'!$C$5:$C$17,"Jun",'Lab Data'!$AA$5:$AA$17,"Y") -> 0.71 | I22: =IF(G22<=D22,"Met","Exceeded") -> Met | J22: =IF(H22<=C22,"Met","Exceeded") -> Met | K22: =IF(E22>=F22,"Met","Below frequency") -> Met
A23: Jul | B23: Cadmium, total | C23: =Parameters!$B$4 -> 0.11 | D23: =Parameters!$C$4 -> 0.07 | E23: =COUNTIFS('Lab Data'!$C$5:$C$17,"Jul",'Lab Data'!$G$5:$G$17,"Y") -> 1 | F23: =Parameters!$B$15 -> 2 | G23: =ROUND(AVERAGEIFS('Lab Data'!$H$5:$H$17,'Lab Data'!$C$5:$C$17,"Jul",'Lab Data'!$G$5:$G$17,"Y"),3) -> 0 | H23: =_xlfn.MAXIFS('Lab Data'!$H$5:$H$17,'Lab Data'!$C$5:$C$17,"Jul",'Lab Data'!$G$5:$G$17,"Y") -> 0 | I23: =IF(G23<=D23,"Met","Exceeded") -> Met | J23: =IF(H23<=C23,"Met","Exceeded") -> Met | K23: =IF(E23>=F23,"Met","Below frequency") -> Below frequency
A24: Jul | B24: Chromium, total | C24: =Parameters!$B$5 -> 2.77 | D24: =Parameters!$C$5 -> 1.71 | E24: =COUNTIFS('Lab Data'!$C$5:$C$17,"Jul",'Lab Data'!$K$5:$K$17,"Y") -> 1 | F24: =Parameters!$B$15 -> 2 | G24: =ROUND(AVERAGEIFS('Lab Data'!$L$5:$L$17,'Lab Data'!$C$5:$C$17,"Jul",'Lab Data'!$K$5:$K$17,"Y"),3) -> 1.21 | H24: =_xlfn.MAXIFS('Lab Data'!$L$5:$L$17,'Lab Data'!$C$5:$C$17,"Jul",'Lab Data'!$K$5:$K$17,"Y") -> 1.21 | I24: =IF(G24<=D24,"Met","Exceeded") -> Met | J24: =IF(H24<=C24,"Met","Exceeded") -> Met | K24: =IF(E24>=F24,"Met","Below frequency") -> Below frequency
A25: Jul | B25: Copper, total | C25: =Parameters!$B$6 -> 3.38 | D25: =Parameters!$C$6 -> 2.07 | E25: =COUNTIFS('Lab Data'!$C$5:$C$17,"Jul",'Lab Data'!$O$5:$O$17,"Y") -> 1 | F25: =Parameters!$B$15 -> 2 | G25: =ROUND(AVERAGEIFS('Lab Data'!$P$5:$P$17,'Lab Data'!$C$5:$C$17,"Jul",'Lab Data'!$O$5:$O$17,"Y"),3) -> 4.09 | H25: =_xlfn.MAXIFS('Lab Data'!$P$5:$P$17,'Lab Data'!$C$5:$C$17,"Jul",'Lab Data'!$O$5:$O$17,"Y") -> 4.09 | I25: =IF(G25<=D25,"Met","Exceeded") -> Exceeded | J25: =IF(H25<=C25,"Met","Exceeded") -> Exceeded | K25: =IF(E25>=F25,"Met","Below frequency") -> Below frequency
A26: Jul | B26: Nickel, total | C26: =Parameters!$B$7 -> 3.98 | D26: =Parameters!$C$7 -> 2.38 | E26: =COUNTIFS('Lab Data'!$C$5:$C$17,"Jul",'Lab Data'!$S$5:$S$17,"Y") -> 1 | F26: =Parameters!$B$15 -> 2 | G26: =ROUND(AVERAGEIFS('Lab Data'!$T$5:$T$17,'Lab Data'!$C$5:$C$17,"Jul",'Lab Data'!$S$5:$S$17,"Y"),3) -> 1.57 | H26: =_xlfn.MAXIFS('Lab Data'!$T$5:$T$17,'Lab Data'!$C$5:$C$17,"Jul",'Lab Data'!$S$5:$S$17,"Y") -> 1.57 | I26: =IF(G26<=D26,"Met","Exceeded") -> Met | J26: =IF(H26<=C26,"Met","Exceeded") -> Met | K26: =IF(E26>=F26,"Met","Below frequency") -> Below frequency
A27: Jul | B27: Zinc, total | C27: =Parameters!$B$8 -> 2.61 | D27: =Parameters!$C$8 -> 1.48 | E27: =COUNTIFS('Lab Data'!$C$5:$C$17,"Jul",'Lab Data'!$W$5:$W$17,"Y") -> 1 | F27: =Parameters!$B$15 -> 2 | G27: =ROUND(AVERAGEIFS('Lab Data'!$X$5:$X$17,'Lab Data'!$C$5:$C$17,"Jul",'Lab Data'!$W$5:$W$17,"Y"),3) -> 1.27 | H27: =_xlfn.MAXIFS('Lab Data'!$X$5:$X$17,'Lab Data'!$C$5:$C$17,"Jul",'Lab Data'!$W$5:$W$17,"Y") -> 1.27 | I27: =IF(G27<=D27,"Met","Exceeded") -> Met | J27: =IF(H27<=C27,"Met","Exceeded") -> Met | K27: =IF(E27>=F27,"Met","Below frequency") -> Below frequency
A28: Jul | B28: Cyanide, total | C28: =Parameters!$B$9 -> 1.2 | D28: =Parameters!$C$9 -> 0.65 | E28: =COUNTIFS('Lab Data'!$C$5:$C$17,"Jul",'Lab Data'!$AA$5:$AA$17,"Y") -> 2 | F28: =Parameters!$B$15 -> 2 | G28: =ROUND(AVERAGEIFS('Lab Data'!$AB$5:$AB$17,'Lab Data'!$C$5:$C$17,"Jul",'Lab Data'!$AA$5:$AA$17,"Y"),3) -> 0.31 | H28: =_xlfn.MAXIFS('Lab Data'!$AB$5:$AB$17,'Lab Data'!$C$5:$C$17,"Jul",'Lab Data'!$AA$5:$AA$17,"Y") -> 0.35 | I28: =IF(G28<=D28,"Met","Exceeded") -> Met | J28: =IF(H28<=C28,"Met","Exceeded") -> Met | K28: =IF(E28>=F28,"Met","Below frequency") -> Met
A29: Aug | B29: Cadmium, total | C29: =Parameters!$B$4 -> 0.11 | D29: =Parameters!$C$4 -> 0.07 | E29: =COUNTIFS('Lab Data'!$C$5:$C$17,"Aug",'Lab Data'!$G$5:$G$17,"Y") -> 2 | F29: =Parameters!$B$15 -> 2 | G29: =ROUND(AVERAGEIFS('Lab Data'!$H$5:$H$17,'Lab Data'!$C$5:$C$17,"Aug",'Lab Data'!$G$5:$G$17,"Y"),3) -> 0.007 | H29: =_xlfn.MAXIFS('Lab Data'!$H$5:$H$17,'Lab Data'!$C$5:$C$17,"Aug",'Lab Data'!$G$5:$G$17,"Y") -> 0.014 | I29: =IF(G29<=D29,"Met","Exceeded") -> Met | J29: =IF(H29<=C29,"Met","Exceeded") -> Met | K29: =IF(E29>=F29,"Met","Below frequency") -> Met
A30: Aug | B30: Chromium, total | C30: =Parameters!$B$5 -> 2.77 | D30: =Parameters!$C$5 -> 1.71 | E30: =COUNTIFS('Lab Data'!$C$5:$C$17,"Aug",'Lab Data'!$K$5:$K$17,"Y") -> 2 | F30: =Parameters!$B$15 -> 2 | G30: =ROUND(AVERAGEIFS('Lab Data'!$L$5:$L$17,'Lab Data'!$C$5:$C$17,"Aug",'Lab Data'!$K$5:$K$17,"Y"),3) -> 0.7 | H30: =_xlfn.MAXIFS('Lab Data'!$L$5:$L$17,'Lab Data'!$C$5:$C$17,"Aug",'Lab Data'!$K$5:$K$17,"Y") -> 0.74 | I30: =IF(G30<=D30,"Met","Exceeded") -> Met | J30: =IF(H30<=C30,"Met","Exceeded") -> Met | K30: =IF(E30>=F30,"Met","Below frequency") -> Met
A31: Aug | B31: Copper, total | C31: =Parameters!$B$6 -> 3.38 | D31: =Parameters!$C$6 -> 2.07 | E31: =COUNTIFS('Lab Data'!$C$5:$C$17,"Aug",'Lab Data'!$O$5:$O$17,"Y") -> 2 | F31: =Parameters!$B$15 -> 2 | G31: =ROUND(AVERAGEIFS('Lab Data'!$P$5:$P$17,'Lab Data'!$C$5:$C$17,"Aug",'Lab Data'!$O$5:$O$17,"Y"),3) -> 4.24 | H31: =_xlfn.MAXIFS('Lab Data'!$P$5:$P$17,'Lab Data'!$C$5:$C$17,"Aug",'Lab Data'!$O$5:$O$17,"Y") -> 4.33 | I31: =IF(G31<=D31,"Met","Exceeded") -> Exceeded | J31: =IF(H31<=C31,"Met","Exceeded") -> Exceeded | K31: =IF(E31>=F31,"Met","Below frequency") -> Met
A32: Aug | B32: Nickel, total | C32: =Parameters!$B$7 -> 3.98 | D32: =Parameters!$C$7 -> 2.38 | E32: =COUNTIFS('Lab Data'!$C$5:$C$17,"Aug",'Lab Data'!$S$5:$S$17,"Y") -> 1 | F32: =Parameters!$B$15 -> 2 | G32: =ROUND(AVERAGEIFS('Lab Data'!$T$5:$T$17,'Lab Data'!$C$5:$C$17,"Aug",'Lab Data'!$S$5:$S$17,"Y"),3) -> 2.61 | H32: =_xlfn.MAXIFS('Lab Data'!$T$5:$T$17,'Lab Data'!$C$5:$C$17,"Aug",'Lab Data'!$S$5:$S$17,"Y") -> 2.61 | I32: =IF(G32<=D32,"Met","Exceeded") -> Exceeded | J32: =IF(H32<=C32,"Met","Exceeded") -> Met | K32: =IF(E32>=F32,"Met","Below frequency") -> Below frequency
A33: Aug | B33: Zinc, total | C33: =Parameters!$B$8 -> 2.61 | D33: =Parameters!$C$8 -> 1.48 | E33: =COUNTIFS('Lab Data'!$C$5:$C$17,"Aug",'Lab Data'!$W$5:$W$17,"Y") -> 2 | F33: =Parameters!$B$15 -> 2 | G33: =ROUND(AVERAGEIFS('Lab Data'!$X$5:$X$17,'Lab Data'!$C$5:$C$17,"Aug",'Lab Data'!$W$5:$W$17,"Y"),3) -> 1.035 | H33: =_xlfn.MAXIFS('Lab Data'!$X$5:$X$17,'Lab Data'!$C$5:$C$17,"Aug",'Lab Data'!$W$5:$W$17,"Y") -> 1.18 | I33: =IF(G33<=D33,"Met","Exceeded") -> Met | J33: =IF(H33<=C33,"Met","Exceeded") -> Met | K33: =IF(E33>=F33,"Met","Below frequency") -> Met
A34: Aug | B34: Cyanide, total | C34: =Parameters!$B$9 -> 1.2 | D34: =Parameters!$C$9 -> 0.65 | E34: =COUNTIFS('Lab Data'!$C$5:$C$17,"Aug",'Lab Data'!$AA$5:$AA$17,"Y") -> 2 | F34: =Parameters!$B$15 -> 2 | G34: =ROUND(AVERAGEIFS('Lab Data'!$AB$5:$AB$17,'Lab Data'!$C$5:$C$17,"Aug",'Lab Data'!$AA$5:$AA$17,"Y"),3) -> 0.24 | H34: =_xlfn.MAXIFS('Lab Data'!$AB$5:$AB$17,'Lab Data'!$C$5:$C$17,"Aug",'Lab Data'!$AA$5:$AA$17,"Y") -> 0.29 | I34: =IF(G34<=D34,"Met","Exceeded") -> Met | J34: =IF(H34<=C34,"Met","Exceeded") -> Met | K34: =IF(E34>=F34,"Met","Below frequency") -> Met
A35: Sep | B35: Cadmium, total | C35: =Parameters!$B$4 -> 0.11 | D35: =Parameters!$C$4 -> 0.07 | E35: =COUNTIFS('Lab Data'!$C$5:$C$17,"Sep",'Lab Data'!$G$5:$G$17,"Y") -> 3 | F35: =Parameters!$B$15 -> 2 | G35: =ROUND(AVERAGEIFS('Lab Data'!$H$5:$H$17,'Lab Data'!$C$5:$C$17,"Sep",'Lab Data'!$G$5:$G$17,"Y"),3) -> 0.004 | H35: =_xlfn.MAXIFS('Lab Data'!$H$5:$H$17,'Lab Data'!$C$5:$C$17,"Sep",'Lab Data'!$G$5:$G$17,"Y") -> 0.012 | I35: =IF(G35<=D35,"Met","Exceeded") -> Met | J35: =IF(H35<=C35,"Met","Exceeded") -> Met | K35: =IF(E35>=F35,"Met","Below frequency") -> Met
A36: Sep | B36: Chromium, total | C36: =Parameters!$B$5 -> 2.77 | D36: =Parameters!$C$5 -> 1.71 | E36: =COUNTIFS('Lab Data'!$C$5:$C$17,"Sep",'Lab Data'!$K$5:$K$17,"Y") -> 3 | F36: =Parameters!$B$15 -> 2 | G36: =ROUND(AVERAGEIFS('Lab Data'!$L$5:$L$17,'Lab Data'!$C$5:$C$17,"Sep",'Lab Data'!$K$5:$K$17,"Y"),3) -> 0.697 | H36: =_xlfn.MAXIFS('Lab Data'!$L$5:$L$17,'Lab Data'!$C$5:$C$17,"Sep",'Lab Data'!$K$5:$K$17,"Y") -> 1.02 | I36: =IF(G36<=D36,"Met","Exceeded") -> Met | J36: =IF(H36<=C36,"Met","Exceeded") -> Met | K36: =IF(E36>=F36,"Met","Below frequency") -> Met
A37: Sep | B37: Copper, total | C37: =Parameters!$B$6 -> 3.38 | D37: =Parameters!$C$6 -> 2.07 | E37: =COUNTIFS('Lab Data'!$C$5:$C$17,"Sep",'Lab Data'!$O$5:$O$17,"Y") -> 3 | F37: =Parameters!$B$15 -> 2 | G37: =ROUND(AVERAGEIFS('Lab Data'!$P$5:$P$17,'Lab Data'!$C$5:$C$17,"Sep",'Lab Data'!$O$5:$O$17,"Y"),3) -> 2.053 | H37: =_xlfn.MAXIFS('Lab Data'!$P$5:$P$17,'Lab Data'!$C$5:$C$17,"Sep",'Lab Data'!$O$5:$O$17,"Y") -> 2.96 | I37: =IF(G37<=D37,"Met","Exceeded") -> Met | J37: =IF(H37<=C37,"Met","Exceeded") -> Met | K37: =IF(E37>=F37,"Met","Below frequency") -> Met
A38: Sep | B38: Nickel, total | C38: =Parameters!$B$7 -> 3.98 | D38: =Parameters!$C$7 -> 2.38 | E38: =COUNTIFS('Lab Data'!$C$5:$C$17,"Sep",'Lab Data'!$S$5:$S$17,"Y") -> 3 | F38: =Parameters!$B$15 -> 2 | G38: =ROUND(AVERAGEIFS('Lab Data'!$T$5:$T$17,'Lab Data'!$C$5:$C$17,"Sep",'Lab Data'!$S$5:$S$17,"Y"),3) -> 1.15 | H38: =_xlfn.MAXIFS('Lab Data'!$T$5:$T$17,'Lab Data'!$C$5:$C$17,"Sep",'Lab Data'!$S$5:$S$17,"Y") -> 1.36 | I38: =IF(G38<=D38,"Met","Exceeded") -> Met | J38: =IF(H38<=C38,"Met","Exceeded") -> Met | K38: =IF(E38>=F38,"Met","Below frequency") -> Met
A39: Sep | B39: Zinc, total | C39: =Parameters!$B$8 -> 2.61 | D39: =Parameters!$C$8 -> 1.48 | E39: =COUNTIFS('Lab Data'!$C$5:$C$17,"Sep",'Lab Data'!$W$5:$W$17,"Y") -> 3 | F39: =Parameters!$B$15 -> 2 | G39: =ROUND(AVERAGEIFS('Lab Data'!$X$5:$X$17,'Lab Data'!$C$5:$C$17,"Sep",'Lab Data'!$W$5:$W$17,"Y"),3) -> 1.653 | H39: =_xlfn.MAXIFS('Lab Data'!$X$5:$X$17,'Lab Data'!$C$5:$C$17,"Sep",'Lab Data'!$W$5:$W$17,"Y") -> 3.14 | I39: =IF(G39<=D39,"Met","Exceeded") -> Exceeded | J39: =IF(H39<=C39,"Met","Exceeded") -> Exceeded | K39: =IF(E39>=F39,"Met","Below frequency") -> Met
A40: Sep | B40: Cyanide, total | C40: =Parameters!$B$9 -> 1.2 | D40: =Parameters!$C$9 -> 0.65 | E40: =COUNTIFS('Lab Data'!$C$5:$C$17,"Sep",'Lab Data'!$AA$5:$AA$17,"Y") -> 2 | F40: =Parameters!$B$15 -> 2 | G40: =ROUND(AVERAGEIFS('Lab Data'!$AB$5:$AB$17,'Lab Data'!$C$5:$C$17,"Sep",'Lab Data'!$AA$5:$AA$17,"Y"),3) -> 0.325 | H40: =_xlfn.MAXIFS('Lab Data'!$AB$5:$AB$17,'Lab Data'!$C$5:$C$17,"Sep",'Lab Data'!$AA$5:$AA$17,"Y") -> 0.41 | I40: =IF(G40<=D40,"Met","Exceeded") -> Met | J40: =IF(H40<=C40,"Met","Exceeded") -> Met | K40: =IF(E40>=F40,"Met","Below frequency") -> Met

Sheet SNC Review
A1: Significant noncompliance evaluation, April 1 through September 30, 2026, Section 3.4 of the permit
A2: Every valid result in the period is a measurement, resamples included. Each measurement is compared with the daily maximum limitation and with the limitation multiplied by the technical review criterion of 1.2.
A4: PARAMETER | B4: MEASUREMENTS | C4: DAILY MAXIMUM LIMIT | D4: TRC MULTIPLIER | E4: TRC THRESHOLD MG/L | F4: ABOVE THE LIMIT | G4: SHARE ABOVE THE LIMIT PCT | H4: ABOVE THE TRC THRESHOLD | I4: SHARE ABOVE THE TRC THRESHOLD PCT | J4: CHRONIC AT 66 PCT | K4: TRC AT 33 PCT | L4: SIGNIFICANT NONCOMPLIANCE | M4: CHRONIC THRESHOLD PCT | N4: TRC THRESHOLD PCT
A5: Cadmium, total | B5: =COUNTIFS('Lab Data'!$G$5:$G$17,"Y") -> 12 | C5: =Parameters!$B$4 -> 0.11 | D5: =Parameters!$B$16 -> 1.2 | E5: =ROUND(C5*D5,3) -> 0.132 | F5: =COUNTIFS('Lab Data'!$H$5:$H$17,">"&C5,'Lab Data'!$G$5:$G$17,"Y") -> 0 | G5: =ROUND(F5/B5*100,1) -> 0 | H5: =COUNTIFS('Lab Data'!$H$5:$H$17,">"&E5,'Lab Data'!$G$5:$G$17,"Y") -> 0 | I5: =ROUND(H5/B5*100,1) -> 0 | J5: =IF(G5>=Parameters!$B$17,"Yes","No") -> No | K5: =IF(I5>=Parameters!$B$18,"Yes","No") -> No | L5: =IF(OR(J5="Yes",K5="Yes"),"Significant noncompliance","Not in significant noncompliance") -> Not in significant noncompliance | M5: =Parameters!$B$17 -> 66 | N5: =Parameters!$B$18 -> 33
A6: Chromium, total | B6: =COUNTIFS('Lab Data'!$K$5:$K$17,"Y") -> 12 | C6: =Parameters!$B$5 -> 2.77 | D6: =Parameters!$B$16 -> 1.2 | E6: =ROUND(C6*D6,3) -> 3.324 | F6: =COUNTIFS('Lab Data'!$L$5:$L$17,">"&C6,'Lab Data'!$K$5:$K$17,"Y") -> 0 | G6: =ROUND(F6/B6*100,1) -> 0 | H6: =COUNTIFS('Lab Data'!$L$5:$L$17,">"&E6,'Lab Data'!$K$5:$K$17,"Y") -> 0 | I6: =ROUND(H6/B6*100,1) -> 0 | J6: =IF(G6>=Parameters!$B$17,"Yes","No") -> No | K6: =IF(I6>=Parameters!$B$18,"Yes","No") -> No | L6: =IF(OR(J6="Yes",K6="Yes"),"Significant noncompliance","Not in significant noncompliance") -> Not in significant noncompliance | M6: =Parameters!$B$17 -> 66 | N6: =Parameters!$B$18 -> 33
A7: Copper, total | B7: =COUNTIFS('Lab Data'!$O$5:$O$17,"Y") -> 12 | C7: =Parameters!$B$6 -> 3.38 | D7: =Parameters!$B$16 -> 1.2 | E7: =ROUND(C7*D7,3) -> 4.056 | F7: =COUNTIFS('Lab Data'!$P$5:$P$17,">"&C7,'Lab Data'!$O$5:$O$17,"Y") -> 6 | G7: =ROUND(F7/B7*100,1) -> 50 | H7: =COUNTIFS('Lab Data'!$P$5:$P$17,">"&E7,'Lab Data'!$O$5:$O$17,"Y") -> 4 | I7: =ROUND(H7/B7*100,1) -> 33.3 | J7: =IF(G7>=Parameters!$B$17,"Yes","No") -> No | K7: =IF(I7>=Parameters!$B$18,"Yes","No") -> Yes | L7: =IF(OR(J7="Yes",K7="Yes"),"Significant noncompliance","Not in significant noncompliance") -> Significant noncompliance | M7: =Parameters!$B$17 -> 66 | N7: =Parameters!$B$18 -> 33
A8: Nickel, total | B8: =COUNTIFS('Lab Data'!$S$5:$S$17,"Y") -> 11 | C8: =Parameters!$B$7 -> 3.98 | D8: =Parameters!$B$16 -> 1.2 | E8: =ROUND(C8*D8,3) -> 4.776 | F8: =COUNTIFS('Lab Data'!$T$5:$T$17,">"&C8,'Lab Data'!$S$5:$S$17,"Y") -> 0 | G8: =ROUND(F8/B8*100,1) -> 0 | H8: =COUNTIFS('Lab Data'!$T$5:$T$17,">"&E8,'Lab Data'!$S$5:$S$17,"Y") -> 0 | I8: =ROUND(H8/B8*100,1) -> 0 | J8: =IF(G8>=Parameters!$B$17,"Yes","No") -> No | K8: =IF(I8>=Parameters!$B$18,"Yes","No") -> No | L8: =IF(OR(J8="Yes",K8="Yes"),"Significant noncompliance","Not in significant noncompliance") -> Not in significant noncompliance | M8: =Parameters!$B$17 -> 66 | N8: =Parameters!$B$18 -> 33
A9: Zinc, total | B9: =COUNTIFS('Lab Data'!$W$5:$W$17,"Y") -> 12 | C9: =Parameters!$B$8 -> 2.61 | D9: =Parameters!$B$16 -> 1.2 | E9: =ROUND(C9*D9,3) -> 3.132 | F9: =COUNTIFS('Lab Data'!$X$5:$X$17,">"&C9,'Lab Data'!$W$5:$W$17,"Y") -> 1 | G9: =ROUND(F9/B9*100,1) -> 8.3 | H9: =COUNTIFS('Lab Data'!$X$5:$X$17,">"&E9,'Lab Data'!$W$5:$W$17,"Y") -> 1 | I9: =ROUND(H9/B9*100,1) -> 8.3 | J9: =IF(G9>=Parameters!$B$17,"Yes","No") -> No | K9: =IF(I9>=Parameters!$B$18,"Yes","No") -> No | L9: =IF(OR(J9="Yes",K9="Yes"),"Significant noncompliance","Not in significant noncompliance") -> Not in significant noncompliance | M9: =Parameters!$B$17 -> 66 | N9: =Parameters!$B$18 -> 33
A10: Cyanide, total | B10: =COUNTIFS('Lab Data'!$AA$5:$AA$17,"Y") -> 12 | C10: =Parameters!$B$9 -> 1.2 | D10: =Parameters!$B$16 -> 1.2 | E10: =ROUND(C10*D10,3) -> 1.44 | F10: =COUNTIFS('Lab Data'!$AB$5:$AB$17,">"&C10,'Lab Data'!$AA$5:$AA$17,"Y") -> 0 | G10: =ROUND(F10/B10*100,1) -> 0 | H10: =COUNTIFS('Lab Data'!$AB$5:$AB$17,">"&E10,'Lab Data'!$AA$5:$AA$17,"Y") -> 0 | I10: =ROUND(H10/B10*100,1) -> 0 | J10: =IF(G10>=Parameters!$B$17,"Yes","No") -> No | K10: =IF(I10>=Parameters!$B$18,"Yes","No") -> No | L10: =IF(OR(J10="Yes",K10="Yes"),"Significant noncompliance","Not in significant noncompliance") -> Not in significant noncompliance | M10: =Parameters!$B$17 -> 66 | N10: =Parameters!$B$18 -> 33
A12: A parameter in significant noncompliance is published in the City's annual notice and goes to the enforcement response plan (Section 3.4). Copper is the one parameter over the technical review criterion threshold, and only because the July 7 sample's metals are not valid measurements.
A14: REPORT DUE IN THE PERIOD | B14: DUE | C14: RECEIVED | D14: 45-DAY ARM OF SECTION 3.4
A15: Second quarter self-monitoring report (Section 3.1) | B15: 07/15/2026 | C15: 07/14/2026 | D15: Not late
A16: The received date is the Pretreatment Coordinator's, from her note of September 30, 2026.

Sheet Flow Sep
A1: Daily flow, September 2026, gallons, worked from the totalizer register readings in the operator log
A2: The log carries the register at 07:00 the following morning; a day's flow is that reading less the one before it. The month's total is the end register less the start register.
A3: DATE | B3: REGISTER AT 07:00 NEXT DAY, GAL | C3: DAILY FLOW, GAL | D3: ABOVE LIMIT
A4: Register at 07:00 on 09/01/2026 | B4: 6418255
A5: 09/01/2026 | B5: 6450959 | C5: =B5-B4 -> 32704 | D5: =IF(C5>Parameters!$B$12,"Yes","No") -> No
A6: 09/02/2026 | B6: 6491552 | C6: =B6-B5 -> 40593 | D6: =IF(C6>Parameters!$B$12,"Yes","No") -> No
A7: 09/03/2026 | B7: 6523848 | C7: =B7-B6 -> 32296 | D7: =IF(C7>Parameters!$B$12,"Yes","No") -> No
A8: 09/04/2026 | B8: 6561503 | C8: =B8-B7 -> 37655 | D8: =IF(C8>Parameters!$B$12,"Yes","No") -> No
A9: 09/05/2026 | B9: 6565112 | C9: =B9-B8 -> 3609 | D9: =IF(C9>Parameters!$B$12,"Yes","No") -> No
A10: 09/06/2026 | B10: 6567087 | C10: =B10-B9 -> 1975 | D10: =IF(C10>Parameters!$B$12,"Yes","No") -> No
A11: 09/07/2026 | B11: 6567087 | C11: =B11-B10 -> 0 | D11: =IF(C11>Parameters!$B$12,"Yes","No") -> No
A12: 09/08/2026 | B12: 6601769 | C12: =B12-B11 -> 34682 | D12: =IF(C12>Parameters!$B$12,"Yes","No") -> No
A13: 09/09/2026 | B13: 6649069 | C13: =B13-B12 -> 47300 | D13: =IF(C13>Parameters!$B$12,"Yes","No") -> Yes
A14: 09/10/2026 | B14: 6680799 | C14: =B14-B13 -> 31730 | D14: =IF(C14>Parameters!$B$12,"Yes","No") -> No
A15: 09/11/2026 | B15: 6709642 | C15: =B15-B14 -> 28843 | D15: =IF(C15>Parameters!$B$12,"Yes","No") -> No
A16: 09/12/2026 | B16: 6712444 | C16: =B16-B15 -> 2802 | D16: =IF(C16>Parameters!$B$12,"Yes","No") -> No
... A34: 09/30/2026 | B34: 7173975 | C34: =B34-B33 -> 34491 | D34: =IF(C34>Parameters!$B$12,"Yes","No") -> No
A36: Highest daily flow in September | B36: =MAX(C5:C34) -> 47300
A37: Days above the daily flow limit | B37: =COUNTIF(D5:D34,"Yes") -> 1
A38: Total for the month, the end register less the start register | B38: =B34-B4 -> 755720
A39: Sum of the daily flows, which ties to the register total | B39: =SUM(C5:C34) -> 755720

Sheet Notifications
A1: Notifications and resampling the quarter required, with the dates due and the dates done
A3: EVENT | B3: PERMIT SECTION | C3: EVENT OR AWARENESS DATE | D3: REQUIREMENT | E3: DUE | F3: DONE | G3: STATUS
A4: Rinse tank RT-4 overflow, a bypass of the pretreatment system, 09/09/2026 at 07:50 | B4: Section 3.2 and Section 4.1 | C4: 09/09/2026 07:50 | D4: Telephone notice within 24 hours | E4: 09/10/2026 07:50 | F4: 09/10/2026 16:30 | G4: Late
A5: Rinse tank RT-4 overflow, written report | B5: Section 3.2 | C5: 09/09/2026 | D5: Written report within 5 days | E5: 09/14/2026 | F5: 09/14/2026 | G5: Met
A6: In-line pH excursion of 09/17/2026, 14:10 to 14:55, called in as a discharge under Section 3.2 | B6: Section 3.2 | C6: 09/17/2026 14:10 | D6: Telephone notice within 24 hours | E6: 09/18/2026 14:10 | F6: 09/17/2026 15:20 | G6: Met
A7: In-line pH excursion of 09/17/2026, written report | B7: Section 3.2 | C7: 09/17/2026 | D7: Written report within 5 days | E7: 09/22/2026 | F7: 09/21/2026 | G7: Met
A8: Zinc daily maximum exceedance, sample VP-260909, 3.14 mg/L | B8: Section 3.3 | C8: 09/15/2026 (lab report) | D8: Resample within 30 days | E8: 10/15/2026 | F8: 09/22/2026 and 09/23/2026 | G8: Met
